Workbook
Name TM1REBUILDOPTION: 1

Sheet Passengers
A1: Projected pax by Cabin 2025
A2: Flight | B2: Route | C2: DEP | D2: ARR | E2: Cabin | F2: Jan2025 | G2: Feb2025 | H2: Mar2025 | I2: Apr2025 | J2: May2025 | K2: Jun2025 | L2: Jul2025 | M2: Aug2025 | N2: Sep2025 | O2: Oct2025 | P2: Nov2025 | Q2: Dec2025
A3: V104 - ATL - LHR | B3: ATLLHR | C3: ATL | D3: LHR | E3: J | F3: 832.78754 | G3: 737.19232 | H3: 937.39783 | I3: 945.17733 | J3: 1000.2494 | K3: 960.20952 | L3: 1006.2552 | M3: 919.08634 | N3: 908.33342 | O3: 923.9775 | P3: 974.0373 | Q3: 977.92373
A4: V116 - ATL - LHR | B4: ATLLHR | C4: ATL | D4: LHR | E4: J | F4: 0 | G4: 0 | H4: 60.47728 | I4: 945.17733 | J4: 1000.2494 | K4: 960.20952 | L4: 1006.2552 | M4: 919.08634 | N4: 908.33342 | O4: 745.14315 | P4: 0 | Q4: 0
A5: V104 - ATL - LHR | B5: ATLLHR | C5: ATL | D5: LHR | E5: W | F5: 1140.0172 | G5: 983.77845 | H5: 1301.4717 | I5: 1275.3856 | J5: 1353.6765 | K5: 1341.2869 | L5: 1318.6175 | M5: 1216.4812 | N5: 1268.3554 | O5: 1202.1893 | P5: 1231.594 | Q5: 1327.2829
A6: V116 - ATL - LHR | B6: ATLLHR | C6: ATL | D6: LHR | E6: W | F6: 0 | G6: 0 | H6: 83.965916 | I6: 1275.3856 | J6: 1353.6765 | K6: 1341.2869 | L6: 1318.6175 | M6: 1216.4812 | N6: 1268.3554 | O6: 969.50749 | P6: 0 | Q6: 0
A7: V104 - ATL - LHR | B7: ATLLHR | C7: ATL | D7: LHR | E7: Y | F7: 3345.1601 | G7: 2264.4854 | H7: 4224.9048 | I7: 3944.1261 | J7: 4771.1531 | K7: 5174.8821 | L7: 5052.9533 | M7: 4231.9332 | N7: 3966.6076 | O7: 3706.4534 | P7: 3803.525 | Q7: 4817.0926
A8: V116 - ATL - LHR | B8: ATLLHR | C8: ATL | D8: LHR | E8: Y | F8: 0 | G8: 0 | H8: 272.5745 | I8: 3944.1261 | J8: 4771.1531 | K8: 5174.8821 | L8: 5052.9533 | M8: 4231.9332 | N8: 3966.6076 | O8: 2989.0753 | P8: 0 | Q8: 0
A9: V110 - ATL - MAN | B9: ATLMAN | C9: ATL | D9: MAN | E9: J | F9: 473.87707 | G9: 420.81939 | H9: 629.62447 | I9: 952.94063 | J9: 765.71585 | K9: 893.33134 | L9: 943.67569 | M9: 843.39065 | N9: 875.91771 | O9: 897.92986 | P9: 592.35597 | Q9: 546.90006
A10: V110 - ATL - MAN | B10: ATLMAN | C10: ATL | D10: MAN | E10: W | F10: 845.30884 | G10: 717.57816 | H10: 974.42529 | I10: 1318.1254 | J10: 1332.9547 | K10: 1334.727 | L10: 1381.5161 | M10: 1338.4031 | N10: 1318.9757 | O10: 1278.4899 | P10: 879.19565 | Q10: 875.82245
A11: V110 - ATL - MAN | B11: ATLMAN | C11: ATL | D11: MAN | E11: Y | F11: 2904.762 | G11: 2198.2484 | H11: 3299.9577 | I11: 5526.887 | J11: 5261.0186 | K11: 5342.992 | L11: 5532.8046 | M11: 5171.7676 | N11: 4949.9374 | O11: 4719.0522 | P11: 3238.2669 | Q11: 3279.6985
A12: V012 - BOS - LHR | B12: BOSLHR | C12: BOS | D12: LHR | E12: J | F12: 793.65398 | G12: 669.24836 | H12: 884.44262 | I12: 826.67927 | J12: 992.48942 | K12: 981.07535 | L12: 991.70695 | M12: 854.79912 | N12: 948.24481 | O12: 1003.464 | P12: 929.09351 | Q12: 864.61355
A13: V158 - BOS - LHR | B13: BOSLHR | C13: BOS | D13: LHR | E13: J | F13: 0 | G13: 0 | H13: 56.857026 | I13: 825.81091 | J13: 994.51078 | K13: 980.04481 | L13: 991.70695 | M13: 854.79912 | N13: 948.24481 | O13: 804.67447 | P13: 0 | Q13: 0
A14: V012 - BOS - LHR | B14: BOSLHR | C14: BOS | D14: LHR | E14: W | F14: 894.37185 | G14: 671.8366 | H14: 1060.9672 | I14: 951.27723 | J14: 1185.9524 | K14: 1088.8914 | L14: 1198.1298 | M14: 1357.178 | N14: 1194.6961 | O14: 1337.3516 | P14: 1198.4426 | Q14: 1283.947
... A92: V130 - TPA - LHR | B92: TPALHR | C92: TPA | D92: LHR | E92: Y | F92: 4276.0396 | G92: 3807.2533 | H92: 4738.8308 | I92: 3645.5794 | J92: 4767.9874 | K92: 4722.1995 | L92: 4746.1836 | M92: 5177.5789 | N92: 3352.607 | O92: 4499.0122 | P92: 4444.4114 | Q92: 4652.7921

Sheet Sectors
A1: Projected sectors by A/C type 2025
A2: Flight | B2: Route | C2: DEP | D2: ARR | E2: A/C Type | F2: Jan2025 | G2: Feb2025 | H2: Mar2025 | I2: Apr2025 | J2: May2025 | K2: Jun2025 | L2: Jul2025 | M2: Aug2025 | N2: Sep2025 | O2: Oct2025 | P2: Nov2025 | Q2: Dec2025
A3: V104 - ATL - LHR | B3: ATLLHR | C3: ATL | D3: LHR | E3: A333 | F3: 0 | G3: 0 | H3: 0 | I3: 0 | J3: 0 | K3: 0 | L3: 0 | M3: 0 | N3: 0 | O3: 0 | P3: 0 | Q3: 0
A4: V110 - ATL - MAN | B4: ATLMAN | C4: ATL | D4: MAN | E4: A333 | F4: 23 | G4: 20 | H4: 23 | I4: 30 | J4: 31 | K4: 30 | L4: 31 | M4: 31 | N4: 30 | O4: 29 | P4: 21 | Q4: 21
A5: V116 - ATL - LHR | B5: ATLLHR | C5: ATL | D5: LHR | E5: A333 | F5: 0 | G5: 0 | H5: 0 | I5: 0 | J5: 0 | K5: 0 | L5: 0 | M5: 0 | N5: 0 | O5: 0 | P5: 0 | Q5: 0
A6: V104 - ATL - LHR | B6: ATLLHR | C6: ATL | D6: LHR | E6: A339 | F6: 31 | G6: 28 | H6: 31 | I6: 30 | J6: 31 | K6: 30 | L6: 31 | M6: 31 | N6: 30 | O6: 31 | P6: 30 | Q6: 31
A7: V110 - ATL - MAN | B7: ATLMAN | C7: ATL | D7: MAN | E7: A339 | F7: 0 | G7: 0 | H7: 0 | I7: 0 | J7: 0 | K7: 0 | L7: 0 | M7: 0 | N7: 0 | O7: 0 | P7: 0 | Q7: 0
A8: V116 - ATL - LHR | B8: ATLLHR | C8: ATL | D8: LHR | E8: A339 | F8: 0 | G8: 0 | H8: 2 | I8: 30 | J8: 31 | K8: 30 | L8: 31 | M8: 31 | N8: 30 | O8: 25 | P8: 0 | Q8: 0
A9: V104 - ATL - LHR | B9: ATLLHR | C9: ATL | D9: LHR | E9: A351B | F9: 0 | G9: 0 | H9: 0 | I9: 0 | J9: 0 | K9: 0 | L9: 0 | M9: 0 | N9: 0 | O9: 0 | P9: 0 | Q9: 0
A10: V110 - ATL - MAN | B10: ATLMAN | C10: ATL | D10: MAN | E10: A351B | F10: 0 | G10: 0 | H10: 0 | I10: 0 | J10: 0 | K10: 0 | L10: 0 | M10: 0 | N10: 0 | O10: 0 | P10: 0 | Q10: 0
A11: V116 - ATL - LHR | B11: ATLLHR | C11: ATL | D11: LHR | E11: A351B | F11: 0 | G11: 0 | H11: 0 | I11: 0 | J11: 0 | K11: 0 | L11: 0 | M11: 0 | N11: 0 | O11: 0 | P11: 0 | Q11: 0
A12: V104 - ATL - LHR | B12: ATLLHR | C12: ATL | D12: LHR | E12: A351A | F12: 0 | G12: 0 | H12: 0 | I12: 0 | J12: 0 | K12: 0 | L12: 0 | M12: 0 | N12: 0 | O12: 0 | P12: 0 | Q12: 0
A13: V110 - ATL - MAN | B13: ATLMAN | C13: ATL | D13: MAN | E13: A351A | F13: 0 | G13: 0 | H13: 0 | I13: 0 | J13: 0 | K13: 0 | L13: 0 | M13: 0 | N13: 0 | O13: 0 | P13: 0 | Q13: 0
A14: V116 - ATL - LHR | B14: ATLLHR | C14: ATL | D14: LHR | E14: A351A | F14: 0 | G14: 0 | H14: 0 | I14: 0 | J14: 0 | K14: 0 | L14: 0 | M14: 0 | N14: 0 | O14: 0 | P14: 0 | Q14: 0
... A152: V130 - TPA - LHR | B152: TPALHR | C152: TPA | D152: LHR | E152: B789 | F152: 0 | G152: 0 | H152: 0 | I152: 0 | J152: 0 | K152: 0 | L152: 0 | M152: 0 | N152: 0 | O152: 0 | P152: 0 | Q152: 0

Sheet Load Factor
A1: Projected load factors by Cabin 2025
A2: Flight | B2: Route | C2: DEP | D2: ARR | E2: Cabin | F2: Jan2025 | G2: Feb2025 | H2: Mar2025 | I2: Apr2025 | J2: May2025 | K2: Jun2025 | L2: Jul2025 | M2: Aug2025 | N2: Sep2025 | O2: Oct2025 | P2: Nov2025 | Q2: Dec2025
A3: V104 - ATL - LHR | B3: ATLLHR | C3: ATL | D3: LHR | E3: J | F3: 0.78695698 | G3: 0.77893989 | H3: 0.89692482 | I3: 0.91134335 | J3: 0.95381147 | K3: 0.95381147 | L3: 0.95532328 | M3: 0.85768698 | N3: 0.88237772 | O3: 0.86692953 | P3: 0.94778613 | Q3: 0.91674877 | R3: =AVERAGE(F3:Q3) -> 0.8923867
A4: V110 - ATL - MAN | B4: ATLMAN | C4: ATL | D4: MAN | E4: J | F4: 0.62302376 | G4: 0.64259183 | H4: 0.8381772 | I4: 0.94846839 | J4: 0.75372024 | K4: 0.91600403 | L4: 0.92481164 | M4: 0.81243678 | N4: 0.87833629 | O4: 0.92964426 | P4: 0.84997818 | Q4: 0.78123917 | R4: =AVERAGE(F4:Q4) -> 0.82486931
A5: V116 - ATL - LHR | B5: ATLLHR | C5: ATL | D5: LHR | E5: J | F5: - | G5: - | H5: 0.89692482 | I5: 0.91134335 | J5: 0.95381147 | K5: 0.95381147 | L5: 0.95532328 | M5: 0.85768698 | N5: 0.88237772 | O5: 0.86692953 | P5: - | Q5: - | R5: =AVERAGE(F5:Q5) -> 0.90977608
A6: V104 - ATL - LHR | B6: ATLLHR | C6: ATL | D6: LHR | E6: W | F6: 0.78236944 | G6: 0.74434933 | H6: 0.88935981 | I6: 0.89009117 | J6: 0.92346845 | K6: 0.94672688 | L6: 0.89858209 | M6: 0.81824888 | N6: 0.88514679 | O6: 0.81104114 | P6: 0.86027879 | Q6: 0.89500768 | R6: =AVERAGE(F6:Q6) -> 0.86205587
A7: V110 - ATL - MAN | B7: ATLMAN | C7: ATL | D7: MAN | E7: W | F7: 0.74931832 | G7: 0.72843925 | H7: 0.86008579 | I7: 0.88158935 | J7: 0.8714434 | K7: 0.90284261 | L7: 0.9022179 | M7: 0.86274724 | N7: 0.88212014 | O7: 0.88358356 | P7: 0.84076713 | Q7: 0.83548437 | R7: =AVERAGE(F7:Q7) -> 0.85005325
A8: V116 - ATL - LHR | B8: ATLLHR | C8: ATL | D8: LHR | E8: W | F8: - | G8: - | H8: 0.88935981 | I8: 0.89009117 | J8: 0.92346845 | K8: 0.94672688 | L8: 0.89858209 | M8: 0.81824888 | N8: 0.88514679 | O8: 0.81104114 | P8: - | Q8: - | R8: =AVERAGE(F8:Q8) -> 0.88283315
A9: V104 - ATL - LHR | B9: ATLLHR | C9: ATL | D9: LHR | E9: Y | F9: 0.58210797 | G9: 0.43339845 | H9: 0.73100307 | I9: 0.71070107 | J9: 0.83169546 | K9: 0.93098848 | L9: 0.88118356 | M9: 0.7389566 | N9: 0.71599719 | O9: 0.64738836 | P9: 0.68662106 | Q9: 0.84133921 | R9: =AVERAGE(F9:Q9) -> 0.72761504
A10: V110 - ATL - MAN | B10: ATLMAN | C10: ATL | D10: MAN | E10: Y | F10: 0.67760585 | G10: 0.58582611 | H10: 0.76540378 | I10: 0.99051911 | J10: 0.91213036 | K10: 0.95603648 | L10: 0.95964926 | M10: 0.89818381 | N10: 0.88866461 | O10: 0.87633652 | P10: 0.83059928 | Q10: 0.84102431 | R10: =AVERAGE(F10:Q10) -> 0.84849829
A11: V116 - ATL - LHR | B11: ATLLHR | C11: ATL | D11: LHR | E11: Y | F11: - | G11: - | H11: 0.73100307 | I11: 0.71070107 | J11: 0.83169546 | K11: 0.93098848 | L11: 0.88118356 | M11: 0.7389566 | N11: 0.71599719 | O11: 0.64738836 | P11: - | Q11: - | R11: =AVERAGE(F11:Q11) -> 0.77348922
A12: V012 - BOS - LHR | B12: BOSLHR | C12: BOS | D12: LHR | E12: J | F12: 0.75993589 | G12: 0.71674752 | H12: 0.85661832 | I12: 0.80378531 | J12: 0.95604939 | K12: 0.98272766 | L12: 0.95013156 | M12: 0.80499786 | N12: 0.92888938 | O12: 0.98416889 | P12: 0.91646407 | Q12: 0.84904182
A13: V158 - BOS - LHR | B13: BOSLHR | C13: BOS | D13: LHR | E13: J | F13: - | G13: - | H13: 0.85661832 | I13: 0.80378531 | J13: 0.95604939 | K13: 0.98272766 | L13: 0.95013156 | M13: 0.80499786 | N13: 0.92888938 | O13: 0.98416889 | P13: - | Q13: -
A14: V012 - BOS - LHR | B14: BOSLHR | C14: BOS | D14: LHR | E14: W | F14: 0.6027976 | G14: 0.49902831 | H14: 0.71301104 | I14: 0.65628695 | J14: 0.79785814 | K14: 0.75976845 | L14: 0.80629713 | M14: 0.90150714 | N14: 0.82418642 | O14: 0.91767129 | P14: 0.82164202 | Q14: 0.87810121
A15: V158 - BOS - LHR | B15: BOSLHR | C15: BOS | D15: LHR | E15: W | F15: - | G15: - | H15: 0.71301104 | I15: 0.65628695 | J15: 0.79785814 | K15: 0.75976845 | L15: 0.80629713 | M15: 0.90150714 | N15: 0.82418642 | O15: 0.91767129 | P15: - | Q15: -
A16: V012 - BOS - LHR | B16: BOSLHR | C16: BOS | D16: LHR | E16: Y | F16: 0.5432402 | G16: 0.42677812 | H16: 0.63372412 | I16: 0.78826368 | J16: 0.87307211 | K16: 0.89938473 | L16: 0.96314711 | M16: 0.95927587 | N16: 0.7882793 | O16: 0.72190692 | P16: 0.6907343 | Q16: 0.83780865
A17: V158 - BOS - LHR | B17: BOSLHR | C17: BOS | D17: LHR | E17: Y | F17: - | G17: - | H17: 0.63372412 | I17: 0.78826368 | J17: 0.87307211 | K17: 0.89938473 | L17: 0.96314711 | M17: 0.95927587 | N17: 0.7882793 | O17: 0.72190692 | P17: - | Q17: -
A18: V022 - IAD - LHR | B18: IADLHR | C18: IAD | D18: LHR | E18: J | F18: 0.4378238 | G18: 0.45600507 | H18: 0.68052898 | I18: 0.82072668 | J18: 0.95584854 | K18: 0.95654814 | L18: 0.89440383 | M18: 0.79654001 | N18: 0.81935023 | O18: 0.82938799 | P18: 0.75699945 | Q18: 0.71481283
A19: V022 - IAD - LHR | B19: IADLHR | C19: IAD | D19: LHR | E19: W | F19: 0.61659649 | G19: 0.56073728 | H19: 0.81083479 | I19: 0.92738006 | J19: 0.88889818 | K19: 0.9226953 | L19: 0.9184718 | M19: 0.79778914 | N19: 0.79154887 | O19: 0.78557457 | P19: 0.80284958 | Q19: 0.79164814
A20: V022 - IAD - LHR | B20: IADLHR | C20: IAD | D20: LHR | E20: Y | F20: 0.49003109 | G20: 0.3959144 | H20: 0.65984162 | I20: 0.78122031 | J20: 0.84903444 | K20: 0.95341981 | L20: 0.96297767 | M20: 0.86254551 | N20: 0.66503784 | O20: 0.72586609 | P20: 0.59355593 | Q20: 0.84266975
A21: V004 - JFK - LHR | B21: JFKLHR | C21: JFK | D21: LHR | E21: J | F21: 0.85778859 | G21: 0.88977506 | H21: 0.98133965 | I21: 0.92030365 | J21: 0.95105361 | K21: 0.98563669 | L21: 0.95684097 | M21: 0.90858227 | N21: 0.88949415 | O21: 0.93346936 | P21: 0.94903166 | Q21: 0.87997398
A22: V010 - JFK - LHR | B22: JFKLHR | C22: JFK | D22: LHR | E22: J | F22: 0.85778859 | G22: 0.88977506 | H22: 0.98133965 | I22: 0.92030365 | J22: 0.95105361 | K22: 0.98563669 | L22: 0.95684097 | M22: 0.90858227 | N22: 0.88949415 | O22: 0.93346936 | P22: 0.94903166 | Q22: 0.87997398
A23: V026 - JFK - LHR | B23: JFKLHR | C23: JFK | D23: LHR | E23: J | F23: 0.85778859 | G23: 0.88977506 | H23: 0.98133965 | I23: 0.92030365 | J23: 0.95105361 | K23: 0.98563669 | L23: 0.95684097 | M23: 0.90858227 | N23: 0.88949415 | O23: 0.93346936 | P23: 0.94903166 | Q23: 0.87997398
A24: V046 - JFK - LHR | B24: JFKLHR | C24: JFK | D24: LHR | E24: J | F24: 0.85778859 | G24: 0.88977506 | H24: 0.98133965 | I24: 0.92030365 | J24: 0.95105361 | K24: 0.98563669 | L24: 0.95684097 | M24: 0.90858227 | N24: 0.88949415 | O24: 0.93346936 | P24: 0.94903166 | Q24: 0.87997398
A25: V048 - JFK - LHR | B25: JFKLHR | C25: JFK | D25: LHR | E25: J | F25: - | G25: - | H25: 0.98133965 | I25: 0.92030365 | J25: 0.95105361 | K25: 0.98563669 | L25: 0.95684097 | M25: 0.90858227 | N25: 0.88949415 | O25: 0.93346936 | P25: - | Q25: -
A26: V128 - JFK - MAN | B26: JFKMAN | C26: JFK | D26: MAN | E26: J | F26: 0.79633593 | G26: 0.81921436 | H26: 0.86675029 | I26: 0.97798845 | J26: 0.99051911 | K26: 0.94728285 | L26: 0.96434878 | M26: 0.83745564 | N26: 0.85745113 | O26: 0.94754226 | P26: 0.97616979 | Q26: 0.96729518
A27: V138 - JFK - LHR | B27: JFKLHR | C27: JFK | D27: LHR | E27: J | F27: 0.85778859 | G27: 0.88977506 | H27: 0.98133965 | I27: 0.92030365 | J27: 0.95105361 | K27: 0.98563669 | L27: 0.95684097 | M27: 0.90858227 | N27: 0.88949415 | O27: 0.93346936 | P27: 0.94903166 | Q27: 0.87997398
A28: V154 - JFK - LHR | B28: JFKLHR | C28: JFK | D28: LHR | E28: J | F28: 0.85778859 | G28: 0.88977506 | H28: 0.98133965 | I28: 0.92030365 | J28: 0.95105361 | K28: 0.98563669 | L28: 0.95684097 | M28: 0.90858227 | N28: 0.88949415 | O28: 0.93346936 | P28: 0.94903166 | Q28: 0.87997398
A29: V004 - JFK - LHR | B29: JFKLHR | C29: JFK | D29: LHR | E29: W | F29: 0.77537271 | G29: 0.75933626 | H29: 0.87172757 | I29: 0.84097886 | J29: 0.86225009 | K29: 0.88928941 | L29: 0.87619548 | M29: 0.79239224 | N29: 0.80188718 | O29: 0.83718449 | P29: 0.87320328 | Q29: 0.8768632
A30: V010 - JFK - LHR | B30: JFKLHR | C30: JFK | D30: LHR | E30: W | F30: 0.77537271 | G30: 0.75933626 | H30: 0.87172757 | I30: 0.84097886 | J30: 0.86225009 | K30: 0.88928941 | L30: 0.87619548 | M30: 0.79239224 | N30: 0.80188718 | O30: 0.83718449 | P30: 0.87320328 | Q30: 0.8768632
A31: V026 - JFK - LHR | B31: JFKLHR | C31: JFK | D31: LHR | E31: W | F31: 0.77537271 | G31: 0.75933626 | H31: 0.87172757 | I31: 0.84097886 | J31: 0.86225009 | K31: 0.88928941 | L31: 0.87619548 | M31: 0.79239224 | N31: 0.80188718 | O31: 0.83718449 | P31: 0.87320328 | Q31: 0.8768632
A32: V046 - JFK - LHR | B32: JFKLHR | C32: JFK | D32: LHR | E32: W | F32: 0.77537271 | G32: 0.75933626 | H32: 0.87172757 | I32: 0.84097886 | J32: 0.86225009 | K32: 0.88928941 | L32: 0.87619548 | M32: 0.79239224 | N32: 0.80188718 | O32: 0.83718449 | P32: 0.87320328 | Q32: 0.8768632
A33: V048 - JFK - LHR | B33: JFKLHR | C33: JFK | D33: LHR | E33: W | F33: - | G33: - | H33: 0.87172757 | I33: 0.84097886 | J33: 0.86225009 | K33: 0.88928941 | L33: 0.87619548 | M33: 0.79239224 | N33: 0.80188718 | O33: 0.83718449 | P33: - | Q33: -
A34: V128 - JFK - MAN | B34: JFKMAN | C34: JFK | D34: MAN | E34: W | F34: 0.90984371 | G34: 0.96649991 | H34: 0.93537789 | I34: 0.95679787 | J34: 0.98809399 | K34: 0.90164482 | L34: 0.93220118 | M34: 0.90398652 | N34: 0.91429702 | O34: 0.87750375 | P34: 0.97463614 | Q34: 0.94883817
A35: V138 - JFK - LHR | B35: JFKLHR | C35: JFK | D35: LHR | E35: W | F35: 0.77537271 | G35: 0.75933626 | H35: 0.87172757 | I35: 0.84097886 | J35: 0.86225009 | K35: 0.88928941 | L35: 0.87619548 | M35: 0.79239224 | N35: 0.80188718 | O35: 0.83718449 | P35: 0.87320328 | Q35: 0.8768632
A36: V154 - JFK - LHR | B36: JFKLHR | C36: JFK | D36: LHR | E36: W | F36: 0.77537271 | G36: 0.75933626 | H36: 0.87172757 | I36: 0.84097886 | J36: 0.86225009 | K36: 0.88928941 | L36: 0.87619548 | M36: 0.79239224 | N36: 0.80188718 | O36: 0.83718449 | P36: 0.87320328 | Q36: 0.8768632
A37: V004 - JFK - LHR | B37: JFKLHR | C37: JFK | D37: LHR | E37: Y | F37: 0.66766432 | G37: 0.71640457 | H37: 0.72761382 | I37: 0.81731421 | J37: 0.79225017 | K37: 0.87333613 | L37: 0.91269345 | M37: 0.97764387 | N37: 0.6898842 | O37: 0.76526925 | P37: 0.71617347 | Q37: 0.83889065
A38: V010 - JFK - LHR | B38: JFKLHR | C38: JFK | D38: LHR | E38: Y | F38: 0.66766432 | G38: 0.71640457 | H38: 0.72761382 | I38: 0.81731421 | J38: 0.79225017 | K38: 0.87333613 | L38: 0.91269345 | M38: 0.97764387 | N38: 0.6898842 | O38: 0.76526925 | P38: 0.71617347 | Q38: 0.83889065
A39: V026 - JFK - LHR | B39: JFKLHR | C39: JFK | D39: LHR | E39: Y | F39: 0.66766432 | G39: 0.71640457 | H39: 0.72761382 | I39: 0.81731421 | J39: 0.79225017 | K39: 0.87333613 | L39: 0.91269345 | M39: 0.97764387 | N39: 0.6898842 | O39: 0.76526925 | P39: 0.71617347 | Q39: 0.83889065
A40: V046 - JFK - LHR | B40: JFKLHR | C40: JFK | D40: LHR | E40: Y | F40: 0.66766432 | G40: 0.71640457 | H40: 0.72761382 | I40: 0.81731421 | J40: 0.79225017 | K40: 0.87333613 | L40: 0.91269345 | M40: 0.97764387 | N40: 0.6898842 | O40: 0.76526925 | P40: 0.71617347 | Q40: 0.83889065
...

Sheet Deps
A1: VAA US departures S25 flying- all times in LOCAL. Confidential.
A2: Flt Nbr | B2: Eff Date | C2: Dis Date | D2: Freq | E2: Dep | F2: DepT | G2: Arr | H2: ArrT | I2: Blk Time | J2: Subfleet | K2: Svc Type
A3: 104 | B3: 45746 | C3: 45954 | D3: 1234567 | E3: ATL | F3: 0.8125 | G3: LHR | H3: 0.35416667 | I3: 0.33333333 | J3: 351A | K3: J
A4: 104 | B4: 45955 | C4: 45955 | D4: .....6. | E4: ATL | F4: 0.8125 | G4: LHR | H4: 0.3125 | I4: 0.33333333 | J4: 351A | K4: J
A5: 110 | B5: 45955 | C5: 45955 | D5: .....6. | E5: ATL | F5: 0.83263889 | G5: MAN | H5: 0.33680556 | I5: 0.3375 | J5: 333C | K5: J
A6: 110 | B6: 45746 | C6: 45954 | D6: 1234567 | E6: ATL | F6: 0.83263889 | G6: MAN | H6: 0.37847222 | I6: 0.3375 | J6: 333C | K6: J
A7: 12 | B7: 45955 | C7: 45955 | D7: .....6. | E7: BOS | F7: 0.92361111 | G7: LHR | H7: 0.36111111 | I7: 0.27083333 | J7: 789C | K7: J
A8: 12 | B8: 45746 | C8: 45954 | D8: 1234567 | E8: BOS | F8: 0.92361111 | G8: LHR | H8: 0.40277778 | I8: 0.27083333 | J8: 789C | K8: J
A9: 158 | B9: 45748 | C9: 45951 | D9: .2..... | E9: BOS | F9: 0.86458333 | G9: LHR | H9: 0.35763889 | I9: 0.28472222 | J9: 333C | K9: J
A10: 158 | B10: 45746 | C10: 45954 | D10: 1.34567 | E10: BOS | F10: 0.86458333 | G10: LHR | H10: 0.35763889 | I10: 0.28472222 | J10: 339A | K10: J
A11: 158 | B11: 45955 | C11: 45955 | D11: .....6. | E11: BOS | F11: 0.86458333 | G11: LHR | H11: 0.31597222 | I11: 0.28472222 | J11: 339A | K11: J
A12: 22 | B12: 45746 | C12: 45954 | D12: 1234567 | E12: IAD | F12: 0.90972222 | G12: LHR | H12: 0.42013889 | I12: 0.30208333 | J12: 789C | K12: J
A13: 22 | B13: 45955 | C13: 45955 | D13: .....6. | E13: IAD | F13: 0.90972222 | G13: LHR | H13: 0.37847222 | I13: 0.30208333 | J13: 789C | K13: J
A14: 4 | B14: 45746 | C14: 45954 | D14: 1234567 | E14: JFK | F14: 0.75 | G14: LHR | H14: 0.26736111 | I14: 0.30902778 | J14: 339A | K14: J
A15: 4 | B15: 45955 | C15: 45955 | D15: .....6. | E15: JFK | F15: 0.77083333 | G15: LHR | H15: 0.25694444 | I15: 0.31944444 | J15: 339A | K15: J
A16: 10 | B16: 45746 | C16: 45954 | D16: 1234567 | E16: JFK | F16: 0.77083333 | G16: LHR | H16: 0.28819444 | I16: 0.30902778 | J16: 339A | K16: J
A17: 10 | B17: 45955 | C17: 45955 | D17: .....6. | E17: JFK | F17: 0.77083333 | G17: LHR | H17: 0.24652778 | I17: 0.30902778 | J17: 339A | K17: J
A18: 26 | B18: 45748 | C18: 45951 | D18: .2..... | E18: JFK | F18: 0.34027778 | G18: LHR | H18: 0.83333333 | I18: 0.28472222 | J18: 339A | K18: J
A19: 26 | B19: 45746 | C19: 45955 | D19: 1.34567 | E19: JFK | F19: 0.34027778 | G19: LHR | H19: 0.83333333 | I19: 0.28472222 | J19: 351A | K19: J
A20: 46 | B20: 45955 | C20: 45955 | D20: .....6. | E20: JFK | F20: 0.82986111 | G20: LHR | H20: 0.30555556 | I20: 0.30902778 | J20: 339A | K20: J
A21: 46 | B21: 45775 | C21: 45954 | D21: 1234567 | E21: JFK | F21: 0.82986111 | G21: LHR | H21: 0.34722222 | I21: 0.30902778 | J21: 339A | K21: J
A22: 128 | B22: 45955 | C22: 45955 | D22: .....6. | E22: JFK | F22: 0.77777778 | G22: MAN | H22: 0.23611111 | I22: 0.29166667 | J22: 351B | K22: J
A23: 128 | B23: 45746 | C23: 45954 | D23: 1234567 | E23: JFK | F23: 0.77777778 | G23: MAN | H23: 0.27777778 | I23: 0.29166667 | J23: 351B | K23: J
A24: 138 | B24: 45955 | C24: 45955 | D24: .....6. | E24: JFK | F24: 0.97222222 | G24: LHR | H24: 0.4375 | I24: 0.29861111 | J24: 351A | K24: J
A25: 138 | B25: 45746 | C25: 45954 | D25: 1234567 | E25: JFK | F25: 0.97222222 | G25: LHR | H25: 0.47916667 | I25: 0.29861111 | J25: 351A | K25: J
A26: 154 | B26: 45746 | C26: 45954 | D26: 1234567 | E26: JFK | F26: 0.875 | G26: LHR | H26: 0.39236111 | I26: 0.30902778 | J26: 339A | K26: J
A27: 154 | B27: 45955 | C27: 45955 | D27: .....6. | E27: JFK | F27: 0.875 | G27: LHR | H27: 0.35069444 | I27: 0.30902778 | J27: 339A | K27: J
A28: 86 | B28: 45776 | C28: 45954 | D28: .2..5.7 | E28: LAS | F28: 0.71527778 | G28: MAN | H28: 0.45138889 | I28: 0.40277778 | J28: 351B | K28: J
A29: 156 | B29: 45746 | C29: 45954 | D29: 1234567 | E29: LAS | F29: 0.86805556 | G29: LHR | H29: 0.61458333 | I29: 0.41319444 | J29: 789C | K29: J
A30: 156 | B30: 45955 | C30: 45955 | D30: .....6. | E30: LAS | F30: 0.90972222 | G30: LHR | H30: 0.61458333 | I30: 0.41319444 | J30: 789C | K30: J
A31: 8 | B31: 45955 | C31: 45955 | D31: .....6. | E31: LAX | F31: 0.70486111 | G31: LHR | H31: 0.42708333 | I31: 0.43055556 | J31: 351A | K31: J
A32: 8 | B32: 45775 | C32: 45954 | D32: 1234567 | E32: LAX | F32: 0.70486111 | G32: LHR | H32: 0.46875 | I32: 0.43055556 | J32: 351A | K32: J
A33: 24 | B33: 45746 | C33: 45954 | D33: 1234567 | E33: LAX | F33: 0.93402778 | G33: LHR | H33: 0.69791667 | I33: 0.43055556 | J33: 351A | K33: J
A34: 24 | B34: 45955 | C34: 45955 | D34: .....6. | E34: LAX | F34: 0.93402778 | G34: LHR | H34: 0.65625 | I34: 0.43055556 | J34: 351A | K34: J
A35: 142 | B35: 45955 | C35: 45955 | D35: .....6. | E35: LAX | F35: 0.79513889 | G35: LHR | H35: 0.51736111 | I35: 0.43055556 | J35: 789C | K35: J
A36: 142 | B36: 45746 | C36: 45954 | D36: 1234567 | E36: LAX | F36: 0.79513889 | G36: LHR | H36: 0.55902778 | I36: 0.43055556 | J36: 789C | K36: J
A37: 74 | B37: 45746 | C37: 45774 | D37: .2..5.7 | E37: MCO | F37: 0.79166667 | G37: MAN | H37: 0.34027778 | I37: 0.34027778 | J37: 351B | K37: J
A38: 74 | B38: 45747 | C38: 45950 | D38: 1...... | E38: MCO | F38: 0.79166667 | G38: MAN | H38: 0.34027778 | I38: 0.34027778 | J38: 333C | K38: J
A39: 74 | B39: 45955 | C39: 45955 | D39: .....6. | E39: MCO | F39: 0.85069444 | G39: MAN | H39: 0.35763889 | I39: 0.34027778 | J39: 351B | K39: J
A40: 74 | B40: 45750 | C40: 45953 | D40: ...4.6. | E40: MCO | F40: 0.85069444 | G40: MAN | H40: 0.39930556 | I40: 0.34027778 | J40: 351B | K40: J
...

Sheet Totals check (live)
A1: CUBE: | B1: =_xll.VIEW("planning:oraclegl-reporting",$B$2,$B$8,$B$3,$B$4,$B$5,$B$9,$B$7,"!","!",$B$6) -> planning:oraclegl-reporting
A2: translation | B2: translated
A3: sob | B3: Total SOB
A4: lob | B4: VA
A5: currency | B5: =_xll.SUBNM("planning:currency","","Total Currency") -> Total Currency
A6: flight | B6: Total VAAL
A7: rcentre | B7: =_xll.SUBNM("planning:rcentre","Default","VALT","desc") -> VALT - Total VAAL
A8: versionreporting | B8: Outlook
A9: subnom2 | B9: ALL
B12: Ye Dec2024 | C12: Jan2024 | D12: Feb2024 | E12: Mar2024 | F12: Apr2024 | G12: May2024 | H12: Jun2024 | I12: Jul2024 | J12: Aug2024 | K12: Sep2024 | L12: Oct2024 | M12: Nov2024 | N12: Dec2024 | O12: Jan2025 | P12: Feb2025 | Q12: Mar2025 | R12: Apr2025 | S12: May2025 | T12: Jun2025 | U12: Jul2025 | V12: Aug2025 | W12: Sep2025 | X12: Oct2025 | Y12: Nov2025 | Z12: Dec2025
A13: 9001 - Sectors | B13: =_xll.DBRW($B$1,$B$2,$B$8,$B$3,$B$4,$B$5,$B$9,$B$7,B$12,$A13,$B$6) -> 25393 | G13: =_xll.DBRW($B$1,$B$2,$B$8,$B$3,$B$4,$B$5,$B$9,$B$7,G$12,$A13,$B$6) -> 2200 | H13: =_xll.DBRW($B$1,$B$2,$B$8,$B$3,$B$4,$B$5,$B$9,$B$7,H$12,$A13,$B$6) -> 2138 | I13: =_xll.DBRW($B$1,$B$2,$B$8,$B$3,$B$4,$B$5,$B$9,$B$7,I$12,$A13,$B$6) -> 2235 | J13: =_xll.DBRW($B$1,$B$2,$B$8,$B$3,$B$4,$B$5,$B$9,$B$7,J$12,$A13,$B$6) -> 2242 | K13: =_xll.DBRW($B$1,$B$2,$B$8,$B$3,$B$4,$B$5,$B$9,$B$7,K$12,$A13,$B$6) -> 2159 | L13: =_xll.DBRW($B$1,$B$2,$B$8,$B$3,$B$4,$B$5,$B$9,$B$7,L$12,$A13,$B$6) -> 2226 | M13: =_xll.DBRW($B$1,$B$2,$B$8,$B$3,$B$4,$B$5,$B$9,$B$7,M$12,$A13,$B$6) -> 2134 | N13: =_xll.DBRW($B$1,$B$2,$B$8,$B$3,$B$4,$B$5,$B$9,$B$7,N$12,$A13,$B$6) -> 2210 | ... Z13: =_xll.DBRW($B$1,$B$2,$B$8,$B$3,$B$4,$B$5,$B$9,$B$7,Z$12,$A13,$B$6) -> 2341
A14: TPAX | B14: =_xll.DBRW($B$1,$B$2,$B$8,$B$3,$B$4,$B$5,$B$9,$B$7,B$12,$A14,$B$6) -> 5858096.1 | G14: =_xll.DBRW($B$1,$B$2,$B$8,$B$3,$B$4,$B$5,$B$9,$B$7,G$12,$A14,$B$6) -> 511599.11 | H14: =_xll.DBRW($B$1,$B$2,$B$8,$B$3,$B$4,$B$5,$B$9,$B$7,H$12,$A14,$B$6) -> 541418.2 | I14: =_xll.DBRW($B$1,$B$2,$B$8,$B$3,$B$4,$B$5,$B$9,$B$7,I$12,$A14,$B$6) -> 556465.45 | J14: =_xll.DBRW($B$1,$B$2,$B$8,$B$3,$B$4,$B$5,$B$9,$B$7,J$12,$A14,$B$6) -> 559047.09 | K14: =_xll.DBRW($B$1,$B$2,$B$8,$B$3,$B$4,$B$5,$B$9,$B$7,K$12,$A14,$B$6) -> 500102.54 | L14: =_xll.DBRW($B$1,$B$2,$B$8,$B$3,$B$4,$B$5,$B$9,$B$7,L$12,$A14,$B$6) -> 512763.74 | M14: =_xll.DBRW($B$1,$B$2,$B$8,$B$3,$B$4,$B$5,$B$9,$B$7,M$12,$A14,$B$6) -> 490089.03 | N14: =_xll.DBRW($B$1,$B$2,$B$8,$B$3,$B$4,$B$5,$B$9,$B$7,N$12,$A14,$B$6) -> 525075.96 | ... Z14: =_xll.DBRW($B$1,$B$2,$B$8,$B$3,$B$4,$B$5,$B$9,$B$7,Z$12,$A14,$B$6) -> 569863.98
A15: 9007 - ASKs | B15: =_xll.DBRW($B$1,$B$2,$B$8,$B$3,$B$4,$B$5,$B$9,$B$7,B$12,$A15,$B$6) -> 50525608946 | G15: =_xll.DBRW($B$1,$B$2,$B$8,$B$3,$B$4,$B$5,$B$9,$B$7,G$12,$A15,$B$6) -> 4364486582 | H15: =_xll.DBRW($B$1,$B$2,$B$8,$B$3,$B$4,$B$5,$B$9,$B$7,H$12,$A15,$B$6) -> 4255812880 | I15: =_xll.DBRW($B$1,$B$2,$B$8,$B$3,$B$4,$B$5,$B$9,$B$7,I$12,$A15,$B$6) -> 4464448238 | J15: =_xll.DBRW($B$1,$B$2,$B$8,$B$3,$B$4,$B$5,$B$9,$B$7,J$12,$A15,$B$6) -> 4480306246 | K15: =_xll.DBRW($B$1,$B$2,$B$8,$B$3,$B$4,$B$5,$B$9,$B$7,K$12,$A15,$B$6) -> 4288996330 | L15: =_xll.DBRW($B$1,$B$2,$B$8,$B$3,$B$4,$B$5,$B$9,$B$7,L$12,$A15,$B$6) -> 4430793712 | M15: =_xll.DBRW($B$1,$B$2,$B$8,$B$3,$B$4,$B$5,$B$9,$B$7,M$12,$A15,$B$6) -> 4273705096 | N15: =_xll.DBRW($B$1,$B$2,$B$8,$B$3,$B$4,$B$5,$B$9,$B$7,N$12,$A15,$B$6) -> 4412079246 | ... Z15: =_xll.DBRW($B$1,$B$2,$B$8,$B$3,$B$4,$B$5,$B$9,$B$7,Z$12,$A15,$B$6) -> 4724067505
A16: 9008 - RPKs | B16: =_xll.DBRW($B$1,$B$2,$B$8,$B$3,$B$4,$B$5,$B$9,$B$7,B$12,$A16,$B$6) -> 3.9966432e+10 | G16: =_xll.DBRW($B$1,$B$2,$B$8,$B$3,$B$4,$B$5,$B$9,$B$7,G$12,$A16,$B$6) -> 3.4787078e+09 | H16: =_xll.DBRW($B$1,$B$2,$B$8,$B$3,$B$4,$B$5,$B$9,$B$7,H$12,$A16,$B$6) -> 3.6812511e+09 | I16: =_xll.DBRW($B$1,$B$2,$B$8,$B$3,$B$4,$B$5,$B$9,$B$7,I$12,$A16,$B$6) -> 3.7914263e+09 | J16: =_xll.DBRW($B$1,$B$2,$B$8,$B$3,$B$4,$B$5,$B$9,$B$7,J$12,$A16,$B$6) -> 3.7816328e+09 | K16: =_xll.DBRW($B$1,$B$2,$B$8,$B$3,$B$4,$B$5,$B$9,$B$7,K$12,$A16,$B$6) -> 3.4007951e+09 | L16: =_xll.DBRW($B$1,$B$2,$B$8,$B$3,$B$4,$B$5,$B$9,$B$7,L$12,$A16,$B$6) -> 3.4588439e+09 | M16: =_xll.DBRW($B$1,$B$2,$B$8,$B$3,$B$4,$B$5,$B$9,$B$7,M$12,$A16,$B$6) -> 3.3085906e+09 | N16: =_xll.DBRW($B$1,$B$2,$B$8,$B$3,$B$4,$B$5,$B$9,$B$7,N$12,$A16,$B$6) -> 3.529379e+09 | ... Z16: =_xll.DBRW($B$1,$B$2,$B$8,$B$3,$B$4,$B$5,$B$9,$B$7,Z$12,$A16,$B$6) -> 3.8949878e+09
A17: Load Factor | B17: =B16/B15 -> 0.79101336 | G17: =G16/G15 -> 0.79704857 | H17: =H16/H15 -> 0.86499364 | I17: =I16/I15 -> 0.84924857 | J17: =J16/J15 -> 0.84405676 | K17: =K16/K15 -> 0.79291164 | L17: =L16/L15 -> 0.78063754 | M17: =M16/M15 -> 0.77417383 | N17: =N16/N15 -> 0.79993554 | ... Z17: =Z16/Z15 -> 0.82449877
A20: Sectors | B20: =SUM(C20:N20) -> 17544 | G20: =SUM('Sectors (live)'!L:L) -> 2200 | H20: =SUM('Sectors (live)'!M:M) -> 2138 | I20: =SUM('Sectors (live)'!N:N) -> 2235 | J20: =SUM('Sectors (live)'!O:O) -> 2242 | K20: =SUM('Sectors (live)'!P:P) -> 2159 | L20: =SUM('Sectors (live)'!Q:Q) -> 2226 | M20: =SUM('Sectors (live)'!R:R) -> 2134 | N20: =SUM('Sectors (live)'!S:S) -> 2210 | O20: =SUM('Sectors (live)'!T:T) -> 2229 | P20: =SUM('Sectors (live)'!U:U) -> 2014 | Q20: =SUM('Sectors (live)'!V:V) -> 2215 | R20: =SUM('Sectors (live)'!W:W) -> 2308 | S20: =SUM('Sectors (live)'!X:X) -> 2382 | T20: =SUM('Sectors (live)'!Y:Y) -> 2304 | U20: =SUM('Sectors (live)'!Z:Z) -> 2386 | V20: =SUM('Sectors (live)'!AA:AA) -> 2380 | W20: =SUM('Sectors (live)'!AB:AB) -> 2307 | X20: =SUM('Sectors (live)'!AC:AC) -> 2396 | Y20: =SUM('Sectors (live)'!AD:AD) -> 2220 | Z20: =SUM('Sectors (live)'!AE:AE) -> 2341
A21: Pax | B21: =SUM(C21:N21) -> 4196561.1 | G21: =SUM('Passengers (live)'!L:L) -> 511599.11 | H21: =SUM('Passengers (live)'!M:M) -> 541418.2 | I21: =SUM('Passengers (live)'!N:N) -> 556465.45 | J21: =SUM('Passengers (live)'!O:O) -> 559047.09 | K21: =SUM('Passengers (live)'!P:P) -> 500102.54 | L21: =SUM('Passengers (live)'!Q:Q) -> 512763.74 | M21: =SUM('Passengers (live)'!R:R) -> 490089.03 | N21: =SUM('Passengers (live)'!S:S) -> 525075.96 | O21: =SUM('Passengers (live)'!T:T) -> 514719.42 | P21: =SUM('Passengers (live)'!U:U) -> 466331.08 | Q21: =SUM('Passengers (live)'!V:V) -> 529829.2 | R21: =SUM('Passengers (live)'!W:W) -> 566651.92 | S21: =SUM('Passengers (live)'!X:X) -> 593948.01 | T21: =SUM('Passengers (live)'!Y:Y) -> 617134.72 | U21: =SUM('Passengers (live)'!Z:Z) -> 646725.09 | V21: =SUM('Passengers (live)'!AA:AA) -> 632369.37 | W21: =SUM('Passengers (live)'!AB:AB) -> 562127.06 | X21: =SUM('Passengers (live)'!AC:AC) -> 580088.4 | Y21: =SUM('Passengers (live)'!AD:AD) -> 531864.4 | Z21: =SUM('Passengers (live)'!AE:AE) -> 569863.98
A22: 9007 - ASKs | B22: =SUM(C22:N22) -> 34970628330 | G22: =SUM('ASK (live)'!L:L) -> 4364486582 | H22: =SUM('ASK (live)'!M:M) -> 4255812880 | I22: =SUM('ASK (live)'!N:N) -> 4464448238 | J22: =SUM('ASK (live)'!O:O) -> 4480306246 | K22: =SUM('ASK (live)'!P:P) -> 4288996330 | L22: =SUM('ASK (live)'!Q:Q) -> 4430793712 | M22: =SUM('ASK (live)'!R:R) -> 4273705096 | N22: =SUM('ASK (live)'!S:S) -> 4412079246 | O22: =SUM('ASK (live)'!T:T) -> 4460380554 | P22: =SUM('ASK (live)'!U:U) -> 4028017928 | Q22: =SUM('ASK (live)'!V:V) -> 4431928134 | R22: =SUM('ASK (live)'!W:W) -> 4624376609 | S22: =SUM('ASK (live)'!X:X) -> 4770631586 | T22: =SUM('ASK (live)'!Y:Y) -> 4608331922 | U22: =SUM('ASK (live)'!Z:Z) -> 4780878783 | V22: =SUM('ASK (live)'!AA:AA) -> 4764655586 | W22: =SUM('ASK (live)'!AB:AB) -> 4616786419 | X22: =SUM('ASK (live)'!AC:AC) -> 4794858683 | Y22: =SUM('ASK (live)'!AD:AD) -> 4466072006 | Z22: =SUM('ASK (live)'!AE:AE) -> 4724067505
A23: 9008 - RPKs | B23: =SUM(C23:N23) -> 2.8430627e+10 | G23: =SUM('RPK (live)'!L:L) -> 3.4787078e+09 | H23: =SUM('RPK (live)'!M:M) -> 3.6812511e+09 | I23: =SUM('RPK (live)'!N:N) -> 3.7914263e+09 | J23: =SUM('RPK (live)'!O:O) -> 3.7816328e+09 | K23: =SUM('RPK (live)'!P:P) -> 3.4007951e+09 | L23: =SUM('RPK (live)'!Q:Q) -> 3.4588439e+09 | M23: =SUM('RPK (live)'!R:R) -> 3.3085906e+09 | N23: =SUM('RPK (live)'!S:S) -> 3.529379e+09 | O23: =SUM('RPK (live)'!T:T) -> 3.5158595e+09 | P23: =SUM('RPK (live)'!U:U) -> 3.1676981e+09 | Q23: =SUM('RPK (live)'!V:V) -> 3.5852471e+09 | R23: =SUM('RPK (live)'!W:W) -> 3.8253055e+09 | S23: =SUM('RPK (live)'!X:X) -> 4.0333938e+09 | T23: =SUM('RPK (live)'!Y:Y) -> 4.2125277e+09 | U23: =SUM('RPK (live)'!Z:Z) -> 4.411769e+09 | V23: =SUM('RPK (live)'!AA:AA) -> 4.2821881e+09 | W23: =SUM('RPK (live)'!AB:AB) -> 3.847546e+09 | X23: =SUM('RPK (live)'!AC:AC) -> 3.9516916e+09 | Y23: =SUM('RPK (live)'!AD:AD) -> 3.627604e+09 | Z23: =SUM('RPK (live)'!AE:AE) -> 3.8949878e+09
B24: =B13-B20 -> 7849 | G24: =G13-G20 -> 0 | H24: =H13-H20 -> 0 | I24: =I13-I20 -> 0 | J24: =J13-J20 -> 0 | K24: =K13-K20 -> 0 | L24: =L13-L20 -> 0 | M24: =M13-M20 -> 0 | N24: =N13-N20 -> 0 | ... Z24: =Z13-Z20 -> 0
B25: =B14-B21 -> 1661535 | G25: =G14-G21 -> 0 | H25: =H14-H21 -> 0 | I25: =I14-I21 -> 0 | J25: =J14-J21 -> 0 | K25: =K14-K21 -> -4.6566129e-10 | L25: =L14-L21 -> 0 | M25: =M14-M21 -> 0 | N25: =N14-N21 -> 0 | ... Z25: =Z14-Z21 -> 0
B26: =B15-B22 -> 15554980616 | G26: =G15-G22 -> 0 | H26: =H15-H22 -> 0 | I26: =I15-I22 -> 0 | J26: =J15-J22 -> 0 | K26: =K15-K22 -> 0 | L26: =L15-L22 -> 0 | M26: =M15-M22 -> 0 | N26: =N15-N22 -> 0 | ... Z26: =Z15-Z22 -> 0
B27: =B16-B23 -> 11535804991 | G27: =G16-G23 -> 0 | H27: =H16-H23 -> 0 | I27: =I16-I23 -> 0 | J27: =J16-J23 -> 0 | K27: =K16-K23 -> 0 | L27: =L16-L23 -> 0 | M27: =M16-M23 -> 0 | N27: =N16-N23 -> 0 | ... Z27: =Z16-Z23 -> 0

Sheet Passengers (live)
A1: CUBE: | B1: =_xll.VIEW("planning:oraclegl-reporting",$B$2,$B$7,$B$3,$B$4,$B$5,"!",$B$6,"!","!","!") -> planning:oraclegl-reporting
A2: translation | B2: =_xll.SUBNM("planning:translation","","translated") -> translated
A3: sob | B3: =_xll.SUBNM("planning:sob","","Total SOB") -> Total SOB
A4: lob | B4: =_xll.SUBNM("planning:lob","","VA") -> VA
A5: currency | B5: =_xll.SUBNM("planning:currency","","Total Currency") -> Total Currency
A6: rcentre | B6: =_xll.SUBNM("planning:rcentre","Default","VALT","desc") -> VALT - Total VAAL
A7: versionreporting | B7: Outlook
B10: Flight | C10: Route | D10: DEP | E10: ARR | F10: SubNom2 | G10: Ye Dec2024 | H10: Jan2024 | I10: Feb2024 | J10: Mar2024 | K10: Apr2024 | L10: May2024 | M10: Jun2024 | N10: Jul2024 | O10: Aug2024 | P10: Sep2024 | Q10: Oct2024 | R10: Nov2024 | S10: Dec2024 | T10: Jan2025 | U10: Feb2025 | V10: Mar2025 | W10: Apr2025 | X10: May2025 | Y10: Jun2025 | Z10: Jul2025 | AA10: Aug2025 | AB10: Sep2025 | AC10: Oct2025 | AD10: Nov2025 | AE10: Dec2025
A11: TPAX | B11: V003 - LHR - JFK | C11: LHRJFK | D11: LHR | E11: JFK | F11: J | L11: =_xll.DBRW($B$1,$B$2,$B$7,$B$3,$B$4,$B$5,$F11,$B$6,L$10,$A11,$B11) -> 786.72514 | M11: =_xll.DBRW($B$1,$B$2,$B$7,$B$3,$B$4,$B$5,$F11,$B$6,M$10,$A11,$B11) -> 807.12715 | N11: =_xll.DBRW($B$1,$B$2,$B$7,$B$3,$B$4,$B$5,$F11,$B$6,N$10,$A11,$B11) -> 884.74707 | O11: =_xll.DBRW($B$1,$B$2,$B$7,$B$3,$B$4,$B$5,$F11,$B$6,O$10,$A11,$B11) -> 859.19441 | P11: =_xll.DBRW($B$1,$B$2,$B$7,$B$3,$B$4,$B$5,$F11,$B$6,P$10,$A11,$B11) -> 868.17557 | Q11: =_xll.DBRW($B$1,$B$2,$B$7,$B$3,$B$4,$B$5,$F11,$B$6,Q$10,$A11,$B11) -> 866.01965 | R11: =_xll.DBRW($B$1,$B$2,$B$7,$B$3,$B$4,$B$5,$F11,$B$6,R$10,$A11,$B11) -> 1151.0376 | S11: =_xll.DBRW($B$1,$B$2,$B$7,$B$3,$B$4,$B$5,$F11,$B$6,S$10,$A11,$B11) -> 1328.937 | ... AE11: =_xll.DBRW($B$1,$B$2,$B$7,$B$3,$B$4,$B$5,$F11,$B$6,AE$10,$A11,$B11) -> 938.69495
A12: TPAX | B12: V004 - JFK - LHR | C12: JFKLHR | D12: JFK | E12: LHR | F12: J | L12: =_xll.DBRW($B$1,$B$2,$B$7,$B$3,$B$4,$B$5,$F12,$B$6,L$10,$A12,$B12) -> 794.62751 | M12: =_xll.DBRW($B$1,$B$2,$B$7,$B$3,$B$4,$B$5,$F12,$B$6,M$10,$A12,$B12) -> 807.12715 | N12: =_xll.DBRW($B$1,$B$2,$B$7,$B$3,$B$4,$B$5,$F12,$B$6,N$10,$A12,$B12) -> 881.88381 | O12: =_xll.DBRW($B$1,$B$2,$B$7,$B$3,$B$4,$B$5,$F12,$B$6,O$10,$A12,$B12) -> 859.19441 | P12: =_xll.DBRW($B$1,$B$2,$B$7,$B$3,$B$4,$B$5,$F12,$B$6,P$10,$A12,$B12) -> 868.17557 | Q12: =_xll.DBRW($B$1,$B$2,$B$7,$B$3,$B$4,$B$5,$F12,$B$6,Q$10,$A12,$B12) -> 866.01965 | R12: =_xll.DBRW($B$1,$B$2,$B$7,$B$3,$B$4,$B$5,$F12,$B$6,R$10,$A12,$B12) -> 1151.0376 | S12: =_xll.DBRW($B$1,$B$2,$B$7,$B$3,$B$4,$B$5,$F12,$B$6,S$10,$A12,$B12) -> 1328.937 | ... AE12: =_xll.DBRW($B$1,$B$2,$B$7,$B$3,$B$4,$B$5,$F12,$B$6,AE$10,$A12,$B12) -> 991.68579
A13: TPAX | B13: V005 - LHR - MIA | C13: LHRMIA | D13: LHR | E13: MIA | F13: J | L13: =_xll.DBRW($B$1,$B$2,$B$7,$B$3,$B$4,$B$5,$F13,$B$6,L$10,$A13,$B13) -> 844.08705 | M13: =_xll.DBRW($B$1,$B$2,$B$7,$B$3,$B$4,$B$5,$F13,$B$6,M$10,$A13,$B13) -> 892.51033 | N13: =_xll.DBRW($B$1,$B$2,$B$7,$B$3,$B$4,$B$5,$F13,$B$6,N$10,$A13,$B13) -> 840.26195 | O13: =_xll.DBRW($B$1,$B$2,$B$7,$B$3,$B$4,$B$5,$F13,$B$6,O$10,$A13,$B13) -> 823.78261 | P13: =_xll.DBRW($B$1,$B$2,$B$7,$B$3,$B$4,$B$5,$F13,$B$6,P$10,$A13,$B13) -> 771.20389 | Q13: =_xll.DBRW($B$1,$B$2,$B$7,$B$3,$B$4,$B$5,$F13,$B$6,Q$10,$A13,$B13) -> 869.2969 | R13: =_xll.DBRW($B$1,$B$2,$B$7,$B$3,$B$4,$B$5,$F13,$B$6,R$10,$A13,$B13) -> 818.03638 | S13: =_xll.DBRW($B$1,$B$2,$B$7,$B$3,$B$4,$B$5,$F13,$B$6,S$10,$A13,$B13) -> 850.05074 | ... AE13: =_xll.DBRW($B$1,$B$2,$B$7,$B$3,$B$4,$B$5,$F13,$B$6,AE$10,$A13,$B13) -> 861.36408
A14: TPAX | B14: V006 - MIA - LHR | C14: MIALHR | D14: MIA | E14: LHR | F14: J | L14: =_xll.DBRW($B$1,$B$2,$B$7,$B$3,$B$4,$B$5,$F14,$B$6,L$10,$A14,$B14) -> 844.08705 | M14: =_xll.DBRW($B$1,$B$2,$B$7,$B$3,$B$4,$B$5,$F14,$B$6,M$10,$A14,$B14) -> 892.51033 | N14: =_xll.DBRW($B$1,$B$2,$B$7,$B$3,$B$4,$B$5,$F14,$B$6,N$10,$A14,$B14) -> 840.26195 | O14: =_xll.DBRW($B$1,$B$2,$B$7,$B$3,$B$4,$B$5,$F14,$B$6,O$10,$A14,$B14) -> 823.78261 | P14: =_xll.DBRW($B$1,$B$2,$B$7,$B$3,$B$4,$B$5,$F14,$B$6,P$10,$A14,$B14) -> 771.20389 | Q14: =_xll.DBRW($B$1,$B$2,$B$7,$B$3,$B$4,$B$5,$F14,$B$6,Q$10,$A14,$B14) -> 869.2969 | R14: =_xll.DBRW($B$1,$B$2,$B$7,$B$3,$B$4,$B$5,$F14,$B$6,R$10,$A14,$B14) -> 818.03638 | S14: =_xll.DBRW($B$1,$B$2,$B$7,$B$3,$B$4,$B$5,$F14,$B$6,S$10,$A14,$B14) -> 850.05074 | ... AE14: =_xll.DBRW($B$1,$B$2,$B$7,$B$3,$B$4,$B$5,$F14,$B$6,AE$10,$A14,$B14) -> 833.57814
A15: TPAX | B15: V007 - LHR - LAX | C15: LHRLAX | D15: LHR | E15: LAX | F15: J | L15: =_xll.DBRW($B$1,$B$2,$B$7,$B$3,$B$4,$B$5,$F15,$B$6,L$10,$A15,$B15) -> 778.64984 | M15: =_xll.DBRW($B$1,$B$2,$B$7,$B$3,$B$4,$B$5,$F15,$B$6,M$10,$A15,$B15) -> 938.05958 | N15: =_xll.DBRW($B$1,$B$2,$B$7,$B$3,$B$4,$B$5,$F15,$B$6,N$10,$A15,$B15) -> 1115.1535 | O15: =_xll.DBRW($B$1,$B$2,$B$7,$B$3,$B$4,$B$5,$F15,$B$6,O$10,$A15,$B15) -> 1399.7607 | P15: =_xll.DBRW($B$1,$B$2,$B$7,$B$3,$B$4,$B$5,$F15,$B$6,P$10,$A15,$B15) -> 1330.5197 | Q15: =_xll.DBRW($B$1,$B$2,$B$7,$B$3,$B$4,$B$5,$F15,$B$6,Q$10,$A15,$B15) -> 1318.9332 | R15: =_xll.DBRW($B$1,$B$2,$B$7,$B$3,$B$4,$B$5,$F15,$B$6,R$10,$A15,$B15) -> 1256.7026 | S15: =_xll.DBRW($B$1,$B$2,$B$7,$B$3,$B$4,$B$5,$F15,$B$6,S$10,$A15,$B15) -> 1320.0788 | ... AE15: =_xll.DBRW($B$1,$B$2,$B$7,$B$3,$B$4,$B$5,$F15,$B$6,AE$10,$A15,$B15) -> 1355.3624
A16: TPAX | B16: V008 - LAX - LHR | C16: LAXLHR | D16: LAX | E16: LHR | F16: J | L16: =_xll.DBRW($B$1,$B$2,$B$7,$B$3,$B$4,$B$5,$F16,$B$6,L$10,$A16,$B16) -> 778.64984 | M16: =_xll.DBRW($B$1,$B$2,$B$7,$B$3,$B$4,$B$5,$F16,$B$6,M$10,$A16,$B16) -> 938.05958 | N16: =_xll.DBRW($B$1,$B$2,$B$7,$B$3,$B$4,$B$5,$F16,$B$6,N$10,$A16,$B16) -> 1160.0043 | O16: =_xll.DBRW($B$1,$B$2,$B$7,$B$3,$B$4,$B$5,$F16,$B$6,O$10,$A16,$B16) -> 1399.7607 | P16: =_xll.DBRW($B$1,$B$2,$B$7,$B$3,$B$4,$B$5,$F16,$B$6,P$10,$A16,$B16) -> 1330.5197 | Q16: =_xll.DBRW($B$1,$B$2,$B$7,$B$3,$B$4,$B$5,$F16,$B$6,Q$10,$A16,$B16) -> 1318.9332 | R16: =_xll.DBRW($B$1,$B$2,$B$7,$B$3,$B$4,$B$5,$F16,$B$6,R$10,$A16,$B16) -> 1256.7026 | S16: =_xll.DBRW($B$1,$B$2,$B$7,$B$3,$B$4,$B$5,$F16,$B$6,S$10,$A16,$B16) -> 1320.0788 | ... AE16: =_xll.DBRW($B$1,$B$2,$B$7,$B$3,$B$4,$B$5,$F16,$B$6,AE$10,$A16,$B16) -> 1311.641
A17: TPAX | B17: V009 - LHR - JFK | C17: LHRJFK | D17: LHR | E17: JFK | F17: J | L17: =_xll.DBRW($B$1,$B$2,$B$7,$B$3,$B$4,$B$5,$F17,$B$6,L$10,$A17,$B17) -> 892.96815 | M17: =_xll.DBRW($B$1,$B$2,$B$7,$B$3,$B$4,$B$5,$F17,$B$6,M$10,$A17,$B17) -> 937.91164 | N17: =_xll.DBRW($B$1,$B$2,$B$7,$B$3,$B$4,$B$5,$F17,$B$6,N$10,$A17,$B17) -> 991.64207 | O17: =_xll.DBRW($B$1,$B$2,$B$7,$B$3,$B$4,$B$5,$F17,$B$6,O$10,$A17,$B17) -> 926.78191 | P17: =_xll.DBRW($B$1,$B$2,$B$7,$B$3,$B$4,$B$5,$F17,$B$6,P$10,$A17,$B17) -> 940.84652 | Q17: =_xll.DBRW($B$1,$B$2,$B$7,$B$3,$B$4,$B$5,$F17,$B$6,Q$10,$A17,$B17) -> 935.82731 | R17: =_xll.DBRW($B$1,$B$2,$B$7,$B$3,$B$4,$B$5,$F17,$B$6,R$10,$A17,$B17) -> 693.72298 | S17: =_xll.DBRW($B$1,$B$2,$B$7,$B$3,$B$4,$B$5,$F17,$B$6,S$10,$A17,$B17) -> 674.21143 | ... AE17: =_xll.DBRW($B$1,$B$2,$B$7,$B$3,$B$4,$B$5,$F17,$B$6,AE$10,$A17,$B17) -> 945.3188
A18: TPAX | B18: V010 - JFK - LHR | C18: JFKLHR | D18: JFK | E18: LHR | F18: J | L18: =_xll.DBRW($B$1,$B$2,$B$7,$B$3,$B$4,$B$5,$F18,$B$6,L$10,$A18,$B18) -> 898.2364 | M18: =_xll.DBRW($B$1,$B$2,$B$7,$B$3,$B$4,$B$5,$F18,$B$6,M$10,$A18,$B18) -> 941.64834 | N18: =_xll.DBRW($B$1,$B$2,$B$7,$B$3,$B$4,$B$5,$F18,$B$6,N$10,$A18,$B18) -> 1004.0495 | O18: =_xll.DBRW($B$1,$B$2,$B$7,$B$3,$B$4,$B$5,$F18,$B$6,O$10,$A18,$B18) -> 962.89029 | P18: =_xll.DBRW($B$1,$B$2,$B$7,$B$3,$B$4,$B$5,$F18,$B$6,P$10,$A18,$B18) -> 976.69752 | Q18: =_xll.DBRW($B$1,$B$2,$B$7,$B$3,$B$4,$B$5,$F18,$B$6,Q$10,$A18,$B18) -> 893.33569 | R18: =_xll.DBRW($B$1,$B$2,$B$7,$B$3,$B$4,$B$5,$F18,$B$6,R$10,$A18,$B18) -> 693.72298 | S18: =_xll.DBRW($B$1,$B$2,$B$7,$B$3,$B$4,$B$5,$F18,$B$6,S$10,$A18,$B18) -> 674.21143 | ... AE18: =_xll.DBRW($B$1,$B$2,$B$7,$B$3,$B$4,$B$5,$F18,$B$6,AE$10,$A18,$B18) -> 930.17856
A19: TPAX | B19: V011 - LHR - BOS | C19: LHRBOS | D19: LHR | E19: BOS | F19: J | L19: =_xll.DBRW($B$1,$B$2,$B$7,$B$3,$B$4,$B$5,$F19,$B$6,L$10,$A19,$B19) -> 915.19054 | M19: =_xll.DBRW($B$1,$B$2,$B$7,$B$3,$B$4,$B$5,$F19,$B$6,M$10,$A19,$B19) -> 963.27623 | N19: =_xll.DBRW($B$1,$B$2,$B$7,$B$3,$B$4,$B$5,$F19,$B$6,N$10,$A19,$B19) -> 949.81933 | O19: =_xll.DBRW($B$1,$B$2,$B$7,$B$3,$B$4,$B$5,$F19,$B$6,O$10,$A19,$B19) -> 897.41102 | P19: =_xll.DBRW($B$1,$B$2,$B$7,$B$3,$B$4,$B$5,$F19,$B$6,P$10,$A19,$B19) -> 916.17992 | Q19: =_xll.DBRW($B$1,$B$2,$B$7,$B$3,$B$4,$B$5,$F19,$B$6,Q$10,$A19,$B19) -> 946.65369 | R19: =_xll.DBRW($B$1,$B$2,$B$7,$B$3,$B$4,$B$5,$F19,$B$6,R$10,$A19,$B19) -> 863.26577 | S19: =_xll.DBRW($B$1,$B$2,$B$7,$B$3,$B$4,$B$5,$F19,$B$6,S$10,$A19,$B19) -> 864.05158 | ... AE19: =_xll.DBRW($B$1,$B$2,$B$7,$B$3,$B$4,$B$5,$F19,$B$6,AE$10,$A19,$B19) -> 893.82963
A20: TPAX | B20: V012 - BOS - LHR | C20: BOSLHR | D20: BOS | E20: LHR | F20: J | L20: =_xll.DBRW($B$1,$B$2,$B$7,$B$3,$B$4,$B$5,$F20,$B$6,L$10,$A20,$B20) -> 915.19054 | M20: =_xll.DBRW($B$1,$B$2,$B$7,$B$3,$B$4,$B$5,$F20,$B$6,M$10,$A20,$B20) -> 963.27623 | N20: =_xll.DBRW($B$1,$B$2,$B$7,$B$3,$B$4,$B$5,$F20,$B$6,N$10,$A20,$B20) -> 949.81933 | O20: =_xll.DBRW($B$1,$B$2,$B$7,$B$3,$B$4,$B$5,$F20,$B$6,O$10,$A20,$B20) -> 897.41102 | P20: =_xll.DBRW($B$1,$B$2,$B$7,$B$3,$B$4,$B$5,$F20,$B$6,P$10,$A20,$B20) -> 916.17992 | Q20: =_xll.DBRW($B$1,$B$2,$B$7,$B$3,$B$4,$B$5,$F20,$B$6,Q$10,$A20,$B20) -> 946.65369 | R20: =_xll.DBRW($B$1,$B$2,$B$7,$B$3,$B$4,$B$5,$F20,$B$6,R$10,$A20,$B20) -> 863.26577 | S20: =_xll.DBRW($B$1,$B$2,$B$7,$B$3,$B$4,$B$5,$F20,$B$6,S$10,$A20,$B20) -> 864.05158 | ... AE20: =_xll.DBRW($B$1,$B$2,$B$7,$B$3,$B$4,$B$5,$F20,$B$6,AE$10,$A20,$B20) -> 864.61355
A21: TPAX | B21: V019 - LHR - SFO | C21: LHRSFO | D21: LHR | E21: SFO | F21: J | L21: =_xll.DBRW($B$1,$B$2,$B$7,$B$3,$B$4,$B$5,$F21,$B$6,L$10,$A21,$B21) -> 914.32368 | M21: =_xll.DBRW($B$1,$B$2,$B$7,$B$3,$B$4,$B$5,$F21,$B$6,M$10,$A21,$B21) -> 916.33609 | N21: =_xll.DBRW($B$1,$B$2,$B$7,$B$3,$B$4,$B$5,$F21,$B$6,N$10,$A21,$B21) -> 849.23423 | O21: =_xll.DBRW($B$1,$B$2,$B$7,$B$3,$B$4,$B$5,$F21,$B$6,O$10,$A21,$B21) -> 863.96713 | P21: =_xll.DBRW($B$1,$B$2,$B$7,$B$3,$B$4,$B$5,$F21,$B$6,P$10,$A21,$B21) -> 809.76408 | Q21: =_xll.DBRW($B$1,$B$2,$B$7,$B$3,$B$4,$B$5,$F21,$B$6,Q$10,$A21,$B21) -> 792.02607 | R21: =_xll.DBRW($B$1,$B$2,$B$7,$B$3,$B$4,$B$5,$F21,$B$6,R$10,$A21,$B21) -> 827.66034 | S21: =_xll.DBRW($B$1,$B$2,$B$7,$B$3,$B$4,$B$5,$F21,$B$6,S$10,$A21,$B21) -> 820.04895 | ... AE21: =_xll.DBRW($B$1,$B$2,$B$7,$B$3,$B$4,$B$5,$F21,$B$6,AE$10,$A21,$B21) -> 1067.411
A22: TPAX | B22: V020 - SFO - LHR | C22: SFOLHR | D22: SFO | E22: LHR | F22: J | L22: =_xll.DBRW($B$1,$B$2,$B$7,$B$3,$B$4,$B$5,$F22,$B$6,L$10,$A22,$B22) -> 914.32368 | M22: =_xll.DBRW($B$1,$B$2,$B$7,$B$3,$B$4,$B$5,$F22,$B$6,M$10,$A22,$B22) -> 916.33609 | N22: =_xll.DBRW($B$1,$B$2,$B$7,$B$3,$B$4,$B$5,$F22,$B$6,N$10,$A22,$B22) -> 849.23423 | O22: =_xll.DBRW($B$1,$B$2,$B$7,$B$3,$B$4,$B$5,$F22,$B$6,O$10,$A22,$B22) -> 863.96713 | P22: =_xll.DBRW($B$1,$B$2,$B$7,$B$3,$B$4,$B$5,$F22,$B$6,P$10,$A22,$B22) -> 809.76408 | Q22: =_xll.DBRW($B$1,$B$2,$B$7,$B$3,$B$4,$B$5,$F22,$B$6,Q$10,$A22,$B22) -> 792.02607 | R22: =_xll.DBRW($B$1,$B$2,$B$7,$B$3,$B$4,$B$5,$F22,$B$6,R$10,$A22,$B22) -> 827.66034 | S22: =_xll.DBRW($B$1,$B$2,$B$7,$B$3,$B$4,$B$5,$F22,$B$6,S$10,$A22,$B22) -> 820.04895 | ... AE22: =_xll.DBRW($B$1,$B$2,$B$7,$B$3,$B$4,$B$5,$F22,$B$6,AE$10,$A22,$B22) -> 1067.411
... A346: TPAX | B346: V479 - CPT - LHR | C346: CPTLHR | D346: CPT | E346: LHR | F346: Y | L346: =_xll.DBRW($B$1,$B$2,$B$7,$B$3,$B$4,$B$5,$F346,$B$6,L$10,$A346,$B346) -> 0 | M346: =_xll.DBRW($B$1,$B$2,$B$7,$B$3,$B$4,$B$5,$F346,$B$6,M$10,$A346,$B346) -> 0 | N346: =_xll.DBRW($B$1,$B$2,$B$7,$B$3,$B$4,$B$5,$F346,$B$6,N$10,$A346,$B346) -> 0 | O346: =_xll.DBRW($B$1,$B$2,$B$7,$B$3,$B$4,$B$5,$F346,$B$6,O$10,$A346,$B346) -> 0 | P346: =_xll.DBRW($B$1,$B$2,$B$7,$B$3,$B$4,$B$5,$F346,$B$6,P$10,$A346,$B346) -> 0 | Q346: =_xll.DBRW($B$1,$B$2,$B$7,$B$3,$B$4,$B$5,$F346,$B$6,Q$10,$A346,$B346) -> 578.1448 | R346: =_xll.DBRW($B$1,$B$2,$B$7,$B$3,$B$4,$B$5,$F346,$B$6,R$10,$A346,$B346) -> 3757.2138 | S346: =_xll.DBRW($B$1,$B$2,$B$7,$B$3,$B$4,$B$5,$F346,$B$6,S$10,$A346,$B346) -> 4540.5751 | ... AE346: =_xll.DBRW($B$1,$B$2,$B$7,$B$3,$B$4,$B$5,$F346,$B$6,AE$10,$A346,$B346) -> 5075.815

Sheet Sectors (live)
A1: CUBE: | B1: =_xll.VIEW("planning:oraclegl-reporting",$B$2,$B$7,$B$3,$B$4,$B$5,"!",$B$6,"!","!","!") -> planning:oraclegl-reporting
A2: translation | B2: =_xll.SUBNM("planning:translation","","translated") -> translated
A3: sob | B3: =_xll.SUBNM("planning:sob","","Total SOB") -> Total SOB
A4: lob | B4: =_xll.SUBNM("planning:lob","","VA") -> VA
A5: currency | B5: =_xll.SUBNM("planning:currency","","Total Currency") -> Total Currency
A6: rcentre | B6: =_xll.SUBNM("planning:rcentre","Default","VALT","desc") -> VALT - Total VAAL
A7: versionreporting | B7: Outlook
B10: Flight | C10: Route | D10: DEP | E10: ARR | F10: SubNom2 | G10: Ye Dec2024 | H10: Jan2024 | I10: Feb2024 | J10: Mar2024 | K10: Apr2024 | L10: May2024 | M10: Jun2024 | N10: Jul2024 | O10: Aug2024 | P10: Sep2024 | Q10: Oct2024 | R10: Nov2024 | S10: Dec2024 | T10: Jan2025 | U10: Feb2025 | V10: Mar2025 | W10: Apr2025 | X10: May2025 | Y10: Jun2025 | Z10: Jul2025 | AA10: Aug2025 | AB10: Sep2025 | AC10: Oct2025 | AD10: Nov2025 | AE10: Dec2025
A11: 9001 - Sectors | B11: V003 - LHR - JFK | C11: LHRJFK | D11: LHR | E11: JFK | F11: A330C | L11: =_xll.DBRW($B$1,$B$2,$B$7,$B$3,$B$4,$B$5,$F11,$B$6,L$10,$A11,$B11) -> 0 | M11: =_xll.DBRW($B$1,$B$2,$B$7,$B$3,$B$4,$B$5,$F11,$B$6,M$10,$A11,$B11) -> 0 | N11: =_xll.DBRW($B$1,$B$2,$B$7,$B$3,$B$4,$B$5,$F11,$B$6,N$10,$A11,$B11) -> 1 | O11: =_xll.DBRW($B$1,$B$2,$B$7,$B$3,$B$4,$B$5,$F11,$B$6,O$10,$A11,$B11) -> 0 | P11: =_xll.DBRW($B$1,$B$2,$B$7,$B$3,$B$4,$B$5,$F11,$B$6,P$10,$A11,$B11) -> 0 | Q11: =_xll.DBRW($B$1,$B$2,$B$7,$B$3,$B$4,$B$5,$F11,$B$6,Q$10,$A11,$B11) -> 0 | R11: =_xll.DBRW($B$1,$B$2,$B$7,$B$3,$B$4,$B$5,$F11,$B$6,R$10,$A11,$B11) -> 0 | S11: =_xll.DBRW($B$1,$B$2,$B$7,$B$3,$B$4,$B$5,$F11,$B$6,S$10,$A11,$B11) -> 0 | ... AE11: =_xll.DBRW($B$1,$B$2,$B$7,$B$3,$B$4,$B$5,$F11,$B$6,AE$10,$A11,$B11) -> 0
A12: 9001 - Sectors | B12: V004 - JFK - LHR | C12: JFKLHR | D12: JFK | E12: LHR | F12: A330C | L12: =_xll.DBRW($B$1,$B$2,$B$7,$B$3,$B$4,$B$5,$F12,$B$6,L$10,$A12,$B12) -> 2 | M12: =_xll.DBRW($B$1,$B$2,$B$7,$B$3,$B$4,$B$5,$F12,$B$6,M$10,$A12,$B12) -> 0 | N12: =_xll.DBRW($B$1,$B$2,$B$7,$B$3,$B$4,$B$5,$F12,$B$6,N$10,$A12,$B12) -> 4 | O12: =_xll.DBRW($B$1,$B$2,$B$7,$B$3,$B$4,$B$5,$F12,$B$6,O$10,$A12,$B12) -> 0 | P12: =_xll.DBRW($B$1,$B$2,$B$7,$B$3,$B$4,$B$5,$F12,$B$6,P$10,$A12,$B12) -> 0 | Q12: =_xll.DBRW($B$1,$B$2,$B$7,$B$3,$B$4,$B$5,$F12,$B$6,Q$10,$A12,$B12) -> 0 | R12: =_xll.DBRW($B$1,$B$2,$B$7,$B$3,$B$4,$B$5,$F12,$B$6,R$10,$A12,$B12) -> 0 | S12: =_xll.DBRW($B$1,$B$2,$B$7,$B$3,$B$4,$B$5,$F12,$B$6,S$10,$A12,$B12) -> 0 | ... AE12: =_xll.DBRW($B$1,$B$2,$B$7,$B$3,$B$4,$B$5,$F12,$B$6,AE$10,$A12,$B12) -> 0
A13: 9001 - Sectors | B13: V005 - LHR - MIA | C13: LHRMIA | D13: LHR | E13: MIA | F13: A330C | L13: =_xll.DBRW($B$1,$B$2,$B$7,$B$3,$B$4,$B$5,$F13,$B$6,L$10,$A13,$B13) -> 28 | M13: =_xll.DBRW($B$1,$B$2,$B$7,$B$3,$B$4,$B$5,$F13,$B$6,M$10,$A13,$B13) -> 26 | N13: =_xll.DBRW($B$1,$B$2,$B$7,$B$3,$B$4,$B$5,$F13,$B$6,N$10,$A13,$B13) -> 16 | O13: =_xll.DBRW($B$1,$B$2,$B$7,$B$3,$B$4,$B$5,$F13,$B$6,O$10,$A13,$B13) -> 18 | P13: =_xll.DBRW($B$1,$B$2,$B$7,$B$3,$B$4,$B$5,$F13,$B$6,P$10,$A13,$B13) -> 2 | Q13: =_xll.DBRW($B$1,$B$2,$B$7,$B$3,$B$4,$B$5,$F13,$B$6,Q$10,$A13,$B13) -> 0 | R13: =_xll.DBRW($B$1,$B$2,$B$7,$B$3,$B$4,$B$5,$F13,$B$6,R$10,$A13,$B13) -> 0 | S13: =_xll.DBRW($B$1,$B$2,$B$7,$B$3,$B$4,$B$5,$F13,$B$6,S$10,$A13,$B13) -> 0 | ... AE13: =_xll.DBRW($B$1,$B$2,$B$7,$B$3,$B$4,$B$5,$F13,$B$6,AE$10,$A13,$B13) -> 0
A14: 9001 - Sectors | B14: V006 - MIA - LHR | C14: MIALHR | D14: MIA | E14: LHR | F14: A330C | L14: =_xll.DBRW($B$1,$B$2,$B$7,$B$3,$B$4,$B$5,$F14,$B$6,L$10,$A14,$B14) -> 28 | M14: =_xll.DBRW($B$1,$B$2,$B$7,$B$3,$B$4,$B$5,$F14,$B$6,M$10,$A14,$B14) -> 26 | N14: =_xll.DBRW($B$1,$B$2,$B$7,$B$3,$B$4,$B$5,$F14,$B$6,N$10,$A14,$B14) -> 16 | O14: =_xll.DBRW($B$1,$B$2,$B$7,$B$3,$B$4,$B$5,$F14,$B$6,O$10,$A14,$B14) -> 18 | P14: =_xll.DBRW($B$1,$B$2,$B$7,$B$3,$B$4,$B$5,$F14,$B$6,P$10,$A14,$B14) -> 2 | Q14: =_xll.DBRW($B$1,$B$2,$B$7,$B$3,$B$4,$B$5,$F14,$B$6,Q$10,$A14,$B14) -> 0 | R14: =_xll.DBRW($B$1,$B$2,$B$7,$B$3,$B$4,$B$5,$F14,$B$6,R$10,$A14,$B14) -> 0 | S14: =_xll.DBRW($B$1,$B$2,$B$7,$B$3,$B$4,$B$5,$F14,$B$6,S$10,$A14,$B14) -> 0 | ... AE14: =_xll.DBRW($B$1,$B$2,$B$7,$B$3,$B$4,$B$5,$F14,$B$6,AE$10,$A14,$B14) -> 0
A15: 9001 - Sectors | B15: V007 - LHR - LAX | C15: LHRLAX | D15: LHR | E15: LAX | F15: A330C | L15: =_xll.DBRW($B$1,$B$2,$B$7,$B$3,$B$4,$B$5,$F15,$B$6,L$10,$A15,$B15) -> 0 | M15: =_xll.DBRW($B$1,$B$2,$B$7,$B$3,$B$4,$B$5,$F15,$B$6,M$10,$A15,$B15) -> 0 | N15: =_xll.DBRW($B$1,$B$2,$B$7,$B$3,$B$4,$B$5,$F15,$B$6,N$10,$A15,$B15) -> 0 | O15: =_xll.DBRW($B$1,$B$2,$B$7,$B$3,$B$4,$B$5,$F15,$B$6,O$10,$A15,$B15) -> 0 | P15: =_xll.DBRW($B$1,$B$2,$B$7,$B$3,$B$4,$B$5,$F15,$B$6,P$10,$A15,$B15) -> 0 | Q15: =_xll.DBRW($B$1,$B$2,$B$7,$B$3,$B$4,$B$5,$F15,$B$6,Q$10,$A15,$B15) -> 0 | R15: =_xll.DBRW($B$1,$B$2,$B$7,$B$3,$B$4,$B$5,$F15,$B$6,R$10,$A15,$B15) -> 0 | S15: =_xll.DBRW($B$1,$B$2,$B$7,$B$3,$B$4,$B$5,$F15,$B$6,S$10,$A15,$B15) -> 0 | ... AE15: =_xll.DBRW($B$1,$B$2,$B$7,$B$3,$B$4,$B$5,$F15,$B$6,AE$10,$A15,$B15) -> 0
A16: 9001 - Sectors | B16: V008 - LAX - LHR | C16: LAXLHR | D16: LAX | E16: LHR | F16: A330C | L16: =_xll.DBRW($B$1,$B$2,$B$7,$B$3,$B$4,$B$5,$F16,$B$6,L$10,$A16,$B16) -> 0 | M16: =_xll.DBRW($B$1,$B$2,$B$7,$B$3,$B$4,$B$5,$F16,$B$6,M$10,$A16,$B16) -> 0 | N16: =_xll.DBRW($B$1,$B$2,$B$7,$B$3,$B$4,$B$5,$F16,$B$6,N$10,$A16,$B16) -> 0 | O16: =_xll.DBRW($B$1,$B$2,$B$7,$B$3,$B$4,$B$5,$F16,$B$6,O$10,$A16,$B16) -> 0 | P16: =_xll.DBRW($B$1,$B$2,$B$7,$B$3,$B$4,$B$5,$F16,$B$6,P$10,$A16,$B16) -> 0 | Q16: =_xll.DBRW($B$1,$B$2,$B$7,$B$3,$B$4,$B$5,$F16,$B$6,Q$10,$A16,$B16) -> 0 | R16: =_xll.DBRW($B$1,$B$2,$B$7,$B$3,$B$4,$B$5,$F16,$B$6,R$10,$A16,$B16) -> 0 | S16: =_xll.DBRW($B$1,$B$2,$B$7,$B$3,$B$4,$B$5,$F16,$B$6,S$10,$A16,$B16) -> 0 | ... AE16: =_xll.DBRW($B$1,$B$2,$B$7,$B$3,$B$4,$B$5,$F16,$B$6,AE$10,$A16,$B16) -> 0
A17: 9001 - Sectors | B17: V009 - LHR - JFK | C17: LHRJFK | D17: LHR | E17: JFK | F17: A330C | L17: =_xll.DBRW($B$1,$B$2,$B$7,$B$3,$B$4,$B$5,$F17,$B$6,L$10,$A17,$B17) -> 3 | M17: =_xll.DBRW($B$1,$B$2,$B$7,$B$3,$B$4,$B$5,$F17,$B$6,M$10,$A17,$B17) -> 4 | N17: =_xll.DBRW($B$1,$B$2,$B$7,$B$3,$B$4,$B$5,$F17,$B$6,N$10,$A17,$B17) -> 1 | O17: =_xll.DBRW($B$1,$B$2,$B$7,$B$3,$B$4,$B$5,$F17,$B$6,O$10,$A17,$B17) -> 3 | P17: =_xll.DBRW($B$1,$B$2,$B$7,$B$3,$B$4,$B$5,$F17,$B$6,P$10,$A17,$B17) -> 1 | Q17: =_xll.DBRW($B$1,$B$2,$B$7,$B$3,$B$4,$B$5,$F17,$B$6,Q$10,$A17,$B17) -> 3 | R17: =_xll.DBRW($B$1,$B$2,$B$7,$B$3,$B$4,$B$5,$F17,$B$6,R$10,$A17,$B17) -> 0 | S17: =_xll.DBRW($B$1,$B$2,$B$7,$B$3,$B$4,$B$5,$F17,$B$6,S$10,$A17,$B17) -> 0 | ... AE17: =_xll.DBRW($B$1,$B$2,$B$7,$B$3,$B$4,$B$5,$F17,$B$6,AE$10,$A17,$B17) -> 0
A18: 9001 - Sectors | B18: V010 - JFK - LHR | C18: JFKLHR | D18: JFK | E18: LHR | F18: A330C | L18: =_xll.DBRW($B$1,$B$2,$B$7,$B$3,$B$4,$B$5,$F18,$B$6,L$10,$A18,$B18) -> 1 | M18: =_xll.DBRW($B$1,$B$2,$B$7,$B$3,$B$4,$B$5,$F18,$B$6,M$10,$A18,$B18) -> 0 | N18: =_xll.DBRW($B$1,$B$2,$B$7,$B$3,$B$4,$B$5,$F18,$B$6,N$10,$A18,$B18) -> 0 | O18: =_xll.DBRW($B$1,$B$2,$B$7,$B$3,$B$4,$B$5,$F18,$B$6,O$10,$A18,$B18) -> 0 | P18: =_xll.DBRW($B$1,$B$2,$B$7,$B$3,$B$4,$B$5,$F18,$B$6,P$10,$A18,$B18) -> 0 | Q18: =_xll.DBRW($B$1,$B$2,$B$7,$B$3,$B$4,$B$5,$F18,$B$6,Q$10,$A18,$B18) -> 1 | R18: =_xll.DBRW($B$1,$B$2,$B$7,$B$3,$B$4,$B$5,$F18,$B$6,R$10,$A18,$B18) -> 0 | S18: =_xll.DBRW($B$1,$B$2,$B$7,$B$3,$B$4,$B$5,$F18,$B$6,S$10,$A18,$B18) -> 0 | ... AE18: =_xll.DBRW($B$1,$B$2,$B$7,$B$3,$B$4,$B$5,$F18,$B$6,AE$10,$A18,$B18) -> 0
A19: 9001 - Sectors | B19: V011 - LHR - BOS | C19: LHRBOS | D19: LHR | E19: BOS | F19: A330C | L19: =_xll.DBRW($B$1,$B$2,$B$7,$B$3,$B$4,$B$5,$F19,$B$6,L$10,$A19,$B19) -> 19 | M19: =_xll.DBRW($B$1,$B$2,$B$7,$B$3,$B$4,$B$5,$F19,$B$6,M$10,$A19,$B19) -> 5 | N19: =_xll.DBRW($B$1,$B$2,$B$7,$B$3,$B$4,$B$5,$F19,$B$6,N$10,$A19,$B19) -> 9 | O19: =_xll.DBRW($B$1,$B$2,$B$7,$B$3,$B$4,$B$5,$F19,$B$6,O$10,$A19,$B19) -> 3 | P19: =_xll.DBRW($B$1,$B$2,$B$7,$B$3,$B$4,$B$5,$F19,$B$6,P$10,$A19,$B19) -> 0 | Q19: =_xll.DBRW($B$1,$B$2,$B$7,$B$3,$B$4,$B$5,$F19,$B$6,Q$10,$A19,$B19) -> 2 | R19: =_xll.DBRW($B$1,$B$2,$B$7,$B$3,$B$4,$B$5,$F19,$B$6,R$10,$A19,$B19) -> 0 | S19: =_xll.DBRW($B$1,$B$2,$B$7,$B$3,$B$4,$B$5,$F19,$B$6,S$10,$A19,$B19) -> 0 | ... AE19: =_xll.DBRW($B$1,$B$2,$B$7,$B$3,$B$4,$B$5,$F19,$B$6,AE$10,$A19,$B19) -> 13
A20: 9001 - Sectors | B20: V012 - BOS - LHR | C20: BOSLHR | D20: BOS | E20: LHR | F20: A330C | L20: =_xll.DBRW($B$1,$B$2,$B$7,$B$3,$B$4,$B$5,$F20,$B$6,L$10,$A20,$B20) -> 19 | M20: =_xll.DBRW($B$1,$B$2,$B$7,$B$3,$B$4,$B$5,$F20,$B$6,M$10,$A20,$B20) -> 5 | N20: =_xll.DBRW($B$1,$B$2,$B$7,$B$3,$B$4,$B$5,$F20,$B$6,N$10,$A20,$B20) -> 9 | O20: =_xll.DBRW($B$1,$B$2,$B$7,$B$3,$B$4,$B$5,$F20,$B$6,O$10,$A20,$B20) -> 3 | P20: =_xll.DBRW($B$1,$B$2,$B$7,$B$3,$B$4,$B$5,$F20,$B$6,P$10,$A20,$B20) -> 0 | Q20: =_xll.DBRW($B$1,$B$2,$B$7,$B$3,$B$4,$B$5,$F20,$B$6,Q$10,$A20,$B20) -> 2 | R20: =_xll.DBRW($B$1,$B$2,$B$7,$B$3,$B$4,$B$5,$F20,$B$6,R$10,$A20,$B20) -> 0 | S20: =_xll.DBRW($B$1,$B$2,$B$7,$B$3,$B$4,$B$5,$F20,$B$6,S$10,$A20,$B20) -> 0 | ... AE20: =_xll.DBRW($B$1,$B$2,$B$7,$B$3,$B$4,$B$5,$F20,$B$6,AE$10,$A20,$B20) -> 13
A21: 9001 - Sectors | B21: V019 - LHR - SFO | C21: LHRSFO | D21: LHR | E21: SFO | F21: A330C | L21: =_xll.DBRW($B$1,$B$2,$B$7,$B$3,$B$4,$B$5,$F21,$B$6,L$10,$A21,$B21) -> 0 | M21: =_xll.DBRW($B$1,$B$2,$B$7,$B$3,$B$4,$B$5,$F21,$B$6,M$10,$A21,$B21) -> 0 | N21: =_xll.DBRW($B$1,$B$2,$B$7,$B$3,$B$4,$B$5,$F21,$B$6,N$10,$A21,$B21) -> 0 | O21: =_xll.DBRW($B$1,$B$2,$B$7,$B$3,$B$4,$B$5,$F21,$B$6,O$10,$A21,$B21) -> 0 | P21: =_xll.DBRW($B$1,$B$2,$B$7,$B$3,$B$4,$B$5,$F21,$B$6,P$10,$A21,$B21) -> 0 | Q21: =_xll.DBRW($B$1,$B$2,$B$7,$B$3,$B$4,$B$5,$F21,$B$6,Q$10,$A21,$B21) -> 0 | R21: =_xll.DBRW($B$1,$B$2,$B$7,$B$3,$B$4,$B$5,$F21,$B$6,R$10,$A21,$B21) -> 0 | S21: =_xll.DBRW($B$1,$B$2,$B$7,$B$3,$B$4,$B$5,$F21,$B$6,S$10,$A21,$B21) -> 0 | ... AE21: =_xll.DBRW($B$1,$B$2,$B$7,$B$3,$B$4,$B$5,$F21,$B$6,AE$10,$A21,$B21) -> 0
A22: 9001 - Sectors | B22: V020 - SFO - LHR | C22: SFOLHR | D22: SFO | E22: LHR | F22: A330C | L22: =_xll.DBRW($B$1,$B$2,$B$7,$B$3,$B$4,$B$5,$F22,$B$6,L$10,$A22,$B22) -> 0 | M22: =_xll.DBRW($B$1,$B$2,$B$7,$B$3,$B$4,$B$5,$F22,$B$6,M$10,$A22,$B22) -> 0 | N22: =_xll.DBRW($B$1,$B$2,$B$7,$B$3,$B$4,$B$5,$F22,$B$6,N$10,$A22,$B22) -> 0 | O22: =_xll.DBRW($B$1,$B$2,$B$7,$B$3,$B$4,$B$5,$F22,$B$6,O$10,$A22,$B22) -> 0 | P22: =_xll.DBRW($B$1,$B$2,$B$7,$B$3,$B$4,$B$5,$F22,$B$6,P$10,$A22,$B22) -> 0 | Q22: =_xll.DBRW($B$1,$B$2,$B$7,$B$3,$B$4,$B$5,$F22,$B$6,Q$10,$A22,$B22) -> 0 | R22: =_xll.DBRW($B$1,$B$2,$B$7,$B$3,$B$4,$B$5,$F22,$B$6,R$10,$A22,$B22) -> 0 | S22: =_xll.DBRW($B$1,$B$2,$B$7,$B$3,$B$4,$B$5,$F22,$B$6,S$10,$A22,$B22) -> 0 | ... AE22: =_xll.DBRW($B$1,$B$2,$B$7,$B$3,$B$4,$B$5,$F22,$B$6,AE$10,$A22,$B22) -> 0
... A682: 9001 - Sectors | B682: V479 - CPT - LHR | C682: CPTLHR | D682: CPT | E682: LHR | F682: B787GEN | L682: =_xll.DBRW($B$1,$B$2,$B$7,$B$3,$B$4,$B$5,$F682,$B$6,L$10,$A682,$B682) -> 0 | M682: =_xll.DBRW($B$1,$B$2,$B$7,$B$3,$B$4,$B$5,$F682,$B$6,M$10,$A682,$B682) -> 0 | N682: =_xll.DBRW($B$1,$B$2,$B$7,$B$3,$B$4,$B$5,$F682,$B$6,N$10,$A682,$B682) -> 0 | O682: =_xll.DBRW($B$1,$B$2,$B$7,$B$3,$B$4,$B$5,$F682,$B$6,O$10,$A682,$B682) -> 0 | P682: =_xll.DBRW($B$1,$B$2,$B$7,$B$3,$B$4,$B$5,$F682,$B$6,P$10,$A682,$B682) -> 0 | Q682: =_xll.DBRW($B$1,$B$2,$B$7,$B$3,$B$4,$B$5,$F682,$B$6,Q$10,$A682,$B682) -> 5 | R682: =_xll.DBRW($B$1,$B$2,$B$7,$B$3,$B$4,$B$5,$F682,$B$6,R$10,$A682,$B682) -> 30 | S682: =_xll.DBRW($B$1,$B$2,$B$7,$B$3,$B$4,$B$5,$F682,$B$6,S$10,$A682,$B682) -> 31 | ... AE682: =_xll.DBRW($B$1,$B$2,$B$7,$B$3,$B$4,$B$5,$F682,$B$6,AE$10,$A682,$B682) -> 31

Sheet Load Factor (live)
A1: CUBE: | B1: =_xll.VIEW("planning:oraclegl-reporting",$B$2,$B$7,$B$3,$B$4,$B$5,"!",$B$6,"!","!","!") -> planning:oraclegl-reporting
A2: translation | B2: =_xll.SUBNM("planning:translation","","translated") -> translated
A3: sob | B3: =_xll.SUBNM("planning:sob","","Total SOB") -> Total SOB
A4: lob | B4: =_xll.SUBNM("planning:lob","","VA") -> VA
A5: currency | B5: =_xll.SUBNM("planning:currency","","Total Currency") -> Total Currency
A6: rcentre | B6: =_xll.SUBNM("planning:rcentre","Default","VALT","desc") -> VALT - Total VAAL
A7: versionreporting | B7: Outlook
B10: Flight | C10: Route | D10: DEP | E10: ARR | F10: SubNom2 | G10: Ye Dec2024 | H10: Jan2024 | I10: Feb2024 | J10: Mar2024 | K10: Apr2024 | L10: May2024 | M10: Jun2024 | N10: Jul2024 | O10: Aug2024 | P10: Sep2024 | Q10: Oct2024 | R10: Nov2024 | S10: Dec2024 | T10: Jan2025 | U10: Feb2025 | V10: Mar2025 | W10: Apr2025 | X10: May2025 | Y10: Jun2025 | Z10: Jul2025 | AA10: Aug2025 | AB10: Sep2025 | AC10: Oct2025 | AD10: Nov2025 | AE10: Dec2025
A11: 9007 - ASKs | B11: V003 - LHR - JFK | C11: LHRJFK | D11: LHR | E11: JFK | F11: J | L11: =IFERROR('RPK (live)'!L11/'ASK (live)'!L11,"-") -> 0.830579 | M11: =IFERROR('RPK (live)'!M11/'ASK (live)'!M11,"-") -> 0.89083235 | N11: =IFERROR('RPK (live)'!N11/'ASK (live)'!N11,"-") -> 0.89886259 | O11: =IFERROR('RPK (live)'!O11/'ASK (live)'!O11,"-") -> 0.85709241 | P11: =IFERROR('RPK (live)'!P11/'ASK (live)'!P11,"-") -> 0.90360791 | Q11: =IFERROR('RPK (live)'!Q11/'ASK (live)'!Q11,"-") -> 0.94164683 | R11: =IFERROR('RPK (live)'!R11/'ASK (live)'!R11,"-") -> 0.90506351 | S11: =IFERROR('RPK (live)'!S11/'ASK (live)'!S11,"-") -> 0.90603931 | ... AE11: =IFERROR('RPK (live)'!AE11/'ASK (live)'!AE11,"-") -> 0.87997398
A12: 9007 - ASKs | B12: V004 - JFK - LHR | C12: JFKLHR | D12: JFK | E12: LHR | F12: J | L12: =IFERROR('RPK (live)'!L12/'ASK (live)'!L12,"-") -> 0.830579 | M12: =IFERROR('RPK (live)'!M12/'ASK (live)'!M12,"-") -> 0.89083235 | N12: =IFERROR('RPK (live)'!N12/'ASK (live)'!N12,"-") -> 0.89886259 | O12: =IFERROR('RPK (live)'!O12/'ASK (live)'!O12,"-") -> 0.85709241 | P12: =IFERROR('RPK (live)'!P12/'ASK (live)'!P12,"-") -> 0.90360791 | Q12: =IFERROR('RPK (live)'!Q12/'ASK (live)'!Q12,"-") -> 0.94164683 | R12: =IFERROR('RPK (live)'!R12/'ASK (live)'!R12,"-") -> 0.90506351 | S12: =IFERROR('RPK (live)'!S12/'ASK (live)'!S12,"-") -> 0.90603931 | ... AE12: =IFERROR('RPK (live)'!AE12/'ASK (live)'!AE12,"-") -> 0.87997398
A13: 9007 - ASKs | B13: V005 - LHR - MIA | C13: LHRMIA | D13: LHR | E13: MIA | F13: J | L13: =IFERROR('RPK (live)'!L13/'ASK (live)'!L13,"-") -> 0.83 | M13: =IFERROR('RPK (live)'!M13/'ASK (live)'!M13,"-") -> 0.91124287 | N13: =IFERROR('RPK (live)'!N13/'ASK (live)'!N13,"-") -> 0.85 | O13: =IFERROR('RPK (live)'!O13/'ASK (live)'!O13,"-") -> 0.82 | P13: =IFERROR('RPK (live)'!P13/'ASK (live)'!P13,"-") -> 0.8 | Q13: =IFERROR('RPK (live)'!Q13/'ASK (live)'!Q13,"-") -> 0.87 | R13: =IFERROR('RPK (live)'!R13/'ASK (live)'!R13,"-") -> 0.85 | S13: =IFERROR('RPK (live)'!S13/'ASK (live)'!S13,"-") -> 0.85 | ... AE13: =IFERROR('RPK (live)'!AE13/'ASK (live)'!AE13,"-") -> 0.80748062
A14: 9007 - ASKs | B14: V006 - MIA - LHR | C14: MIALHR | D14: MIA | E14: LHR | F14: J | L14: =IFERROR('RPK (live)'!L14/'ASK (live)'!L14,"-") -> 0.83 | M14: =IFERROR('RPK (live)'!M14/'ASK (live)'!M14,"-") -> 0.91124287 | N14: =IFERROR('RPK (live)'!N14/'ASK (live)'!N14,"-") -> 0.85 | O14: =IFERROR('RPK (live)'!O14/'ASK (live)'!O14,"-") -> 0.82 | P14: =IFERROR('RPK (live)'!P14/'ASK (live)'!P14,"-") -> 0.8 | Q14: =IFERROR('RPK (live)'!Q14/'ASK (live)'!Q14,"-") -> 0.87 | R14: =IFERROR('RPK (live)'!R14/'ASK (live)'!R14,"-") -> 0.85 | S14: =IFERROR('RPK (live)'!S14/'ASK (live)'!S14,"-") -> 0.85 | ... AE14: =IFERROR('RPK (live)'!AE14/'ASK (live)'!AE14,"-") -> 0.80748062
