Workbook
Name _Hlk503992398: 'SPML POML'!$C$3
Name CDﾚｰﾄ: #REF!
Name DATA: [1]DATA!$C:$J
Name DB_◆新マスタ09値: #REF!
Name DB_AF07Bコード: #REF!
Name DB_AF07Bコード新: #REF!
Name DB_NEW: #REF!
Name DB_SK07Bコード現: #REF!
Name JL0004_1月: "DB_JAL07便別情報"
Name MMレート: #REF!
Name Newagain: #REF!
Name Newagains: #REF!
Name Newcc: #REF!
Name Newname: #REF!
Name NEWSAS: #REF!

Sheet PL spec codes C1-3
A1: Caterer: TBD | Station: ATL | B1: Concept: 01JUN24 | Version: 1 | Updated: 05DEC23
A2: C1-C4 Overview all spec Codes
A3: SAS IFX Spec Code | B3: SAS IFX Description | C3: Weight / Pc | D3: Unit of M | E3: Quality, supplier, origin, comments | F3: Direct Material | G3: Direct Labor | H3: Selling Price ex contrubtion | I3: Class | J3: Loading Instructions (Widebody) | K3: Note
A4: 4ATL-411050 | B4: IC C S1 CUTLERY C1-4 | F4: =SUM(F5:F13) -> 0 | G4: =SUM(G5:G13) -> 0 | H4: =SUM(F4:G4) -> 0 | I4: C | J4: Fix Qty 40
A5: 2ATL-411011 | B5: IC C S1 SALAD C1 | I5: C | J5: Load Scale IC-27
A6: 2ATL-411012 | B6: IC C S1 SALAD C2 | I6: C | J6: Load Scale IC-27
A7: 2ATL-411013 | B7: IC C S1 SALAD C3 | I7: C | J7: Load Scale IC-27
A8: 2ATL-411031 | B8: IC C S1 SA GARNISH C1 | I8: C | J8: Fix Qty 2
A9: 2ATL-411050 | B9: IC C S1+S2 BUTTER C1-4 | I9: C | J9: 1
A10: 2ATL-411061 | B10: IC C S1 ST-A MEAT C1 | I10: C | J10: 60% (U)
A11: 2ATL-411071 | B11: IC C S1 ST-B FISH C1 | I11: C | J11: 60% (D)
A12: 2ATL-411081 | B12: IC C S1 ST GARNISH C1 | I12: C | J12: Fix Qty 2 | M12: =SUM(M13:M21) -> 0 | N12: =SUM(N13:N21) -> 0
A13: 2ATL-411091 | B13: IC C S1 HM-A MEAT C1 | I13: C | J13: 30% (U)
A14: 2ATL-411101 | B14: IC C S1 HM-B FISH C1 | I14: C | J14: 35% (D)
A15: 2ATL-411111 | B15: IC C S1 HM-C POULTRY C1 | I15: C | J15: 35% (D)
A16: 2ATL-411121 | B16: IC C S1 HM-D VEG C1 | I16: C | J16: 20% (U)
A17: 2ATL-411131 | B17: IC C S1 HM GARNISH C1 | I17: C | J17: Fix Qty 2
A18: 2ATL-411141 | B18: IC C S1 DE CHEESE C1 | I18: C | J18: Load Scale IC-27
A19: 2ATL-411151 | B19: IC C S1 DE CAKE C1 | I19: C | J19: Load Scale IC-27
A20: 2ATL-411161 | B20: IC C S1 DE CAKE GARNISH C1 | I20: C | J20: Fix Qty 2
A21: 2ATL-411171 | B21: IC C S1 DE ICE CREAM C1 | I21: C | J21: 60% (N)
A22: 2ATL-411180 | B22: IC C S1 DE FRUIT C1 | I22: C | J22: Load Scale IC-27
A23: 2ATL-411181 | B23: IC C S1 DE FRUIT C2 | I23: C | J23: Load Scale IC-27
A24: 2ATL-411182 | B24: IC C S1 DE FRUIT C3 | I24: C | J24: Load Scale IC-27
A25: 4ATL-411010 | B25: IC C S1 BRD Type 1 C1-4 | I25: C | J25: 75% (N) | K25: Min qty 5.
A26: 4ATL-411020 | B26: IC C S1+S2 BRD Type 2 C1-4 | I26: C | J26: 75% (N) | K26: Min qty 5.
A27: 4ATL-411030 | B27: IC C S1 BRD Type 3 C1-4 | I27: C | J27: Fix Qty 2
A28: 2ATL-411032 | B28: IC C S1 SA GARNISH C2 | I28: C | J28: Fix Qty 2
A29: 2ATL-411062 | B29: IC C S1 ST-A MEAT C2 | I29: C | J29: 60% (U)
A30: 2ATL-411072 | B30: IC C S1 ST-B FISH C2 | I30: C | J30: 60% (D)
A31: 2ATL-411082 | B31: IC C S1 ST GARNISH C2 | I31: C | J31: Fix Qty 2
A32: 2ATL-411092 | B32: IC C S1 HM-A MEAT C2 | I32: C | J32: 30% (U)
A33: 2ATL-411102 | B33: IC C S1 HM-B FISH C2 | I33: C | J33: 35% (D)
A34: 2ATL-411112 | B34: IC C S1 HM-C POULTRY C2 | I34: C | J34: 35% (D)
A35: 2ATL-411122 | B35: IC C S1 HM-D VEG C2 | I35: C | J35: 20% (U)
A36: 2ATL-411132 | B36: IC C S1 HM GARNISH C2 | I36: C | J36: Fix Qty 2
A37: 2ATL-411142 | B37: IC C S1 DE CHEESE C2 | I37: C | J37: Load Scale IC-27
A38: 2ATL-411152 | B38: IC C S1 DE CAKE C2 | I38: C | J38: Load Scale IC-27
... A53: 2ATL-411173 | B53: IC C S1 DE ICE CREAM C3 | I53: C | J53: 60% (N)
A54: 3ATL-412010 | B54: IC C S2 TSU C1 | I54: C | J54: 1
...

Sheet SPML POML
B2: SPECIAL MEALS (SPML) | D2: SPECIAL MEALS (SPML) | F2: PRE-ORDER MEALS (POML) | H2: SPECIAL MEALS (SPML) | I2: Note | J2: Description of meal
B3: LH Business & Plus class | D3: LH Go class | F3: LH for GO pax | H3: LH for CREW
B6: AVML | D6: ADML | F6: - | H6: - | I6: 1st & 2nd Service | J6: Asian vegetarian, spicy (may contain eggs and/or dairy)
B7: CHML | D7: CDML | F7: - | H7: - | I7: 1st & 2nd Service | J7: Child meal
B8: LGML | D8: GCML | F8: - | H8: LGML | I8: 1st & 2nd Service | J8: A meal adapted to gluten and lactose intolerance
B9: VLML | D9: EVML | F9: - | H9: VLML | I9: 1st & 2nd Service | J9: A lacto-ovo vegetarian meal (contains eggs and/or dairy)
B10: VGML | D10: VVML | F10: - | H10: VGML | I10: 1st & 2nd Service | J10: A vegan vegetarian meal
B11: - | D11: - | F11: FIML | H11: - | I11: ONLY 1st Service | J11: SAS Premium Menu – Fish, N.B. only available in SAS GO | K11: Plus TSU with Business class Hot meal in YM Disposable casserole
B12: - | D12: - | F12: MEML | H12: - | I12: ONLY 1st Service | J12: SAS Premium Menu – Meat, N.B. only available in SAS GO | K12: Plus TSU with Business class Hot meal in YM Disposable casserole
B13: - | D13: - | F13: CKML | H13: - | I13: ONLY 1st Service | J13: SAS Premium Menu – Poultry, N.B. only available in SAS GO | K13: Plus TSU with Business class Hot meal in YM Disposable casserole
B14: - | D14: - | F14: GHML | H14: - | I14: 1st & 2nd Service | J14: SAS Premium Menu – Green, N.B. only available in SAS GO, Lacto ovo veg For 2nd service when ordering GHML - EVML should be provided (vegetarian lacto-ovo meal) | K14: Plus TSU with Business class Hot meal in YM Disposable casserole

Sheet Read First
B1: READ FIRST - Instructions
B3: To be able to fill in the quotation in this RFP overview it is of importance to understand SAS by reading and understanding the below information:
B4: Please study supporting documentation in suggested order in the RFP intro letter.
B5: SAS Gastronomic Guidelines. The document that describes the main frame work for SAS Gastronomical values and guidelines.
B6: How to fill out the cost sheets:
B7: Cycle 1 is only as a guiding reference as for the meals and shall not be calculated.
B8: For cycle 2 and 3, Please fill in your proposals of suggested meals, products and rawmaterials into SAS framework of concept of equipment per your optimizied sourcing, supply chain and production methods.
B9: Cycle 2 is set with a total cost with a cap per pax per class with an A350 configuration and load factor.
B10: Cycle 2 Max cost for Business Class for all services including contribution for a regular meal of 40 USD.
B11: Cycle 2 Max cost for SAS Plus for all services including contributionfor are for a regular meal of 22 USD.
B12: Cycle 2 Max cost for SAS Go all services including contribution for a regular meal of 15 USD.
B13: Cycle 3 is your proposed menu without any budget cap of max cost. The total cost per pax per class for all regular may be higher or lower and than cycle 2.
... B29: All other cells shall not be changed or altered.
B43: Brand/Origin/Quality grade | C43: This information is fundamental to understand in what extent the product choosen relate to SAS Gastronomic Guidelines
B44: Nominated SAS owned product | C44: Owned and supplied by SAS
B45: Selected SAS nominated product | C45: Purchased by caterer and supplied direct to the units by the nominated supplier. Invoiced to SAS by caterer as part of the meal cost.
B47: Abbreviations
B48: IC | C48: Long Haul, Intercontinental routes to/from the North America and Asia according SAS traffic program
B49: P | C49: Flight deck Crew meal, 2 flight deck crew meal per flight as present standard. Crew can chose to opt out crew meal.
B50: K | C50: Cabin Crew meal, 8 crew for A330 and 9 crew for A350 per flight as present standard. Crew can chose to opt out crew meal.
B51: C | C51: SAS Business class
B52: Y | C52: SAS class equivallent to premium economy class
B53: M | C53: SAS class equivallent to economy class
B54: C, C1-4 (C1, C2 etc) | C54: Cycle or menu. The naming of a certain menu running for a set period
B55: CB | C55: Cold Breakfast
B56: HB | C56: Hot Breakfast
B57: CM | C57: Cold Meal
B58: HM | C58: Hot Meal
B59: TSU | C59: Tray setup
... B68: Selling price | C68: Total dM and total dL summarized
B71: Evaluation
B72: Evaluation of the submission in this RFP document will be on total dM, total dL and how the gastromomic guidelines are adheard to and described in the column Brand/Origin/Quality grade
B73: If a generic product on a raw material is used describe it as generic and origin.
B75: Note
B76: Approximately 10% of crew meals are special meals.
B78: SAS Special meals and Pre order meal codes:
B96: MEML SAS Premium Menu – Meat, N.B. only available in SAS GO. SAS Plus 1st serving Tray setup with the Business class Hot meal Meat portioned the aluminium disposable casserole 973113 and lid 973114. Regular 2nd service
B97: CKML SAS Premium Menu – Poultry, N.B. only available in SAS GO. SAS Plus 1st serving Tray setup with the Business class Hot meal Chicken portioned the aluminium disposable casserole 973113 and lid 973114. Regular 2nd service
B98: GHML SAS Premium Menu – Green, N.B. only available in SAS GO, Lacto ovo veg. SAS Plus 1st serving Tray setup with the Business class Hot meal fish portioned the aluminium disposable casserole 973113 and lid 973114 and 2nd serivce EVML

Sheet CS C C1-3
A1: Caterer: TBD | B1: Station: ATL | C1: Concept: 01JUN24 | Version: 1 | Updated: 15DEC23 Currency USD
B2: CS C spec codes C1-3 | C2: BUSINESS CLASS
A3: Supplier, please fill in name of Company in the first row | B3: SAS IFX Spec Code | C3: SAS IFX Description | D3: Weight / Pc | E3: Unit of M | F3: Quality, brand, supplier, origin, comments | G3: Direct Material | H3: Direct Labor | I3: Selling Price ex contrubtion | J3: Class | K3: Loading Instructions N.B only information | L3: Note | M3: Cycle / Menu | N3: Dish Name
A4: Please fill in Supplier Name | B4: 4ATL-411050C2 | C4: IC C S1 CUTLERY C2 | G4: =SUM(G5:G13) -> 0 | H4: =SUM(H5:H13) -> 1.04 | I4: =SUM(G4:H4) -> 1.04 | J4: C | K4: Fix Qty 40 | M4: C2 | N4: Cutlery pack
C5: Napkin/Tablecloth, Poly/Cotton, Grey | D5: 1 | E5: Pc | G5: 0 | H5: 0.09 | L5: 972062
C6: Knife, Stainless, RS | D6: 3 | E6: Pc | G6: 0 | H6: 0.27 | L6: 971090
C7: Fork, Stainless, RS | D7: 3 | E7: Pc | G7: 0 | H7: 0.27 | L7: 971091
C8: Spoon, Stainless, Dessert/Soup, RS | D8: 1 | E8: Pc | G8: 0 | H8: 0.27 | L8: 971093
C9: Salt & Pepper, Twinpack | D9: 1 | E9: Pc | G9: 0 | H9: 0.09 | L9: 973034
C10: Toothpick, Individually Packed | D10: 1 | E10: Pc | G10: 0 | H10: 0.05 | L10: 973020
A15: =$A$4 -> Please fill in Supplier Name | B15: 4ATL-411050C3 | C15: IC C S1 CUTLERY C3 | G15: =SUM(G16:G24) -> 0 | H15: =SUM(H16:H24) -> 1.04 | I15: =SUM(G15:H15) -> 1.04 | J15: C | K15: Fix Qty 40 | M15: C3 | N15: Cutlery pack
C16: Napkin/Tablecloth, Poly/Cotton, Grey | D16: 1 | E16: Pc | G16: 0 | H16: 0.09 | L16: 972062
C17: Knife, Stainless, RS | D17: 3 | E17: Pc | G17: 0 | H17: 0.27 | L17: 971090
C18: Fork, Stainless, RS | D18: 3 | E18: Pc | G18: 0 | H18: 0.27 | L18: 971091
C19: Spoon, Stainless, Dessert/Soup, RS | D19: 1 | E19: Pc | G19: 0 | H19: 0.27 | L19: 971093
C20: Salt & Pepper, Twinpack | D20: 1 | E20: Pc | G20: 0 | H20: 0.09 | L20: 973034
C21: Toothpick, Individually Packed | D21: 1 | E21: Pc | G21: 0 | H21: 0.05 | L21: 973020
A26: =$A$4 -> Please fill in Supplier Name | B26: 2ATL-411011 | C26: IC C S1 SALAD C1 | G26: =SUM(G27:G29) -> 0 | H26: =SUM(H27:H29) -> 0 | I26: =SUM(G26:H26) -> 0 | J26: C | K26: Load Scale IC-27 | M26: C1 | N26: Starter salad
C27: Mixed salad leaves | D27: 15 | E27: gm | F27: Seasonal
A31: =$A$4 -> Please fill in Supplier Name | B31: 2ATL-411012 | C31: IC C S1 SALAD C2 | G31: =SUM(G32:G34) -> 0 | H31: =SUM(H32:H34) -> 0 | I31: =SUM(G31:H31) -> 0 | J31: C | K31: Load Scale IC-27 | M31: C2 | N31: Starter salad
C32: Mesclun Mixed Greens | D32: 15 | E32: gm
C33: Heirloom Cherry/Grape tomato | D33: 15 | E33: gm
C34: Cucumber Slices | D34: 2 | E34: each
A36: =$A$4 -> Please fill in Supplier Name | B36: 2ATL-411013 | C36: IC C S1 SALAD C3 | G36: =SUM(G37:G39) -> 0 | H36: =SUM(H37:H39) -> 0 | I36: =SUM(G36:H36) -> 0 | J36: C | K36: Load Scale IC-27 | M36: C3 | N36: Starter salad
C37: Baby Arugula | D37: 15 | E37: gm
C38: Aromatic Poached Bosc Pear | D38: 15 | E38: gm | F38: Premium Produced Product Locally Produced
C39: Goat Cheese | D39: 10 | E39: gm
A41: =$A$4 -> Please fill in Supplier Name | B41: 2ATL-411031 | C41: IC C S1 SA GARNISH C1 | G41: =SUM(G42:G44) -> 0 | H41: =SUM(H42:H44) -> 0 | I41: =SUM(G41:H41) -> 0 | J41: C | K41: Fix Qty 2 | M41: C1 | N41: Salad side garnish
C42: Shaved watermelon radish 1 mm | D42: 3 | E42: Gm
A46: =$A$4 -> Please fill in Supplier Name | B46: 2ATL-411032 | C46: IC C S1 SA GARNISH C2 | G46: =SUM(G47:G49) -> 0 | H46: =SUM(H47:H49) -> 0 | I46: =SUM(G46:H46) -> 0 | J46: C | K46: Fix Qty 2 | M46: C2 | N46: Salad garnish
C47: Toasted Sunflower Seeds | D47: 3 | E47: gm
A51: =$A$4 -> Please fill in Supplier Name | B51: 2ATL-411033 | C51: IC C S1 SA GARNISH C3 | G51: =SUM(G52:G54) -> 0 | H51: =SUM(H52:H54) -> 0 | I51: =SUM(G51:H51) -> 0 | J51: C | K51: Fix Qty 2 | M51: C3 | N51: Garnish
C52: Toasted Pepitas | D52: 3 | E52: gm
A56: =$A$4 -> Please fill in Supplier Name | B56: 2ATL-411050 | C56: IC C S1+S2 BUTTER C1 | G56: =SUM(G57:G59) -> 0 | H56: =SUM(H57:H59) -> 0 | I56: =SUM(G56:H56) -> 0 | J56: C | K56: 1 | M56: C1 | N56: Butter
C57: Butter puck salted | D57: 10 | E57: gm | F57: Organic valley
A61: =$A$4 -> Please fill in Supplier Name | B61: 2ATL-411050C2 | C61: IC C S1+S2 BUTTER C2 | G61: =SUM(G62:G64) -> 0 | H61: =SUM(H62:H64) -> 0 | I61: =SUM(G61:H61) -> 0 | J61: C | K61: 1 | M61: C2 | N61: Butter
C62: Banner Butter | D62: 1 | E62: each | F62: Locally Sourced Sustainable Butter 1/2 oz. UW
A66: =$A$4 -> Please fill in Supplier Name | B66: 2ATL-411050C3 | C66: IC C S1+S2 BUTTER C3 | G66: =SUM(G67:G69) -> 0 | H66: =SUM(H67:H69) -> 0 | I66: =SUM(G66:H66) -> 0 | J66: C | K66: 1 | M66: C3 | N66: Butter
C67: Banner Butter | D67: 1 | E67: each | F67: Locally Sourced Sustainable Butter 1/2 oz. UW
A71: =$A$4 -> Please fill in Supplier Name | B71: 2ATL-411061 | C71: IC C S1 ST-A MEAT C1 | G71: =SUM(G72:G80) -> 0 | H71: =SUM(H72:H80) -> 0 | I71: =SUM(G71:H71) -> 0 | J71: C | K71: 60% (U) | M71: C1 | N71: Butcher board
...

Sheet CS Y C1-3
A1: Caterer: TBD | B1: | Station: ATL | C1: Concept: 01JUN24 | Version: 1 | Updated: 15DEC23 Currency USD
B2: CS Y spec codes C1-3 | C2: PLUS (PREMIUM ECO)
A3: Supplier, please fill in name of Company in the first row | B3: SAS IFX Spec Code | C3: SAS IFX Description | D3: Weight / Pc | E3: Unit of M | F3: Quality, brand, supplier, origin, comments | G3: Direct Material | H3: Direct Labor | I3: Selling Price ex contrubtion | J3: Class | K3: Loading Instructions N.B only information | L3: Note | M3: Cycle / Menu | N3: Dish Name
A4: ='CS C C1-3'!$A$4 -> Please fill in Supplier Name | B4: 3ATL-421010C2 | C4: IC Y S1 TSU C2 | G4: =SUM(G5:G18) -> 0 | H4: =SUM(H5:H18) -> 1.06 | I4: =SUM(G4:H4) -> 1.06 | J4: Y | K4: 1 | M4: C2 | N4: Tray setup
C5: Tray, Food, Large, ATLAS | D5: 1 | E5: Pc | G5: 0 | H5: 0.09 | L5: 971168
C6: Traymat, Large, Black, Disposable | D6: 1 | E6: Pc | G6: 0 | H6: 0.05 | L6: 973186
C7: Bag, For Cutlery | D7: 1 | E7: Pc | G7: 0 | H7: 0.05 | L7: 973012
C8: 1 x Fork, Stainless, RS | D8: 1 | E8: Pc | G8: 0 | H8: 0.09 | L8: 971091
C9: 1 x Spoon, Stainless, Coffee/Tea, RS | D9: 1 | E9: Pc | G9: 0 | H9: 0.09 | L9: 971092
C10: 1 x Spoon, Stainless, Dessert/Soup, RS | D10: 1 | E10: Pc | G10: 0 | H10: 0.09 | L10: 971093
C11: 1 x Knife, Stainless, RS | D11: 1 | E11: Pc | G11: 0 | H11: 0.09 | L11: 971090
C12: 1 x Napkin, Paper, White | D12: 1 | E12: Pc | G12: 0 | H12: 0.05 | L12: 973099
C13: 1 x Sugar, Portion Packed | D13: 1 | E13: Pc | G13: 0 | H13: 0.05 | L13: 973023
C14: 1 x Salt & Pepper, Twinpack | D14: 1 | E14: Pc | G14: 0 | H14: 0.09 | L14: 973034
C15: 1 x Toothpick, Individually Packed | D15: 1 | E15: Pc | G15: 0 | H15: 0.05
C16: Portioned packed butter 10-15 gm | D16: 1 | E16: Pc | H16: 0.09
C17: Portioned packed cracker | D17: 1 | E17: Pc | H17: 0.09
C18: Portioned packed cheese 15 g | D18: 1 | E18: Pc | H18: 0.09 | L18: 973020
A20: =$A$4 -> Please fill in Supplier Name | B20: 3ATL-421010C3 | C20: IC Y S1 TSU C3 | G20: =SUM(G21:G33) -> 0 | H20: =SUM(H21:H33) -> 1.01 | I20: =SUM(G20:H20) -> 1.01 | J20: Y | K20: 1 | M20: C3 | N20: Tray setup
C21: Tray, Food, Large, ATLAS | D21: 1 | E21: Pc | G21: 0 | H21: 0.09 | L21: 971168
C22: Traymat, Large, Black, Disposable | D22: 1 | E22: Pc | G22: 0 | H22: 0.05 | L22: 973186
C23: Bag, For Cutlery | D23: 1 | E23: Pc | G23: 0 | H23: 0.05 | L23: 973012
C24: 1 x Fork, Stainless, RS | D24: 1 | E24: Pc | G24: 0 | H24: 0.09 | L24: 971091
C25: 1 x Spoon, Stainless, Coffee/Tea, RS | D25: 1 | E25: Pc | G25: 0 | H25: 0.09 | L25: 971092
C26: 1 x Spoon, Stainless, Dessert/Soup, RS | D26: 1 | E26: Pc | G26: 0 | H26: 0.09 | L26: 971093
C27: 1 x Knife, Stainless, RS | D27: 1 | E27: Pc | G27: 0 | H27: 0.09 | L27: 971090
C28: 1 x Napkin, Paper, White | D28: 1 | E28: Pc | G28: 0 | H28: 0.05 | L28: 973099
C29: 1 x Sugar, Portion Packed | D29: 1 | E29: Pc | G29: 0 | H29: 0.05 | L29: 973023
C30: 1 x Salt & Pepper, Twinpack | D30: 1 | E30: Pc | G30: 0 | H30: 0.09 | L30: 973034
C31: Portioned packed butter 10-15 gm | D31: 1 | E31: Pc | H31: 0.09
C32: Portioned packed cracker | D32: 1 | E32: Pc | H32: 0.09
C33: Portioned packed cheese 15 g | D33: 1 | E33: Pc | H33: 0.09
A35: =$A$4 -> Please fill in Supplier Name | B35: 2ATL-421011 | C35: IC Y S1 ST C1 | G35: =SUM(G36:G44) -> 0 | H35: =SUM(H36:H44) -> 0 | I35: =SUM(G35:H35) -> 0 | J35: Y | K35: 1 | M35: C1 | N35: Local air dried ham with broccoli slaw and kale grain salad
C36: Local air dried ham x 2 slices | D36: 15 | E36: Gm
C37: Kale grain salad | D37: 20 | E37: Gm
C38: Broccoli slaw | D38: 35 | E38: Gm
A46: =$A$4 -> Please fill in Supplier Name | B46: 2ATL-421012 | C46: IC Y S1 ST C2 | G46: =SUM(G47:G55) -> 0 | H46: =SUM(H47:H55) -> 0 | I46: =SUM(G46:H46) -> 0 | J46: Y | K46: 1 | M46: C2
C47: Black Forest Ham Slice | D47: 2pc x 15 | E47: gm
C48: Farro Salad | D48: 30 | E48: gm
C49: Horseradish Slaw | D49: 30 | E49: gm
...

Sheet CS M C1-3
A1: Caterer: TBD | B1: Station: ATL | C1: Concept: 01JUN24 | Version: 1 | Updated: 15DEC23 Currency USD
B2: CS M spec codes C1-3 | C2: GO (ECONOMY)
A3: Supplier, please fill in name of Company in the first row | B3: SAS IFX Spec Code | C3: SAS IFX Description | D3: Weight / Pc | E3: Unit of M | F3: Quality, brand, supplier, origin, comments | G3: Direct Material | H3: Direct Labor | I3: Selling Price ex contrubtion | J3: Class | K3: Loading Instructions N.B only information | L3: Note | M3: Cycle / Menu | N3: Dish Name
A4: ='CS C C1-3'!$A$4 -> Please fill in Supplier Name | B4: 3ATL-431010C2 | C4: IC M S1 TSU C2 | G4: =SUM(G5:G14) -> 0 | H4: =SUM(H5:H14) -> 0.62 | I4: =SUM(G4:H4) -> 0.62 | J4: M | K4: 1 | M4: C1 | N4: Tray Setup
C5: Tray, Food, Medium, ATLAS | D5: 1 | E5: Pc | G5: 0 | H5: 0.09 | L5: 971167
C6: 1 x Traymat, Medium, Anti-Skid, Disposable | D6: 1 | E6: Pc | G6: 0 | H6: 0.05 | L6: 973172
C7: 1 x Cutlery, Type 4/1, Disp, Neutral | D7: 1 | E7: Pc | G7: 0 | H7: 0.05 | L7: 973605
C8: 1 x Insert, For Casserole, Disposable | D8: 1 | E8: Pc | G8: 0 | H8: 0.05 | L8: 973045
C9: 1 x Insert, X-Large, Disposable (for salad) | D9: 1 | E9: Pc | G9: 0 | H9: 0.05 | L9: 971205
C10: 1 x Lid, For 971205, Disposable | D10: 1 | E10: Pc | G10: 0 | H10: 0.05 | L10: 971206
C11: 1 x Insert, Small, Disposable (for dessert) | D11: 1 | E11: Pc | G11: 0 | H11: 0.05 | L11: 971207
C12: 1 x Lid , For 971207, Disposable, Small | D12: 1 | E12: Pc | G12: 0 | H12: 0.05
C13: Portioned packed butter 10-15 g | D13: 1 | E13: Pc | H13: 0.09 | L13: 971208
C14: Portioned packed milk jigger | D14: 1 | E14: Pc | H14: 0.09
A16: =$A$4 -> Please fill in Supplier Name | B16: 3ATL-431010C3 | C16: IC M S1 TSU C3 | G16: =SUM(G17:G26) -> 0 | H16: =SUM(H17:H26) -> 0.62 | I16: =SUM(G16:H16) -> 0.62 | J16: M | K16: 1 | M16: C1 | N16: Tray Setup
C17: Tray, Food, Medium, ATLAS | D17: 1 | E17: Pc | G17: 0 | H17: 0.09 | L17: 971167
C18: 1 x Traymat, Medium, Anti-Skid, Disposable | D18: 1 | E18: Pc | G18: 0 | H18: 0.05 | L18: 973172
C19: 1 x Cutlery, Type 4/1, Disp, Neutral | D19: 1 | E19: Pc | G19: 0 | H19: 0.05 | L19: 973605
C20: 1 x Insert, For Casserole, Disposable | D20: 1 | E20: Pc | G20: 0 | H20: 0.05 | L20: 973045
C21: 1 x Insert, X-Large, Disposable (for salad) | D21: 1 | E21: Pc | G21: 0 | H21: 0.05 | L21: 971205
C22: 1 x Lid, For 971205, Disposable | D22: 1 | E22: Pc | G22: 0 | H22: 0.05 | L22: 971206
C23: 1 x Insert, Small, Disposable (for dessert) | D23: 1 | E23: Pc | G23: 0 | H23: 0.05 | L23: 971207
C24: 1 x Lid , For 971207, Disposable, Small | D24: 1 | E24: Pc | G24: 0 | H24: 0.05 | L24: 971208
C25: Portioned packed butter 10-15 g | D25: 1 | E25: Pc | H25: 0.09
C26: Portioned packed milk jigger | D26: 1 | E26: Pc | H26: 0.09
A28: =$A$4 -> Please fill in Supplier Name | B28: 2ATL-431011 | C28: IC M S1 SALAD C1 | G28: =SUM(G29:G37) -> 0 | H28: =SUM(H29:H37) -> 0 | I28: =SUM(G28:H28) -> 0 | J28: M | K28: 1 | M28: C1 | N28: Mixed starter salad
C29: Mesclun mix | D29: 10 | E29: Gm
C30: Blue cheese crumbled | D30: 10 | E30: Gm
C31: Shredded carrots (julienned) | D31: 10 | E31: Gm
C32: Toasted pepitas | D32: 3 | E32: Gm
A39: =$A$4 -> Please fill in Supplier Name | B39: 2ATL-431012 | C39: IC M S1 SALAD C2 | G39: =SUM(G40:G48) -> 0 | H39: =SUM(H40:H48) -> 0 | I39: =SUM(G39:H39) -> 0 | J39: M | K39: 1 | M39: C2
C40: Mesclun Mixed Green Mix | D40: 10 | E40: gm
C41: English Cucumber Slice | D41: 15 | E41: Gm
C42: Shredded carrots (julienned) | D42: 10 | E42: gm
A50: =$A$4 -> Please fill in Supplier Name | B50: 2ATL-431013 | C50: IC M S1 SALAD C3 | G50: =SUM(G51:G59) -> 0 | H50: =SUM(H51:H59) -> 0 | I50: =SUM(G50:H50) -> 0 | J50: M | K50: 1 | M50: C3
C51: Baby Arugula | D51: 10 | E51: gm
C52: Strawberry quartered | D52: 15 | E52: gm
C53: Feta | D53: 10 | E53: gm
A61: =$A$4 -> Please fill in Supplier Name | B61: 2ATL-421031 | C61: IC Y/M S1 HM-B C1 | G61: =SUM(G62:G70) -> 0 | H61: =SUM(H62:H70) -> 0 | I61: =SUM(G61:H61) -> 0 | J61: M | K61: 1 | L61: Also used for Y. | M61: C1 | N61: Oven roasted chicken with mashed sweet potatoes
C62: Oven roasted chicken ( half thigh/ half breast) Wellfare | D62: 100 | E62: Gm
...

Sheet CS P K C3
A1: Caterer: TBD | B1: Station: ATL | C1: Concept: 01JUN24 | Version: 1 | Updated: 15DEC23 Currency USD
B2: CS PKspec codes | C2: Crew Meals
A3: Supplier, please fill in name of Company in the first row | B3: SAS IFX Spec Code | C3: SAS IFX Description | D3: Weight / Pc | E3: Unit of M | F3: Quality, brand, supplier, origin, comments | G3: Direct Material | H3: Direct Labor | I3: Selling Price ex contrubtion | J3: Class | K3: Loading Instructions N.B only information | L3: Note
A4: ='CS C C1-3'!$A$4 -> Please fill in Supplier Name | B4: 3ATL-550003 | C4: CRW P CM TSU | G4: =SUM(G5:G13) -> 0 | H4: =SUM(H5:H13) -> 0 | I4: =SUM(G4:H4) -> 0 | J4: P | K4: 1
C5: SK Disposable cutlery | D5: 1 | E5: Pc | G5: 0
C6: Portion packed local butter | D6: 1 | E6: Pc
C7: Bread roll multigrain | D7: 1 | E7: Pc
A15: =$A$4 -> Please fill in Supplier Name | B15: 3ATL-560003 | C15: CRW K CM A | G15: =SUM(G16:G24) -> 0 | H15: =SUM(H16:H24) -> 0 | I15: =SUM(G15:H15) -> 0 | J15: K | K15: 0.5
C16: Roast beef x 2 slices | D16: 30 | E16: Gm
C17: Mayo (top and bottom) | D17: 10 | E17: Gm
C18: Red pepper stripes x 2 | D18: 20 | E18: Gm
C19: Ronman lettuce liner | D19: 3 | E19: Gm
C20: Ciabatta bread (50-60gr) | D20: 1 | E20: Pc
A26: =$A$4 -> Please fill in Supplier Name | B26: 3ATL-560004 | C26: CRW K CM B | G26: =SUM(G27:G35) -> 0 | H26: =SUM(H27:H35) -> 0 | I26: =SUM(G26:H26) -> 0 | J26: M | K26: 0.5
C27: Monterey jack cheese x 2 | D27: 20 | E27: Gm
C28: Cream cheese (top and bottom) | D28: 10 | E28: Gm
C29: Tomato spread | D29: 50 | E29: Gm
C30: Roman lettuce liner | D30: 3 | E30: Gm
C31: Wheat pullman bread slices | D31: 2 | E31: Pc
A37: =$A$4 -> Please fill in Supplier Name | B37: 2ATL-550025 | C37: CRW P CM - Poultry or Salmon A | G37: =SUM(G38:G46) -> 0 | H37: =SUM(H38:H46) -> 0 | I37: =SUM(G37:H37) -> 0 | J37: P | K37: 0.5
C38: Smoked salmon slices | D38: 40 | E38: Gm
C39: Blue cheese 3x10gm | D39: 30 | E39: Gm
C40: Mesclun mix | D40: 4 | E40: Gm
C41: Frisee salad | D41: 5 | E41: Gm
C42: Yellow cherry tomato | D42: 1 | E42: Pc
C43: Red cherry tomato | D43: 1 | E43: Pc
C44: Caper berry | D44: 1 | E44: Pc
A48: =$A$4 -> Please fill in Supplier Name | B48: 2ATL-550026 | C48: CRW P CM - Meat B | G48: =SUM(G49:G57) -> 0 | H48: =SUM(H49:H57) -> 0 | I48: =SUM(G48:H48) -> 0 | J48: P | K48: 1
C49: Air dried ham US | D49: 10 | E49: Gm
C50: Ham cured "81" | D50: 13 | E50: Gm
C51: Swiss cheese x 3 | D51: 30 | E51: Gm
C52: Mesclun mix | D52: 4 | E52: Gm
C53: Frisee salad | D53: 3 | E53: Gm
C54: cherry tomato | D54: 1 | E54: Pc
C55: Black olives | D55: 3 | E55: Pc
C56: Red grapes x 4 | D56: 30 | E56: Gm
A59: =$A$4 -> Please fill in Supplier Name | B59: 3ATL-550001 | C59: CRW P HM TSU | G59: =SUM(G60:G68) -> 0 | H59: =SUM(H60:H68) -> 0 | I59: =SUM(G59:H59) -> 0 | J59: P | K59: 1
C60: Vinaigrette dressing | D60: 1 | E60: Pc
C61: PP local butter | D61: 1 | E61: Pc
C62: Bread | D62: 1 | E62: Pc
...

Sheet CS X
A1: Caterer: TBD | B1: Caterer: TBD | Station: ATL | C1: Concept: 01JUN24 | Version: 1 | Updated: 15DEC23 Currency USD
B2: CS X spec codes C1-3 | C2: HANDLING & STANDARD ITEMS
A3: Supplier, please fill in name of Company in the first row | B3: SAS IFX Spec Code | C3: SAS IFX Description | D3: Weight / Pc | E3: Unit of M | F3: Quality, supplier, origin, comments | G3: Direct Material | H3: Direct Labor | I3: Selling Price ex contrubtion | J3: Class | K3: Loading Instructions N.B only information | L3: Note
A4: ='CS C C1-3'!$A$4 -> Please fill in Supplier Name | B4: 3333-IC954 | C4: SK0930 | G4: 0 | H4: 0 | I4: =SUM(G4:H4) -> 0 | J4: X | K4: - | L4: Turnaround
A5: =$A$4 -> Please fill in Supplier Name | B5: 3333-IC954-T | C5: SK0930 | G5: 0 | H5: 0 | I5: =SUM(G5:H5) -> 0 | J5: X | K5: - | L5: Strip
A6: =$A$4 -> Please fill in Supplier Name | B6: 3333-IC954-OR | C6: SK0930 | G6: 0 | H6: 0 | I6: =SUM(G6:H6) -> 0 | J6: X | K6: - | L6: Load
A7: =$A$4 -> Please fill in Supplier Name | B7: 3334-IC954 | C7: SK0930 | G7: 0 | H7: 0 | I7: =SUM(G7:H7) -> 0 | J7: X | K7: - | L7: Turnaround
A8: =$A$4 -> Please fill in Supplier Name | B8: 3333-IC954-T | C8: SK0930 | G8: 0 | H8: 0 | I8: =SUM(G8:H8) -> 0 | J8: X | K8: - | L8: Strip
A9: =$A$4 -> Please fill in Supplier Name | B9: 3333-IC954-OR | C9: SK0930 | G9: 0 | H9: 0 | I9: =SUM(G9:H9) -> 0 | J9: X | K9: - | L9: Load
A10: =$A$4 -> Please fill in Supplier Name | B10: 3591-IC954 | C10: SK0930 | G10: 0 | H10: 0 | I10: =SUM(G10:H10) -> 0 | J10: X | K10: - | L10: Turnaround
A11: =$A$4 -> Please fill in Supplier Name | B11: 3591-IC954-T | C11: SK0930 | G11: 0 | H11: 0 | I11: =SUM(G11:H11) -> 0 | J11: X | K11: - | L11: Strip
A12: =$A$4 -> Please fill in Supplier Name | B12: 3591-IC954-OR | C12: SK0930 | G12: 0 | H12: 0 | I12: =SUM(G12:H12) -> 0 | J12: X | K12: - | L12: Load
A13: =$A$4 -> Please fill in Supplier Name | B13: 8ALL-WETICE | C13: Wet ice | I13: 0 | J13: X | K13: -
A14: =$A$4 -> Please fill in Supplier Name | B14: 8ALL-DRYICE | C14: Dry Ice | I14: 0 | J14: X | K14: -
A15: =$A$4 -> Please fill in Supplier Name | B15: 8ALL-GARBAGE3333 | C15: International Garbage Charge (3333) | I15: 0 | J15: X | K15: -
A16: =$A$4 -> Please fill in Supplier Name | B16: 8ALL-GARBAGE3334 | C16: International Garbage Charge (3334) | I16: 0 | J16: X | K16: -
A17: =$A$4 -> Please fill in Supplier Name | B17: 8ALL-GARBAGE3591 | C17: International Garbage Charge (3591) | I17: 0 | J17: X | K17: -
A18: =$A$4 -> Please fill in Supplier Name | B18: 8ALL-ACDELIVERY | C18: Aircraft Delivery Charge | I18: 0 | J18: X | K18: -
A19: =$A$4 -> Please fill in Supplier Name | B19: Water Still 1.5L | E19: Pc | I19: 0 | J19: X | K19: -
A20: =$A$4 -> Please fill in Supplier Name | B20: Water Still 0.5L/16oz | E20: Pc | I20: 0 | J20: X | K20: -
A21: =$A$4 -> Please fill in Supplier Name | B21: Water Sparkling 1.0L/32oz | E21: Pc | I21: 0 | J21: X | K21: -
A22: =$A$4 -> Please fill in Supplier Name | B22: Milk whole 0.25L/8oz | E22: Pc | I22: 0 | J22: X | K22: -
A23: =$A$4 -> Please fill in Supplier Name | B23: Creamer portion packed 0.25oz | E23: Pc | I23: 0 | J23: X | K23: -
A24: =$A$4 -> Please fill in Supplier Name | B24: Apple Juice 1L/32oz | E24: Pc | I24: 0 | J24: X | K24: -
A25: =$A$4 -> Please fill in Supplier Name | B25: Tomato Juice Aseptic 1L/32oz | E25: Pc | I25: 0 | J25: X | K25: -
A26: =$A$4 -> Please fill in Supplier Name | B26: Orange Juice Aseptic 1L/32oz | E26: Pc | I26: 0 | J26: X | K26: -
A27: =$A$4 -> Please fill in Supplier Name | B27: Celery Stick 6in x10 | E27: Pc | I27: 0 | J27: X | K27: -
A28: =$A$4 -> Please fill in Supplier Name | B28: Lime Wedges (1lime cut in 8 wedges) in plastic glass | E28: Pc | I28: 0 | J28: X | K28: -
A29: =$A$4 -> Please fill in Supplier Name | B29: Lemon Wedges (1 lemon cut in 8 wegdes) in plastic glass | E29: Pc | I29: 0 | J29: X | K29: -
A30: =$A$4 -> Please fill in Supplier Name | B30: Lemon Slice (1 lemon cut in 20 1/2 wheel slices) | E30: Pc | I30: 0 | J30: X | K30: -
... A36: =$A$4 -> Please fill in Supplier Name | B36: Soda Sprite 12oz Can (Crew request only) | E36: Pc | I36: 0 | J36: X | K36: -

Sheet CS M Alt
A1: Caterer: TBD | B1: Station: ATL | C1: Concept: 01JUN24 | Version: 1 | Updated: 15DEC23 Currency USD
B2: CS M spec codes C1-3 | C2: GO (ECONOMY) DISHWASH EQ & NOMINATED SK OWNED MEALS and Dessert
A3: Supplier, please fill in name of Company in the first row | B3: SAS IFX Spec Code | C3: SAS IFX Description | D3: Weight / Pc | E3: Unit of M | F3: Quality, brand, supplier, origin, comments | G3: Direct Material | H3: Direct Labor | I3: Selling Price ex contrubtion | J3: Class | K3: Loading Instructions N.B only information | L3: Note | M3: Cycle / Menu | N3: Dish Name
A4: ='CS C C1-3'!$A$4 -> Please fill in Supplier Name | B4: 2ATL-431020N | C4: IC M S1 DE C1 | G4: =SUM(G5:G6) -> 0 | H4: =SUM(H5:H6) -> 0 | I4: =SUM(G4:H4) -> 0 | J4: M | K4: 1 | M4: C1
C5: Frozen Dessert, SAS Nominated and SAS owned | G5: 0
C6: Defrost and trayset | G6: 0
A8: =$A$4 -> Please fill in Supplier Name | B8: 2ATL-432020N | C8: IC M S2 SW C1-4 | G8: =SUM(G9:G10) -> 0 | H8: =SUM(H9:H10) -> 0 | I8: =SUM(G8:H8) -> 0 | J8: M | K8: 1
C9: Frozen Sandwich, SAS Nominated and SAS owned | D9: 1 | E9: Pc | G9: 0 | N9: Breakfast sandwich
C10: Defrost and load | G10: 0
A12: =$A$4 -> Please fill in Supplier Name | B12: 2ATL-421031N | C12: IC Y/M S1 HM-B C1 | G12: =SUM(G13:G14) -> 0 | H12: =SUM(H13:H14) -> 0 | I12: =SUM(G12:H12) -> 0 | J12: M | K12: 1 | L12: Also used for Y. | M12: C1
C13: Frozen Hot Meal, SAS Nominated and SAS owned | D13: 1 | E13: Pc | G13: 0
C14: Defrost and load | G14: 0
A16: =$A$4 -> Please fill in Supplier Name | B16: 8ATL-OVERHEAD-NM | C16: IC M Overhead Nominated | J16: M | K16: 1

Sheet C Cost_Pax
A1: Caterer: TBD | B1: Station: ATL | C1: Concept: 01JUN24 | Version: 1 | Updated: 15DEC23 Currency USD
B2: CS C spec codes C1-3 | C2: BUSINESS CLASS
A3: Supplier, please fill in name of Company in the first row | B3: SAS IFX Spec Code | C3: SAS IFX Description | D3: Weight / Pc | E3: Unit of M | F3: Quality, brand, supplier, origin, comments | G3: Direct Material | H3: Direct Labor | I3: Selling Price ex contrubtion | J3: Class | K3: Loading Instructions N.B only information | N3: Note | O3: Cycle / Menu | P3: Dish Name
A4: ='CS C C1-3'!$A$4 -> Please fill in Supplier Name | B4: 4ATL-411050C2 | C4: IC C S1 CUTLERY C2 | G4: ='CS C C1-3'!G4 -> 0 | H4: ='CS C C1-3'!H4 -> 1.04 | I4: ='CS C C1-3'!I4 -> 1.04 | J4: C | K4: Fix Qty 40 | L4: 40 | M4: =I4*L4 -> 41.6 | O4: C2 | P4: Cutlery pack
C5: Napkin/Tablecloth, Poly/Cotton, Grey | D5: 1 | E5: Pc | G5: 0 | N5: 972062
C6: Knife, Stainless, RS | D6: 3 | E6: Pc | G6: 0 | N6: 971090
C7: Fork, Stainless, RS | D7: 3 | E7: Pc | G7: 0 | N7: 971091
C8: Spoon, Stainless, Dessert/Soup, RS | D8: 1 | E8: Pc | G8: 0 | N8: 971093
C9: Salt & Pepper, Twinpack | D9: 1 | E9: Pc | G9: 0 | N9: 973034
C10: Toothpick, Individually Packed | D10: 1 | E10: Pc | G10: 0 | N10: 973020
A15: =$A$4 -> Please fill in Supplier Name | B15: 4ATL-411050C3 | C15: IC C S1 CUTLERY C3 | G15: ='CS C C1-3'!G15 -> 0 | H15: ='CS C C1-3'!H15 -> 1.04 | I15: ='CS C C1-3'!I15 -> 1.04 | J15: C | K15: Fix Qty 40 | L15: 40 | M15: =I15*L15 -> 41.6 | O15: C3 | P15: Cutlery pack
C16: Napkin/Tablecloth, Poly/Cotton, Grey | D16: 1 | E16: Pc | G16: 0 | N16: 972062
C17: Knife, Stainless, RS | D17: 3 | E17: Pc | G17: 0 | N17: 971090
C18: Fork, Stainless, RS | D18: 3 | E18: Pc | G18: 0 | N18: 971091
C19: Spoon, Stainless, Dessert/Soup, RS | D19: 1 | E19: Pc | G19: 0 | N19: 971093
C20: Salt & Pepper, Twinpack | D20: 1 | E20: Pc | G20: 0 | N20: 973034
C21: Toothpick, Individually Packed | D21: 1 | E21: Pc | G21: 0 | N21: 973020
A26: =$A$4 -> Please fill in Supplier Name | B26: 2ATL-411011 | C26: IC C S1 SALAD C1 | G26: =SUM(G27:G29) -> 0 | H26: =SUM(H27:H29) -> 0 | I26: =SUM(G26:H26) -> 0 | J26: C | K26: Load Scale IC-27 | L26: 4 | M26: =I26*L26 -> 0 | O26: C1 | P26: Starter salad
C27: Mixed salad leaves | D27: 15 | E27: gm | F27: Seasonal
A31: =$A$4 -> Please fill in Supplier Name | B31: 2ATL-411012 | C31: IC C S1 SALAD C2 | G31: ='CS C C1-3'!G31 -> 0 | H31: ='CS C C1-3'!H31 -> 0 | I31: ='CS C C1-3'!I31 -> 0 | J31: C | K31: Load Scale IC-27 | L31: 4 | M31: =I31*L31 -> 0 | O31: C2 | P31: Starter salad
A36: =$A$4 -> Please fill in Supplier Name | B36: 2ATL-411013 | C36: IC C S1 SALAD C3 | G36: ='CS C C1-3'!G36 -> 0 | H36: ='CS C C1-3'!H36 -> 0 | I36: ='CS C C1-3'!I36 -> 0 | J36: C | K36: Load Scale IC-27 | L36: 4 | M36: =I36*L36 -> 0 | O36: C3 | P36: Starter salad
A41: =$A$4 -> Please fill in Supplier Name | B41: 2ATL-411031 | C41: IC C S1 SA GARNISH C1 | G41: =SUM(G42:G44) -> 0 | H41: =SUM(H42:H44) -> 0 | I41: =SUM(G41:H41) -> 0 | J41: C | K41: Fix Qty 2 | L41: 2 | M41: =I41*L41 -> 0 | O41: C1 | P41: Salad side garnish
C42: Shaved watermelon radish 1 mm | D42: 3 | E42: Gm
A46: =$A$4 -> Please fill in Supplier Name | B46: 2ATL-411032 | C46: IC C S1 SA GARNISH C2 | G46: ='CS C C1-3'!G46 -> 0 | H46: ='CS C C1-3'!H46 -> 0 | I46: ='CS C C1-3'!I46 -> 0 | J46: C | K46: Fix Qty 2 | L46: 2 | M46: =I46*L46 -> 0 | O46: C2 | P46: Salad garnish
A51: =$A$4 -> Please fill in Supplier Name | B51: 2ATL-411033 | C51: IC C S1 SA GARNISH C3 | G51: ='CS C C1-3'!G51 -> 0 | H51: ='CS C C1-3'!H51 -> 0 | I51: ='CS C C1-3'!I51 -> 0 | J51: C | K51: Fix Qty 2 | L51: 2 | M51: =I51*L51 -> 0 | O51: C3 | P51: Garnish
A56: =$A$4 -> Please fill in Supplier Name | B56: 2ATL-411050 | C56: IC C S1+S2 BUTTER C1 | G56: =SUM(G57:G59) -> 0 | H56: =SUM(H57:H59) -> 0 | I56: =SUM(G56:H56) -> 0 | J56: C | K56: 1 | L56: 1 | M56: =I56*L56 -> 0 | O56: C1 | P56: Butter
C57: Butter puck salted | D57: 10 | E57: gm | F57: Organic valley
A61: =$A$4 -> Please fill in Supplier Name | B61: 2ATL-411050C2 | C61: IC C S1+S2 BUTTER C2 | G61: ='CS C C1-3'!G61 -> 0 | H61: ='CS C C1-3'!H61 -> 0 | I61: ='CS C C1-3'!I61 -> 0 | J61: C | K61: 1 | L61: 1 | M61: =I61*L61*$K$576 -> 0 | O61: C2 | P61: Butter
A66: =$A$4 -> Please fill in Supplier Name | B66: 2ATL-411050C3 | C66: IC C S1+S2 BUTTER C3 | G66: ='CS C C1-3'!G66 -> 0 | H66: ='CS C C1-3'!H66 -> 0 | I66: ='CS C C1-3'!I66 -> 0 | J66: C | K66: 1 | L66: 1 | M66: =I66*L66*$K$576 -> 0 | O66: C3 | P66: Butter
A71: =$A$4 -> Please fill in Supplier Name | B71: 2ATL-411061 | C71: IC C S1 ST-A MEAT C1 | G71: =SUM(G72:G80) -> 0 | H71: =SUM(H72:H80) -> 0 | I71: =SUM(G71:H71) -> 0 | J71: C | K71: 60% (U) | L71: 0.6 | M71: =I71*L71*$K$576 -> 0 | O71: C1 | P71: Butcher board
C72: Truffle saucisson sec | D72: 3 x 4 | E72: gm
C73: Pork pate de campagne with pistachio | D73: 20 | E73: gm
C74: Duck prosciutto | D74: 10 | E74: gm
C75: Upland cress | D75: 2 | E75: gm
C76: Cornichons | D76: 1 | E76: pc
C77: Cracked black Tellecherry pepper | D77: 1 | E77: gm
A82: =$A$4 -> Please fill in Supplier Name | B82: 2ATL-411062 | C82: IC C S1 ST-A MEAT C2 | G82: ='CS C C1-3'!G82 -> 0 | H82: ='CS C C1-3'!H82 -> 0 | I82: ='CS C C1-3'!I82 -> 0 | J82: C | K82: 60% (U) | L82: 0.6 | M82: =I82*L82*$K$576 -> 0 | O82: C2
A93: =$A$4 -> Please fill in Supplier Name | B93: 2ATL-411063 | C93: IC C S1 ST-A MEAT C3 | G93: ='CS C C1-3'!G93 -> 0 | H93: ='CS C C1-3'!H93 -> 0 | I93: ='CS C C1-3'!I93 -> 0 | J93: C | K93: 60% (U) | L93: 0.6 | M93: =I93*L93*$K$576 -> 0 | O93: C3
A104: =$A$4 -> Please fill in Supplier Name | B104: 2ATL-411071 | C104: IC C S1 ST-B FISH C1 | G104: =SUM(G105:G113) -> 0 | H104: =SUM(H105:H113) -> 0 | I104: =SUM(G104:H104) -> 0 | J104: C | K104: 60% (D) | L104: 0.6 | M104: =I104*L104*$K$576 -> 0 | O104: C1 | P104: Cured salmon with baked beets and goat cheese
C105: Herb cured salmon (rosemary, thyme & chives) | D105: 2x20 | E105: gm
...

Sheet Y Cost_Pax
A1: Caterer: TBD | B1: | Station: ATL | C1: Concept: 01JUN24 | Version: 1 | Updated: 15DEC23 Currency USD
B2: CS Y spec codes C1-3 | C2: PLUS (PREMIUM ECO)
A3: Supplier, please fill in name of Company in the first row | B3: SAS IFX Spec Code | C3: SAS IFX Description | D3: Weight / Pc | E3: Unit of M | F3: Quality, brand, supplier, origin, comments | G3: Direct Material | H3: Direct Labor | I3: Selling Price ex contrubtion | J3: Class | K3: Loading Instructions N.B only information | N3: Note | O3: Cycle / Menu | P3: Dish Name
A4: ='CS Y C1-3'!$A$4 -> Please fill in Supplier Name | B4: 3ATL-421010C2 | C4: IC Y S1 TSU C2 | G4: ='CS Y C1-3'!G4 -> 0 | H4: ='CS Y C1-3'!H4 -> 1.06 | I4: ='CS Y C1-3'!I4 -> 1.06 | J4: Y | K4: 1 | L4: 1 | M4: =I4*L4*$K$233 -> 28.62 | O4: C2 | P4: Tray setup
C5: Tray, Food, Large, ATLAS | D5: 1 | E5: Pc | G5: 0 | N5: 971168
C6: Traymat, Large, Black, Disposable | D6: 1 | E6: Pc | G6: 0 | N6: 973186
C7: Bag, For Cutlery | D7: 1 | E7: Pc | G7: 0 | N7: 973012
C8: 1 x Fork, Stainless, RS | D8: 1 | E8: Pc | G8: 0 | N8: 971091
C9: 1 x Spoon, Stainless, Coffee/Tea, RS | D9: 1 | E9: Pc | G9: 0 | N9: 971092
C10: 1 x Spoon, Stainless, Dessert/Soup, RS | D10: 1 | E10: Pc | G10: 0 | N10: 971093
C11: 1 x Knife, Stainless, RS | D11: 1 | E11: Pc | G11: 0 | N11: 971090
C12: 1 x Napkin, Paper, White | D12: 1 | E12: Pc | G12: 0 | N12: 973099
C13: 1 x Sugar, Portion Packed | D13: 1 | E13: Pc | G13: 0 | N13: 973023
C14: 1 x Salt & Pepper, Twinpack | D14: 1 | E14: Pc | G14: 0 | N14: 973034
C15: 1 x Toothpick, Individually Packed | D15: 1 | E15: Pc | G15: 0 | N15: 973020
A17: =$A$4 -> Please fill in Supplier Name | B17: 3ATL-421010C3 | C17: IC Y S1 TSU C3 | G17: ='CS Y C1-3'!G20 -> 0 | H17: ='CS Y C1-3'!H20 -> 1.01 | I17: ='CS Y C1-3'!I20 -> 1.01 | J17: Y | K17: 1 | L17: 1 | M17: =I17*L17*$K$233 -> 27.27 | O17: C3 | P17: Tray setup
C18: Tray, Food, Large, ATLAS | D18: 1 | E18: Pc | G18: 0 | N18: 971168
C19: Traymat, Large, Black, Disposable | D19: 1 | E19: Pc | G19: 0 | N19: 973186
C20: Bag, For Cutlery | D20: 1 | E20: Pc | G20: 0 | N20: 973012
C21: 1 x Fork, Stainless, RS | D21: 1 | E21: Pc | G21: 0 | N21: 971091
C22: 1 x Spoon, Stainless, Coffee/Tea, RS | D22: 1 | E22: Pc | G22: 0 | N22: 971092
C23: 1 x Spoon, Stainless, Dessert/Soup, RS | D23: 1 | E23: Pc | G23: 0 | N23: 971093
C24: 1 x Knife, Stainless, RS | D24: 1 | E24: Pc | G24: 0 | N24: 971090
C25: 1 x Napkin, Paper, White | D25: 1 | E25: Pc | G25: 0 | N25: 973099
C26: 1 x Sugar, Portion Packed | D26: 1 | E26: Pc | G26: 0 | N26: 973023
C27: 1 x Salt & Pepper, Twinpack | D27: 1 | E27: Pc | G27: 0 | N27: 973034
C28: 1 x Toothpick, Individually Packed | D28: 1 | E28: Pc | G28: 0 | N28: 973020
A30: =$A$4 -> Please fill in Supplier Name | B30: 2ATL-421011 | C30: IC Y S1 ST C1 | G30: =SUM(G31:G39) -> 0 | H30: =SUM(H31:H39) -> 0 | I30: =SUM(G30:H30) -> 0 | J30: Y | K30: 1 | M30: =I30*L30 -> 0 | O30: C1 | P30: Local air dried ham with broccoli slaw and kale grain salad
C31: Local air dried ham x 2 slices | D31: 15 | E31: Gm
C32: Kale grain salad | D32: 20 | E32: Gm
C33: Broccoli slaw | D33: 35 | E33: Gm
A41: =$A$4 -> Please fill in Supplier Name | B41: 2ATL-421012 | C41: IC Y S1 ST C2 | G41: ='CS Y C1-3'!G46 -> 0 | H41: ='CS Y C1-3'!H46 -> 0 | I41: ='CS Y C1-3'!I46 -> 0 | J41: Y | K41: 1 | L41: 1 | M41: =I41*L41*$K$233 -> 0 | O41: C2 | P41: Couscous salad with feta cheese
A52: =$A$4 -> Please fill in Supplier Name | B52: 2ATL-421013 | C52: IC Y S1 ST C3 | G52: ='CS Y C1-3'!G57 -> 0 | H52: ='CS Y C1-3'!H57 -> 0 | I52: ='CS Y C1-3'!I57 -> 0 | J52: Y | K52: 1 | L52: 1 | M52: =I52*L52*$K$233 -> 0 | O52: C3 | P52: Starter
A63: =$A$4 -> Please fill in Supplier Name | B63: 2ATL-421021 | C63: IC Y S1 HM-A C1 | G63: =SUM(G64:G72) -> 0 | H63: =SUM(H64:H72) -> 0 | I63: =SUM(G63:H63) -> 0 | J63: Y | K63: 60% (D) | M63: =I63*L63 -> 0 | O63: C1 | P63: Hake fish with farro, white wine sauce and sauteed zucchini and cherry tomatoes
C64: Hake fish fillet | D64: 4 | E64: Oz
C65: White wine cream sauce | D65: 30 | E65: Ml
C66: Farro with fresh herbes | D66: 80 | E66: Gm
C67: Sauteed fresh zucchini & mixed tomatoes | D67: 60 | E67: Gm
A74: =$A$4 -> Please fill in Supplier Name | B74: 2ATL-421022 | C74: IC Y S1 HM-A C2 | G74: ='CS Y C1-3'!G79 -> 0 | H74: ='CS Y C1-3'!H79 -> 0 | I74: ='CS Y C1-3'!I79 -> 0 | J74: Y | K74: 60% (D) | L74: 0.6 | M74: =I74*L74*$K$233 -> 0 | O74: C2 | P74: Beef Provencale with roasted Yukon wedges and roasted carrots
A85: =$A$4 -> Please fill in Supplier Name | B85: 2ATL-421023 | C85: IC Y S1 HM-A C3 | G85: ='CS Y C1-3'!G90 -> 0 | H85: ='CS Y C1-3'!H90 -> 0 | I85: ='CS Y C1-3'!I90 -> 0 | J85: Y | K85: 60% (D) | L85: 0.6 | M85: =I85*L85*$K$233 -> 0 | O85: C3
...

Sheet M Cost_Pax
A1: Caterer: TBD | B1: Station: ATL | C1: Concept: 01JUN24 | Version: 1 | Updated: 15DEC23 Currency USD
B2: CS M spec codes C1-3 | C2: GO (ECONOMY)
A3: Supplier, please fill in name of Company in the first row | B3: SAS IFX Spec Code | C3: SAS IFX Description | D3: Weight / Pc | E3: Unit of M | F3: Quality, brand, supplier, origin, comments | G3: Direct Material | H3: Direct Labor | I3: Selling Price ex contrubtion | J3: Class | K3: Loading Instructions N.B only information | N3: Note | O3: Cycle / Menu | P3: Dish Name
A4: ='CS M C1-3'!$A$4 -> Please fill in Supplier Name | B4: 3ATL-431010C2 | C4: IC M S1 TSU C2 | G4: ='CS M C1-3'!G4 -> 0 | H4: ='CS M C1-3'!H4 -> 0.62 | I4: ='CS M C1-3'!I4 -> 0.62 | J4: M | K4: 1 | L4: 1 | M4: =I4*L4*$K$235 -> 120.28 | O4: C2 | P4: Tray Setup
C5: Tray, Food, Medium, ATLAS | D5: 1 | G5: 0 | N5: 971167
C6: 1 x Traymat, Medium, Anti-Skid, Disposable | D6: 1 | G6: 0 | N6: 973172
C7: 1 x Cutlery, Type 4/1, Disp, Neutral | D7: 1 | G7: 0 | N7: 973605
C8: 1 x Insert, For Casserole, Disposable | D8: 1 | G8: 0 | N8: 973045
C9: 1 x Insert, X-Large, Disposable (for salad) | D9: 1 | G9: 0 | N9: 971205
C10: 1 x Lid, For 971205, Disposable | D10: 1 | G10: 0 | N10: 971206
C11: 1 x Insert, Small, Disposable (for dessert) | D11: 1 | G11: 0 | N11: 971207
C12: 1 x Lid , For 971207, Disposable, Small | D12: 1 | G12: 0 | N12: 971208
G13: 0
A15: =$A$4 -> Please fill in Supplier Name | B15: 3ATL-431010C3 | C15: IC M S1 TSU C3 | G15: ='C Cost_Pax'!G15 -> 0 | H15: ='CS M C1-3'!H16 -> 0.62 | I15: ='CS M C1-3'!I16 -> 0.62 | J15: M | K15: 1 | L15: 1 | M15: =I15*L15*$K$235 -> 120.28 | O15: C3 | P15: Tray Setup
C16: Tray, Food, Medium, ATLAS | D16: 1 | G16: 0 | N16: 971167
C17: 1 x Traymat, Medium, Anti-Skid, Disposable | D17: 1 | G17: 0 | N17: 973172
C18: 1 x Cutlery, Type 4/1, Disp, Neutral | D18: 1 | G18: 0 | N18: 973605
C19: 1 x Insert, For Casserole, Disposable | D19: 1 | G19: 0 | N19: 973045
C20: 1 x Insert, X-Large, Disposable (for salad) | D20: 1 | G20: 0 | N20: 971205
C21: 1 x Lid, For 971205, Disposable | D21: 1 | G21: 0 | N21: 971206
C22: 1 x Insert, Small, Disposable (for dessert) | D22: 1 | G22: 0 | N22: 971207
C23: 1 x Lid , For 971207, Disposable, Small | D23: 1 | G23: 0 | N23: 971208
G24: 0
A26: =$A$4 -> Please fill in Supplier Name | B26: 2ATL-431011 | C26: IC M S1 SALAD C1 | G26: =SUM(G27:G35) -> 0 | H26: ='CS M C1-3'!H28 -> 0 | I26: ='CS M C1-3'!I28 -> 0 | J26: M | K26: 1 | L26: 1 | M26: =I26*K26 -> 0 | O26: C1 | P26: Mixed starter salad
C27: Mesclun mix | D27: 10
C28: Blue cheese crumbled | D28: 10
C29: Shredded carrots (julienned) | D29: 10
C30: Toasted pepitas | D30: 3
A37: =$A$4 -> Please fill in Supplier Name | B37: 2ATL-431012 | C37: IC M S1 SALAD C2 | G37: ='CS M C1-3'!G39 -> 0 | H37: ='CS M C1-3'!H39 -> 0 | I37: ='CS M C1-3'!I39 -> 0 | J37: M | K37: 1 | L37: 1 | M37: =I37*L37*$K$235 -> 0 | O37: C2
A48: =$A$4 -> Please fill in Supplier Name | B48: 2ATL-431013 | C48: IC M S1 SALAD C3 | G48: ='CS M C1-3'!G50 -> 0 | H48: ='CS M C1-3'!H50 -> 0 | I48: ='CS M C1-3'!I50 -> 0 | J48: M | K48: 1 | L48: 1 | M48: =I48*L48*$K$235 -> 0 | O48: C3
A59: =$A$4 -> Please fill in Supplier Name | B59: 2ATL-421031 | C59: IC Y/M S1 HM-B C1 | G59: =SUM(G60:G68) -> 0 | H59: ='CS M C1-3'!H61 -> 0 | I59: ='CS M C1-3'!I61 -> 0 | J59: M | K59: 1 | L59: 1 | M59: =I59*K59 -> 0 | N59: Also used for Y. | O59: C1 | P59: Oven roasted chicken with mashed sweet potatoes
C60: Oven roasted chicken ( half thigh/ half breast) Wellfare | D60: 100 | E60: Gm
C61: Chicken jus | D61: 30 | E61: Ml
C62: Mashed orange sweet potatoes | D62: 80 | E62: Gm
C63: Sauteed spring vegetables | D63: 40 | E63: Gm
C64: (green beans, peas, snow peas & mexican onions) | D64: 0
A70: =$A$4 -> Please fill in Supplier Name | B70: 2ATL-421032 | C70: IC Y/M S1 HM-B C2 | G70: ='CS M C1-3'!G72 -> 0 | H70: ='CS M C1-3'!H72 -> 0 | I70: ='CS M C1-3'!I72 -> 0 | J70: M | K70: 1 | L70: 1 | M70: =I70*L70*$K$235 -> 0 | N70: Also used for Y. | O70: C2
A81: =$A$4 -> Please fill in Supplier Name | B81: 2ATL-421033 | C81: IC Y/M S1 HM-B C3 | G81: ='CS M C1-3'!G83 -> 0 | H81: ='CS M C1-3'!H83 -> 0 | I81: ='CS M C1-3'!I83 -> 0 | J81: M | K81: 1 | L81: 1 | M81: =I81*L81*$K$235 -> 0 | N81: Also used for Y. | O81: C3
A92: =$A$4 -> Please fill in Supplier Name | B92: 2ATL-431020 | C92: IC M S1 DE C1 | G92: =SUM(G93:G95) -> 0 | H92: ='CS M C1-3'!H94 -> 0 | I92: ='CS M C1-3'!I94 -> 0 | J92: M | K92: 1 | L92: 1 | M92: =I92*K92 -> 0 | O92: C1 | P92: Appe cheese cake with vanilla sauce
C93: Apple cheese cake | D93: 50 | E93: Gm
...

Sheet IC-27
A1: LOAD SCALE
H3: Description | I3: : | K3: 1-20=2/21-32=3/33-40=4/41-46=5
B4: Load Scale Code | D4: : | E4: IC-27
B7: Version | D7: : | E7: 2 | H7: Is Used (Y/N) | I7: :
B9: Eff Date | D9: : | E9: 10/05/2023 | H9: End Date | I9: :
C10: Pax Interval or Pax Count | F10: Board Quantity
C11: 1 | F11: 2
C12: 2 | F12: 2
C13: 3 | F13: 2
C14: 4 | F14: 2
C15: 5 | F15: 2
C16: 6 | F16: 2
C17: 7 | F17: 2
C18: 8 | F18: 2
C19: 9 | F19: 2
C20: 10 | F20: 2
C21: 11 | F21: 2
... C56: 46 | F56: 5

Sheet IC-29
A1: LOAD SCALE
H3: Description | I3: : | K3: 1-24=2/25-40=3
B4: Load Scale Code | D4: : | E4: IC-29
B6: Version | D6: : | E6: 1 | H6: Is Used (Y/N) | I6: : | K6: N
B7: Eff Date | D7: : | E7: 01/02/2024 | H7: End Date | I7: :
C8: Pax Interval or Pax Count | F8: Board Quantity
C9: 1 | F9: 2
C10: 2 | F10: 2
C11: 3 | F11: 2
C12: 4 | F12: 2
C13: 5 | F13: 2
C14: 6 | F14: 2
C15: 7 | F15: 2
C16: 8 | F16: 2
C17: 9 | F17: 2
C18: 10 | F18: 2
C19: 11 | F19: 2
... C48: 40 | F48: 3

Sheet CF
B2: Config | C2: AC | D2: C | E2: Y | F2: M
C3: 330 | D3: 32 | E3: 56 | F3: 174
C4: 350 | D4: 40 | E4: 32 | F4: 228
B6: Loadfactor | C6: AC | D6: C | E6: Y | F6: M
B7: 0.85 | C7: 330 | D7: =D3*B7 -> 27.2 | E7: =E3*B7 -> 47.6 | F7: =F3*B7 -> 147.9
C8: 350 | D8: =D4*B7 -> 34 | E8: =E4*B7 -> 27.2 | F8: =F4*B7 -> 193.8
