Workbook
Name Bid_usage_summary_with_vertical__short_: ATL!$A$2:$E$268

Sheet Sheet1
A1: FACILITY | B1: Total Price | C1: Total Price | D1: Labor Price | E1: EFF.DATE | F1: UPLOAD DATE | H1: TOTAL | I1: LABOR | J1: MATCH | K1: MATCH
A2: C1 | B2: 82608 | C2: 3.4608 | D2: 0 | E2: 46120 | F2: 46121 | H2: =VLOOKUP(B2,ATL!C:K,8,0) -> 3.4608 | I2: =VLOOKUP(B2,ATL!C:K,7,0) -> 0 | J2: =C2=H2 -> TRUE | K2: =D2=I2 -> TRUE
A3: C1 | B3: 82610 | C3: 3.1808 | D3: 0 | E3: 46120 | F3: 46121 | H3: =VLOOKUP(B3,ATL!C:K,8,0) -> 3.1808 | I3: =VLOOKUP(B3,ATL!C:K,7,0) -> 0 | J3: =C3=H3 -> TRUE | K3: =D3=I3 -> TRUE
A4: C1 | B4: 87833 | C4: 2.8896 | D4: 0 | E4: 46120 | F4: 46121 | H4: =VLOOKUP(B4,ATL!C:K,8,0) -> 2.8896 | I4: =VLOOKUP(B4,ATL!C:K,7,0) -> 0 | J4: =C4=H4 -> TRUE | K4: =D4=I4 -> TRUE
A5: C1 | B5: 87990 | C5: 4.4206485 | D5: 1.15 | E5: 46120 | F5: 46121 | H5: =VLOOKUP(B5,ATL!C:K,8,0) -> 4.4206485 | I5: =VLOOKUP(B5,ATL!C:K,7,0) -> 1.15 | J5: =C5=H5 -> TRUE | K5: =D5=I5 -> TRUE
A6: C1 | B6: 87991 | C6: 2.0126814 | D6: 0.69 | E6: 46120 | F6: 46121 | H6: =VLOOKUP(B6,ATL!C:K,8,0) -> 2.0126814 | I6: =VLOOKUP(B6,ATL!C:K,7,0) -> 0.69 | J6: =C6=H6 -> TRUE | K6: =D6=I6 -> TRUE
A7: C1 | B7: 87992 | C7: 2.0126814 | D7: 0.69 | E7: 46120 | F7: 46121 | H7: =VLOOKUP(B7,ATL!C:K,8,0) -> 2.0126814 | I7: =VLOOKUP(B7,ATL!C:K,7,0) -> 0.69 | J7: =C7=H7 -> TRUE | K7: =D7=I7 -> TRUE
A8: C1 | B8: 88303 | C8: 4.2791811 | D8: 1.15 | E8: 46120 | F8: 46121 | H8: =VLOOKUP(B8,ATL!C:K,8,0) -> 4.2791811 | I8: =VLOOKUP(B8,ATL!C:K,7,0) -> 1.15 | J8: =C8=H8 -> TRUE | K8: =D8=I8 -> TRUE
A9: C1 | B9: 89766 | C9: 4.6134483 | D9: 0.805 | E9: 46120 | F9: 46121 | H9: =VLOOKUP(B9,ATL!C:K,8,0) -> 4.6134483 | I9: =VLOOKUP(B9,ATL!C:K,7,0) -> 0.805 | J9: =C9=H9 -> TRUE | K9: =D9=I9 -> TRUE
A10: C1 | B10: 89773 | C10: 4.1142559 | D10: 1.38 | E10: 46120 | F10: 46121 | H10: =VLOOKUP(B10,ATL!C:K,8,0) -> 4.1142559 | I10: =VLOOKUP(B10,ATL!C:K,7,0) -> 1.38 | J10: =C10=H10 -> TRUE | K10: =D10=I10 -> TRUE
A11: C1 | B11: 89779 | C11: 4.6763594 | D11: 1.035 | E11: 46120 | F11: 46121 | H11: =VLOOKUP(B11,ATL!C:K,8,0) -> 4.6763594 | I11: =VLOOKUP(B11,ATL!C:K,7,0) -> 1.035 | J11: =C11=H11 -> TRUE | K11: =D11=I11 -> TRUE
A12: C1 | B12: 90009 | C12: 3.2961642 | D12: 1.38 | E12: 46120 | F12: 46121 | H12: =VLOOKUP(B12,ATL!C:K,8,0) -> 3.2961642 | I12: =VLOOKUP(B12,ATL!C:K,7,0) -> 1.38 | J12: =C12=H12 -> TRUE | K12: =D12=I12 -> TRUE
A13: C1 | B13: 90593 | C13: 5.8053184 | D13: 0 | E13: 46120 | F13: 46121 | H13: =VLOOKUP(B13,ATL!C:K,8,0) -> 5.8053184 | I13: =VLOOKUP(B13,ATL!C:K,7,0) -> 0 | J13: =C13=H13 -> TRUE | K13: =D13=I13 -> TRUE
... A280: C1 | B280: 78473 | C280: 34.9264 | D280: 1.08 | E280: 46120 | F280: 46121 | H280: =VLOOKUP(B280,ATL!C:K,8,0) -> 34.9264 | I280: =VLOOKUP(B280,ATL!C:K,7,0) -> 1.08 | J280: =C280=H280 -> TRUE | K280: =D280=I280 -> TRUE
A282: C9 | B282: 66575 | C282: 0.7752 | D282: 0 | E282: 46120 | F282: 46121 | H282: =VLOOKUP(B282,ATL!C:K,8,0) -> 0.8904 | I282: =VLOOKUP(B282,ATL!C:K,7,0) -> 0.138 | J282: =C282=H282 -> FALSE | K282: =D282=I282 -> FALSE | L282: SAME CODE DIFFERENT FACILITY, NO LABOR
A283: C9 | B283: 955 | C283: 2.4474 | D283: 0.27 | E283: 46120 | F283: 46121 | H283: =VLOOKUP(B283,ATL!C:K,8,0) -> 2.4474 | I283: =VLOOKUP(B283,ATL!C:K,7,0) -> 0.27 | J283: =C283=H283 -> TRUE | K283: =D283=I283 -> TRUE
A284: C9 | B284: 77752 | C284: 78.705 | D284: 78.705 | E284: 46120 | F284: 46121 | H284: =VLOOKUP(B284,ATL!C:K,8,0) -> 78.705 | I284: =VLOOKUP(B284,ATL!C:K,7,0) -> 78.705 | J284: =C284=H284 -> TRUE | K284: =D284=I284 -> TRUE
A285: C9 | B285: 77754 | C285: 78.705 | D285: 78.705 | E285: 46120 | F285: 46121 | H285: =VLOOKUP(B285,ATL!C:K,8,0) -> 78.705 | I285: =VLOOKUP(B285,ATL!C:K,7,0) -> 78.705 | J285: =C285=H285 -> TRUE | K285: =D285=I285 -> TRUE

Sheet ATL
A1: ATL MAINLINE - USAGE APRIL 2024 - MARCH 2025
A2: Vertical | B2: Vertical Name | C2: Spec Number | D2: Spec Description | E2: Annual Usage | F2: Comments | G2: Product Price | H2: Product Mark Up | I2: Labor Price | J2: Total Price | K2: Annual Total Cost
A3: 1A | B3: FOOD PRODUCT AND PREP | C3: 82608 | D3: ENT, CC/WC, PP, SWISS AND ROASTED TOMATO OMELET W/ HOLLANDAISE, SEASONED POTATOES AND ITALIAN CHICKEN SAUSAGE, CY2/4, EGGS | E3: 1467 | G3: 3.09 | H3: 0.3708 | I3: 0 | J3: =G3+H3+I3 -> 3.4608 | K3: =J3*E3 -> 5076.9936
A4: 1A | B4: FOOD PRODUCT AND PREP | C4: 82610 | D4: ENT, CC, PP, EGG AND FIRE ROASTED CORN ENCHILADA W/ SRIRACHA PINEAPPLE CHICKEN SAUSAGE AND BLACK BEANS, CY2, EGGS | E4: 1713 | G4: 2.84 | H4: 0.3408 | I4: 0 | J4: =G4+H4+I4 -> 3.1808 | K4: =J4*E4 -> 5448.7104
A5: 1A | B5: FOOD PRODUCT AND PREP | C5: 87833 | D5: ENT, WC/CC, PP, THREE CHEESE AU GRATIN OMELET, VEGETARIAN, EGGS | E5: 1687 | G5: 2.58 | H5: 0.3096 | I5: 0 | J5: =G5+H5+I5 -> 2.8896 | K5: =J5*E5 -> 4874.7552
A6: 1A | B6: FOOD PRODUCT AND PREP | C6: 87990 | D6: ENT, FC/CC, PP, CHARCUTERIE PLATE, BREAKFAST, LARGE BOWL, PORK | E6: 553 | G6: 2.9550596 | H6: 0.31558889 | I6: 1.15 | J6: =G6+H6+I6 -> 4.4206485 | K6: =J6*E6 -> 2444.6186
A7: 1A | B7: FOOD PRODUCT AND PREP | C7: 87991 | D7: ENT, FC/CC, PP, FRESH FRUIT PLATE, CANTALOUPE, PINEAPPLE, HONEY DEW, BLUEBERRIES, STRAWBERRIES, LARGE BOWL, I, FRUT | E7: 609 | G7: 1.1950542 | H7: 0.12762715 | I7: 0.69 | J7: =G7+H7+I7 -> 2.0126814 | K7: =J7*E7 -> 1225.723
A8: 1A | B8: FOOD PRODUCT AND PREP | C8: 87992 | D8: ENT, FC/CC, PP, FRESH FRUIT PLATE, CANTALOUPE, PINEAPPLE, HONEY DEW, BLUEBERRIES, STRAWBERRIES, LARGE BOWL, II, FRUT | E8: 498 | G8: 1.1950542 | H8: 0.12762715 | I8: 0.69 | J8: =G8+H8+I8 -> 2.0126814 | K8: =J8*E8 -> 1002.3153
A9: 1A | B9: FOOD PRODUCT AND PREP | C9: 88303 | D9: ENT, FC/CC, FRUIT AND CHEESE, DOM, CHES | E9: 0 | G9: 2.8272426 | H9: 0.30193853 | I9: 1.15 | J9: =G9+H9+I9 -> 4.2791811 | K9: =J9*E9 -> 0
A10: 1A | B10: FOOD PRODUCT AND PREP | C10: 89766 | D10: ENT, CC, EGGS, ASPARAGUS, LEEK AND MUSHROOM FRITTATA, HONEY ROASTED SWEET POTATOES, TOMATOES, IN CASSEROLE, ALTF | E10: 1518 | G10: 3.4409664 | H10: 0.36748185 | I10: 0.805 | J10: =G10+H10+I10 -> 4.6134483 | K10: =J10*E10 -> 7003.2145
A11: 1A | B11: FOOD PRODUCT AND PREP | C11: 89773 | D11: ENT, FC/CC, PP, COLD PLATE, VEGETABLES AND GRAINS, IN LARGE BOWL, FALL/WINTER, PRE-ORDER ONLY, ALTG | E11: 0 | G11: 2.4704242 | H11: 0.26383171 | I11: 1.38 | J11: =G11+H11+I11 -> 4.1142559 | K11: =J11*E11 -> 0
A12: 1A | B12: FOOD PRODUCT AND PREP | C12: 89779 | D12: ENT, FC/CC, PP, GOLDEN ROASTED CHICKEN, TOMATO CHUTNEY, YUKON SMASHED POTATOES, HARICOT VERT, LEMON, IN CASSEROLE, PRE-ORDER ONLY, ALTE | E12: 0 | G12: 3.2900002 | H12: 0.35135924 | I12: 1.035 | J12: =G12+H12+I12 -> 4.6763594 | K12: =J12*E12 -> 0
A13: 1A | B13: FOOD PRODUCT AND PREP | C13: 90009 | D13: ENT, FC/CC, PP/BP, COLD PLATE, VEGETABLES AND GRAINS, LARGE BOWL, SPRING/SUMMER, ALTG | E13: 0 | G13: 1.7312712 | H13: 0.18489304 | I13: 1.38 | J13: =G13+H13+I13 -> 3.2961642 | K13: =J13*E13 -> 0
A14: 1A | B14: FOOD PRODUCT AND PREP | C14: 90593 | D14: ENT, FC/CC, CHICKEN BREAST, SHAWARMA SEASONED, TUMERIC RICE, LABNEH, IN CASSEROLE, CHCK | E14: 2198 | G14: 5.18332 | H14: 0.6219984 | I14: 0 | J14: =G14+H14+I14 -> 5.8053184 | K14: =J14*E14 -> 12760.09
... A26: 1A | B26: FOOD PRODUCT AND PREP | C26: 91891 | D26: ENT, CC, PP, EGGS, SPINACH, RED PEPPERS AND CHEESE FRITTATA W WHITE CHEDDAR SAUCE, EVERYTHING SEASONED WEDGE POTATOES, ROASTED TOMATOES, IN CASSEROLE, EGGS | E26: 560 | G26: 3.333 | H26: 0.39996 | I26: 0 | J26: =G26+H26+I26 -> 3.73296 | K26: =J26*E26 -> 2090.4576
A27: 1A | B27: FOOD PRODUCT AND PREP | C27: 50808 | D27: ENT, FRUIT AND CHEESE PLATE, FD4SALE, POFC | E27: 9526 | F27: labor paid 72011 | G27: 2.5815589 | H27: 0.27570047 | J27: =G27+H27+I27 -> 2.8572594 | K27: =J27*E27 -> 27218.253
A28: 1A | B28: FOOD PRODUCT AND PREP | C28: 89910 | D28: FFS SNACKS, YC, STANDARD SNACK DRAWER, SHELF STABLE, II | E28: 615 | F28: LABOR PAID IN 83710/PRODUCT IS AA | G28: 0
A29: 1A | B29: FOOD PRODUCT AND PREP | C29: 87987 | D29: TSU, CC, DOM, BRK, HOT, EGGS, MH | E29: 6339 | F29: LABOR PAID IN TSC | G29: 0.0206 | H29: 0.0022 | J29: =G29+H29+I29 -> 0.0228 | K29: =J29*E29 -> 144.5292
A30: 1A | B30: FOOD PRODUCT AND PREP | C30: 87988 | D30: TSU, CC, DOM, BRK, COLD PLATE, PROTEIN, MH | E30: 543 | F30: LABOR PAID IN TSC | G30: 0.0206 | H30: 0.0022 | J30: =G30+H30+I30 -> 0.0228 | K30: =J30*E30 -> 12.3804
A31: 1A | B31: FOOD PRODUCT AND PREP | C31: 87989 | D31: TSU, CC, DOM, BRK, COLD PLATE, FRUIT, MH/LH | E31: 1045 | F31: LABOR PAID IN TSC | G31: 0.0206 | H31: 0.0022 | J31: =G31+H31+I31 -> 0.0228 | K31: =J31*E31 -> 23.826
A32: 1A | B32: FOOD PRODUCT AND PREP | C32: 88002 | D32: TSU, CC, DOM, BRK, COLD PLATE, SMOKED SALMON AND BAGEL, MH | E32: 734 | F32: LABOR PAID IN TSC | G32: 0.0206 | H32: 0.0022 | J32: =G32+H32+I32 -> 0.0228 | K32: =J32*E32 -> 16.7352
A33: 1A | B33: FOOD PRODUCT AND PREP | C33: 88007 | D33: TSU, CC, DOM, L/D, W/PROTEIN APP, MH | E33: 8600 | F33: LABOR PAID IN TSC | G33: 0.0206 | H33: 0.0022 | J33: =G33+H33+I33 -> 0.0228 | K33: =J33*E33 -> 196.08
A34: 1A | B34: FOOD PRODUCT AND PREP | C34: 88008 | D34: TSU, CC, DOM, L/D, W/VEGETARIAN APP, MH | E34: 3498 | F34: LABOR PAID IN TSC | G34: 0.0206 | H34: 0.0022 | J34: =G34+H34+I34 -> 0.0228 | K34: =J34*E34 -> 79.7544
A35: 1A | B35: FOOD PRODUCT AND PREP | C35: 88273 | D35: TSU, FC/CC, DOM SH BRK, VEG, CY 1/3 | E35: 49 | F35: LABOR PAID IN TSC | G35: 0.0206 | H35: 0.0022 | J35: =G35+H35+I35 -> 0.0228 | K35: =J35*E35 -> 1.1172
A36: 1A | B36: FOOD PRODUCT AND PREP | C36: 88274 | D36: TSU, FC/CC, PROTEIN BRK, DOM SH, CY1 | E36: 20 | F36: LABOR PAID IN TSC | G36: 0.0206 | H36: 0.0022 | J36: =G36+H36+I36 -> 0.0228 | K36: =J36*E36 -> 0.456
A37: 1A | B37: FOOD PRODUCT AND PREP | C37: 88275 | D37: TSU, FC/CC, PROTEIN BRK, DOM SH, CY4 | E37: 6 | F37: LABOR PAID IN TSC | G37: 0.0206 | H37: 0.0022 | J37: =G37+H37+I37 -> 0.0228 | K37: =J37*E37 -> 0.1368
A38: 1A | B38: FOOD PRODUCT AND PREP | C38: 88276 | D38: TSU, FC/CC, CONTINENTAL FRUIT BRK, DOM SH, CY 2/4 | E38: 62 | F38: LABOR PAID IN TSC | G38: 0.0206 | H38: 0.0022 | J38: =G38+H38+I38 -> 0.0228 | K38: =J38*E38 -> 1.4136
A39: 1A | B39: FOOD PRODUCT AND PREP | C39: 88807 | D39: TSU, XX, LUN/DIN, LH, W/APP & SAL IN SM BOWLS | E39: 1230 | F39: LABOR PAID IN TSC | G39: 0.0206 | H39: 0.0022 | J39: =G39+H39+I39 -> 0.0228 | K39: =J39*E39 -> 28.044
A40: 1A | B40: FOOD PRODUCT AND PREP | C40: 88808 | D40: TSU, XX, LUN/DIN, LH, W/VEGETARIAN APP & SAL IN SM BOWLS | E40: 438 | F40: LABOR PAID IN TSC | G40: 0.0206 | H40: 0.0022 | J40: =G40+H40+I40 -> 0.0228 | K40: =J40*E40 -> 9.9864
... A45: 1A | B45: FOOD PRODUCT AND PREP | C45: 89962 | D45: TSU, FC/CC, PROTEIN BRK, DOM SH, CY3 | E45: 78 | F45: LABOR PAID IN TSC | G45: 0.0206 | H45: 0.0022 | J45: =G45+H45+I45 -> 0.0228 | K45: =J45*E45 -> 1.7784
A46: 1A | B46: FOOD PRODUCT AND PREP | C46: 17817 | D46: MISC, FC/CC, BP, BUTTER, GRASSLAND, 1 EA, UP TO 16 IN A BAG | E46: 9842 | G46: 0.097755 | H46: 0.0117306 | I46: 0 | J46: =G46+H46+I46 -> 0.1094856 | K46: =J46*E46 -> 1077.5573
A47: 1A | B47: FOOD PRODUCT AND PREP | C47: 32727 | D47: GARN, GARNISH, LIQ/BEV, 5 LEMON / 5 LIME IN PLASTIC CUP AND LID | E47: 6756 | G47: 0.32774951 | H47: 0.035002375 | I47: 0.46 | J47: =G47+H47+I47 -> 0.82275189 | K47: =J47*E47 -> 5558.5117
A48: 1A | B48: FOOD PRODUCT AND PREP | C48: 39289 | D48: MISC, FC/CC, BP, PRESERVES, STRAWBERRY, BONNE MAMAN, 0.5 OZ STICK, 20030, UP TO 16 EA IN A BAG | E48: 5694 | G48: 0.1491 | H48: 0.017892 | I48: 0 | J48: =G48+H48+I48 -> 0.166992 | K48: =J48*E48 -> 950.85245
A49: 1A | B49: FOOD PRODUCT AND PREP | C49: 39505 | D49: MISC, CONDIMENT, BP, HONEY, STICK, .5 OZ, PC, UP TO 16 EA IN A BAG | E49: 3796 | G49: 0.2856 | H49: 0.034272 | I49: 0 | J49: =G49+H49+I49 -> 0.319872 | K49: =J49*E49 -> 1214.2341
A50: 1A | B50: FOOD PRODUCT AND PREP | C50: 459 | D50: MISC, MIXED NUTS, BP | E50: 1801 | G50: 5.88 | H50: 0.7056 | I50: 0 | J50: =G50+H50+I50 -> 6.5856 | K50: =J50*E50 -> 11860.666
A51: 1A | B51: FOOD PRODUCT AND PREP | C51: 48561 | D51: GARN, FC, BP, CHEESE, COTIJA, CRUMBLED | E51: 2360 | G51: 0.37617391 | H51: 0.040173913 | I51: 0.115 | J51: =G51+H51+I51 -> 0.53134783 | K51: =J51*E51 -> 1253.9809
A52: 1A | B52: FOOD PRODUCT AND PREP | C52: 49964 | D52: MILK, 2% ASEPTIC, 8 FLOZ, BULK | E52: 9068 | F52: AA PRODUCT/;ABOR PAID IN DRAWER PK | G52: 0 | H52: 0 | I52: 0 | J52: =G52+H52+I52 -> 0 | K52: =J52*E52 -> 0
A53: 1A | B53: FOOD PRODUCT AND PREP | C53: 58117 | D53: BRD, FC/CC, BP, BISCUIT, SOUTHERN STYLE, WARM ON BOARD, 1 EA, UP TO 6 EA IN A BAG | E53: 3796 | G53: 0.30865625 | H53: 0.03703875 | I53: 0 | J53: =G53+H53+I53 -> 0.345695 | K53: =J53*E53 -> 1312.2582
A54: 1A | B54: FOOD PRODUCT AND PREP | C54: 58738 | D54: MISC, YC, BP, PRETZEL, MINI, KING NUT, .75OZ, BAG OF 25 EA, SNACKS | E54: 2460 | F54: AA PRODUCT/;ABOR PAID IN DRAWER PK | G54: 0 | H54: 0 | I54: 0 | J54: =G54+H54+I54 -> 0 | K54: =J54*E54 -> 0
A55: 1A | B55: FOOD PRODUCT AND PREP | C55: 58848 | D55: GARN, PP/BP, GARNISH, PARSLEY, CHOPPED, IN SOLO CUP | E55: 2500 | G55: 0.22890843 | H55: 0.024446531 | I55: 0.345 | J55: =G55+H55+I55 -> 0.59835496 | K55: =J55*E55 -> 1495.8874
...
