Workbook

Sheet Flights
A1: Sullivan Rd — Financial Master Sheet | Add new rows below. Blue = enter data. Column L auto-flags duplicates. To import: open dashboard → Load Data → select this file.
A2: Airline | B2: Date | C2: Flight / Invoice | D2: Food Revenue | E2: Service Revenue | F2: Total Revenue | G2: Pax Count | H2: Status | I2: Notes | J2: Source File | K2: Unique Key | L2: Duplicate?
A3: VS | B3: 46023 | C3: Monthly Summary | D3: 229644.41 | E3: 140927.3 | F3: =IF(AND(D2="",E2=""),"",IFERROR(D2+E2,"")) | H3: Paid | I3: Jan 2026 Sage Intacct | J3: Sage Intacct Export | K3: =A2&"|"&TEXT(B2,"YYYY-MM-DD")&"|"&C2 -> Airline|Date|Flight / Invoice | L3: =IF(COUNTIFS($A$2:A2,$A2,$B$2:$B2,$B2,$C$2:$C2,$C2)>1,"⚠ DUPLICATE","✓ OK") -> ✓ OK
A4: VS | B4: 46054 | C4: Monthly Summary | D4: 186972.31 | E4: 114949.32 | F4: =IF(AND(D3="",E3=""),"",IFERROR(D3+E3,"")) -> 370571.71 | H4: Paid | I4: Feb 2026 Sage Intacct | J4: Sage Intacct Export | K4: =A3&"|"&TEXT(B3,"YYYY-MM-DD")&"|"&C3 -> VS|2026-01-01|Monthly Summary | L4: =IF(COUNTIFS($A$2:A3,$A3,$B$2:$B3,$B3,$C$2:$C3,$C3)>1,"⚠ DUPLICATE","✓ OK") -> ✓ OK
A5: VS | B5: 46082 | C5: Monthly Summary | D5: 241979.11 | E5: 127316.08 | F5: =IF(AND(D4="",E4=""),"",IFERROR(D4+E4,"")) -> 301921.63 | H5: Paid | I5: Mar 2026 Sage Intacct | J5: Sage Intacct Export | K5: =A4&"|"&TEXT(B4,"YYYY-MM-DD")&"|"&C4 -> VS|2026-02-01|Monthly Summary | L5: =IF(COUNTIFS($A$2:A4,$A4,$B$2:$B4,$B4,$C$2:$C4,$C4)>1,"⚠ DUPLICATE","✓ OK") -> ✓ OK
A6: VS | B6: 46113 | C6: Monthly Summary | D6: 285489.64 | E6: 142136.08 | F6: =IF(AND(D5="",E5=""),"",IFERROR(D5+E5,"")) -> 369295.19 | H6: Paid | I6: Apr 2026 Sage Intacct | J6: Sage Intacct Export | K6: =A5&"|"&TEXT(B5,"YYYY-MM-DD")&"|"&C5 -> VS|2026-03-01|Monthly Summary | L6: =IF(COUNTIFS($A$2:A5,$A5,$B$2:$B5,$B5,$C$2:$C5,$C5)>1,"⚠ DUPLICATE","✓ OK") -> ✓ OK
A7: VS | B7: 46143 | C7: Monthly Summary | D7: 302760.27 | E7: 149155.53 | F7: =IF(AND(D6="",E6=""),"",IFERROR(D6+E6,"")) -> 427625.72 | H7: Paid | I7: May 2026 Sage Intacct | J7: Sage Intacct Export | K7: =A6&"|"&TEXT(B6,"YYYY-MM-DD")&"|"&C6 -> VS|2026-04-01|Monthly Summary | L7: =IF(COUNTIFS($A$2:A6,$A6,$B$2:$B6,$B6,$C$2:$C6,$C6)>1,"⚠ DUPLICATE","✓ OK") -> ✓ OK
A8: AA | B8: 46023 | C8: AA-INV-0101 | D8: 4653.37 | E8: 0 | F8: =IF(AND(D7="",E7=""),"",IFERROR(D7+E7,"")) -> 451915.8 | H8: Paid | J8: Sage Intacct Export | K8: =A7&"|"&TEXT(B7,"YYYY-MM-DD")&"|"&C7 -> VS|2026-05-01|Monthly Summary | L8: =IF(COUNTIFS($A$2:A7,$A7,$B$2:$B7,$B7,$C$2:$C7,$C7)>1,"⚠ DUPLICATE","✓ OK") -> ✓ OK
A9: AA | B9: 46026 | C9: AA-INV-0104 | D9: 1725.76 | E9: 9801.78 | F9: =IF(AND(D8="",E8=""),"",IFERROR(D8+E8,"")) -> 4653.37 | H9: Paid | J9: Sage Intacct Export | K9: =A8&"|"&TEXT(B8,"YYYY-MM-DD")&"|"&C8 -> AA|2026-01-01|AA-INV-0101 | L9: =IF(COUNTIFS($A$2:A8,$A8,$B$2:$B8,$B8,$C$2:$C8,$C8)>1,"⚠ DUPLICATE","✓ OK") -> ✓ OK
A10: AA | B10: 46033 | C10: AA-INV-0111 | D10: 2240.11 | E10: 14853.85 | F10: =IF(AND(D9="",E9=""),"",IFERROR(D9+E9,"")) -> 11527.54 | H10: Paid | J10: Sage Intacct Export | K10: =A9&"|"&TEXT(B9,"YYYY-MM-DD")&"|"&C9 -> AA|2026-01-04|AA-INV-0104 | L10: =IF(COUNTIFS($A$2:A9,$A9,$B$2:$B9,$B9,$C$2:$C9,$C9)>1,"⚠ DUPLICATE","✓ OK") -> ✓ OK
A11: AA | B11: 46040 | C11: AA-INV-0118 | D11: 2327.43 | E11: 14442.99 | F11: =IF(AND(D10="",E10=""),"",IFERROR(D10+E10,"")) -> 17093.96 | H11: Paid | J11: Sage Intacct Export | K11: =A10&"|"&TEXT(B10,"YYYY-MM-DD")&"|"&C10 -> AA|2026-01-11|AA-INV-0111 | L11: =IF(COUNTIFS($A$2:A10,$A10,$B$2:$B10,$B10,$C$2:$C10,$C10)>1,"⚠ DUPLICATE","✓ OK") -> ✓ OK
A12: AA | B12: 46047 | C12: AA-INV-0125 | D12: 2385.76 | E12: 13536.27 | F12: =IF(AND(D11="",E11=""),"",IFERROR(D11+E11,"")) -> 16770.42 | H12: Paid | J12: Sage Intacct Export | K12: =A11&"|"&TEXT(B11,"YYYY-MM-DD")&"|"&C11 -> AA|2026-01-18|AA-INV-0118 | L12: =IF(COUNTIFS($A$2:A11,$A11,$B$2:$B11,$B11,$C$2:$C11,$C11)>1,"⚠ DUPLICATE","✓ OK") -> ✓ OK
A13: AA | B13: 46053 | C13: AA-INV-0131 | D13: 6246.17 | E13: 9208.3 | F13: =IF(AND(D12="",E12=""),"",IFERROR(D12+E12,"")) -> 15922.03 | H13: Paid | J13: Sage Intacct Export | K13: =A12&"|"&TEXT(B12,"YYYY-MM-DD")&"|"&C12 -> AA|2026-01-25|AA-INV-0125 | L13: =IF(COUNTIFS($A$2:A12,$A12,$B$2:$B12,$B12,$C$2:$C12,$C12)>1,"⚠ DUPLICATE","✓ OK") -> ✓ OK
A14: AA | B14: 46054 | C14: AA-INV-0201 | D14: 528.47 | E14: 2378.68 | F14: =IF(AND(D13="",E13=""),"",IFERROR(D13+E13,"")) -> 15454.47 | H14: Paid | J14: Sage Intacct Export | K14: =A13&"|"&TEXT(B13,"YYYY-MM-DD")&"|"&C13 -> AA|2026-01-31|AA-INV-0131 | L14: =IF(COUNTIFS($A$2:A13,$A13,$B$2:$B13,$B13,$C$2:$C13,$C13)>1,"⚠ DUPLICATE","✓ OK") -> ✓ OK
A15: AA | B15: 46061 | C15: AA-INV-0208 | D15: 2453.21 | E15: 13601.09 | F15: =IF(AND(D14="",E14=""),"",IFERROR(D14+E14,"")) -> 2907.15 | H15: Paid | J15: Sage Intacct Export | K15: =A14&"|"&TEXT(B14,"YYYY-MM-DD")&"|"&C14 -> AA|2026-02-01|AA-INV-0201 | L15: =IF(COUNTIFS($A$2:A14,$A14,$B$2:$B14,$B14,$C$2:$C14,$C14)>1,"⚠ DUPLICATE","✓ OK") -> ✓ OK
A16: AA | B16: 46068 | C16: AA-INV-0215 | D16: 2659.18 | E16: 15439 | F16: =IF(AND(D15="",E15=""),"",IFERROR(D15+E15,"")) -> 16054.3 | H16: Paid | J16: Sage Intacct Export | K16: =A15&"|"&TEXT(B15,"YYYY-MM-DD")&"|"&C15 -> AA|2026-02-08|AA-INV-0208 | L16: =IF(COUNTIFS($A$2:A15,$A15,$B$2:$B15,$B15,$C$2:$C15,$C15)>1,"⚠ DUPLICATE","✓ OK") -> ✓ OK
A17: AA | B17: 46075 | C17: AA-INV-0222 | D17: 2884.78 | E17: 17396.34 | F17: =IF(AND(D16="",E16=""),"",IFERROR(D16+E16,"")) -> 18098.18 | H17: Paid | J17: Sage Intacct Export | K17: =A16&"|"&TEXT(B16,"YYYY-MM-DD")&"|"&C16 -> AA|2026-02-15|AA-INV-0215 | L17: =IF(COUNTIFS($A$2:A16,$A16,$B$2:$B16,$B16,$C$2:$C16,$C16)>1,"⚠ DUPLICATE","✓ OK") -> ✓ OK
A18: AA | B18: 46081 | C18: AA-INV-0228 | D18: 2452.76 | E18: 14857.51 | F18: =IF(AND(D17="",E17=""),"",IFERROR(D17+E17,"")) -> 20281.12 | H18: Paid | J18: Sage Intacct Export | K18: =A17&"|"&TEXT(B17,"YYYY-MM-DD")&"|"&C17 -> AA|2026-02-22|AA-INV-0222 | L18: =IF(COUNTIFS($A$2:A17,$A17,$B$2:$B17,$B17,$C$2:$C17,$C17)>1,"⚠ DUPLICATE","✓ OK") -> ✓ OK
A19: AA | B19: 46082 | C19: AA-INV-0301 | D19: 4485.91 | E19: 1791.77 | F19: =IF(AND(D18="",E18=""),"",IFERROR(D18+E18,"")) -> 17310.27 | H19: Paid | J19: Sage Intacct Export | K19: =A18&"|"&TEXT(B18,"YYYY-MM-DD")&"|"&C18 -> AA|2026-02-28|AA-INV-0228 | L19: =IF(COUNTIFS($A$2:A18,$A18,$B$2:$B18,$B18,$C$2:$C18,$C18)>1,"⚠ DUPLICATE","✓ OK") -> ✓ OK
... A24: AA | B24: 46112 | C24: AA-INV-0331 | D24: 4041.49 | E24: 4805.44 | F24: =IF(AND(D23="",E23=""),"",IFERROR(D23+E23,"")) -> 21510.88 | H24: Paid | J24: Sage Intacct Export | K24: =A23&"|"&TEXT(B23,"YYYY-MM-DD")&"|"&C23 -> AA|2026-03-29|AA-INV-0329 | L24: =IF(COUNTIFS($A$2:A23,$A23,$B$2:$B23,$B23,$C$2:$C23,$C23)>1,"⚠ DUPLICATE","✓ OK") -> ✓ OK
A25: AA | B25: 46113 | C25: AA-INV-0401 | D25: 0 | E25: -1325 | F25: =IF(AND(D24="",E24=""),"",IFERROR(D24+E24,"")) -> 8846.93 | H25: Paid | I25: Credit memo | J25: Sage Intacct Export | K25: =A24&"|"&TEXT(B24,"YYYY-MM-DD")&"|"&C24 -> AA|2026-03-31|AA-INV-0331 | L25: =IF(COUNTIFS($A$2:A24,$A24,$B$2:$B24,$B24,$C$2:$C24,$C24)>1,"⚠ DUPLICATE","✓ OK") -> ✓ OK
A26: AA | B26: 46117 | C26: AA-INV-0405 | D26: 3914.46 | E26: 12091.79 | F26: =IF(AND(D25="",E25=""),"",IFERROR(D25+E25,"")) -> -1325 | H26: Paid | J26: Sage Intacct Export | K26: =A25&"|"&TEXT(B25,"YYYY-MM-DD")&"|"&C25 -> AA|2026-04-01|AA-INV-0401 | L26: =IF(COUNTIFS($A$2:A25,$A25,$B$2:$B25,$B25,$C$2:$C25,$C25)>1,"⚠ DUPLICATE","✓ OK") -> ✓ OK
A27: AA | B27: 46124 | C27: AA-INV-0412 | D27: 6730.62 | E27: 17606.52 | F27: =IF(AND(D26="",E26=""),"",IFERROR(D26+E26,"")) -> 16006.25 | H27: Paid | J27: Sage Intacct Export | K27: =A26&"|"&TEXT(B26,"YYYY-MM-DD")&"|"&C26 -> AA|2026-04-05|AA-INV-0405 | L27: =IF(COUNTIFS($A$2:A26,$A26,$B$2:$B26,$B26,$C$2:$C26,$C26)>1,"⚠ DUPLICATE","✓ OK") -> ✓ OK
A28: AA | B28: 46131 | C28: AA-INV-0419 | D28: 4342.34 | E28: 18544.58 | F28: =IF(AND(D27="",E27=""),"",IFERROR(D27+E27,"")) -> 24337.14 | H28: Paid | J28: Sage Intacct Export | K28: =A27&"|"&TEXT(B27,"YYYY-MM-DD")&"|"&C27 -> AA|2026-04-12|AA-INV-0412 | L28: =IF(COUNTIFS($A$2:A27,$A27,$B$2:$B27,$B27,$C$2:$C27,$C27)>1,"⚠ DUPLICATE","✓ OK") -> ✓ OK
A29: AA | B29: 46138 | C29: AA-INV-0426 | D29: 4651.73 | E29: 18805.23 | F29: =IF(AND(D28="",E28=""),"",IFERROR(D28+E28,"")) -> 22886.92 | H29: Paid | J29: Sage Intacct Export | K29: =A28&"|"&TEXT(B28,"YYYY-MM-DD")&"|"&C28 -> AA|2026-04-19|AA-INV-0419 | L29: =IF(COUNTIFS($A$2:A28,$A28,$B$2:$B28,$B28,$C$2:$C28,$C28)>1,"⚠ DUPLICATE","✓ OK") -> ✓ OK
A30: AA | B30: 46142 | C30: AA-INV-0430 | D30: 2522.48 | E30: 10711.27 | F30: =IF(AND(D29="",E29=""),"",IFERROR(D29+E29,"")) -> 23456.96 | H30: Paid | J30: Sage Intacct Export | K30: =A29&"|"&TEXT(B29,"YYYY-MM-DD")&"|"&C29 -> AA|2026-04-26|AA-INV-0426 | L30: =IF(COUNTIFS($A$2:A29,$A29,$B$2:$B29,$B29,$C$2:$C29,$C29)>1,"⚠ DUPLICATE","✓ OK") -> ✓ OK
A31: AA | B31: 46145 | C31: AA-INV-0503 | D31: 1890.43 | E31: 8267.94 | F31: =IF(AND(D30="",E30=""),"",IFERROR(D30+E30,"")) -> 13233.75 | H31: Paid | J31: Sage Intacct Export | K31: =A30&"|"&TEXT(B30,"YYYY-MM-DD")&"|"&C30 -> AA|2026-04-30|AA-INV-0430 | L31: =IF(COUNTIFS($A$2:A30,$A30,$B$2:$B30,$B30,$C$2:$C30,$C30)>1,"⚠ DUPLICATE","✓ OK") -> ✓ OK
A32: ET | B32: 46030 | C32: ET-INV-0108 | D32: 63302.84 | E32: 5535 | F32: =IF(AND(D31="",E31=""),"",IFERROR(D31+E31,"")) -> 10158.37 | H32: Invoiced | J32: Sage Intacct Export | K32: =A31&"|"&TEXT(B31,"YYYY-MM-DD")&"|"&C31 -> AA|2026-05-03|AA-INV-0503 | L32: =IF(COUNTIFS($A$2:A31,$A31,$B$2:$B31,$B31,$C$2:$C31,$C31)>1,"⚠ DUPLICATE","✓ OK") -> ✓ OK
A33: ET | B33: 46041 | C33: ET-INV-0119 | D33: 35275.77 | E33: 4920 | F33: =IF(AND(D32="",E32=""),"",IFERROR(D32+E32,"")) -> 68837.84 | H33: Invoiced | J33: Sage Intacct Export | K33: =A32&"|"&TEXT(B32,"YYYY-MM-DD")&"|"&C32 -> ET|2026-01-08|ET-INV-0108 | L33: =IF(COUNTIFS($A$2:A32,$A32,$B$2:$B32,$B32,$C$2:$C32,$C32)>1,"⚠ DUPLICATE","✓ OK") -> ✓ OK
A34: ET | B34: 46057 | C34: ET-INV-0204 | D34: 26563.54 | E34: 4305 | F34: =IF(AND(D33="",E33=""),"",IFERROR(D33+E33,"")) -> 40195.77 | H34: Invoiced | J34: Sage Intacct Export | K34: =A33&"|"&TEXT(B33,"YYYY-MM-DD")&"|"&C33 -> ET|2026-01-19|ET-INV-0119 | L34: =IF(COUNTIFS($A$2:A33,$A33,$B$2:$B33,$B33,$C$2:$C33,$C33)>1,"⚠ DUPLICATE","✓ OK") -> ✓ OK
A35: ET | B35: 46076 | C35: ET-INV-0223 | D35: 5283.81 | E35: 615 | F35: =IF(AND(D34="",E34=""),"",IFERROR(D34+E34,"")) -> 30868.54 | H35: Invoiced | J35: Sage Intacct Export | K35: =A34&"|"&TEXT(B34,"YYYY-MM-DD")&"|"&C34 -> ET|2026-02-04|ET-INV-0204 | L35: =IF(COUNTIFS($A$2:A34,$A34,$B$2:$B34,$B34,$C$2:$C34,$C34)>1,"⚠ DUPLICATE","✓ OK") -> ✓ OK
A36: ET | B36: 46164 | C36: ET519 | D36: 10358.19 | E36: 1050 | F36: =IF(AND(D35="",E35=""),"",IFERROR(D35+E35,"")) -> 5898.81 | G36: 251 | H36: Invoiced | I36: ET20260522 · 20 biz / 231 econ pax | J36: Mainline Aviation - ET Invoice NEW revised.xlsx | K36: =A35&"|"&TEXT(B35,"YYYY-MM-DD")&"|"&C35 -> ET|2026-02-23|ET-INV-0223 | L36: =IF(COUNTIFS($A$2:A35,$A35,$B$2:$B35,$B35,$C$2:$C35,$C35)>1,"⚠ DUPLICATE","✓ OK") -> ✓ OK
A37: ET | B37: 46167 | C37: ET519 | D37: 10093.14 | E37: 1050 | F37: =IF(AND(D36="",E36=""),"",IFERROR(D36+E36,"")) -> 11408.19 | G37: 261 | H37: Invoiced | I37: ET20260525 · 22 biz / 239 econ pax | J37: Mainline Aviation - ET Invoice NEW revised.xlsx | K37: =A36&"|"&TEXT(B36,"YYYY-MM-DD")&"|"&C36 -> ET|2026-05-22|ET519 | L37: =IF(COUNTIFS($A$2:A36,$A36,$B$2:$B36,$B36,$C$2:$C36,$C36)>1,"⚠ DUPLICATE","✓ OK") -> ✓ OK
A38: ET | B38: 46169 | C38: ET519 | D38: 9724.11 | E38: 1050 | F38: =IF(AND(D37="",E37=""),"",IFERROR(D37+E37,"")) -> 11143.14 | G38: 245 | H38: Invoiced | I38: ET20260527 · 20 biz / 225 econ pax | J38: Mainline Aviation - ET Invoice NEW revised.xlsx | K38: =A37&"|"&TEXT(B37,"YYYY-MM-DD")&"|"&C37 -> ET|2026-05-25|ET519 | L38: =IF(COUNTIFS($A$2:A37,$A37,$B$2:$B37,$B37,$C$2:$C37,$C37)>1,"⚠ DUPLICATE","✓ OK") -> ✓ OK
A39: ET | B39: 46171 | C39: ET519 | D39: 9444.54 | E39: 1050 | F39: =IF(AND(D38="",E38=""),"",IFERROR(D38+E38,"")) -> 10774.11 | G39: 244 | H39: Invoiced | I39: ET20260529 · 22 biz / 222 econ pax | J39: Mainline Aviation - ET Invoice NEW revised.xlsx | K39: =A38&"|"&TEXT(B38,"YYYY-MM-DD")&"|"&C38 -> ET|2026-05-27|ET519 | L39: =IF(COUNTIFS($A$2:A38,$A38,$B$2:$B38,$B38,$C$2:$C38,$C38)>1,"⚠ DUPLICATE","✓ OK") -> ✓ OK
A40: SK | B40: 46029 | C40: Monthly Summary | D40: 85416.64 | E40: 11400 | F40: =IF(AND(D39="",E39=""),"",IFERROR(D39+E39,"")) -> 10494.54 | H40: Paid | I40: Jan 2026 Sage Intacct | J40: Sage Intacct Export | K40: =A39&"|"&TEXT(B39,"YYYY-MM-DD")&"|"&C39 -> ET|2026-05-29|ET519 | L40: =IF(COUNTIFS($A$2:A39,$A39,$B$2:$B39,$B39,$C$2:$C39,$C39)>1,"⚠ DUPLICATE","✓ OK") -> ✓ OK
A41: SK | B41: 46062 | C41: Monthly Summary | D41: 79976.49 | E41: 12160 | F41: =IF(AND(D40="",E40=""),"",IFERROR(D40+E40,"")) -> 96816.64 | H41: Paid | I41: Feb 2026 Sage Intacct | J41: Sage Intacct Export | K41: =A40&"|"&TEXT(B40,"YYYY-MM-DD")&"|"&C40 -> SK|2026-01-07|Monthly Summary | L41: =IF(COUNTIFS($A$2:A40,$A40,$B$2:$B40,$B40,$C$2:$C40,$C40)>1,"⚠ DUPLICATE","✓ OK") -> ✓ OK
A42: SK | B42: 46092 | C42: Monthly Summary | D42: 79753.24 | E42: 12160 | F42: =IF(AND(D41="",E41=""),"",IFERROR(D41+E41,"")) -> 92136.49 | H42: Paid | I42: Mar 2026 Sage Intacct | J42: Sage Intacct Export | K42: =A41&"|"&TEXT(B41,"YYYY-MM-DD")&"|"&C41 -> SK|2026-02-09|Monthly Summary | L42: =IF(COUNTIFS($A$2:A41,$A41,$B$2:$B41,$B41,$C$2:$C41,$C41)>1,"⚠ DUPLICATE","✓ OK") -> ✓ OK
A43: SK | B43: 46120 | C43: Monthly Summary | D43: 86748.82 | E43: 12920 | F43: =IF(AND(D42="",E42=""),"",IFERROR(D42+E42,"")) -> 91913.24 | H43: Paid | I43: Apr 2026 Sage Intacct | J43: Sage Intacct Export | K43: =A42&"|"&TEXT(B42,"YYYY-MM-DD")&"|"&C42 -> SK|2026-03-11|Monthly Summary | L43: =IF(COUNTIFS($A$2:A42,$A42,$B$2:$B42,$B42,$C$2:$C42,$C42)>1,"⚠ DUPLICATE","✓ OK") -> ✓ OK
A44: SK | B44: 46153 | C44: Monthly Summary | D44: 87021.12 | E44: 12160 | F44: =IF(AND(D43="",E43=""),"",IFERROR(D43+E43,"")) -> 99668.82 | H44: Paid | I44: May 2026 Sage Intacct | J44: Sage Intacct Export | K44: =A43&"|"&TEXT(B43,"YYYY-MM-DD")&"|"&C43 -> SK|2026-04-08|Monthly Summary | L44: =IF(COUNTIFS($A$2:A43,$A43,$B$2:$B43,$B43,$C$2:$C43,$C43)>1,"⚠ DUPLICATE","✓ OK") -> ✓ OK
...

Sheet Monthly Summary
A1: Sullivan Rd — Monthly Revenue Summary (auto-calculated from Flights sheet)
A2: Month | B2: Month Start | C2: VS Food | D2: VS Svc | E2: VS Total | F2: AA Food | G2: AA Svc | H2: AA Total | I2: ET Food | J2: ET Svc | K2: ET Total | L2: SK Food | M2: SK Svc | N2: SK Total | O2: Grand Food | P2: Grand Svc | Q2: Grand Total
A3: Jan 2026 | B3: 46023 | C3: =IFERROR(SUMIFS(Flights!$D:$D,Flights!$A:$A,"VS",Flights!$B:$B,">="&$B3,Flights!$B:$B,"<"&DATE(2026,2,1)),0) -> 229644.41 | D3: =IFERROR(SUMIFS(Flights!$E:$E,Flights!$A:$A,"VS",Flights!$B:$B,">="&$B3,Flights!$B:$B,"<"&DATE(2026,2,1)),0) -> 140927.3 | E3: =C3+D3 -> 370571.71 | F3: =IFERROR(SUMIFS(Flights!$D:$D,Flights!$A:$A,"AA",Flights!$B:$B,">="&$B3,Flights!$B:$B,"<"&DATE(2026,2,1)),0) -> 19578.6 | G3: =IFERROR(SUMIFS(Flights!$E:$E,Flights!$A:$A,"AA",Flights!$B:$B,">="&$B3,Flights!$B:$B,"<"&DATE(2026,2,1)),0) -> 61843.19 | H3: =F3+G3 -> 81421.79 | I3: =IFERROR(SUMIFS(Flights!$D:$D,Flights!$A:$A,"ET",Flights!$B:$B,">="&$B3,Flights!$B:$B,"<"&DATE(2026,2,1)),0) -> 98578.61 | J3: =IFERROR(SUMIFS(Flights!$E:$E,Flights!$A:$A,"ET",Flights!$B:$B,">="&$B3,Flights!$B:$B,"<"&DATE(2026,2,1)),0) -> 10455 | K3: =I3+J3 -> 109033.61 | L3: =IFERROR(SUMIFS(Flights!$D:$D,Flights!$A:$A,"SK",Flights!$B:$B,">="&$B3,Flights!$B:$B,"<"&DATE(2026,2,1)),0) -> 85416.64 | M3: =IFERROR(SUMIFS(Flights!$E:$E,Flights!$A:$A,"SK",Flights!$B:$B,">="&$B3,Flights!$B:$B,"<"&DATE(2026,2,1)),0) -> 11400 | N3: =L3+M3 -> 96816.64 | O3: =C3+F3+I3+L3 -> 433218.26 | P3: =D3+G3+J3+M3 -> 224625.49 | Q3: =E3+H3+K3+N3 -> 657843.75
A4: Feb 2026 | B4: 46054 | C4: =IFERROR(SUMIFS(Flights!$D:$D,Flights!$A:$A,"VS",Flights!$B:$B,">="&$B4,Flights!$B:$B,"<"&DATE(2026,3,1)),0) -> 186972.31 | D4: =IFERROR(SUMIFS(Flights!$E:$E,Flights!$A:$A,"VS",Flights!$B:$B,">="&$B4,Flights!$B:$B,"<"&DATE(2026,3,1)),0) -> 114949.32 | E4: =C4+D4 -> 301921.63 | F4: =IFERROR(SUMIFS(Flights!$D:$D,Flights!$A:$A,"AA",Flights!$B:$B,">="&$B4,Flights!$B:$B,"<"&DATE(2026,3,1)),0) -> 10978.4 | G4: =IFERROR(SUMIFS(Flights!$E:$E,Flights!$A:$A,"AA",Flights!$B:$B,">="&$B4,Flights!$B:$B,"<"&DATE(2026,3,1)),0) -> 63672.62 | H4: =F4+G4 -> 74651.02 | I4: =IFERROR(SUMIFS(Flights!$D:$D,Flights!$A:$A,"ET",Flights!$B:$B,">="&$B4,Flights!$B:$B,"<"&DATE(2026,3,1)),0) -> 31847.35 | J4: =IFERROR(SUMIFS(Flights!$E:$E,Flights!$A:$A,"ET",Flights!$B:$B,">="&$B4,Flights!$B:$B,"<"&DATE(2026,3,1)),0) -> 4920 | K4: =I4+J4 -> 36767.35 | L4: =IFERROR(SUMIFS(Flights!$D:$D,Flights!$A:$A,"SK",Flights!$B:$B,">="&$B4,Flights!$B:$B,"<"&DATE(2026,3,1)),0) -> 79976.49 | M4: =IFERROR(SUMIFS(Flights!$E:$E,Flights!$A:$A,"SK",Flights!$B:$B,">="&$B4,Flights!$B:$B,"<"&DATE(2026,3,1)),0) -> 12160 | N4: =L4+M4 -> 92136.49 | O4: =C4+F4+I4+L4 -> 309774.55 | P4: =D4+G4+J4+M4 -> 195701.94 | Q4: =E4+H4+K4+N4 -> 505476.49
A5: Mar 2026 | B5: 46082 | C5: =IFERROR(SUMIFS(Flights!$D:$D,Flights!$A:$A,"VS",Flights!$B:$B,">="&$B5,Flights!$B:$B,"<"&DATE(2026,4,1)),0) -> 241979.11 | D5: =IFERROR(SUMIFS(Flights!$E:$E,Flights!$A:$A,"VS",Flights!$B:$B,">="&$B5,Flights!$B:$B,"<"&DATE(2026,4,1)),0) -> 127316.08 | E5: =C5+D5 -> 369295.19 | F5: =IFERROR(SUMIFS(Flights!$D:$D,Flights!$A:$A,"AA",Flights!$B:$B,">="&$B5,Flights!$B:$B,"<"&DATE(2026,4,1)),0) -> 27301.42 | G5: =IFERROR(SUMIFS(Flights!$E:$E,Flights!$A:$A,"AA",Flights!$B:$B,">="&$B5,Flights!$B:$B,"<"&DATE(2026,4,1)),0) -> 72587.53 | H5: =F5+G5 -> 99888.95 | I5: =IFERROR(SUMIFS(Flights!$D:$D,Flights!$A:$A,"ET",Flights!$B:$B,">="&$B5,Flights!$B:$B,"<"&DATE(2026,4,1)),0) -> 0 | J5: =IFERROR(SUMIFS(Flights!$E:$E,Flights!$A:$A,"ET",Flights!$B:$B,">="&$B5,Flights!$B:$B,"<"&DATE(2026,4,1)),0) -> 0 | K5: =I5+J5 -> 0 | L5: =IFERROR(SUMIFS(Flights!$D:$D,Flights!$A:$A,"SK",Flights!$B:$B,">="&$B5,Flights!$B:$B,"<"&DATE(2026,4,1)),0) -> 79753.24 | M5: =IFERROR(SUMIFS(Flights!$E:$E,Flights!$A:$A,"SK",Flights!$B:$B,">="&$B5,Flights!$B:$B,"<"&DATE(2026,4,1)),0) -> 12160 | N5: =L5+M5 -> 91913.24 | O5: =C5+F5+I5+L5 -> 349033.77 | P5: =D5+G5+J5+M5 -> 212063.61 | Q5: =E5+H5+K5+N5 -> 561097.38
A6: Apr 2026 | B6: 46113 | C6: =IFERROR(SUMIFS(Flights!$D:$D,Flights!$A:$A,"VS",Flights!$B:$B,">="&$B6,Flights!$B:$B,"<"&DATE(2026,5,1)),0) -> 285489.64 | D6: =IFERROR(SUMIFS(Flights!$E:$E,Flights!$A:$A,"VS",Flights!$B:$B,">="&$B6,Flights!$B:$B,"<"&DATE(2026,5,1)),0) -> 142136.08 | E6: =C6+D6 -> 427625.72 | F6: =IFERROR(SUMIFS(Flights!$D:$D,Flights!$A:$A,"AA",Flights!$B:$B,">="&$B6,Flights!$B:$B,"<"&DATE(2026,5,1)),0) -> 22161.63 | G6: =IFERROR(SUMIFS(Flights!$E:$E,Flights!$A:$A,"AA",Flights!$B:$B,">="&$B6,Flights!$B:$B,"<"&DATE(2026,5,1)),0) -> 76434.39 | H6: =F6+G6 -> 98596.02 | I6: =IFERROR(SUMIFS(Flights!$D:$D,Flights!$A:$A,"ET",Flights!$B:$B,">="&$B6,Flights!$B:$B,"<"&DATE(2026,5,1)),0) -> 0 | J6: =IFERROR(SUMIFS(Flights!$E:$E,Flights!$A:$A,"ET",Flights!$B:$B,">="&$B6,Flights!$B:$B,"<"&DATE(2026,5,1)),0) -> 0 | K6: =I6+J6 -> 0 | L6: =IFERROR(SUMIFS(Flights!$D:$D,Flights!$A:$A,"SK",Flights!$B:$B,">="&$B6,Flights!$B:$B,"<"&DATE(2026,5,1)),0) -> 86748.82 | M6: =IFERROR(SUMIFS(Flights!$E:$E,Flights!$A:$A,"SK",Flights!$B:$B,">="&$B6,Flights!$B:$B,"<"&DATE(2026,5,1)),0) -> 12920 | N6: =L6+M6 -> 99668.82 | O6: =C6+F6+I6+L6 -> 394400.09 | P6: =D6+G6+J6+M6 -> 231490.47 | Q6: =E6+H6+K6+N6 -> 625890.56
A7: May 2026 | B7: 46143 | C7: =IFERROR(SUMIFS(Flights!$D:$D,Flights!$A:$A,"VS",Flights!$B:$B,">="&$B7,Flights!$B:$B,"<"&DATE(2026,6,1)),0) -> 302760.27 | D7: =IFERROR(SUMIFS(Flights!$E:$E,Flights!$A:$A,"VS",Flights!$B:$B,">="&$B7,Flights!$B:$B,"<"&DATE(2026,6,1)),0) -> 149155.53 | E7: =C7+D7 -> 451915.8 | F7: =IFERROR(SUMIFS(Flights!$D:$D,Flights!$A:$A,"AA",Flights!$B:$B,">="&$B7,Flights!$B:$B,"<"&DATE(2026,6,1)),0) -> 1890.43 | G7: =IFERROR(SUMIFS(Flights!$E:$E,Flights!$A:$A,"AA",Flights!$B:$B,">="&$B7,Flights!$B:$B,"<"&DATE(2026,6,1)),0) -> 8267.94 | H7: =F7+G7 -> 10158.37 | I7: =IFERROR(SUMIFS(Flights!$D:$D,Flights!$A:$A,"ET",Flights!$B:$B,">="&$B7,Flights!$B:$B,"<"&DATE(2026,6,1)),0) -> 39619.98 | J7: =IFERROR(SUMIFS(Flights!$E:$E,Flights!$A:$A,"ET",Flights!$B:$B,">="&$B7,Flights!$B:$B,"<"&DATE(2026,6,1)),0) -> 4200 | K7: =I7+J7 -> 43819.98 | L7: =IFERROR(SUMIFS(Flights!$D:$D,Flights!$A:$A,"SK",Flights!$B:$B,">="&$B7,Flights!$B:$B,"<"&DATE(2026,6,1)),0) -> 87021.12 | M7: =IFERROR(SUMIFS(Flights!$E:$E,Flights!$A:$A,"SK",Flights!$B:$B,">="&$B7,Flights!$B:$B,"<"&DATE(2026,6,1)),0) -> 12160 | N7: =L7+M7 -> 99181.12 | O7: =C7+F7+I7+L7 -> 431291.8 | P7: =D7+G7+J7+M7 -> 173783.47 | Q7: =E7+H7+K7+N7 -> 605075.27
A8: Jun 2026 | B8: 46174 | C8: =IFERROR(SUMIFS(Flights!$D:$D,Flights!$A:$A,"VS",Flights!$B:$B,">="&$B8,Flights!$B:$B,"<"&DATE(2026,7,1)),0) -> 0 | D8: =IFERROR(SUMIFS(Flights!$E:$E,Flights!$A:$A,"VS",Flights!$B:$B,">="&$B8,Flights!$B:$B,"<"&DATE(2026,7,1)),0) -> 0 | E8: =C8+D8 -> 0 | F8: =IFERROR(SUMIFS(Flights!$D:$D,Flights!$A:$A,"AA",Flights!$B:$B,">="&$B8,Flights!$B:$B,"<"&DATE(2026,7,1)),0) -> 0 | G8: =IFERROR(SUMIFS(Flights!$E:$E,Flights!$A:$A,"AA",Flights!$B:$B,">="&$B8,Flights!$B:$B,"<"&DATE(2026,7,1)),0) -> 0 | H8: =F8+G8 -> 0 | I8: =IFERROR(SUMIFS(Flights!$D:$D,Flights!$A:$A,"ET",Flights!$B:$B,">="&$B8,Flights!$B:$B,"<"&DATE(2026,7,1)),0) -> 0 | J8: =IFERROR(SUMIFS(Flights!$E:$E,Flights!$A:$A,"ET",Flights!$B:$B,">="&$B8,Flights!$B:$B,"<"&DATE(2026,7,1)),0) -> 0 | K8: =I8+J8 -> 0 | L8: =IFERROR(SUMIFS(Flights!$D:$D,Flights!$A:$A,"SK",Flights!$B:$B,">="&$B8,Flights!$B:$B,"<"&DATE(2026,7,1)),0) -> 0 | M8: =IFERROR(SUMIFS(Flights!$E:$E,Flights!$A:$A,"SK",Flights!$B:$B,">="&$B8,Flights!$B:$B,"<"&DATE(2026,7,1)),0) -> 0 | N8: =L8+M8 -> 0 | O8: =C8+F8+I8+L8 -> 0 | P8: =D8+G8+J8+M8 -> 0 | Q8: =E8+H8+K8+N8 -> 0
A9: Jul 2026 | B9: 46204 | C9: =IFERROR(SUMIFS(Flights!$D:$D,Flights!$A:$A,"VS",Flights!$B:$B,">="&$B9,Flights!$B:$B,"<"&DATE(2026,8,1)),0) -> 0 | D9: =IFERROR(SUMIFS(Flights!$E:$E,Flights!$A:$A,"VS",Flights!$B:$B,">="&$B9,Flights!$B:$B,"<"&DATE(2026,8,1)),0) -> 0 | E9: =C9+D9 -> 0 | F9: =IFERROR(SUMIFS(Flights!$D:$D,Flights!$A:$A,"AA",Flights!$B:$B,">="&$B9,Flights!$B:$B,"<"&DATE(2026,8,1)),0) -> 0 | G9: =IFERROR(SUMIFS(Flights!$E:$E,Flights!$A:$A,"AA",Flights!$B:$B,">="&$B9,Flights!$B:$B,"<"&DATE(2026,8,1)),0) -> 0 | H9: =F9+G9 -> 0 | I9: =IFERROR(SUMIFS(Flights!$D:$D,Flights!$A:$A,"ET",Flights!$B:$B,">="&$B9,Flights!$B:$B,"<"&DATE(2026,8,1)),0) -> 0 | J9: =IFERROR(SUMIFS(Flights!$E:$E,Flights!$A:$A,"ET",Flights!$B:$B,">="&$B9,Flights!$B:$B,"<"&DATE(2026,8,1)),0) -> 0 | K9: =I9+J9 -> 0 | L9: =IFERROR(SUMIFS(Flights!$D:$D,Flights!$A:$A,"SK",Flights!$B:$B,">="&$B9,Flights!$B:$B,"<"&DATE(2026,8,1)),0) -> 0 | M9: =IFERROR(SUMIFS(Flights!$E:$E,Flights!$A:$A,"SK",Flights!$B:$B,">="&$B9,Flights!$B:$B,"<"&DATE(2026,8,1)),0) -> 0 | N9: =L9+M9 -> 0 | O9: =C9+F9+I9+L9 -> 0 | P9: =D9+G9+J9+M9 -> 0 | Q9: =E9+H9+K9+N9 -> 0
A10: Aug 2026 | B10: 46235 | C10: =IFERROR(SUMIFS(Flights!$D:$D,Flights!$A:$A,"VS",Flights!$B:$B,">="&$B10,Flights!$B:$B,"<"&DATE(2026,9,1)),0) -> 0 | D10: =IFERROR(SUMIFS(Flights!$E:$E,Flights!$A:$A,"VS",Flights!$B:$B,">="&$B10,Flights!$B:$B,"<"&DATE(2026,9,1)),0) -> 0 | E10: =C10+D10 -> 0 | F10: =IFERROR(SUMIFS(Flights!$D:$D,Flights!$A:$A,"AA",Flights!$B:$B,">="&$B10,Flights!$B:$B,"<"&DATE(2026,9,1)),0) -> 0 | G10: =IFERROR(SUMIFS(Flights!$E:$E,Flights!$A:$A,"AA",Flights!$B:$B,">="&$B10,Flights!$B:$B,"<"&DATE(2026,9,1)),0) -> 0 | H10: =F10+G10 -> 0 | I10: =IFERROR(SUMIFS(Flights!$D:$D,Flights!$A:$A,"ET",Flights!$B:$B,">="&$B10,Flights!$B:$B,"<"&DATE(2026,9,1)),0) -> 0 | J10: =IFERROR(SUMIFS(Flights!$E:$E,Flights!$A:$A,"ET",Flights!$B:$B,">="&$B10,Flights!$B:$B,"<"&DATE(2026,9,1)),0) -> 0 | K10: =I10+J10 -> 0 | L10: =IFERROR(SUMIFS(Flights!$D:$D,Flights!$A:$A,"SK",Flights!$B:$B,">="&$B10,Flights!$B:$B,"<"&DATE(2026,9,1)),0) -> 0 | M10: =IFERROR(SUMIFS(Flights!$E:$E,Flights!$A:$A,"SK",Flights!$B:$B,">="&$B10,Flights!$B:$B,"<"&DATE(2026,9,1)),0) -> 0 | N10: =L10+M10 -> 0 | O10: =C10+F10+I10+L10 -> 0 | P10: =D10+G10+J10+M10 -> 0 | Q10: =E10+H10+K10+N10 -> 0
A11: Sep 2026 | B11: 46266 | C11: =IFERROR(SUMIFS(Flights!$D:$D,Flights!$A:$A,"VS",Flights!$B:$B,">="&$B11,Flights!$B:$B,"<"&DATE(2026,10,1)),0) -> 0 | D11: =IFERROR(SUMIFS(Flights!$E:$E,Flights!$A:$A,"VS",Flights!$B:$B,">="&$B11,Flights!$B:$B,"<"&DATE(2026,10,1)),0) -> 0 | E11: =C11+D11 -> 0 | F11: =IFERROR(SUMIFS(Flights!$D:$D,Flights!$A:$A,"AA",Flights!$B:$B,">="&$B11,Flights!$B:$B,"<"&DATE(2026,10,1)),0) -> 0 | G11: =IFERROR(SUMIFS(Flights!$E:$E,Flights!$A:$A,"AA",Flights!$B:$B,">="&$B11,Flights!$B:$B,"<"&DATE(2026,10,1)),0) -> 0 | H11: =F11+G11 -> 0 | I11: =IFERROR(SUMIFS(Flights!$D:$D,Flights!$A:$A,"ET",Flights!$B:$B,">="&$B11,Flights!$B:$B,"<"&DATE(2026,10,1)),0) -> 0 | J11: =IFERROR(SUMIFS(Flights!$E:$E,Flights!$A:$A,"ET",Flights!$B:$B,">="&$B11,Flights!$B:$B,"<"&DATE(2026,10,1)),0) -> 0 | K11: =I11+J11 -> 0 | L11: =IFERROR(SUMIFS(Flights!$D:$D,Flights!$A:$A,"SK",Flights!$B:$B,">="&$B11,Flights!$B:$B,"<"&DATE(2026,10,1)),0) -> 0 | M11: =IFERROR(SUMIFS(Flights!$E:$E,Flights!$A:$A,"SK",Flights!$B:$B,">="&$B11,Flights!$B:$B,"<"&DATE(2026,10,1)),0) -> 0 | N11: =L11+M11 -> 0 | O11: =C11+F11+I11+L11 -> 0 | P11: =D11+G11+J11+M11 -> 0 | Q11: =E11+H11+K11+N11 -> 0
A12: Oct 2026 | B12: 46296 | C12: =IFERROR(SUMIFS(Flights!$D:$D,Flights!$A:$A,"VS",Flights!$B:$B,">="&$B12,Flights!$B:$B,"<"&DATE(2026,11,1)),0) -> 0 | D12: =IFERROR(SUMIFS(Flights!$E:$E,Flights!$A:$A,"VS",Flights!$B:$B,">="&$B12,Flights!$B:$B,"<"&DATE(2026,11,1)),0) -> 0 | E12: =C12+D12 -> 0 | F12: =IFERROR(SUMIFS(Flights!$D:$D,Flights!$A:$A,"AA",Flights!$B:$B,">="&$B12,Flights!$B:$B,"<"&DATE(2026,11,1)),0) -> 0 | G12: =IFERROR(SUMIFS(Flights!$E:$E,Flights!$A:$A,"AA",Flights!$B:$B,">="&$B12,Flights!$B:$B,"<"&DATE(2026,11,1)),0) -> 0 | H12: =F12+G12 -> 0 | I12: =IFERROR(SUMIFS(Flights!$D:$D,Flights!$A:$A,"ET",Flights!$B:$B,">="&$B12,Flights!$B:$B,"<"&DATE(2026,11,1)),0) -> 0 | J12: =IFERROR(SUMIFS(Flights!$E:$E,Flights!$A:$A,"ET",Flights!$B:$B,">="&$B12,Flights!$B:$B,"<"&DATE(2026,11,1)),0) -> 0 | K12: =I12+J12 -> 0 | L12: =IFERROR(SUMIFS(Flights!$D:$D,Flights!$A:$A,"SK",Flights!$B:$B,">="&$B12,Flights!$B:$B,"<"&DATE(2026,11,1)),0) -> 0 | M12: =IFERROR(SUMIFS(Flights!$E:$E,Flights!$A:$A,"SK",Flights!$B:$B,">="&$B12,Flights!$B:$B,"<"&DATE(2026,11,1)),0) -> 0 | N12: =L12+M12 -> 0 | O12: =C12+F12+I12+L12 -> 0 | P12: =D12+G12+J12+M12 -> 0 | Q12: =E12+H12+K12+N12 -> 0
A13: Nov 2026 | B13: 46327 | C13: =IFERROR(SUMIFS(Flights!$D:$D,Flights!$A:$A,"VS",Flights!$B:$B,">="&$B13,Flights!$B:$B,"<"&DATE(2026,12,1)),0) -> 0 | D13: =IFERROR(SUMIFS(Flights!$E:$E,Flights!$A:$A,"VS",Flights!$B:$B,">="&$B13,Flights!$B:$B,"<"&DATE(2026,12,1)),0) -> 0 | E13: =C13+D13 -> 0 | F13: =IFERROR(SUMIFS(Flights!$D:$D,Flights!$A:$A,"AA",Flights!$B:$B,">="&$B13,Flights!$B:$B,"<"&DATE(2026,12,1)),0) -> 0 | G13: =IFERROR(SUMIFS(Flights!$E:$E,Flights!$A:$A,"AA",Flights!$B:$B,">="&$B13,Flights!$B:$B,"<"&DATE(2026,12,1)),0) -> 0 | H13: =F13+G13 -> 0 | I13: =IFERROR(SUMIFS(Flights!$D:$D,Flights!$A:$A,"ET",Flights!$B:$B,">="&$B13,Flights!$B:$B,"<"&DATE(2026,12,1)),0) -> 0 | J13: =IFERROR(SUMIFS(Flights!$E:$E,Flights!$A:$A,"ET",Flights!$B:$B,">="&$B13,Flights!$B:$B,"<"&DATE(2026,12,1)),0) -> 0 | K13: =I13+J13 -> 0 | L13: =IFERROR(SUMIFS(Flights!$D:$D,Flights!$A:$A,"SK",Flights!$B:$B,">="&$B13,Flights!$B:$B,"<"&DATE(2026,12,1)),0) -> 0 | M13: =IFERROR(SUMIFS(Flights!$E:$E,Flights!$A:$A,"SK",Flights!$B:$B,">="&$B13,Flights!$B:$B,"<"&DATE(2026,12,1)),0) -> 0 | N13: =L13+M13 -> 0 | O13: =C13+F13+I13+L13 -> 0 | P13: =D13+G13+J13+M13 -> 0 | Q13: =E13+H13+K13+N13 -> 0
A14: Dec 2026 | B14: 46357 | C14: =IFERROR(SUMIFS(Flights!$D:$D,Flights!$A:$A,"VS",Flights!$B:$B,">="&$B14,Flights!$B:$B,"<"&DATE(2027,1,1)),0) -> 0 | D14: =IFERROR(SUMIFS(Flights!$E:$E,Flights!$A:$A,"VS",Flights!$B:$B,">="&$B14,Flights!$B:$B,"<"&DATE(2027,1,1)),0) -> 0 | E14: =C14+D14 -> 0 | F14: =IFERROR(SUMIFS(Flights!$D:$D,Flights!$A:$A,"AA",Flights!$B:$B,">="&$B14,Flights!$B:$B,"<"&DATE(2027,1,1)),0) -> 0 | G14: =IFERROR(SUMIFS(Flights!$E:$E,Flights!$A:$A,"AA",Flights!$B:$B,">="&$B14,Flights!$B:$B,"<"&DATE(2027,1,1)),0) -> 0 | H14: =F14+G14 -> 0 | I14: =IFERROR(SUMIFS(Flights!$D:$D,Flights!$A:$A,"ET",Flights!$B:$B,">="&$B14,Flights!$B:$B,"<"&DATE(2027,1,1)),0) -> 0 | J14: =IFERROR(SUMIFS(Flights!$E:$E,Flights!$A:$A,"ET",Flights!$B:$B,">="&$B14,Flights!$B:$B,"<"&DATE(2027,1,1)),0) -> 0 | K14: =I14+J14 -> 0 | L14: =IFERROR(SUMIFS(Flights!$D:$D,Flights!$A:$A,"SK",Flights!$B:$B,">="&$B14,Flights!$B:$B,"<"&DATE(2027,1,1)),0) -> 0 | M14: =IFERROR(SUMIFS(Flights!$E:$E,Flights!$A:$A,"SK",Flights!$B:$B,">="&$B14,Flights!$B:$B,"<"&DATE(2027,1,1)),0) -> 0 | N14: =L14+M14 -> 0 | O14: =C14+F14+I14+L14 -> 0 | P14: =D14+G14+J14+M14 -> 0 | Q14: =E14+H14+K14+N14 -> 0
A15: TOTAL | C15: =SUM(C3:C14) -> 1246845.7 | D15: =SUM(D3:D14) -> 674484.31 | E15: =SUM(E3:E14) -> 1921330.1 | F15: =SUM(F3:F14) -> 81910.48 | G15: =SUM(G3:G14) -> 282805.67 | H15: =SUM(H3:H14) -> 364716.15 | I15: =SUM(I3:I14) -> 170045.94 | J15: =SUM(J3:J14) -> 19575 | ... Q15: =SUM(Q3:Q14) -> 2955383.5
