Workbook
Name COMMERCIAL_ITEMS: [2]POLICY!$G$3:$G$348
Name COMMERCIAL_ITEMS: [3]POLICY!$G$3:$G$317

Sheet P&L
P2: 7 | Q2: Flights Per Week
P3: =FlightConfig!K17 -> 364 | Q3: Flights Annually
P4: 0.8 | Q4: Load
B5: Description | C5: Grand Total | E5: SAS | G5: Unit Central Cost | P5: 3 | Q5: Cycle
C6: $ | D6: % | E6: $ | F6: % | G6: $ | H6: % | P6: 0 | Q6: Discount
B7: Revenue Meals | C7: =SUM(E7,G7) -> 4460170.2 | D7: =C7/$C$12 -> 0.89904749 | E7: =SUM('Summary '!J11:J14) -> 1285870.2 | F7: =E7/$E$12 -> 0.71969201 | G7: =529050*6 -> 3174300 | H7: =G7/$G$12 -> 1
B8: Revenue Handling | C8: =SUM(E8,G8) -> 276600.9 | D8: =C8/$C$12 -> 0.055755126 | E8: =SUM('Summary '!J16:J17) -> 276600.9 | F8: =E8/$E$12 -> 0.15481148 | H8: =G8/$G$12 -> 0 | P8: 0.13 | Q8: Mark up on Food
B9: Revenue Overheads | C9: =SUM(E9,G9) -> 224224 | D9: =C9/$C$12 -> 0.045197384 | E9: ='Summary '!J10 -> 224224 | F9: =E9/$E$12 -> 0.12549651 | H9: =G9/$G$12 -> 0 | P9: 0.13 | Q9: Mark up on Labor
B10: Revenue Other | C10: =SUM(E10,G10) -> 0 | D10: =C10/$C$12 -> 0 | E10: ='Summary '!J15 -> 0 | F10: =E10/$E$12 -> 0 | H10: =G10/$G$12 -> 0 | P10: 0.087 | Q10: Mark up on Handling
B11: Discount | C11: =SUM(E11,G11) -> 0 | D11: =C11/$C$12 -> 0 | E11: =SUM(E7:E9)*P6 -> 0 | F11: =E11/$E$12 -> 0 | H11: =G11/$G$12 -> 0 | P11: 0 | Q11: Mark up on TRASH REMOVAL
B12: Net Revenue | C12: =SUM(C7:C11) -> 4960995.1 | D12: =C12/$C$12 -> 1 | E12: =SUM(E7:E11) -> 1786695.1 | F12: =E12/$E$12 -> 1 | G12: =SUM(G7:G11) -> 3174300 | H12: =G12/$G$12 -> 1 | I12: =E12/12 -> 148891.26
B13: Food Cost | C13: =SUM(E13,G13) -> 1430652.4 | D13: =C13/$C$12 -> 0.28838013 | E13: ='Summary '!J11 -> 672414.41 | F13: =E13/$E$12 -> 0.37634536 | G13: =126373*6 -> 758238 | H13: =G13/$G$12 -> 0.23886778 | I13: 30245 - 2 weeks | P13: SAS HANDLING
B14: Other product cost | C14: =SUM(E14,G14) -> 0 | D14: =C14/$C$12 -> 0 | E14: 0 | F14: =E14/$E$12 -> 0 | G14: =0+E14 -> 0 | H14: =G14/$G$12 -> 0 | I14: =E13/12 -> 56034.534 | P14: =Handling!C24 -> 559.89259 | Q14: SAS 330/350 TURNAROUND
B15: Total Direct Materials | C15: =SUM(C13:C14) -> 1430652.4 | D15: =C15/$C$12 -> 0.28838013 | E15: =SUM(E13:E14) -> 672414.41 | F15: =E15/$E$12 -> 0.37634536 | G15: =SUM(G13:G14) -> 758238 | H15: =G15/$G$12 -> 0.23886778
B16: Direct Labor - Wages | C16: =SUM(E16,G16) -> 1919837.2 | D16: =C16/$C$12 -> 0.38698631 | E16: ='Summary '!L17 -> 579235.56 | F16: =E16/$E$12 -> 0.32419385 | G16: =223433.6*6 -> 1340601.6 | H16: =G16/$G$12 -> 0.42232984 | P16: SAS HANDLING
B17: Direct Labor - OT Premium | C17: =SUM(E17,G17) -> 0 | D17: =C17/$C$12 -> 0 | E17: 0 | F17: =E17/$E$12 -> 0 | G17: =0+E17 -> 0 | H17: =G17/$G$12 -> 0 | P17: =Handling!C28 -> 200 | Q17: INTERNATIONAL GARBAGE
B18: Direct Labor - Benefit Cost | C18: =SUM(E18,G18) -> 464959.29 | D18: =C18/$C$12 -> 0.09372299 | E18: ='Summary '!L18 -> 144808.89 | F18: =E18/$E$12 -> 0.081048463 | G18: =53358.4*6 -> 320150.4 | H18: =G18/$G$12 -> 0.10085701
B19: Direct Labor - Other | C19: =SUM(E19,G19) -> 0 | D19: =C19/$C$12 -> 0 | E19: 0 | F19: =E19/$E$12 -> 0 | H19: =G19/$G$12 -> 0
B20: Direct Management Labor Cost | C20: =SUM(E20,G20) -> 0 | D20: =C20/$C$12 -> 0 | E20: 0 | F20: =E20/$E$12 -> 0 | H20: =G20/$G$12 -> 0
B21: Total Direct Labor | C21: =SUM(C16:C20) -> 2384796.4 | D21: =C21/$C$12 -> 0.4807093 | E21: =SUM(E16:E20) -> 724044.45 | F21: =E21/$E$12 -> 0.40524231 | G21: =SUM(G16:G20) -> 1660752 | H21: =G21/$G$12 -> 0.52318684 | I21: =(41000-22000)*4 -> 76000 | J21: =E21/12 -> 60337.037
B22: Gross Profit Margin (CM1) | C22: =C12-C15-C21 -> 1145546.2 | D22: =C22/$C$12 -> 0.23091057 | E22: =E12-E15-E21 -> 390236.22 | F22: =E22/$E$12 -> 0.21841232 | G22: =G12-G15-G21 -> 755310 | H22: =G22/$G$12 -> 0.23794537
J23: SAS Avg. Revenue Per Flight | N23: ='Summary '!H18 -> 4908.503
B24: Indirect Management Labor Cost | C24: =SUM(E24,G24) -> 551988.29 | D24: =C24/$C$12 -> 0.11126564 | F24: =E24/E12 -> 0 | G24: =91998.048*6 -> 551988.29 | H24: =G24/$G$12 -> 0.17389292 | J24: A
B25: Indirect Hourly Labor Cost | C25: =SUM(E25,G25) -> 0 | D25: =C25/$C$12 -> 0 | E25: 0 | F25: =E25/$E$12 -> 0 | H25: =G25/$G$12 -> 0 | J25: FC | K25: BC | L25: PY | M25: EY | N25: TC | O25: CY
B26: Total Indirect Labor | C26: =SUM(C24:C25) -> 551988.29 | D26: =C26/$C$12 -> 0.11126564 | E26: =SUM(E24:E25) -> 0 | F26: =E26/$E$12 -> 0 | G26: =SUM(G24:G25) -> 551988.29 | H26: =G26/$G$12 -> 0.17389292 | J26: ='Summary '!B28 -> 0 | K26: ='Summary '!C28 -> 37.008577 | L26: ='Summary '!D28 -> 24.716885 | M26: ='Summary '!E28 -> 13.422623 | N26: ='Summary '!F28 -> 20.841802 | O26: ='Summary '!G28 -> 21.896664
B27: Operating Expense-Variable | C27: =SUM(E27,G27) -> 930840 | D27: =C27/$C$12 -> 0.18763171 | E27: =G27/10+270000/3 -> 166440 | F27: =E27/E12 -> 0.093155235 | G27: =63700*12 -> 764400 | H27: =G27/$G$12 -> 0.240809 | I27: =E27/12 -> 13870 | K27: 40 | L27: 22 | M27: 15
B28: Operating Expense-Fixed | C28: =SUM(E28,G28) -> 0 | D28: =C28/$C$12 -> 0 | F28: 0 | H28: =G28/$G$12 -> 0 | J28: Overhead
B29: Other OPEX Cost | C29: =SUM(C27:C28) -> 930840 | D29: =C29/$C$12 -> 0.18763171 | E29: =SUM(E27:E28) -> 166440 | F29: =E29/E12 -> 0.093155235 | G29: =SUM(G27:G28) -> 764400 | H29: =G29/$G$12 -> 0.240809 | J29: FC | K29: BC | L29: PY | M29: YC | N29: TC | O29: CC
B30: EBITDA | C30: =C22-C26-C29 -> -337282.07 | D30: =C30/$C$12 -> -0.067986777 | E30: =E22-E26-E29 -> 223796.22 | F30: =E30/$E$12 -> 0.12525709 | G30: =G22-G26-G29 -> -561078.29 | H30: =G30/$G$12 -> -0.17675654 | I30: =E30/12 -> 18649.685 | J30: 0 | K30: 4 | L30: 3 | M30: 2.5 | N30: 3 | O30: 3
B32: Note - On the P&L we can update the Flights per week, AC type, Load Factor, Cycle & Mark up's | L32: =35.12*27+21.27*48+10.99*148+29*2+20*8+670+220 -> 4703.72
K33: =K27*32 -> 1280 | L33: =22*53 -> 1166 | M33: =M27*176 -> 2640
G36: =180000*12 -> 2160000
G37: =G16+G24+G18 -> 2212740.3
G38: Refrigrated truck $270,000

Sheet Bid Assumption 
A1: Bid Fact Sheet
A2: Airline Name | B2: NEOS
A3: City Code and Unit Number | B3: JFK
A4: Date Bid Preparation Begins
A5: Period used for Annualization
A6: Access Fee %
A7: Trade Discount %
A8: Cash Discount %
A9: Start Up Date
A12: Aircraft Type | B12: 787
A13: Configuration: First Class | B13: =+FlightConfig!B3 -> 0
A14: Business Class | B14: =+FlightConfig!C3 -> 32
A15: Tourist Class | B15: =SUM(FlightConfig!D3:E3) -> 230
A16: ETA | B16: 0.26736111
A17: ETD | B17: 0.93402778
A18: Frequency (days of operations) | B18: =+FlightConfig!K2 -> 7
A19: Total No. of Flights per Year | B19: =+FlightConfig!K3 -> 364
A20: Load Factor %
A21: Source of Load Factor | B21: Flight Config
A22: Account Rep. | B22: Kathy Shi
A23: Reason For Bid | B23: New Unit | E23: Food Markup
A24: Incumbent | E24: Ancillary Markup
A25: New or Old Route | B25: New | E25: Service Markup
A26: Credit Established/Payment Status
A27: Was Account Previously Bid | E27: Overhead Recovery per Pax F/C
A28: Outcome | E28: Overhead Recovery per Pax B/C
A29: Is there a Global Agreement | E29: Overhead Recovery per Pax E/U
A30: Date Building Lease expires | E30: Overhead Recovery per Pax Y/C
E31: Overhead Recovery per Pax C/Y
E32: Overhead Recovery per Pax C/C
A33: Investment | B33: Amount | C33: No. Years | D33: $ per Year | E33: Overhead Recovery per Pax T/C
A34: Building | C34: 0 | D34: =+B34/C34 -> #DIV/0!
A35: Land | C35: N/A | D35: N/A
A36: Building - Leasehold Improvements | C36: 0 | D36: =+B36/C36 -> #DIV/0!
A37: Trucks - Highlifts | C37: 0 | D37: =+B37/C37 -> #DIV/0!
A38: Trucks - Vans/Utility Vehicles | C38: 0 | D38: =+B38/C38 -> #DIV/0!
A39: Equipment | C39: 0 | D39: =+B39/C39 -> #DIV/0!
A40: Rent of Property | C40: 0 | D40: =+B40/C40 -> #DIV/0!
A42: Other Cities that Dnata serves this Customer and Discounts applied:
A43: SFO
...

Sheet Summary 
A2: Customer | G2: Flights Per week | H2: =FlightConfig!K16 -> 7 | L2: AC type | M2: Cycle
E3: AC Type | F3: 737 | G3: Flights Per Month | H3: =H4/2 -> 182 | J3: Total Revenues | L3: 330 | M3: 1
E4: Load | F4: ='P&L'!P4 -> 0.8 | G4: Annual Flights | H4: =FlightConfig!K3 -> 364 | J4: =H18*H4 -> 1786695.1 | M4: 2
A5: Summary | M5: 3
A6: BNA | B6: FC | C6: BC | D6: PY | E6: EY | F6: TC | G6: CY | H6: Total | I6: Hnd
A7: FLIGHT CONFIG | B7: =+FlightConfig!B17 -> 0 | C7: =+FlightConfig!C17 -> 32 | D7: =+FlightConfig!D17 -> 56 | E7: =+FlightConfig!E17 -> 174 | F7: =+FlightConfig!F17 -> 2 | G7: =+FlightConfig!G17 -> 8 | H7: =SUM(B7:G7) -> 272
A8: Load Factor | B8: =ROUNDUP(B7*$F$4,0) -> 0 | C8: =ROUNDUP(C7*$F$4,0) -> 26 | D8: =ROUNDUP(D7*$F$4,0) -> 45 | E8: =ROUNDUP(E7*$F$4,0) -> 140 | F8: =ROUNDUP(F7*$F$4,0) -> 2 | G8: =ROUNDUP(G7*$F$4,0) -> 7 | H8: =SUM(B8:G8) -> 220
B9: FIRST CLASS | C9: BUSINESS CLASS | D9: PREMIUM ECONOMY CLASS | E9: ECONOMY CLASS | F9: TECH CREW CLASS | G9: cABIN CREW CLASS | H9: Per Flight | J9: Annual
A10: OVERHEAD | B10: =Summary!B10 -> 0 | C10: =Summary!C10 -> 104 | D10: =Summary!D10 -> 135 | E10: =Summary!E10 -> 350 | F10: =Summary!F10 -> 6 | G10: =Summary!G10 -> 21 | H10: =SUM(B10:G10) -> 616 | J10: =H10*$H$4 -> 224224
A11: Food Cost (DM) | B11: =Summary!B11 -> 0 | C11: =Summary!C11 -> 479.5082 | D11: =Summary!D11 -> 549.19246 | E11: =Summary!E11 -> 708.7566 | F11: =Summary!F11 -> 21.93841 | G11: =Summary!G11 -> 87.89665 | H11: =SUM(B11:G11) -> 1847.2923 | J11: =H11*$H$4 -> 672414.41
A12: Wage Cost (DL) | B12: =Summary!B12 -> 0 | C12: =Summary!C12 -> 274.2675 | D12: =Summary!D12 -> 325.83214 | E12: =Summary!E12 -> 619.93287 | F12: =Summary!F12 -> 9.64 | G12: =Summary!G12 -> 44.38 | H12: =SUM(B12:G12) -> 1274.0525 | J12: =H12*$H$4 -> 463755.12
A13: Food Mark up | B13: =Summary!B13 | C13: =Summary!C13 -> 68.792523 | D13: =Summary!D13 -> 59.877061 | E13: =Summary!E13 -> 107.64987 | F13: =Summary!F13 -> 2.8519933 | G13: =Summary!G13 -> 0 | H13: =SUM(B13:G13) -> 239.17145 | J13: =H13*$H$4 -> 87058.406
A14: Labor Mark up | B14: =Summary!B14 | C14: =Summary!C14 -> 35.654775 | D14: =Summary!D14 -> 42.358179 | E14: =Summary!E14 -> 92.827917 | F14: =Summary!F14 -> 1.2532 | G14: =Summary!G14 -> 0 | H14: =SUM(B14:G14) -> 172.09407 | J14: =H14*$H$4 -> 62642.242
A15: Extra Revenue/Loss | B15: =IFERROR(B46*$E$8,0) -> 0 | C15: =IFERROR(C47*C$8,0) -> 0 | D15: =IFERROR(D47*D$8,0) -> 0 | E15: =IFERROR(E47*E$8,0) -> 0 | F15: =IFERROR(F47*F$8,0) -> 0 | G15: =IFERROR(G47*G$8,0) -> 0 | H15: =SUM(B15:G15) -> 0 | J15: =H15*$H$4 -> 0 | L15: Direct Labour
A16: Handling Cost | B16: =Summary!B15 -> 0 | C16: =Summary!C15 -> 0 | D16: =Summary!D15 -> 0 | E16: =Summary!E15 -> 715.08058 | F16: =Summary!F15 -> 0 | G16: =Summary!G15 -> 0 | H16: =SUM(B16:G16) -> 715.08058 | J16: =H16*$H$4 -> 260289.33 | L16: =J12+J16 -> 724044.45 | M16: 1
A17: Handling Mark up | B17: =Summary!B16 -> 0 | C17: =Summary!C16 -> 0 | D17: =Summary!D16 -> 0 | E17: =Summary!E16+C26 -> 44.812011 | F17: =Summary!F16 -> 0 | G17: =Summary!G16 -> 0 | H17: =SUM(B17:G17) -> 44.812011 | J17: =H17*$H$4 -> 16311.572 | L17: =L16*M17 -> 579235.56 | M17: 0.8
A18: Total Per Flight | B18: =SUM(B11:B17) -> 0 | C18: =SUM(C11:C17) -> 858.223 | D18: =SUM(D10:D17) -> 1112.2598 | E18: =SUM(E10:E17) -> 2639.0599 | F18: =SUM(F10:F17) -> 41.683603 | G18: =SUM(G10:G17) -> 153.27665 | H18: =SUM(H10:H17) -> 4908.503 | I18: 862832.68 | J18: =SUM(J10:J17) -> 1786695.1 | L18: =L16*M18 -> 144808.89 | M18: 0.2
B19: =B18 -> 0 | C19: =C18 -> 858.223 | D19: =D18 -> 1112.2598 | E19: =E18-E16-E17 -> 1879.1673 | F19: =F18 -> 41.683603 | G19: =G18 -> 153.27665 | I19: =E16+E17 -> 759.89259
A20: Handling | B20: Cost | C20: Mark Up | D20: Price | I20: =E17 -> 44.812011
A21: 330 Handling | B21: =Handling!C22 -> 515.08058 | C21: =Handling!C23 -> 44.812011 | D21: =SUM(B21:C21) -> 559.89259
A22: B777 Handling | B22: =Handling!#REF! -> #REF! | C22: =Handling!#REF! -> #REF! | D22: =Handling!#REF! -> #REF!
A23: A380 Handling | B23: =Handling!#REF! -> #REF! | C23: =Handling!#REF! -> #REF! | D23: =Handling!#REF! -> #REF!
A25: TRASH REMOVACL | B25: Cost | C25: Mark Up | D25: Price | I25: =E21 -> 0
A26: 330 | B26: =Handling!C26 -> 200 | C26: =B26*'P&L'!$P$11 -> 0 | D26: =SUM(B26:C26) -> 200
A28: Avg Price Per Pax | B28: =IFERROR(((B11+B12+B13+B14)/B8),0) -> 0 | C28: =IFERROR(((+C10+C11+C12+C13+C14)/C8),0) -> 37.008577 | D28: =IFERROR(((D10+D11+D12+D13+D14)/D8),0) -> 24.716885 | E28: =IFERROR(((E10+E11+E12+E13+E14)/E8),0) -> 13.422623 | F28: =IFERROR(((F10+F11+F12+F13+F14)/F8),0) -> 20.841802 | G28: =IFERROR(((G10+G11+G12+G13+G14)/G8),0) -> 21.896664
A29: Avg Mark up Per Pax | B29: =IFERROR(((B13+B14)/B8),0) -> 0 | C29: =IFERROR(((C13+C14)/C8),0) -> 4.0172038 | D29: =IFERROR(((D13+D14)/D8),0) -> 2.2718942 | E29: =IFERROR(((E13+E14)/E8),0) -> 1.4319842 | F29: =IFERROR(((F13+F14)/F8),0) -> 2.0525966 | G29: =IFERROR(((G13+G14)/G8),0) -> 0
A30: Over head Per Pax | B30: =IFERROR((B10/B8),0) -> 0 | C30: =IFERROR((C10/C8),0) -> 4 | D30: =IFERROR((D10/D8),0) -> 3 | E30: =IFERROR((E10/E8),0) -> 2.5 | F30: =IFERROR((F10/F8),0) -> 3 | G30: =IFERROR((G10/G8),0) -> 3
B32: CYCLE | C32: FLT
A33: Config | B33: =Summary!B34 -> 3
A34: OVERHEAD | B34: =B42*B8 -> 0 | C34: =C42*C8 -> 104 | D34: =D42*D8 -> 135 | E34: =E42*E8 -> 350 | F34: =F42*F8 -> 6 | G34: =G42*G8 -> 21
A35: Food Cost (DM) | B35: =Summary!B36 -> 0 | C35: =Summary!C36 -> 590.16394 | D35: =Summary!D36 -> 683.43951 | E35: =Summary!E36 -> 880.88321 | F35: =Summary!F36 -> 21.93841 | G35: =Summary!G36 -> 100.45331
A36: Wage Cost (DL) | B36: =Summary!B37 -> 0 | C36: =Summary!C37 -> 337.56 | D36: =Summary!D37 -> 405.48 | E36: =Summary!E37 -> 770.488 | F36: =Summary!F37 -> 9.64 | G36: =Summary!G37 -> 50.72
A37: Markup Food | B37: =Summary!B38 -> 0 | C37: =Summary!C38 -> 84.66772 | D37: =Summary!D38 -> 74.513676 | E37: =Summary!E38 -> 133.79341 | F37: =Summary!F38 -> 2.8519933 | G37: =Summary!G38 -> 2.3732394
A38: Markup Labor | B38: =Summary!B39 -> 0 | C38: =Summary!C39 -> 43.8828 | D38: =Summary!D39 -> 52.7124 | E38: =Summary!E39 -> 115.37184 | F38: =Summary!F39 -> 1.2532 | G38: =Summary!G39 -> 1.3312
A39: Extra Profit or Loss | B39: =Summary!B40 -> 0 | C39: =Summary!C40 | D39: =Summary!D40 | E39: =Summary!E40 | F39: =Summary!F40 | G39: =Summary!G40
A41: Per Pax Avg
A42: OVERHEAD | B42: ='P&L'!$J$30 -> 0 | C42: ='P&L'!$K$30 -> 4 | D42: ='P&L'!$L$30 -> 3 | E42: ='P&L'!$M$30 -> 2.5 | F42: ='P&L'!$N$30 -> 3 | G42: ='P&L'!$O$30 -> 3
A43: Food Cost (DM) | B43: =IFERROR(B35/B7," ") | C43: =IFERROR(C35/C7," ") -> 18.442623 | D43: =IFERROR(D35/D7," ") -> 12.204277 | E43: =IFERROR(E35/E7," ") -> 5.0625472 | F43: =IFERROR(F35/F7," ") -> 10.969205 | G43: =IFERROR(G35/G7," ") -> 12.556664
A44: Wage Cost (DL) | B44: =IFERROR(B36/B7," ") | C44: =IFERROR(C36/C7," ") -> 10.54875 | D44: =IFERROR(D36/D7," ") -> 7.2407143 | E44: =IFERROR(E36/E7," ") -> 4.428092 | F44: =IFERROR(F36/F7," ") -> 4.82 | G44: =IFERROR(G36/G7," ") -> 6.34
A45: Markup Food | B45: =IFERROR(B37/B8," ") | C45: =IFERROR(C37/C7," ") -> 2.6458663 | D45: =IFERROR(D37/D7," ") -> 1.3306014 | E45: =IFERROR(E37/E7," ") -> 0.76892763 | F45: =IFERROR(F37/F7," ") -> 1.4259966 | G45: =IFERROR(G37/G7," ") -> 0.29665492
...

Sheet Summary Short Haul
A2: Customer | G2: Flights Per week | H2: ='Summary 735'!H2+'Summary 2221'!H2+'Summary 2439'!H2+'Summary 2682'!H2+'Summary 2855'!H2 -> 0 | L2: AC type | M2: Cycle
E3: AC Type | F3: 737 | G3: Flights Per Month | H3: =H4/12 -> 0 | J3: Total Revenues | L3: 737 | M3: 1
E4: Load | F4: ='P&L'!P4 -> 0.8 | G4: Annual Flights | H4: =H2*52 -> 0 | J4: =H17*H4 -> #REF!
A5: Summary
A6: BNA | B6: FC | C6: BC | D6: PY | E6: EY | F6: TC | G6: CY | H6: Total | I6: Hnd
A7: FLIGHT CONFIG | B7: =+FlightConfig!B17 -> 0 | C7: =+FlightConfig!C17 -> 32 | D7: =+FlightConfig!D17 -> 56 | E7: =+FlightConfig!E17 -> 174 | F7: =+FlightConfig!F17 -> 2 | G7: =+FlightConfig!G17 -> 8 | H7: =SUM(B7:G7) -> 272
A8: Load Factor | B8: =ROUNDUP(B7*$F$4,0) -> 0 | C8: =ROUNDUP(C7*$F$4,0) -> 26 | D8: =ROUNDUP(D7*$F$4,0) -> 45 | E8: =ROUNDUP(E7*$F$4,0) -> 140 | F8: =ROUNDUP(F7*$F$4,0) -> 2 | G8: =ROUNDUP(G7*$F$4,0) -> 7 | H8: =SUM(B8:G8) -> 220
B9: FIRST CLASS | C9: BUSINESS CLASS | D9: PREMIUM ECONOMY CLASS | E9: ECONOMY CLASS | F9: TECH CREW CLASS | G9: cABIN CREW CLASS | H9: Per Flight | J9: Annual
A10: OVERHEAD | B10: =B37*B8 -> 0 | C10: =('Summary 735'!C10+'Summary 2221'!C10+'Summary 2439'!C10+'Summary 2682'!C10+'Summary 2855'!C10+Summary!C10+#REF!+#REF!+#REF!+#REF!+#REF!+'Summary 2037'!C10+'Summary 2817'!C10)/13 -> #REF! | D10: =('Summary 735'!D10+'Summary 2221'!D10+'Summary 2439'!D10+'Summary 2682'!D10+'Summary 2855'!D10+Summary!D10+#REF!+#REF!+#REF!+#REF!+#REF!+'Summary 2037'!D10+'Summary 2817'!D10)/13 -> #REF! | E10: =('Summary 735'!E10+'Summary 2221'!E10+'Summary 2439'!E10+'Summary 2682'!E10+'Summary 2855'!E10+Summary!E10+#REF!+#REF!+#REF!+#REF!+#REF!+'Summary 2037'!E10+'Summary 2817'!E10)/13 -> #REF! | F10: =('Summary 735'!F10+'Summary 2221'!F10+'Summary 2439'!F10+'Summary 2682'!F10+'Summary 2855'!F10+Summary!F10+#REF!+#REF!+#REF!+#REF!+#REF!+'Summary 2037'!F10+'Summary 2817'!F10)/13 -> #REF! | G10: =('Summary 735'!G10+'Summary 2221'!G10+'Summary 2439'!G10+'Summary 2682'!G10+'Summary 2855'!G10+Summary!G10+#REF!+#REF!+#REF!+#REF!+#REF!+'Summary 2037'!G10+'Summary 2817'!G10)/13 -> #REF! | H10: =SUM(B10:G10) -> #REF! | J10: =H10*$H$4 -> #REF!
A11: Food Cost (DM) | B11: =('Summary 735'!B11+'Summary 2221'!B11+'Summary 2439'!B11+'Summary 2682'!B11+'Summary 2855'!B11)/5 -> 0 | C11: =('Summary 735'!C11+'Summary 2221'!C11+'Summary 2439'!C11+'Summary 2682'!C11+'Summary 2855'!C11)/5 -> 0 | D11: =('Summary 735'!D11+'Summary 2221'!D11+'Summary 2439'!D11+'Summary 2682'!D11+'Summary 2855'!D11)/5 -> 0 | E11: =('Summary 735'!E11+'Summary 2221'!E11+'Summary 2439'!E11+'Summary 2682'!E11+'Summary 2855'!E11)/5 -> 0 | F11: =('Summary 735'!F11+'Summary 2221'!F11+'Summary 2439'!F11+'Summary 2682'!F11+'Summary 2855'!F11)/5 -> 0 | G11: =('Summary 735'!G11+'Summary 2221'!G11+'Summary 2439'!G11+'Summary 2682'!G11+'Summary 2855'!G11)/5 -> 0 | H11: =SUM(B11:G11) -> 0 | I11: =I12*45% -> #REF! | J11: =H11*$H$4 -> 0
A12: Wage Cost (DL) | B12: =('Summary 735'!B12+'Summary 2221'!B12+'Summary 2439'!B12+'Summary 2682'!B12+'Summary 2855'!B12+Summary!B12+#REF!+#REF!+#REF!+#REF!+#REF!+'Summary 2037'!B12+'Summary 2817'!B12)/13 -> #REF! | C12: =('Summary 735'!C12+'Summary 2221'!C12+'Summary 2439'!C12+'Summary 2682'!C12+'Summary 2855'!C12)/5 -> 0 | D12: =('Summary 735'!D12+'Summary 2221'!D12+'Summary 2439'!D12+'Summary 2682'!D12+'Summary 2855'!D12)/5 -> 0 | E12: =('Summary 735'!E12+'Summary 2221'!E12+'Summary 2439'!E12+'Summary 2682'!E12+'Summary 2855'!E12)/5 -> 0 | F12: =('Summary 735'!F12+'Summary 2221'!F12+'Summary 2439'!F12+'Summary 2682'!F12+'Summary 2855'!F12)/5 -> 0 | G12: =('Summary 735'!G12+'Summary 2221'!G12+'Summary 2439'!G12+'Summary 2682'!G12+'Summary 2855'!G12)/5 -> 0 | H12: =SUM(B12:G12) -> #REF! | I12: =H11+H12 -> #REF! | J12: =H12*$H$4 -> #REF!
A13: Food Mark up | B13: =('Summary 735'!B13+'Summary 2221'!B13+'Summary 2439'!B13+'Summary 2682'!B13+'Summary 2855'!B13+Summary!B13+#REF!+#REF!+#REF!+#REF!+#REF!+'Summary 2037'!B13+'Summary 2817'!B13)/13 -> #VALUE! | C13: =('Summary 735'!C13+'Summary 2221'!C13+'Summary 2439'!C13+'Summary 2682'!C13+'Summary 2855'!C13)/5 -> 0 | D13: =('Summary 735'!D13+'Summary 2221'!D13+'Summary 2439'!D13+'Summary 2682'!D13+'Summary 2855'!D13)/5 -> 0 | E13: =('Summary 735'!E13+'Summary 2221'!E13+'Summary 2439'!E13+'Summary 2682'!E13+'Summary 2855'!E13)/5 -> 0 | F13: =('Summary 735'!F13+'Summary 2221'!F13+'Summary 2439'!F13+'Summary 2682'!F13+'Summary 2855'!F13)/5 -> 0 | G13: =('Summary 735'!G13+'Summary 2221'!G13+'Summary 2439'!G13+'Summary 2682'!G13+'Summary 2855'!G13)/5 -> 0 | H13: =SUM(B13:G13) -> #VALUE! | J13: =H13*$H$4 -> #VALUE!
A14: Labor Mark up | B14: =('Summary 735'!B14+'Summary 2221'!B14+'Summary 2439'!B14+'Summary 2682'!B14+'Summary 2855'!B14+Summary!B14+#REF!+#REF!+#REF!+#REF!+#REF!+'Summary 2037'!B14+'Summary 2817'!B14)/13 -> #VALUE! | C14: =('Summary 735'!C14+'Summary 2221'!C14+'Summary 2439'!C14+'Summary 2682'!C14+'Summary 2855'!C14)/5 -> 0 | D14: =('Summary 735'!D14+'Summary 2221'!D14+'Summary 2439'!D14+'Summary 2682'!D14+'Summary 2855'!D14)/5 -> 0 | E14: =('Summary 735'!E14+'Summary 2221'!E14+'Summary 2439'!E14+'Summary 2682'!E14+'Summary 2855'!E14)/5 -> 0 | F14: =('Summary 735'!F14+'Summary 2221'!F14+'Summary 2439'!F14+'Summary 2682'!F14+'Summary 2855'!F14)/5 -> 0 | G14: =('Summary 735'!G14+'Summary 2221'!G14+'Summary 2439'!G14+'Summary 2682'!G14+'Summary 2855'!G14)/5 -> 0 | H14: =SUM(B14:G14) -> #VALUE! | J14: =H14*$H$4 -> #VALUE! | L14: Direct Labour
A15: Handling Cost | B15: =SUM('Summary 735'!B15+'Summary 2221'!B15+'Summary 2221'!B15+'Summary 2439'!B15+'Summary 2682'!B15+'Summary 2855'!B15+Summary!B15+#REF!+#REF!+#REF!+#REF!+#REF!+'Summary 2037'!B15+'Summary 2817'!B15)/13 -> #REF! | C15: =('Summary 735'!C15+'Summary 2221'!C15+'Summary 2439'!C15+'Summary 2682'!C15+'Summary 2855'!C15)/5 -> 0 | D15: =('Summary 735'!D15+'Summary 2221'!D15+'Summary 2439'!D15+'Summary 2682'!D15+'Summary 2855'!D15)/5 -> 0 | E15: =('Summary 735'!E15+'Summary 2221'!E15+'Summary 2439'!E15+'Summary 2682'!E15+'Summary 2855'!E15)/5 -> 0 | F15: =('Summary 735'!F15+'Summary 2221'!F15+'Summary 2439'!F15+'Summary 2682'!F15+'Summary 2855'!F15)/5 -> 0 | G15: =('Summary 735'!G15+'Summary 2221'!G15+'Summary 2439'!G15+'Summary 2682'!G15+'Summary 2855'!G15)/5 -> 0 | H15: =SUM(B15:G15) -> #REF! | J15: =H15*$H$4 -> #REF! | L15: =J12+J15 -> #REF! | M15: 1
A16: Handling Mark up | B16: =SUM('Summary 735'!B16+'Summary 2221'!B16+'Summary 2221'!B16+'Summary 2439'!B16+'Summary 2682'!B16+'Summary 2855'!B16+Summary!B16+#REF!+#REF!+#REF!+#REF!+#REF!+'Summary 2037'!B16+'Summary 2817'!B16)/13 -> #REF! | C16: =('Summary 735'!C16+'Summary 2221'!C16+'Summary 2439'!C16+'Summary 2682'!C16+'Summary 2855'!C16)/5 -> 0 | D16: =('Summary 735'!D16+'Summary 2221'!D16+'Summary 2439'!D16+'Summary 2682'!D16+'Summary 2855'!D16)/5 -> 0 | E16: =('Summary 735'!E16+'Summary 2221'!E16+'Summary 2439'!E16+'Summary 2682'!E16+'Summary 2855'!E16)/5 -> 0 | F16: =('Summary 735'!F16+'Summary 2221'!F16+'Summary 2439'!F16+'Summary 2682'!F16+'Summary 2855'!F16)/5 -> 0 | G16: =('Summary 735'!G16+'Summary 2221'!G16+'Summary 2439'!G16+'Summary 2682'!G16+'Summary 2855'!G16)/5 -> 0 | H16: =SUM(B16:G16) -> #REF! | J16: =H16*$H$4 -> #REF! | L16: =L15*M16 -> #REF! | M16: 0.8
A17: Total Per Flight | B17: =SUM(B11:B16) -> #REF! | C17: =SUM(C11:C16) -> 0 | D17: =SUM(D10:D16) -> #REF! | E17: =SUM(E10:E16) -> #REF! | F17: =SUM(F10:F16) -> #REF! | G17: =SUM(G10:G16) -> #REF! | H17: =SUM(H10:H16) -> #REF! | J17: =H17*$H$4 -> #REF! | L17: =L15*M17 -> #REF! | M17: 0.2
B18: =B17 -> #REF! | C18: =C17 -> 0 | D18: =D17 -> #REF! | E18: =E17-E15-E16 -> #REF! | F18: =F17 -> #REF! | G18: =G17 -> #REF! | I18: =E15+E16 -> 0
A19: Handling | B19: Cost | C19: Mark Up | D19: Price | I19: =E16 -> 0
A20: 737 Handling | B20: =SUM('Summary 735'!B20+'Summary 2221'!B20+'Summary 2221'!B20+'Summary 2439'!B20+'Summary 2682'!B20+'Summary 2855'!B20+Summary!B21+#REF!+#REF!+#REF!+#REF!+#REF!+'Summary 2037'!B20+'Summary 2817'!B20)/13 -> #REF! | C20: =B20*'P&L'!$P$10 -> #REF! | D20: =SUM(B20:C20) -> #REF!
A21: B777 Handling | B21: =Handling!#REF! -> #REF! | C21: =Handling!#REF! -> #REF! | D21: =Handling!#REF! -> #REF!
A22: A380 Handling | B22: =Handling!#REF! -> #REF! | C22: =Handling!#REF! -> #REF! | D22: =Handling!#REF! -> #REF!
A24: Avg Price Per Pax | B24: =IFERROR(((B11+B12+B13+B14)/B8),0) -> 0 | C24: =IFERROR(((C11+C12+C13+C14)/C8),0) -> 0 | D24: =IFERROR(((D10+D11+D12+D13+D14)/D8),0) -> 0 | E24: =IFERROR(((E10+E11+E12+E13+E14)/E8),0) -> 0 | F24: =IFERROR(((F10+F11+F12+F13+F14)/F8),0) -> 0 | G24: =IFERROR(((G10+G11+G12+G13+G14)/G8),0) -> 0
A25: Avg Mark up Per Pax | B25: =IFERROR(((B13+B14)/B8),0) -> 0 | C25: =IFERROR(((C13+C14)/C8),0) -> 0 | D25: =IFERROR(((D13+D14)/D8),0) -> 0 | E25: =IFERROR(((E13+E14)/E8),0) -> 0 | F25: =IFERROR(((F13+F14)/F8),0) -> 0 | G25: =IFERROR(((G13+G14)/G8),0) -> 0
A26: Over head Per Pax | B26: =IFERROR((B10/B8),0) -> 0 | C26: =IFERROR((C10/C8),0) -> 0 | D26: =IFERROR((D10/D8),0) -> 0 | E26: =IFERROR((E10/E8),0) -> 0 | F26: =IFERROR((F10/F8),0) -> 0 | G26: =IFERROR((G10/G8),0) -> 0
B28: CYCLE | C28: FLT
A29: Config | B29: ='P&L'!P5 -> 3
A30: OVERHEAD | B30: =B37*B8 -> 0 | C30: =C37*C8 -> 104 | D30: =D37*D8 -> 135 | E30: =E37*E8 -> 350 | F30: =F37*F8 -> 6 | G30: =G37*G8 -> 21
A31: Food Cost (DM) | B31: =('Summary 735'!B31+'Summary 2221'!B31+'Summary 2439'!B31+'Summary 2682'!B31+'Summary 2855'!B31)/5 -> 0 | C31: =('Summary 735'!C31+'Summary 2221'!C31+'Summary 2439'!C31+'Summary 2682'!C31+'Summary 2855'!C31+Summary!C36+#REF!+#REF!+#REF!+#REF!+#REF!+'Summary 2037'!C31+'Summary 2817'!C31)/13 -> #REF! | D31: =('Summary 735'!D31+'Summary 2221'!D31+'Summary 2439'!D31+'Summary 2682'!D31+'Summary 2855'!D31+Summary!D36+#REF!+#REF!+#REF!+#REF!+#REF!+'Summary 2037'!D31+'Summary 2817'!D31)/13 -> #REF! | E31: =('Summary 735'!E31+'Summary 2221'!E31+'Summary 2439'!E31+'Summary 2682'!E31+'Summary 2855'!E31)/5 -> 0 | F31: =('Summary 735'!F31+'Summary 2221'!F31+'Summary 2439'!F31+'Summary 2682'!F31+'Summary 2855'!F31+Summary!F36+#REF!+#REF!+#REF!+#REF!+#REF!+'Summary 2037'!F31+'Summary 2817'!F31)/13 -> #REF! | G31: =('Summary 735'!G31+'Summary 2221'!G31+'Summary 2439'!G31+'Summary 2682'!G31+'Summary 2855'!G31+Summary!G36+#REF!+#REF!+#REF!+#REF!+#REF!+'Summary 2037'!G31+'Summary 2817'!G31)/13 -> #REF!
A32: Wage Cost (DL) | B32: =('Summary 735'!B32+'Summary 2221'!B32+'Summary 2439'!B32+'Summary 2682'!B32+'Summary 2855'!B32)/5 -> 0 | C32: =('Summary 735'!C32+'Summary 2221'!C32+'Summary 2439'!C32+'Summary 2682'!C32+'Summary 2855'!C32+Summary!C37+#REF!+#REF!+#REF!+#REF!+#REF!+'Summary 2037'!C32+'Summary 2817'!C32)/13 -> #REF! | D32: =('Summary 735'!D32+'Summary 2221'!D32+'Summary 2439'!D32+'Summary 2682'!D32+'Summary 2855'!D32+Summary!D37+#REF!+#REF!+#REF!+#REF!+#REF!+'Summary 2037'!D32+'Summary 2817'!D32)/13 -> #REF! | E32: =('Summary 735'!E32+'Summary 2221'!E32+'Summary 2439'!E32+'Summary 2682'!E32+'Summary 2855'!E32)/5 -> 0 | F32: =('Summary 735'!F32+'Summary 2221'!F32+'Summary 2439'!F32+'Summary 2682'!F32+'Summary 2855'!F32+Summary!F37+#REF!+#REF!+#REF!+#REF!+#REF!+'Summary 2037'!F32+'Summary 2817'!F32)/13 -> #REF! | G32: =('Summary 735'!G32+'Summary 2221'!G32+'Summary 2439'!G32+'Summary 2682'!G32+'Summary 2855'!G32+Summary!G37+#REF!+#REF!+#REF!+#REF!+#REF!+'Summary 2037'!G32+'Summary 2817'!G32)/13 -> #REF!
A33: Markup Food | B33: =('Summary 735'!B33+'Summary 2221'!B33+'Summary 2439'!B33+'Summary 2682'!B33+'Summary 2855'!B33)/5 -> 0 | C33: =('Summary 735'!C33+'Summary 2221'!C33+'Summary 2439'!C33+'Summary 2682'!C33+'Summary 2855'!C33+Summary!C38+#REF!+#REF!+#REF!+#REF!+#REF!+'Summary 2037'!C33+'Summary 2817'!C33)/13 -> #REF! | D33: =('Summary 735'!D33+'Summary 2221'!D33+'Summary 2439'!D33+'Summary 2682'!D33+'Summary 2855'!D33+Summary!D38+#REF!+#REF!+#REF!+#REF!+#REF!+'Summary 2037'!D33+'Summary 2817'!D33)/13 -> #REF! | E33: =('Summary 735'!E33+'Summary 2221'!E33+'Summary 2439'!E33+'Summary 2682'!E33+'Summary 2855'!E33)/5 -> 0 | F33: =('Summary 735'!F33+'Summary 2221'!F33+'Summary 2439'!F33+'Summary 2682'!F33+'Summary 2855'!F33+Summary!F38+#REF!+#REF!+#REF!+#REF!+#REF!+'Summary 2037'!F33+'Summary 2817'!F33)/13 -> #REF! | G33: =('Summary 735'!G33+'Summary 2221'!G33+'Summary 2439'!G33+'Summary 2682'!G33+'Summary 2855'!G33+Summary!G38+#REF!+#REF!+#REF!+#REF!+#REF!+'Summary 2037'!G33+'Summary 2817'!G33)/13 -> #REF!
A34: Markup Labor | B34: =('Summary 735'!B34+'Summary 2221'!B34+'Summary 2439'!B34+'Summary 2682'!B34+'Summary 2855'!B34)/5 -> 0 | C34: =('Summary 735'!C34+'Summary 2221'!C34+'Summary 2439'!C34+'Summary 2682'!C34+'Summary 2855'!C34+Summary!C39+#REF!+#REF!+#REF!+#REF!+#REF!+'Summary 2037'!C34+'Summary 2817'!C34)/13 -> #REF! | D34: =('Summary 735'!D34+'Summary 2221'!D34+'Summary 2439'!D34+'Summary 2682'!D34+'Summary 2855'!D34+Summary!D39+#REF!+#REF!+#REF!+#REF!+#REF!+'Summary 2037'!D34+'Summary 2817'!D34)/13 -> #REF! | E34: =('Summary 735'!E34+'Summary 2221'!E34+'Summary 2439'!E34+'Summary 2682'!E34+'Summary 2855'!E34)/5 -> 0 | F34: =('Summary 735'!F34+'Summary 2221'!F34+'Summary 2439'!F34+'Summary 2682'!F34+'Summary 2855'!F34+Summary!F39+#REF!+#REF!+#REF!+#REF!+#REF!+'Summary 2037'!F34+'Summary 2817'!F34)/13 -> #REF! | G34: =('Summary 735'!G34+'Summary 2221'!G34+'Summary 2439'!G34+'Summary 2682'!G34+'Summary 2855'!G34+Summary!G39+#REF!+#REF!+#REF!+#REF!+#REF!+'Summary 2037'!G34+'Summary 2817'!G34)/13 -> #REF!
A36: Per Pax Avg
A37: OVERHEAD | B37: ='P&L'!$J$30 -> 0 | C37: ='P&L'!$K$30 -> 4 | D37: ='P&L'!$L$30 -> 3 | E37: ='P&L'!$M$30 -> 2.5 | F37: ='P&L'!$N$30 -> 3 | G37: ='P&L'!$O$30 -> 3
A38: Food Cost (DM) | B38: =IFERROR(B31/B7," ") | C38: =IFERROR(C31/C7," ") | D38: =IFERROR(D31/D7," ") | E38: =IFERROR(E31/E7," ") -> 0 | F38: =IFERROR(F31/F7," ") | G38: =IFERROR(G31/G7," ")
A39: Wage Cost (DL) | B39: =IFERROR(B32/B7," ") | C39: =IFERROR(C32/C7," ") | D39: =IFERROR(D32/D7," ") | E39: =IFERROR(E32/E7," ") -> 0 | F39: =IFERROR(F32/F7," ") | G39: =IFERROR(G32/G7," ")
A40: Markup Food | B40: =IFERROR(B33/B8," ") | C40: =IFERROR(C33/C7," ") | D40: =IFERROR(D33/D7," ") | E40: =IFERROR(E33/E7," ") -> 0 | F40: =IFERROR(F33/F7," ") | G40: =IFERROR(G33/G7," ")
A41: Markup Labor | B41: =IFERROR(B34/B7," ") | C41: =IFERROR(C34/C7," ") | D41: =IFERROR(D34/D7," ") | E41: =IFERROR(E34/E7," ") -> 0 | F41: =IFERROR(F34/F7," ") | G41: =IFERROR(G34/G7," ")
A108: 388
A109: 787

Sheet Summary Long Haul
A2: Customer | G2: Flights Per week | H2: =Summary!H2+#REF!+#REF!+#REF!+#REF!+#REF!+'Summary 2037'!H2+'Summary 2817'!H2 -> #REF! | L2: AC type | M2: Cycle
E3: AC Type | F3: 737 | G3: Flights Per Month | H3: =H4/12 -> #REF! | J3: Total Revenues | L3: 737 | M3: 1
E4: Load | F4: ='P&L'!P4 -> 0.8 | G4: Annual Flights | H4: =H2*52 -> #REF! | J4: =H17*H4 -> #REF!
A5: Summary
A6: BNA | B6: FC | C6: BC | D6: PY | E6: EY | F6: TC | G6: CY | H6: Total | I6: Hnd
A7: FLIGHT CONFIG | B7: =+FlightConfig!B17 -> 0 | C7: =+FlightConfig!C17 -> 32 | D7: =+FlightConfig!D17 -> 56 | E7: =+FlightConfig!E17 -> 174 | F7: =+FlightConfig!F17 -> 2 | G7: =+FlightConfig!G17 -> 8 | H7: =SUM(B7:G7) -> 272
A8: Load Factor | B8: =ROUNDUP(B7*$F$4,0) -> 0 | C8: =ROUNDUP(C7*$F$4,0) -> 26 | D8: =ROUNDUP(D7*$F$4,0) -> 45 | E8: =ROUNDUP(E7*$F$4,0) -> 140 | F8: =ROUNDUP(F7*$F$4,0) -> 2 | G8: =ROUNDUP(G7*$F$4,0) -> 7 | H8: =SUM(B8:G8) -> 220
B9: FIRST CLASS | C9: BUSINESS CLASS | D9: PREMIUM ECONOMY CLASS | E9: ECONOMY CLASS | F9: TECH CREW CLASS | G9: cABIN CREW CLASS | H9: Per Flight | J9: Annual
A10: OVERHEAD | B10: =(Summary!B10+#REF!+#REF!+#REF!+#REF!+#REF!)/6 -> #REF! | C10: =(Summary!C10+#REF!+#REF!+#REF!+#REF!+#REF!)/6 -> #REF! | D10: =(Summary!D10+#REF!+#REF!+#REF!+#REF!+#REF!)/6 -> #REF! | E10: =(Summary!E10+#REF!+#REF!+#REF!+#REF!+#REF!)/6 -> #REF! | F10: =(Summary!F10+#REF!+#REF!+#REF!+#REF!+#REF!)/6 -> #REF! | G10: =(Summary!G10+#REF!+#REF!+#REF!+#REF!+#REF!)/6 -> #REF! | H10: =(Summary!H10+#REF!+#REF!+#REF!+#REF!+#REF!)/6 -> #REF! | J10: =H10*$H$4 -> #REF!
A11: Food Cost (DM) | B11: =(Summary!B11+#REF!+#REF!+#REF!+#REF!+#REF!)/6 -> #REF! | C11: =(Summary!C11+#REF!+#REF!+#REF!+#REF!+#REF!)/6 -> #REF! | D11: =(Summary!D11+#REF!+#REF!+#REF!+#REF!+#REF!)/6 -> #REF! | E11: =(Summary!E11+#REF!+#REF!+#REF!+#REF!+#REF!)/6 -> #REF! | F11: =(Summary!F11+#REF!+#REF!+#REF!+#REF!+#REF!)/6 -> #REF! | G11: =(Summary!G11+#REF!+#REF!+#REF!+#REF!+#REF!)/6 -> #REF! | H11: =(Summary!H11+#REF!+#REF!+#REF!+#REF!+#REF!)/6 -> #REF! | I11: =I12*45% -> #REF! | J11: =H11*$H$4 -> #REF!
A12: Wage Cost (DL) | B12: =(Summary!B12+#REF!+#REF!+#REF!+#REF!+#REF!)/6 -> #REF! | C12: =(Summary!C12+#REF!+#REF!+#REF!+#REF!+#REF!)/6 -> #REF! | D12: =(Summary!D12+#REF!+#REF!+#REF!+#REF!+#REF!)/6 -> #REF! | E12: =(Summary!E12+#REF!+#REF!+#REF!+#REF!+#REF!)/6 -> #REF! | F12: =(Summary!F12+#REF!+#REF!+#REF!+#REF!+#REF!)/6 -> #REF! | G12: =(Summary!G12+#REF!+#REF!+#REF!+#REF!+#REF!)/6 -> #REF! | H12: =(Summary!H12+#REF!+#REF!+#REF!+#REF!+#REF!)/6 -> #REF! | I12: =H11+H12 -> #REF! | J12: =H12*$H$4 -> #REF!
A13: Food Mark up | B13: =(Summary!B13+#REF!+#REF!+#REF!+#REF!+#REF!)/6 -> #VALUE! | C13: =(Summary!C13+#REF!+#REF!+#REF!+#REF!+#REF!)/6 -> #REF! | D13: =(Summary!D13+#REF!+#REF!+#REF!+#REF!+#REF!)/6 -> #REF! | E13: =(Summary!E13+#REF!+#REF!+#REF!+#REF!+#REF!)/6 -> #REF! | F13: =(Summary!F13+#REF!+#REF!+#REF!+#REF!+#REF!)/6 -> #REF! | G13: =(Summary!G13+#REF!+#REF!+#REF!+#REF!+#REF!)/6 -> #REF! | H13: =(Summary!H13+#REF!+#REF!+#REF!+#REF!+#REF!)/6 -> #REF! | J13: =H13*$H$4 -> #REF!
A14: Labor Mark up | B14: =(Summary!B14+#REF!+#REF!+#REF!+#REF!+#REF!)/6 -> #VALUE! | C14: =(Summary!C14+#REF!+#REF!+#REF!+#REF!+#REF!)/6 -> #REF! | D14: =(Summary!D14+#REF!+#REF!+#REF!+#REF!+#REF!)/6 -> #REF! | E14: =(Summary!E14+#REF!+#REF!+#REF!+#REF!+#REF!)/6 -> #REF! | F14: =(Summary!F14+#REF!+#REF!+#REF!+#REF!+#REF!)/6 -> #REF! | G14: =(Summary!G14+#REF!+#REF!+#REF!+#REF!+#REF!)/6 -> #REF! | H14: =(Summary!H14+#REF!+#REF!+#REF!+#REF!+#REF!)/6 -> #REF! | J14: =H14*$H$4 -> #REF! | L14: Direct Labour
A15: Handling Cost | B15: =(Summary!B15+#REF!+#REF!+#REF!+#REF!+#REF!)/6 -> #REF! | C15: =(Summary!C15+#REF!+#REF!+#REF!+#REF!+#REF!)/6 -> #REF! | D15: =(Summary!D15+#REF!+#REF!+#REF!+#REF!+#REF!)/6 -> #REF! | E15: =(Summary!E15+#REF!+#REF!+#REF!+#REF!+#REF!)/6 -> #REF! | F15: =(Summary!F15+#REF!+#REF!+#REF!+#REF!+#REF!)/6 -> #REF! | G15: =(Summary!G15+#REF!+#REF!+#REF!+#REF!+#REF!)/6 -> #REF! | H15: =(Summary!H15+#REF!+#REF!+#REF!+#REF!+#REF!)/6 -> #REF! | J15: =H15*$H$4 -> #REF! | L15: =J12+J15 -> #REF! | M15: 1
A16: Handling Mark up | B16: =(Summary!B16+#REF!+#REF!+#REF!+#REF!+#REF!)/6 -> #REF! | C16: =(Summary!C16+#REF!+#REF!+#REF!+#REF!+#REF!)/6 -> #REF! | D16: =(Summary!D16+#REF!+#REF!+#REF!+#REF!+#REF!)/6 -> #REF! | E16: =(Summary!E16+#REF!+#REF!+#REF!+#REF!+#REF!)/6 -> #REF! | F16: =(Summary!F16+#REF!+#REF!+#REF!+#REF!+#REF!)/6 -> #REF! | G16: =(Summary!G16+#REF!+#REF!+#REF!+#REF!+#REF!)/6 -> #REF! | H16: =(Summary!H16+#REF!+#REF!+#REF!+#REF!+#REF!)/6 -> #REF! | J16: =H16*$H$4 -> #REF! | L16: =L15*M16 -> #REF! | M16: 0.8
A17: Total Per Flight | B17: =SUM(B11:B16) -> #REF! | C17: =SUM(C11:C16) -> #REF! | D17: =SUM(D10:D16) -> #REF! | E17: =SUM(E10:E16) -> #REF! | F17: =SUM(F10:F16) -> #REF! | G17: =SUM(G10:G16) -> #REF! | H17: =SUM(H10:H16) -> #REF! | J17: =H17*$H$4 -> #REF! | L17: =L15*M17 -> #REF! | M17: 0.2
B18: =B17 -> #REF! | C18: =C17 -> #REF! | D18: =D17 -> #REF! | E18: =E17-E15-E16 -> #REF! | F18: =F17 -> #REF! | G18: =G17 -> #REF! | I18: =E15+E16 -> #REF!
A19: Handling | B19: Cost | C19: Mark Up | D19: Price | I19: =E16 -> #REF!
A20: 737 Handling | B20: =(Summary!B21+#REF!+#REF!+#REF!+#REF!+#REF!+'Summary 2037'!B20+'Summary 2817'!B20)/8 -> #REF! | C20: =B20*'P&L'!$P$10 -> #REF! | D20: =SUM(B20:C20) -> #REF!
A21: B777 Handling | B21: =Handling!#REF! -> #REF! | C21: =Handling!#REF! -> #REF! | D21: =Handling!#REF! -> #REF!
A22: A380 Handling | B22: =Handling!#REF! -> #REF! | C22: =Handling!#REF! -> #REF! | D22: =Handling!#REF! -> #REF!
A24: Avg Price Per Pax | B24: =IFERROR(((B11+B12+B13+B14)/B8),0) -> 0 | C24: =IFERROR(((C11+C12+C13+C14)/C8),0) -> 0 | D24: =IFERROR(((D10+D11+D12+D13+D14)/D8),0) -> 0 | E24: =IFERROR(((E10+E11+E12+E13+E14)/E8),0) -> 0 | F24: =IFERROR(((F10+F11+F12+F13+F14)/F8),0) -> 0 | G24: =IFERROR(((G10+G11+G12+G13+G14)/G8),0) -> 0
A25: Avg Mark up Per Pax | B25: =IFERROR(((B13+B14)/B8),0) -> 0 | C25: =IFERROR(((C13+C14)/C8),0) -> 0 | D25: =IFERROR(((D13+D14)/D8),0) -> 0 | E25: =IFERROR(((E13+E14)/E8),0) -> 0 | F25: =IFERROR(((F13+F14)/F8),0) -> 0 | G25: =IFERROR(((G13+G14)/G8),0) -> 0
A26: Over head Per Pax | B26: =IFERROR((B10/B8),0) -> 0 | C26: =IFERROR((C10/C8),0) -> 0 | D26: =IFERROR((D10/D8),0) -> 0 | E26: =IFERROR((E10/E8),0) -> 0 | F26: =IFERROR((F10/F8),0) -> 0 | G26: =IFERROR((G10/G8),0) -> 0
B28: CYCLE | C28: FLT
A29: Config | B29: ='P&L'!P5 -> 3
A30: OVERHEAD | B30: =(Summary!B35+#REF!+#REF!+#REF!+#REF!+#REF!)/6 -> #REF! | C30: =(Summary!C35+#REF!+#REF!+#REF!+#REF!+#REF!)/6 -> #REF! | D30: =(Summary!D35+#REF!+#REF!+#REF!+#REF!+#REF!)/6 -> #REF! | E30: =(Summary!E35+#REF!+#REF!+#REF!+#REF!+#REF!)/6 -> #REF! | F30: =(Summary!F35+#REF!+#REF!+#REF!+#REF!+#REF!)/6 -> #REF! | G30: =(Summary!G35+#REF!+#REF!+#REF!+#REF!+#REF!)/6 -> #REF!
A31: Food Cost (DM) | B31: =(Summary!B36+#REF!+#REF!+#REF!+#REF!+#REF!)/6 -> #REF! | C31: =(Summary!C36+#REF!+#REF!+#REF!+#REF!+#REF!)/6 -> #REF! | D31: =(Summary!D36+#REF!+#REF!+#REF!+#REF!+#REF!)/6 -> #REF! | E31: =(Summary!E36+#REF!+#REF!+#REF!+#REF!+#REF!)/6 -> #REF! | F31: =(Summary!F36+#REF!+#REF!+#REF!+#REF!+#REF!)/6 -> #REF! | G31: =(Summary!G36+#REF!+#REF!+#REF!+#REF!+#REF!)/6 -> #REF!
A32: Wage Cost (DL) | B32: =(Summary!B37+#REF!+#REF!+#REF!+#REF!+#REF!)/6 -> #REF! | C32: =(Summary!C37+#REF!+#REF!+#REF!+#REF!+#REF!)/6 -> #REF! | D32: =(Summary!D37+#REF!+#REF!+#REF!+#REF!+#REF!)/6 -> #REF! | E32: =(Summary!E37+#REF!+#REF!+#REF!+#REF!+#REF!)/6 -> #REF! | F32: =(Summary!F37+#REF!+#REF!+#REF!+#REF!+#REF!)/6 -> #REF! | G32: =(Summary!G37+#REF!+#REF!+#REF!+#REF!+#REF!)/6 -> #REF!
A33: Markup Food | B33: =(Summary!B38+#REF!+#REF!+#REF!+#REF!+#REF!)/6 -> #REF! | C33: =(Summary!C38+#REF!+#REF!+#REF!+#REF!+#REF!)/6 -> #REF! | D33: =(Summary!D38+#REF!+#REF!+#REF!+#REF!+#REF!)/6 -> #REF! | E33: =(Summary!E38+#REF!+#REF!+#REF!+#REF!+#REF!)/6 -> #REF! | F33: =(Summary!F38+#REF!+#REF!+#REF!+#REF!+#REF!)/6 -> #REF! | G33: =(Summary!G38+#REF!+#REF!+#REF!+#REF!+#REF!)/6 -> #REF!
A34: Markup Labor | B34: =(Summary!B39+#REF!+#REF!+#REF!+#REF!+#REF!)/6 -> #REF! | C34: =(Summary!C39+#REF!+#REF!+#REF!+#REF!+#REF!)/6 -> #REF! | D34: =(Summary!D39+#REF!+#REF!+#REF!+#REF!+#REF!)/6 -> #REF! | E34: =(Summary!E39+#REF!+#REF!+#REF!+#REF!+#REF!)/6 -> #REF! | F34: =(Summary!F39+#REF!+#REF!+#REF!+#REF!+#REF!)/6 -> #REF! | G34: =(Summary!G39+#REF!+#REF!+#REF!+#REF!+#REF!)/6 -> #REF!
A36: Per Pax Avg
A37: OVERHEAD | B37: ='P&L'!$J$30 -> 0 | C37: ='P&L'!$K$30 -> 4 | D37: ='P&L'!$L$30 -> 3 | E37: ='P&L'!$M$30 -> 2.5 | F37: ='P&L'!$N$30 -> 3 | G37: ='P&L'!$O$30 -> 3
A38: Food Cost (DM) | B38: =IFERROR(B31/B7," ") | C38: =IFERROR(C31/C7," ") | D38: =IFERROR(D31/D7," ") | E38: =IFERROR(E31/E7," ") | F38: =IFERROR(F31/F7," ") | G38: =IFERROR(G31/G7," ")
A39: Wage Cost (DL) | B39: =IFERROR(B32/B7," ") | C39: =IFERROR(C32/C7," ") | D39: =IFERROR(D32/D7," ") | E39: =IFERROR(E32/E7," ") | F39: =IFERROR(F32/F7," ") | G39: =IFERROR(G32/G7," ")
A40: Markup Food | B40: =IFERROR(B33/B8," ") | C40: =IFERROR(C33/C7," ") | D40: =IFERROR(D33/D7," ") | E40: =IFERROR(E33/E7," ") | F40: =IFERROR(F33/F7," ") | G40: =IFERROR(G33/G7," ")
A41: Markup Labor | B41: =IFERROR(B34/B7," ") | C41: =IFERROR(C34/C7," ") | D41: =IFERROR(D34/D7," ") | E41: =IFERROR(E34/E7," ") | F41: =IFERROR(F34/F7," ") | G41: =IFERROR(G34/G7," ")
A108: 388
A109: 787

Sheet Summary  735
A2: Customer | G2: Flights Per week | H2: 0 | L2: AC type | M2: Cycle
E3: AC Type | F3: 738 | G3: Flights Per Month | H3: =H4/12 -> 0 | J3: Total Revenues | L3: 737 | M3: 1
E4: Load | F4: ='P&L'!P4 -> 0.8 | G4: Annual Flights | H4: =H2*52 -> 0 | J4: =H17*H4 -> 0
A5: Summary
A6: BNA | B6: FC | C6: BC | D6: PY | E6: EY | F6: TC | G6: CY | H6: Total | I6: Hnd
A7: FLIGHT CONFIG | B7: =+FlightConfig!B17 -> 0 | C7: =+FlightConfig!C17 -> 32 | D7: =+FlightConfig!D17 -> 56 | E7: =+FlightConfig!E17 -> 174 | F7: =+FlightConfig!F17 -> 2 | G7: =+FlightConfig!G17 -> 8 | H7: =SUM(B7:G7) -> 272
A8: Load Factor | B8: =ROUNDUP(B7*$F$4,0) -> 0 | C8: =ROUNDUP(C7*$F$4,0) -> 26 | D8: =ROUNDUP(D7*$F$4,0) -> 45 | E8: =ROUNDUP(E7*$F$4,0) -> 140 | F8: =ROUNDUP(F7*$F$4,0) -> 2 | G8: =ROUNDUP(G7*$F$4,0) -> 7 | H8: =SUM(B8:G8) -> 220
B9: FIRST CLASS | C9: BUSINESS CLASS | D9: PREMIUM ECONOMY CLASS | E9: ECONOMY CLASS | F9: TECH CREW CLASS | G9: cABIN CREW CLASS | H9: Per Flight | J9: Annual
A10: OVERHEAD | B10: =B37*B8 -> 0 | C10: =C37*C8 -> 104 | D10: =D37*D8 -> 135 | E10: =E37*E8 -> 350 | F10: =F37*F8 -> 6 | G10: =G37*G8 -> 21 | H10: =SUM(B10:G10) -> 616 | J10: =H10*$H$4 -> 0
A11: Food Cost (DM) | B11: =IFERROR(B38*B8,0) -> 0 | C11: =IFERROR(C38*$C$8,0) -> 0 | D11: =IFERROR(D38*$D$8,0) -> 0 | E11: =IFERROR(E38*$E$8,0) -> 0 | F11: =IFERROR(F38*$F$8,0) -> 0 | G11: =IFERROR(G38*G8,0) -> 0 | H11: =SUM(B11:G11) -> 0 | I11: =I12*45% -> 0 | J11: =H11*$H$4 -> 0
A12: Wage Cost (DL) | B12: =IFERROR(B39*B8,0) -> 0 | C12: =IFERROR(C39*$C$8,0) -> 0 | D12: =IFERROR(D39*$D$8,0) -> 0 | E12: =IFERROR(E39*$E$8,0) -> 0 | F12: =IFERROR(F39*$F$8,0) -> 0 | G12: =IFERROR(G39*G8,0) -> 0 | H12: =SUM(B12:G12) -> 0 | I12: =H11+H12 -> 0 | J12: =H12*$H$4 -> 0
A13: Food Mark up | B13: =IFERROR(B40*B8," ") | C13: =IFERROR(C40*$C$8,0) -> 0 | D13: =IFERROR(D40*$D$8,0) -> 0 | E13: =IFERROR(E40*$E$8,0) -> 0 | F13: =IFERROR(F40*$F$8,0) -> 0 | G13: 0 | H13: =SUM(B13:G13) -> 0 | J13: =H13*$H$4 -> 0
A14: Labor Mark up | B14: =IFERROR(B41*B8," ") | C14: =IFERROR(C41*$C$8,0) -> 0 | D14: =IFERROR(D41*$D$8,0) -> 0 | E14: =IFERROR(E41*$E$8,0) -> 0 | F14: =IFERROR(F41*$F$8,0) -> 0 | G14: 0 | H14: =SUM(B14:G14) -> 0 | J14: =H14*$H$4 -> 0 | L14: Direct Labour
A15: Handling Cost | B15: 0 | C15: 0 | D15: 0 | E15: =+B20 -> 0 | F15: 0 | G15: 0 | H15: =SUM(B15:G15) -> 0 | J15: =H15*$H$4 -> 0 | L15: =J12+J15 -> 0 | M15: 1
A16: Handling Mark up | B16: 0 | C16: 0 | D16: 0 | E16: =+C20 -> 0 | F16: 0 | G16: 0 | H16: =SUM(B16:G16) -> 0 | J16: =H16*$H$4 -> 0 | L16: =L15*M16 -> 0 | M16: 0.8
A17: Total Per Flight | B17: =SUM(B11:B16) -> 0 | C17: =SUM(C11:C16) -> 0 | D17: =SUM(D10:D16) -> 135 | E17: =SUM(E10:E16) -> 350 | F17: =SUM(F10:F16) -> 6 | G17: =SUM(G10:G16) -> 21 | H17: =SUM(H10:H16) -> 616 | J17: =H17*$H$4 -> 0 | L17: =L15*M17 -> 0 | M17: 0.2
B18: =B17 -> 0 | C18: =C17 -> 0 | D18: =D17 -> 135 | E18: =E17-E15-E16 -> 350 | F18: =F17 -> 6 | G18: =G17 -> 21 | I18: =E15+E16 -> 0
A19: Handling | B19: Cost | C19: Mark Up | D19: Price | I19: =E16 -> 0
A20: 738 Handling | B20: =Handling!C58 -> 0 | C20: =B20*'P&L'!$P$10 -> 0 | D20: =SUM(B20:C20) -> 0
A21: B777 Handling | B21: =Handling!#REF! -> #REF! | C21: =Handling!#REF! -> #REF! | D21: =Handling!#REF! -> #REF!
A22: A380 Handling | B22: =Handling!#REF! -> #REF! | C22: =Handling!#REF! -> #REF! | D22: =Handling!#REF! -> #REF!
A24: Avg Price Per Pax | B24: =IFERROR(((B11+B12+B13+B14)/B8),0) -> 0 | C24: =IFERROR(((C11+C12+C13+C14)/C8),0) -> 0 | D24: =IFERROR(((D10+D11+D12+D13+D14)/D8),0) -> 3 | E24: =IFERROR(((E10+E11+E12+E13+E14)/E8),0) -> 2.5 | F24: =IFERROR(((F10+F11+F12+F13+F14)/F8),0) -> 3 | G24: =IFERROR(((G10+G11+G12+G13+G14)/G8),0) -> 3
A25: Avg Mark up Per Pax | B25: =IFERROR(((B13+B14)/B8),0) -> 0 | C25: =IFERROR(((C13+C14)/C8),0) -> 0 | D25: =IFERROR(((D13+D14)/D8),0) -> 0 | E25: =IFERROR(((E13+E14)/E8),0) -> 0 | F25: =IFERROR(((F13+F14)/F8),0) -> 0 | G25: =IFERROR(((G13+G14)/G8),0) -> 0
A26: Over head Per Pax | B26: =IFERROR((B10/B8),0) -> 0 | C26: =IFERROR((C10/C8),0) -> 4 | D26: =IFERROR((D10/D8),0) -> 3 | E26: =IFERROR((E10/E8),0) -> 2.5 | F26: =IFERROR((F10/F8),0) -> 3 | G26: =IFERROR((G10/G8),0) -> 3
B28: CYCLE | C28: FLT
A29: Config | B29: ='P&L'!P5 -> 3 | C29: 735
A30: OVERHEAD | B30: =B37*B8 -> 0 | C30: =C37*C8 -> 104 | D30: =D37*D8 -> 135 | E30: =E37*E8 -> 350 | F30: =F37*F8 -> 6 | G30: =G37*G8 -> 21
A31: Food Cost (DM) | B31: =IFERROR(IF($B$29=$B$29,SUMIF(Food!$C:$C,B$9&$B$29&$C$29,Food!$V:$V),0),"") -> 0 | C31: =IFERROR(IF($B$29=$B$29,SUMIF(Food!$C:$C,C$9&$B$29&$C$29,Food!$V:$V),0),"") -> 0 | D31: =IFERROR(IF($B$29=$B$29,SUMIF(Food!$C:$C,D$9&$B$29&$C$29,Food!$V:$V),0),"") -> 0 | E31: =IFERROR(IF($B$29=$B$29,SUMIF(Food!$C:$C,E$9&$B$29&$C$29,Food!$V:$V),0),"") -> 0 | F31: =IFERROR(IF($B$29=$B$29,SUMIF(Food!$C:$C,F$9&$B$29&$C$29,Food!$V:$V),0),"") -> 0 | G31: =IFERROR(IF($B$29=$B$29,SUMIF(Food!$C:$C,G$9&$B$29&$C$29,Food!$V:$V),0),"") -> 0
A32: Wage Cost (DL) | B32: =IFERROR(IF($B$29=$B$29,SUMIF(Food!$C:$C,B$9&$B$29&$C$29,Food!$X:$X),0),"") -> 0 | C32: =IFERROR(IF($B$29=$B$29,SUMIF(Food!$C:$C,C$9&$B$29&$C$29,Food!$X:$X),0),"") -> 0 | D32: =IFERROR(IF($B$29=$B$29,SUMIF(Food!$C:$C,D$9&$B$29&$C$29,Food!$X:$X),0),"") -> 0 | E32: =IFERROR(IF($B$29=$B$29,SUMIF(Food!$C:$C,E$9&$B$29&$C$29,Food!$X:$X),0),"") -> 0 | F32: =IFERROR(IF($B$29=$B$29,SUMIF(Food!$C:$C,F$9&$B$29&$C$29,Food!$X:$X),0),"") -> 0 | G32: =IFERROR(IF($B$29=$B$29,SUMIF(Food!$C:$C,G$9&$B$29&$C$29,Food!$X:$X),0),"") -> 0
A33: Markup Food | B33: =IFERROR(IF($B$29=$B$29,SUMIF(Food!$C:$C,B$9&$B$29&$C$29,Food!$Z:$Z),0),"") -> 0 | C33: =IFERROR(IF($B$29=$B$29,SUMIF(Food!$C:$C,C$9&$B$29&$C$29,Food!$Z:$Z),0),"") -> 0 | D33: =IFERROR(IF($B$29=$B$29,SUMIF(Food!$C:$C,D$9&$B$29&$C$29,Food!$Z:$Z),0),"") -> 0 | E33: =IFERROR(IF($B$29=$B$29,SUMIF(Food!$C:$C,E$9&$B$29&$C$29,Food!$Z:$Z),0),"") -> 0 | F33: =IFERROR(IF($B$29=$B$29,SUMIF(Food!$C:$C,F$9&$B$29&$C$29,Food!$Z:$Z),0),"") -> 0 | G33: =IFERROR(IF($B$29=$B$29,SUMIF(Food!$C:$C,G$9&$B$29&$C$29,Food!$O:$O),0),"") -> 0
A34: Markup Labor | B34: =IFERROR(IF($B$29=$B$29,SUMIF(Food!$C:$C,B$9&$B$29&$C$29,Food!$AA:$AA),0),"") -> 0 | C34: =IFERROR(IF($B$29=$B$29,SUMIF(Food!$C:$C,C$9&$B$29&$C$29,Food!$AA:$AA),0),"") -> 0 | D34: =IFERROR(IF($B$29=$B$29,SUMIF(Food!$C:$C,D$9&$B$29&$C$29,Food!$AA:$AA),0),"") -> 0 | E34: =IFERROR(IF($B$29=$B$29,SUMIF(Food!$C:$C,E$9&$B$29&$C$29,Food!$AA:$AA),0),"") -> 0 | F34: =IFERROR(IF($B$29=$B$29,SUMIF(Food!$C:$C,F$9&$B$29&$C$29,Food!$AA:$AA),0),"") -> 0 | G34: =IFERROR(IF($B$29=$B$29,SUMIF(Food!$C:$C,G$9&$B$29&$C$29,Food!$P:$P),0),"") -> 0
A36: Per Pax Avg
A37: OVERHEAD | B37: ='P&L'!$J$30 -> 0 | C37: ='P&L'!$K$30 -> 4 | D37: ='P&L'!$L$30 -> 3 | E37: ='P&L'!$M$30 -> 2.5 | F37: ='P&L'!$N$30 -> 3 | G37: ='P&L'!$O$30 -> 3
A38: Food Cost (DM) | B38: =IFERROR(B31/B7," ") | C38: =IFERROR(C31/C7," ") -> 0 | D38: =IFERROR(D31/D7," ") -> 0 | E38: =IFERROR(E31/E7," ") -> 0 | F38: =IFERROR(F31/F7," ") -> 0 | G38: =IFERROR(G31/G7," ") -> 0
A39: Wage Cost (DL) | B39: =IFERROR(B32/B7," ") | C39: =IFERROR(C32/C7," ") -> 0 | D39: =IFERROR(D32/D7," ") -> 0 | E39: =IFERROR(E32/E7," ") -> 0 | F39: =IFERROR(F32/F7," ") -> 0 | G39: =IFERROR(G32/G7," ") -> 0
A40: Markup Food | B40: =IFERROR(B33/B8," ") | C40: =IFERROR(C33/C7," ") -> 0 | D40: =IFERROR(D33/D7," ") -> 0 | E40: =IFERROR(E33/E7," ") -> 0 | F40: =IFERROR(F33/F7," ") -> 0 | G40: =IFERROR(G33/G7," ") -> 0
A41: Markup Labor | B41: =IFERROR(B34/B7," ") | C41: =IFERROR(C34/C7," ") -> 0 | D41: =IFERROR(D34/D7," ") -> 0 | E41: =IFERROR(E34/E7," ") -> 0 | F41: =IFERROR(F34/F7," ") -> 0 | G41: =IFERROR(G34/G7," ") -> 0
A108: 388
A109: 787

Sheet Summary 2221
A2: Customer | G2: Flights Per week | H2: 0 | L2: AC type | M2: Cycle
E3: AC Type | F3: 738 | G3: Flights Per Month | H3: =H4/12 -> 0 | J3: Total Revenues | L3: 737 | M3: 1
E4: Load | F4: ='P&L'!P4 -> 0.8 | G4: Annual Flights | H4: =H2*52 -> 0 | J4: =H17*H4 -> 0
A5: Summary
A6: BNA | B6: FC | C6: BC | D6: PY | E6: EY | F6: TC | G6: CY | H6: Total | I6: Hnd
A7: FLIGHT CONFIG | B7: =+FlightConfig!B17 -> 0 | C7: =+FlightConfig!C17 -> 32 | D7: =+FlightConfig!D17 -> 56 | E7: =+FlightConfig!E17 -> 174 | F7: =+FlightConfig!F17 -> 2 | G7: =+FlightConfig!G17 -> 8 | H7: =SUM(B7:G7) -> 272
A8: Load Factor | B8: =ROUNDUP(B7*$F$4,0) -> 0 | C8: =ROUNDUP(C7*$F$4,0) -> 26 | D8: =ROUNDUP(D7*$F$4,0) -> 45 | E8: =ROUNDUP(E7*$F$4,0) -> 140 | F8: =ROUNDUP(F7*$F$4,0) -> 2 | G8: =ROUNDUP(G7*$F$4,0) -> 7 | H8: =SUM(B8:G8) -> 220
B9: FIRST CLASS | C9: BUSINESS CLASS | D9: PREMIUM ECONOMY CLASS | E9: ECONOMY CLASS | F9: TECH CREW CLASS | G9: cABIN CREW CLASS | H9: Per Flight | J9: Annual
A10: OVERHEAD | B10: =B37*B8 -> 0 | C10: =C37*C8 -> 104 | D10: =D37*D8 -> 135 | E10: =E37*E8 -> 350 | F10: =F37*F8 -> 6 | G10: =G37*G8 -> 21 | H10: =SUM(B10:G10) -> 616 | J10: =H10*$H$4 -> 0
A11: Food Cost (DM) | B11: =IFERROR(B38*B8,0) -> 0 | C11: =IFERROR(C38*$C$8,0) -> 0 | D11: =IFERROR(D38*$D$8,0) -> 0 | E11: =IFERROR(E38*$E$8,0) -> 0 | F11: =IFERROR(F38*$F$8,0) -> 0 | G11: =IFERROR(G38*G8,0) -> 0 | H11: =SUM(B11:G11) -> 0 | I11: =I12*45% -> 0 | J11: =H11*$H$4 -> 0
A12: Wage Cost (DL) | B12: =IFERROR(B39*B8,0) -> 0 | C12: =IFERROR(C39*$C$8,0) -> 0 | D12: =IFERROR(D39*$D$8,0) -> 0 | E12: =IFERROR(E39*$E$8,0) -> 0 | F12: =IFERROR(F39*$F$8,0) -> 0 | G12: =IFERROR(G39*G8,0) -> 0 | H12: =SUM(B12:G12) -> 0 | I12: =H11+H12 -> 0 | J12: =H12*$H$4 -> 0
A13: Food Mark up | B13: =IFERROR(B40*B8," ") | C13: =IFERROR(C40*$C$8,0) -> 0 | D13: =IFERROR(D40*$D$8,0) -> 0 | E13: =IFERROR(E40*$E$8,0) -> 0 | F13: =IFERROR(F40*$F$8,0) -> 0 | G13: 0 | H13: =SUM(B13:G13) -> 0 | J13: =H13*$H$4 -> 0
A14: Labor Mark up | B14: =IFERROR(B41*B8," ") | C14: =IFERROR(C41*$C$8,0) -> 0 | D14: =IFERROR(D41*$D$8,0) -> 0 | E14: =IFERROR(E41*$E$8,0) -> 0 | F14: =IFERROR(F41*$F$8,0) -> 0 | G14: 0 | H14: =SUM(B14:G14) -> 0 | J14: =H14*$H$4 -> 0 | L14: Direct Labour
A15: Handling Cost | B15: 0 | C15: 0 | D15: 0 | E15: =+B20 -> 0 | F15: 0 | G15: 0 | H15: =SUM(B15:G15) -> 0 | J15: =H15*$H$4 -> 0 | L15: =J12+J15 -> 0 | M15: 1
A16: Handling Mark up | B16: 0 | C16: 0 | D16: 0 | E16: =+C20 -> 0 | F16: 0 | G16: 0 | H16: =SUM(B16:G16) -> 0 | J16: =H16*$H$4 -> 0 | L16: =L15*M16 -> 0 | M16: 0.8
A17: Total Per Flight | B17: =SUM(B11:B16) -> 0 | C17: =SUM(C11:C16) -> 0 | D17: =SUM(D10:D16) -> 135 | E17: =SUM(E10:E16) -> 350 | F17: =SUM(F10:F16) -> 6 | G17: =SUM(G10:G16) -> 21 | H17: =SUM(H10:H16) -> 616 | J17: =H17*$H$4 -> 0 | L17: =L15*M17 -> 0 | M17: 0.2
B18: =B17 -> 0 | C18: =C17 -> 0 | D18: =D17 -> 135 | E18: =E17-E15-E16 -> 350 | F18: =F17 -> 6 | G18: =G17 -> 21 | I18: =E15+E16 -> 0
A19: Handling | B19: Cost | C19: Mark Up | D19: Price | I19: =E16 -> 0
A20: 738 Handling | B20: =Handling!C58 -> 0 | C20: =B20*'P&L'!$P$10 -> 0 | D20: =SUM(B20:C20) -> 0
A21: B777 Handling | B21: =Handling!#REF! -> #REF! | C21: =Handling!#REF! -> #REF! | D21: =Handling!#REF! -> #REF!
A22: A380 Handling | B22: =Handling!#REF! -> #REF! | C22: =Handling!#REF! -> #REF! | D22: =Handling!#REF! -> #REF!
A24: Avg Price Per Pax | B24: =IFERROR(((B11+B12+B13+B14)/B8),0) -> 0 | C24: =IFERROR(((C11+C12+C13+C14)/C8),0) -> 0 | D24: =IFERROR(((D10+D11+D12+D13+D14)/D8),0) -> 3 | E24: =IFERROR(((E10+E11+E12+E13+E14)/E8),0) -> 2.5 | F24: =IFERROR(((F10+F11+F12+F13+F14)/F8),0) -> 3 | G24: =IFERROR(((G10+G11+G12+G13+G14)/G8),0) -> 3
A25: Avg Mark up Per Pax | B25: =IFERROR(((B13+B14)/B8),0) -> 0 | C25: =IFERROR(((C13+C14)/C8),0) -> 0 | D25: =IFERROR(((D13+D14)/D8),0) -> 0 | E25: =IFERROR(((E13+E14)/E8),0) -> 0 | F25: =IFERROR(((F13+F14)/F8),0) -> 0 | G25: =IFERROR(((G13+G14)/G8),0) -> 0
A26: Over head Per Pax | B26: =IFERROR((B10/B8),0) -> 0 | C26: =IFERROR((C10/C8),0) -> 4 | D26: =IFERROR((D10/D8),0) -> 3 | E26: =IFERROR((E10/E8),0) -> 2.5 | F26: =IFERROR((F10/F8),0) -> 3 | G26: =IFERROR((G10/G8),0) -> 3
B28: CYCLE | C28: FLT
A29: Config | B29: ='P&L'!P5 -> 3 | C29: 2221
A30: OVERHEAD | B30: =B37*B8 -> 0 | C30: =C37*C8 -> 104 | D30: =D37*D8 -> 135 | E30: =E37*E8 -> 350 | F30: =F37*F8 -> 6 | G30: =G37*G8 -> 21
A31: Food Cost (DM) | B31: =IFERROR(IF($B$29=$B$29,SUMIF(Food!$C:$C,B$9&$B$29&$C$29,Food!$V:$V),0),"") -> 0 | C31: =IFERROR(IF($B$29=$B$29,SUMIF(Food!$C:$C,C$9&$B$29&$C$29,Food!$V:$V),0),"") -> 0 | D31: =IFERROR(IF($B$29=$B$29,SUMIF(Food!$C:$C,D$9&$B$29&$C$29,Food!$V:$V),0),"") -> 0 | E31: =IFERROR(IF($B$29=$B$29,SUMIF(Food!$C:$C,E$9&$B$29&$C$29,Food!$V:$V),0),"") -> 0 | F31: =IFERROR(IF($B$29=$B$29,SUMIF(Food!$C:$C,F$9&$B$29&$C$29,Food!$V:$V),0),"") -> 0 | G31: =IFERROR(IF($B$29=$B$29,SUMIF(Food!$C:$C,G$9&$B$29&$C$29,Food!$V:$V),0),"") -> 0
A32: Wage Cost (DL) | B32: =IFERROR(IF($B$29=$B$29,SUMIF(Food!$C:$C,B$9&$B$29&$C$29,Food!$X:$X),0),"") -> 0 | C32: =IFERROR(IF($B$29=$B$29,SUMIF(Food!$C:$C,C$9&$B$29&$C$29,Food!$X:$X),0),"") -> 0 | D32: =IFERROR(IF($B$29=$B$29,SUMIF(Food!$C:$C,D$9&$B$29&$C$29,Food!$X:$X),0),"") -> 0 | E32: =IFERROR(IF($B$29=$B$29,SUMIF(Food!$C:$C,E$9&$B$29&$C$29,Food!$X:$X),0),"") -> 0 | F32: =IFERROR(IF($B$29=$B$29,SUMIF(Food!$C:$C,F$9&$B$29&$C$29,Food!$X:$X),0),"") -> 0 | G32: =IFERROR(IF($B$29=$B$29,SUMIF(Food!$C:$C,G$9&$B$29&$C$29,Food!$X:$X),0),"") -> 0
A33: Markup Food | B33: =IFERROR(IF($B$29=$B$29,SUMIF(Food!$C:$C,B$9&$B$29&$C$29,Food!$Z:$Z),0),"") -> 0 | C33: =IFERROR(IF($B$29=$B$29,SUMIF(Food!$C:$C,C$9&$B$29&$C$29,Food!$Z:$Z),0),"") -> 0 | D33: =IFERROR(IF($B$29=$B$29,SUMIF(Food!$C:$C,D$9&$B$29&$C$29,Food!$Z:$Z),0),"") -> 0 | E33: =IFERROR(IF($B$29=$B$29,SUMIF(Food!$C:$C,E$9&$B$29&$C$29,Food!$Z:$Z),0),"") -> 0 | F33: =IFERROR(IF($B$29=$B$29,SUMIF(Food!$C:$C,F$9&$B$29&$C$29,Food!$Z:$Z),0),"") -> 0 | G33: =IFERROR(IF($B$29=$B$29,SUMIF(Food!$C:$C,G$9&$B$29&$C$29,Food!$O:$O),0),"") -> 0
A34: Markup Labor | B34: =IFERROR(IF($B$29=$B$29,SUMIF(Food!$C:$C,B$9&$B$29&$C$29,Food!$AA:$AA),0),"") -> 0 | C34: =IFERROR(IF($B$29=$B$29,SUMIF(Food!$C:$C,C$9&$B$29&$C$29,Food!$AA:$AA),0),"") -> 0 | D34: =IFERROR(IF($B$29=$B$29,SUMIF(Food!$C:$C,D$9&$B$29&$C$29,Food!$AA:$AA),0),"") -> 0 | E34: =IFERROR(IF($B$29=$B$29,SUMIF(Food!$C:$C,E$9&$B$29&$C$29,Food!$AA:$AA),0),"") -> 0 | F34: =IFERROR(IF($B$29=$B$29,SUMIF(Food!$C:$C,F$9&$B$29&$C$29,Food!$AA:$AA),0),"") -> 0 | G34: =IFERROR(IF($B$29=$B$29,SUMIF(Food!$C:$C,G$9&$B$29&$C$29,Food!$P:$P),0),"") -> 0
A36: Per Pax Avg
A37: OVERHEAD | B37: ='P&L'!$J$30 -> 0 | C37: ='P&L'!$K$30 -> 4 | D37: ='P&L'!$L$30 -> 3 | E37: ='P&L'!$M$30 -> 2.5 | F37: ='P&L'!$N$30 -> 3 | G37: ='P&L'!$O$30 -> 3
A38: Food Cost (DM) | B38: =IFERROR(B31/B7," ") | C38: =IFERROR(C31/C7," ") -> 0 | D38: =IFERROR(D31/D7," ") -> 0 | E38: =IFERROR(E31/E7," ") -> 0 | F38: =IFERROR(F31/F7," ") -> 0 | G38: =IFERROR(G31/G7," ") -> 0
A39: Wage Cost (DL) | B39: =IFERROR(B32/B7," ") | C39: =IFERROR(C32/C7," ") -> 0 | D39: =IFERROR(D32/D7," ") -> 0 | E39: =IFERROR(E32/E7," ") -> 0 | F39: =IFERROR(F32/F7," ") -> 0 | G39: =IFERROR(G32/G7," ") -> 0
A40: Markup Food | B40: =IFERROR(B33/B8," ") | C40: =IFERROR(C33/C7," ") -> 0 | D40: =IFERROR(D33/D7," ") -> 0 | E40: =IFERROR(E33/E7," ") -> 0 | F40: =IFERROR(F33/F7," ") -> 0 | G40: =IFERROR(G33/G7," ") -> 0
A41: Markup Labor | B41: =IFERROR(B34/B7," ") | C41: =IFERROR(C34/C7," ") -> 0 | D41: =IFERROR(D34/D7," ") -> 0 | E41: =IFERROR(E34/E7," ") -> 0 | F41: =IFERROR(F34/F7," ") -> 0 | G41: =IFERROR(G34/G7," ") -> 0
A108: 388
A109: 787

Sheet Summary 2439
A2: Customer | G2: Flights Per week | H2: 0 | L2: AC type | M2: Cycle
E3: AC Type | F3: 738 | G3: Flights Per Month | H3: =H4/12 -> 0 | J3: Total Revenues | L3: 737 | M3: 1
E4: Load | F4: ='P&L'!P4 -> 0.8 | G4: Annual Flights | H4: =H2*52 -> 0 | J4: =H17*H4 -> 0
A5: Summary
A6: BNA | B6: FC | C6: BC | D6: PY | E6: EY | F6: TC | G6: CY | H6: Total | I6: Hnd
A7: FLIGHT CONFIG | B7: =+FlightConfig!B17 -> 0 | C7: =+FlightConfig!C17 -> 32 | D7: =+FlightConfig!D17 -> 56 | E7: =+FlightConfig!E17 -> 174 | F7: =+FlightConfig!F17 -> 2 | G7: =+FlightConfig!G17 -> 8 | H7: =SUM(B7:G7) -> 272
A8: Load Factor | B8: =ROUNDUP(B7*$F$4,0) -> 0 | C8: =ROUNDUP(C7*$F$4,0) -> 26 | D8: =ROUNDUP(D7*$F$4,0) -> 45 | E8: =ROUNDUP(E7*$F$4,0) -> 140 | F8: =ROUNDUP(F7*$F$4,0) -> 2 | G8: =ROUNDUP(G7*$F$4,0) -> 7 | H8: =SUM(B8:G8) -> 220
B9: FIRST CLASS | C9: BUSINESS CLASS | D9: PREMIUM ECONOMY CLASS | E9: ECONOMY CLASS | F9: TECH CREW CLASS | G9: cABIN CREW CLASS | H9: Per Flight | J9: Annual
A10: OVERHEAD | B10: =B37*B8 -> 0 | C10: =C37*C8 -> 104 | D10: =D37*D8 -> 135 | E10: =E37*E8 -> 350 | F10: =F37*F8 -> 6 | G10: =G37*G8 -> 21 | H10: =SUM(B10:G10) -> 616 | J10: =H10*$H$4 -> 0
A11: Food Cost (DM) | B11: =IFERROR(B38*B8,0) -> 0 | C11: =IFERROR(C38*$C$8,0) -> 0 | D11: =IFERROR(D38*$D$8,0) -> 0 | E11: =IFERROR(E38*$E$8,0) -> 0 | F11: =IFERROR(F38*$F$8,0) -> 0 | G11: =IFERROR(G38*G8,0) -> 0 | H11: =SUM(B11:G11) -> 0 | I11: =I12*45% -> 0 | J11: =H11*$H$4 -> 0
A12: Wage Cost (DL) | B12: =IFERROR(B39*B8,0) -> 0 | C12: =IFERROR(C39*$C$8,0) -> 0 | D12: =IFERROR(D39*$D$8,0) -> 0 | E12: =IFERROR(E39*$E$8,0) -> 0 | F12: =IFERROR(F39*$F$8,0) -> 0 | G12: =IFERROR(G39*G8,0) -> 0 | H12: =SUM(B12:G12) -> 0 | I12: =H11+H12 -> 0 | J12: =H12*$H$4 -> 0
A13: Food Mark up | B13: =IFERROR(B40*B8," ") | C13: =IFERROR(C40*$C$8,0) -> 0 | D13: =IFERROR(D40*$D$8,0) -> 0 | E13: =IFERROR(E40*$E$8,0) -> 0 | F13: =IFERROR(F40*$F$8,0) -> 0 | G13: 0 | H13: =SUM(B13:G13) -> 0 | J13: =H13*$H$4 -> 0
A14: Labor Mark up | B14: =IFERROR(B41*B8," ") | C14: =IFERROR(C41*$C$8,0) -> 0 | D14: =IFERROR(D41*$D$8,0) -> 0 | E14: =IFERROR(E41*$E$8,0) -> 0 | F14: =IFERROR(F41*$F$8,0) -> 0 | G14: 0 | H14: =SUM(B14:G14) -> 0 | J14: =H14*$H$4 -> 0 | L14: Direct Labour
A15: Handling Cost | B15: 0 | C15: 0 | D15: 0 | E15: =+B20 -> 0 | F15: 0 | G15: 0 | H15: =SUM(B15:G15) -> 0 | J15: =H15*$H$4 -> 0 | L15: =J12+J15 -> 0 | M15: 1
A16: Handling Mark up | B16: 0 | C16: 0 | D16: 0 | E16: =+C20 -> 0 | F16: 0 | G16: 0 | H16: =SUM(B16:G16) -> 0 | J16: =H16*$H$4 -> 0 | L16: =L15*M16 -> 0 | M16: 0.8
A17: Total Per Flight | B17: =SUM(B11:B16) -> 0 | C17: =SUM(C11:C16) -> 0 | D17: =SUM(D10:D16) -> 135 | E17: =SUM(E10:E16) -> 350 | F17: =SUM(F10:F16) -> 6 | G17: =SUM(G10:G16) -> 21 | H17: =SUM(H10:H16) -> 616 | J17: =H17*$H$4 -> 0 | L17: =L15*M17 -> 0 | M17: 0.2
B18: =B17 -> 0 | C18: =C17 -> 0 | D18: =D17 -> 135 | E18: =E17-E15-E16 -> 350 | F18: =F17 -> 6 | G18: =G17 -> 21 | I18: =E15+E16 -> 0
A19: Handling | B19: Cost | C19: Mark Up | D19: Price | I19: =E16 -> 0
A20: 738 Handling | B20: =Handling!C58 -> 0 | C20: =B20*'P&L'!$P$10 -> 0 | D20: =SUM(B20:C20) -> 0
A21: B777 Handling | B21: =Handling!#REF! -> #REF! | C21: =Handling!#REF! -> #REF! | D21: =Handling!#REF! -> #REF!
A22: A380 Handling | B22: =Handling!#REF! -> #REF! | C22: =Handling!#REF! -> #REF! | D22: =Handling!#REF! -> #REF!
A24: Avg Price Per Pax | B24: =IFERROR(((B11+B12+B13+B14)/B8),0) -> 0 | C24: =IFERROR(((C11+C12+C13+C14)/C8),0) -> 0 | D24: =IFERROR(((D10+D11+D12+D13+D14)/D8),0) -> 3 | E24: =IFERROR(((E10+E11+E12+E13+E14)/E8),0) -> 2.5 | F24: =IFERROR(((F10+F11+F12+F13+F14)/F8),0) -> 3 | G24: =IFERROR(((G10+G11+G12+G13+G14)/G8),0) -> 3
A25: Avg Mark up Per Pax | B25: =IFERROR(((B13+B14)/B8),0) -> 0 | C25: =IFERROR(((C13+C14)/C8),0) -> 0 | D25: =IFERROR(((D13+D14)/D8),0) -> 0 | E25: =IFERROR(((E13+E14)/E8),0) -> 0 | F25: =IFERROR(((F13+F14)/F8),0) -> 0 | G25: =IFERROR(((G13+G14)/G8),0) -> 0
A26: Over head Per Pax | B26: =IFERROR((B10/B8),0) -> 0 | C26: =IFERROR((C10/C8),0) -> 4 | D26: =IFERROR((D10/D8),0) -> 3 | E26: =IFERROR((E10/E8),0) -> 2.5 | F26: =IFERROR((F10/F8),0) -> 3 | G26: =IFERROR((G10/G8),0) -> 3
B28: CYCLE | C28: FLT
A29: Config | B29: ='P&L'!P5 -> 3 | C29: 2439
A30: OVERHEAD | B30: =B37*B8 -> 0 | C30: =C37*C8 -> 104 | D30: =D37*D8 -> 135 | E30: =E37*E8 -> 350 | F30: =F37*F8 -> 6 | G30: =G37*G8 -> 21
A31: Food Cost (DM) | B31: =IFERROR(IF($B$29=$B$29,SUMIF(Food!$C:$C,B$9&$B$29&$C$29,Food!$V:$V),0),"") -> 0 | C31: =IFERROR(IF($B$29=$B$29,SUMIF(Food!$C:$C,C$9&$B$29&$C$29,Food!$V:$V),0),"") -> 0 | D31: =IFERROR(IF($B$29=$B$29,SUMIF(Food!$C:$C,D$9&$B$29&$C$29,Food!$V:$V),0),"") -> 0 | E31: =IFERROR(IF($B$29=$B$29,SUMIF(Food!$C:$C,E$9&$B$29&$C$29,Food!$V:$V),0),"") -> 0 | F31: =IFERROR(IF($B$29=$B$29,SUMIF(Food!$C:$C,F$9&$B$29&$C$29,Food!$V:$V),0),"") -> 0 | G31: =IFERROR(IF($B$29=$B$29,SUMIF(Food!$C:$C,G$9&$B$29&$C$29,Food!$V:$V),0),"") -> 0
A32: Wage Cost (DL) | B32: =IFERROR(IF($B$29=$B$29,SUMIF(Food!$C:$C,B$9&$B$29&$C$29,Food!$X:$X),0),"") -> 0 | C32: =IFERROR(IF($B$29=$B$29,SUMIF(Food!$C:$C,C$9&$B$29&$C$29,Food!$X:$X),0),"") -> 0 | D32: =IFERROR(IF($B$29=$B$29,SUMIF(Food!$C:$C,D$9&$B$29&$C$29,Food!$X:$X),0),"") -> 0 | E32: =IFERROR(IF($B$29=$B$29,SUMIF(Food!$C:$C,E$9&$B$29&$C$29,Food!$X:$X),0),"") -> 0 | F32: =IFERROR(IF($B$29=$B$29,SUMIF(Food!$C:$C,F$9&$B$29&$C$29,Food!$X:$X),0),"") -> 0 | G32: =IFERROR(IF($B$29=$B$29,SUMIF(Food!$C:$C,G$9&$B$29&$C$29,Food!$X:$X),0),"") -> 0
A33: Markup Food | B33: =IFERROR(IF($B$29=$B$29,SUMIF(Food!$C:$C,B$9&$B$29&$C$29,Food!$Z:$Z),0),"") -> 0 | C33: =IFERROR(IF($B$29=$B$29,SUMIF(Food!$C:$C,C$9&$B$29&$C$29,Food!$Z:$Z),0),"") -> 0 | D33: =IFERROR(IF($B$29=$B$29,SUMIF(Food!$C:$C,D$9&$B$29&$C$29,Food!$Z:$Z),0),"") -> 0 | E33: =IFERROR(IF($B$29=$B$29,SUMIF(Food!$C:$C,E$9&$B$29&$C$29,Food!$Z:$Z),0),"") -> 0 | F33: =IFERROR(IF($B$29=$B$29,SUMIF(Food!$C:$C,F$9&$B$29&$C$29,Food!$Z:$Z),0),"") -> 0 | G33: =IFERROR(IF($B$29=$B$29,SUMIF(Food!$C:$C,G$9&$B$29&$C$29,Food!$O:$O),0),"") -> 0
