Workbook
Name COMMERCIAL_ITEMS: #REF!
Name COMMERCIAL_ITEMS: #REF!

Sheet P&L
R2: 21 | S2: Flights Per Week
R3: ='Summary '!H4 -> 1092 | S3: Flights Per Year
R4: 0.85 | S4: Load
B5: Description | C5: Grand Total | E5: Virgin Atlantic | G5: Unit Central Cost | R5: 1 | S5: Cycle
C6: $ | D6: % | E6: $ | F6: % | G6: $ | H6: % | R6: 0 | S6: Discount
B7: Revenue Meals | C7: =SUM(E7,G7) -> 3811938.7 | D7: =C7/$C$12 -> 0.62718915 | E7: =SUM('Summary '!J11:J14) -> 3811938.7 | F7: =E7/$E$12 -> 0.62718915 | G7: 1e-05 | H7: =G7/$G$12 -> 1
B8: Revenue Handling | C8: =SUM(E8,G8) -> 1915574.8 | D8: =C8/$C$12 -> 0.31517499 | E8: =SUM('Summary '!J15:J16) -> 1915574.8 | F8: =E8/$E$12 -> 0.31517499 | H8: =G8/$G$12 -> 0 | R8: 0.13 | S8: Mark up on Food
B9: Revenue Overheads | C9: =SUM(E9,G9) -> 310000 | D9: =C9/$C$12 -> 0.051005184 | E9: =160000+150000 -> 310000 | F9: =E9/$E$12 -> 0.051005184 | H9: =G9/$G$12 -> 0 | I9: 160000 employee +150000 overhead facility | R9: 0.13 | S9: Mark up on Food Labor
B10: Revenue Other | C10: =SUM(E10,G10) -> 40300 | D10: =C10/$C$12 -> 0.0066306739 | E10: =SUM(E9)*R9 -> 40300 | F10: =E10/$E$12 -> 0.0066306739 | H10: =G10/$G$12 -> 0 | I10: EXTRA REVENUE FROM MANAGEMENT LABOR COST (OP Overhead | R10: 0.13 | S10: Mark up on Handling
B11: Discount | C11: =SUM(E11,G11) -> 0 | D11: =C11/$C$12 -> 0 | E11: =SUM(E7:E9)*R6 -> 0 | F11: =E11/$E$12 -> 0 | H11: =G11/$G$12 -> 0
B12: Net Revenue | C12: =SUM(C7:C11) -> 6077813.6 | D12: =C12/$C$12 -> 1 | E12: =SUM(E7:E11) -> 6077813.6 | F12: =E12/$E$12 -> 1 | G12: =SUM(G7:G11) -> 1e-05 | H12: =G12/$G$12 -> 1
B13: Food Cost | C13: =SUM(E13,G13) -> 2152816.8 | D13: =C13/$C$12 -> 0.3542091 | E13: ='Summary '!J11 -> 2152816.8 | F13: =E13/$E$12 -> 0.3542091 | H13: =G13/$G$12 -> 0 | R13: VA ATL TOTAL HANDLING
B14: Other product cost | C14: =SUM(E14,G14) -> 0 | D14: =C14/$C$12 -> 0 | E14: 0 | F14: =E14/$E$12 -> 0 | H14: =G14/$G$12 -> 0 | R14: =R20+R25+R30+R35 -> 1575.559 | S14: A330
B15: Total Direct Materials | C15: =SUM(C13:C14) -> 2152816.8 | D15: =C15/$C$12 -> 0.3542091 | E15: =SUM(E13:E14) -> 2152816.8 | F15: =E15/$E$12 -> 0.3542091 | G15: =SUM(G13:G14) -> 0 | H15: =G15/$G$12 -> 0 | R15: =R21+R26+R31+R36 -> 1932.8198 | S15: A350
B16: Direct Labor - Wages | C16: =SUM(E16,G16) -> 2332623.4 | D16: =C16/$C$12 -> 0.38379318 | E16: ='Summary '!L16 -> 2332623.4 | F16: =E16/$E$12 -> 0.38379318 | H16: =G16/$G$12 -> 0 | R16: =R22+R27+R32+R37 -> 1529.342 | S16: 787
B17: Direct Labor - OT Premium | C17: =SUM(E17,G17) -> 0 | D17: =C17/$C$12 -> 0 | E17: 0 | F17: =E17/$E$12 -> 0 | H17: =G17/$G$12 -> 0
B18: Direct Labor - Benefit Cost | C18: =SUM(E18,G18) -> 583155.85 | D18: =C18/$C$12 -> 0.095948294 | E18: ='Summary '!L17 -> 583155.85 | F18: =E18/$E$12 -> 0.095948294 | H18: =G18/$G$12 -> 0
B19: Direct Labor - Other | C19: =SUM(E19,G19) -> 0 | D19: =C19/$C$12 -> 0 | E19: 0 | F19: =E19/$E$12 -> 0 | H19: =G19/$G$12 -> 0 | R19: VA ATL TRANSPORT
B20: Direct Management Labor Cost | C20: =SUM(E20,G20) -> 0 | D20: =C20/$C$12 -> 0 | E20: 0 | F20: =E20/$E$12 -> 0 | H20: =G20/$G$12 -> 0 | R20: =Handling!V53 -> 313.236 | S20: A330 TURNAROUND
B21: Total Direct Labor | C21: =SUM(C16:C20) -> 2915779.2 | D21: =C21/$C$12 -> 0.47974147 | E21: =SUM(E16:E20) -> 2915779.2 | F21: =E21/$E$12 -> 0.47974147 | G21: =SUM(G16:G20) -> 0 | H21: =G21/$G$12 -> 0 | I21: =E21-E8 -> 1000204.4 | R21: =Handling!X53 -> 362.956 | S21: A350 TURNAROUND
B22: Gross Profit Margin (CM1) | C22: =C12-C15-C21 -> 1009217.5 | D22: =C22/$C$12 -> 0.16604943 | E22: =E12-E15-E21 -> 1009217.5 | F22: =E22/$E$12 -> 0.16604943 | G22: =G12-G15-G21 -> 1e-05 | H22: =G22/$G$12 -> 1 | R22: =Handling!Z53 -> 313.236 | S22: 787 TURNAROUND
K23: VA ATL Avg. Revenue Per Flight | O23: ='Summary '!H17 -> 5244.9758
B24: Indirect Management Labor Cost | C24: =SUM(E24,G24) -> 310000 | D24: =C24/$C$12 -> 0.051005184 | E24: =E9 -> 310000 | F24: =E24/$C$12 -> 0.051005184 | H24: =G24/$G$12 -> 0 | K24: Avg. Price Per Pax | R24: VA ATL INTERNATIONAL GARBAGE
B25: Indirect Hourly Labor Cost | C25: =SUM(E25,G25) -> 0 | D25: =C25/$C$12 -> 0 | E25: 0 | F25: =E25/$C$12 -> 0 | H25: =G25/$G$12 -> 0 | K25: FC | L25: BC | M25: PY | N25: EY | O25: TC | P25: CY | R25: =Handling!AD39 -> 339 | S25: A330
B26: Total Indirect Labor | C26: =SUM(C24:C25) -> 310000 | D26: =C26/$C$12 -> 0.051005184 | E26: =SUM(E24:E25) -> 310000 | F26: =E26/$E$12 -> 0.051005184 | G26: =SUM(G24:G25) -> 0 | H26: =G26/$G$12 -> 0 | K26: ='Summary '!B24 -> 0 | L26: ='Summary '!C24 -> 29.247679 | M26: ='Summary '!D24 -> 21.524671 | N26: ='Summary '!E24 -> 9.24905 | O26: ='Summary '!F24 -> 0 | P26: ='Summary '!G24 -> 50.5449 | R26: =Handling!AD41 -> 395.5 | S26: A350
B27: Operating Expense-Variable | C27: =SUM(E27,G27) -> 36000 | D27: =C27/$C$12 -> 0.0059231827 | E27: =3000*12 -> 36000 | F27: =E27/E12 -> 0.0059231827 | H27: =G27/$G$12 -> 0 | I27: Utility | R27: =Handling!AD43 -> 339 | S27: 787
B28: Operating Expense-Fixed | C28: =SUM(E28,G28) -> 0 | D28: =C28/$C$12 -> 0 | F28: =E28/E12 -> 0 | H28: =G28/$G$12 -> 0 | I28: ??? Freezer and Cooler | K28: Overhead
B29: Other OPEX Cost | C29: =SUM(C27:C28) -> 36000 | D29: =C29/$C$12 -> 0.0059231827 | E29: =SUM(E27:E28) -> 36000 | F29: =E29/E12 -> 0.0059231827 | G29: =SUM(G27:G28) -> 0 | H29: =G29/$G$12 -> 0 | K29: FC | L29: BC | M29: PY | N29: YC | O29: TC | P29: CC | R29: VA ATL WASH UP
B30: EBITDA | C30: =C22-C26-C29 -> 663217.49 | D30: =C30/$C$12 -> 0.10912107 | E30: =E22-E26-E29 -> 663217.49 | F30: =E30/$E$12 -> 0.10912107 | G30: =G22-G26-G29 -> 1e-05 | H30: =G30/$G$12 -> 1 | I30: =E30/12 -> 55268.124 | K30: 0 | L30: 0 | M30: 0 | N30: 0 | O30: 0 | P30: 0 | R30: =Handling!C84 -> 704.103 | S30: A330
E31: =E30/(E9+'Summary '!J25) -> 0.1233068 | R31: =Handling!E84 -> 878.3038 | S31: A350
B32: Note - On the P&L we can update the Flights per week, AC type, Load Factor, Cycle & Mark up's | R32: =Handling!G84 -> 653.366 | S32: 787
E34: Overhead =(2/3)*(property tax+utility) | R34: VA ATL PACKING
R35: =Handling!S39+Handling!S45 -> 219.22 | S35: A330
B36: customer service account manager | R36: =Handling!S41+Handling!S47 -> 296.06 | S36: A350
B37: culinary operation duty manager | R37: =Handling!S43+Handling!S50 -> 223.74 | S37: 787
B38: hourly invoice assisant
B39: ramp duty manager
B67: CONTRACTORS | C67: 271755
B68: EXTERIOR SIGNAGE | C68: 2000
B69: MULTITEMP FREEZERS | C69: 164340
...

Sheet Bid Assumption 
A1: Bid Fact Sheet
A2: Airline Name | B2: NEOS
A3: City Code and Unit Number | B3: JFK
A4: Date Bid Preparation Begins
A5: Period used for Annualization
A6: Access Fee %
A7: Trade Discount %
A8: Cash Discount %
A9: Start Up Date
A12: Aircraft Type | B12: 787
A13: Configuration: First Class | B13: =+'FlightConfig '!B3 -> 0
A14: Business Class | B14: =+'FlightConfig '!C3 -> 34
A15: Tourist Class | B15: =SUM('FlightConfig '!D3:E3) -> 246
A16: ETA | B16: 0.26736111
A17: ETD | B17: 0.93402778
A18: Frequency (days of operations) | B18: =+'FlightConfig '!K2 -> 0
A19: Total No. of Flights per Year | B19: =+'FlightConfig '!K3 -> 0
A20: Load Factor %
A21: Source of Load Factor | B21: Flight Config
A22: Account Rep. | B22: Kathy Shi
A23: Reason For Bid | B23: New Unit | E23: Food Markup
A24: Incumbent | E24: Ancillary Markup
A25: New or Old Route | B25: New | E25: Service Markup
A26: Credit Established/Payment Status
A27: Was Account Previously Bid | E27: Overhead Recovery per Pax F/C
A28: Outcome | E28: Overhead Recovery per Pax B/C
A29: Is there a Global Agreement | E29: Overhead Recovery per Pax E/U
A30: Date Building Lease expires | E30: Overhead Recovery per Pax Y/C
E31: Overhead Recovery per Pax C/Y
E32: Overhead Recovery per Pax C/C
A33: Investment | B33: Amount | C33: No. Years | D33: $ per Year | E33: Overhead Recovery per Pax T/C
A34: Building | C34: 0 | D34: =+B34/C34 -> #DIV/0!
A35: Land | C35: N/A | D35: N/A
A36: Building - Leasehold Improvements | C36: 0 | D36: =+B36/C36 -> #DIV/0!
A37: Trucks - Highlifts | C37: 0 | D37: =+B37/C37 -> #DIV/0!
A38: Trucks - Vans/Utility Vehicles | C38: 0 | D38: =+B38/C38 -> #DIV/0!
A39: Equipment | C39: 0 | D39: =+B39/C39 -> #DIV/0!
A40: Rent of Property | C40: 0 | D40: =+B40/C40 -> #DIV/0!
A42: Other Cities that Dnata serves this Customer and Discounts applied:
A43: SFO
...

Sheet Summary 
A2: Customer | G2: Flights Per week | H2: ='P&L'!R2 -> 21 | L2: AC type | M2: Cycle
E3: AC Type | G3: Flights Per Month | H3: =H4/12 -> 91 | J3: Total Revenues | L3: 737 | M3: 1
E4: Load | F4: ='P&L'!R4 -> 0.85 | G4: Annual Flights | H4: =H2*52 -> 1092 | J4: =H17*H4 -> 5727513.6
A5: Summary
A6: BNA | B6: FC | C6: BC | D6: PY | E6: EY | F6: TC | G6: CY | H6: Total | I6: Hnd
A7: FLIGHT CONFIG | B7: =+'FlightConfig '!B17 -> 0 | C7: =('Summary FLT104'!C7+'Summary FLT110'!C7)/2 -> 32 | D7: =('Summary FLT104'!D7+'Summary FLT110'!D7)/2 -> 46 | E7: =('Summary FLT104'!E7+'Summary FLT110'!E7)/2 -> 191 | F7: =('Summary FLT104'!F7+'Summary FLT110'!F7)/2 -> 0 | G7: =('Summary FLT104'!G7+'Summary FLT110'!G7)/2 -> 6 | H7: =('Summary FLT104'!H7+'Summary FLT110'!H7)/2 -> 275
A8: Load Factor | B8: =ROUNDUP(B7*$F$4,0) -> 0 | C8: =ROUNDUP(C7*$F$4,0) -> 28 | D8: =ROUNDUP(D7*$F$4,0) -> 40 | E8: =ROUNDUP(E7*$F$4,0) -> 163 | F8: =ROUNDUP(F7*$F$4,0) -> 0 | G8: =ROUNDUP(G7*$F$4,0) -> 6 | H8: =SUM(B8:G8) -> 237
B9: FIRST CLASS | C9: BUSINESS CLASS | D9: PREMIUM ECONOMY CLASS | E9: ECONOMY CLASS | F9: TECH CREW CLASS | G9: cABIN CREW CLASS | H9: Per Flight | J9: Annual
A10: OVERHEAD | B10: =('Summary FLT104'!B10+'Summary FLT110'!B10)/2 -> 0 | C10: =('Summary FLT104'!C10+'Summary FLT110'!C10)/2 -> 0 | D10: =('Summary FLT104'!D10+'Summary FLT110'!D10)/2 -> 0 | E10: =('Summary FLT104'!E10+'Summary FLT110'!E10)/2 -> 0 | F10: =('Summary FLT104'!F10+'Summary FLT110'!F10)/2 -> 0 | G10: =('Summary FLT104'!G10+'Summary FLT110'!G10)/2 -> 0 | H10: =('Summary FLT104'!H10+'Summary FLT110'!H10)/2 -> 0 | J10: =H10*$H$4 -> 0
A11: Food Cost (DM) | B11: =('Summary FLT104'!B11+'Summary FLT110'!B11)/2 -> 0 | C11: =('Summary FLT104'!C11+'Summary FLT110'!C11)/2 -> 521.52375 | D11: =('Summary FLT104'!D11+'Summary FLT110'!D11)/2 -> 518.61525 | E11: =('Summary FLT104'!E11+'Summary FLT110'!E11)/2 -> 745.725 | F11: =('Summary FLT104'!F11+'Summary FLT110'!F11)/2 -> 0 | G11: =('Summary FLT104'!G11+'Summary FLT110'!G11)/2 -> 185.58 | H11: =('Summary FLT104'!H11+'Summary FLT110'!H11)/2 -> 1971.444 | I11: =I12*45% -> 1390.1362 | J11: =H11*$H$4 -> 2152816.8
A12: Wage Cost (DL) | B12: =('Summary FLT104'!B12+'Summary FLT110'!B12)/2 -> 0 | C12: =('Summary FLT104'!C12+'Summary FLT110'!C12)/2 -> 203.1975 | D12: =('Summary FLT104'!D12+'Summary FLT110'!D12)/2 -> 243.32 | E12: =('Summary FLT104'!E12+'Summary FLT110'!E12)/2 -> 588.43 | F12: =('Summary FLT104'!F12+'Summary FLT110'!F12)/2 -> 0 | G12: =('Summary FLT104'!G12+'Summary FLT110'!G12)/2 -> 82.8 | H12: =('Summary FLT104'!H12+'Summary FLT110'!H12)/2 -> 1117.7475 | I12: =H11+H12 -> 3089.1915 | J12: =H12*$H$4 -> 1220580.3
A13: Food Mark up | B13: =('Summary FLT104'!B13+'Summary FLT110'!B13)/2 -> 0 | C13: =('Summary FLT104'!C13+'Summary FLT110'!C13)/2 -> 67.798087 | D13: =('Summary FLT104'!D13+'Summary FLT110'!D13)/2 -> 67.419982 | E13: =('Summary FLT104'!E13+'Summary FLT110'!E13)/2 -> 96.94425 | F13: =('Summary FLT104'!F13+'Summary FLT110'!F13)/2 -> 0 | G13: =('Summary FLT104'!G13+'Summary FLT110'!G13)/2 -> 24.1254 | H13: =('Summary FLT104'!H13+'Summary FLT110'!H13)/2 -> 256.28772 | J13: =H13*$H$4 -> 279866.19
A14: Labor Mark up | B14: =('Summary FLT104'!B14+'Summary FLT110'!B14)/2 -> 0 | C14: =('Summary FLT104'!C14+'Summary FLT110'!C14)/2 -> 26.415675 | D14: =('Summary FLT104'!D14+'Summary FLT110'!D14)/2 -> 31.6316 | E14: =('Summary FLT104'!E14+'Summary FLT110'!E14)/2 -> 76.4959 | F14: =('Summary FLT104'!F14+'Summary FLT110'!F14)/2 -> 0 | G14: =('Summary FLT104'!G14+'Summary FLT110'!G14)/2 -> 10.764 | H14: =('Summary FLT104'!H14+'Summary FLT110'!H14)/2 -> 145.30717 | J14: =H14*$H$4 -> 158675.44 | L14: Direct Labour
A15: Handling Cost | B15: =('Summary FLT104'!B15+'Summary FLT110'!B15)/2 -> 0 | C15: =('Summary FLT104'!C15+'Summary FLT110'!C15)/2 -> 0 | D15: =('Summary FLT104'!D15+'Summary FLT110'!D15)/2 -> 0 | E15: =('Summary FLT104'!E15+'Summary FLT110'!E15)/2 -> 1552.38 | F15: =('Summary FLT104'!F15+'Summary FLT110'!F15)/2 -> 0 | G15: =('Summary FLT104'!G15+'Summary FLT110'!G15)/2 -> 0 | H15: =('Summary FLT104'!H15+'Summary FLT110'!H15)/2 -> 1552.38 | J15: =H15*$H$4 -> 1695199 | L15: =J12+J15 -> 2915779.2 | M15: 1
A16: Handling Mark up | B16: =('Summary FLT104'!B16+'Summary FLT110'!B16)/2 -> 0 | C16: =('Summary FLT104'!C16+'Summary FLT110'!C16)/2 -> 0 | D16: =('Summary FLT104'!D16+'Summary FLT110'!D16)/2 -> 0 | E16: =('Summary FLT104'!E16+'Summary FLT110'!E16)/2 -> 201.8094 | F16: =('Summary FLT104'!F16+'Summary FLT110'!F16)/2 -> 0 | G16: =('Summary FLT104'!G16+'Summary FLT110'!G16)/2 -> 0 | H16: =('Summary FLT104'!H16+'Summary FLT110'!H16)/2 -> 201.8094 | J16: =H16*$H$4 -> 220375.86 | L16: =L15*M16 -> 2332623.4 | M16: 0.8
A17: Total Per Flight | B17: =SUM(B11:B16) -> 0 | C17: =SUM(C11:C16) -> 818.93501 | D17: =SUM(D10:D16) -> 860.98683 | E17: =SUM(E10:E16) -> 3261.7846 | F17: =SUM(F10:F16) -> 0 | G17: =SUM(G10:G16) -> 303.2694 | H17: =SUM(H10:H16) -> 5244.9758 | J17: =H17*$H$4 -> 5727513.6 | L17: =L15*M17 -> 583155.85 | M17: 0.2
B18: =B17 -> 0 | C18: =C17 -> 818.93501 | D18: =D17 -> 860.98683 | E18: =E17-E15-E16 -> 1507.5952 | F18: =F17 -> 0 | G18: =G17 -> 303.2694 | I18: =E15+E16 -> 1754.1894
A19: Handling | B19: Cost | C19: Mark Up | D19: Price | I19: =E16 -> 201.8094 | J19: =H11+H12+H15 -> 4641.5715
A20: 737 Handling | B20: =('Summary FLT104'!B20+'Summary FLT110'!B20)/2 -> 1552.38 | C20: =('Summary FLT104'!C20+'Summary FLT110'!C20)/2 -> 201.8094 | D20: =SUM(B20:C20) -> 1754.1894 | J20: =H13+H14+H16 -> 603.40429
A21: B777 Handling | B21: =Handling!#REF! -> #REF! | C21: =Handling!#REF! -> #REF! | D21: =Handling!#REF! -> #REF!
A22: A380 Handling | B22: =Handling!#REF! -> #REF! | C22: =Handling!#REF! -> #REF! | D22: =Handling!#REF! -> #REF!
A24: Avg Price Per Pax | B24: =IFERROR(((B11+B12+B13+B14)/B8),0) -> 0 | C24: =IFERROR(((C11+C12+C13+C14)/C8),0) -> 29.247679 | D24: =IFERROR(((D10+D11+D12+D13+D14)/D8),0) -> 21.524671 | E24: =IFERROR(((E10+E11+E12+E13+E14)/E8),0) -> 9.24905 | F24: =IFERROR(((F10+F11+F12+F13+F14)/F8),0) -> 0 | G24: =IFERROR(((G10+G11+G12+G13+G14)/G8),0) -> 50.5449
A25: Avg Mark up Per Pax | B25: =IFERROR(((B13+B14)/B8),0) -> 0 | C25: =IFERROR(((C13+C14)/C8),0) -> 3.3647772 | D25: =IFERROR(((D13+D14)/D8),0) -> 2.4762896 | E25: =IFERROR(((E13+E14)/E8),0) -> 1.06405 | F25: =IFERROR(((F13+F14)/F8),0) -> 0 | G25: =IFERROR(((G13+G14)/G8),0) -> 5.8149 | J25: =J11+J12+J15 -> 5068596.1
A26: Over head Per Pax | B26: =IFERROR((B10/B8),0) -> 0 | C26: =IFERROR((C10/C8),0) -> 0 | D26: =IFERROR((D10/D8),0) -> 0 | E26: =IFERROR((E10/E8),0) -> 0 | F26: =IFERROR((F10/F8),0) -> 0 | G26: =IFERROR((G10/G8),0) -> 0 | J26: =J13+J14+J16 -> 658917.49
B28: CYCLE | C28: FLT
A29: Config | B29: ='P&L'!R5 -> 1
A30: OVERHEAD | B30: =B37*B8 -> 0 | C30: =C37*C8 -> 0 | D30: =D37*D8 -> 0 | E30: =E37*E8 -> 0 | F30: =F37*F8 -> 0 | G30: =G37*G8 -> 0
A31: Food Cost (DM) | B31: =('Summary FLT104'!B31+'Summary FLT110'!B31)/2 -> 0 | C31: =('Summary FLT104'!C31+'Summary FLT110'!C31)/2 -> 606.864 | D31: =('Summary FLT104'!D31+'Summary FLT110'!D31)/2 -> 603.957 | E31: =('Summary FLT104'!E31+'Summary FLT110'!E31)/2 -> 873.825 | F31: =('Summary FLT104'!F31+'Summary FLT110'!F31)/2 -> 0 | G31: =('Summary FLT104'!G31+'Summary FLT110'!G31)/2 -> 185.58
A32: Wage Cost (DL) | B32: =('Summary FLT104'!B32+'Summary FLT110'!B32)/2 -> 0 | C32: =('Summary FLT104'!C32+'Summary FLT110'!C32)/2 -> 236.448 | D32: =('Summary FLT104'!D32+'Summary FLT110'!D32)/2 -> 283.36 | E32: =('Summary FLT104'!E32+'Summary FLT110'!E32)/2 -> 689.51 | F32: =('Summary FLT104'!F32+'Summary FLT110'!F32)/2 -> 0 | G32: =('Summary FLT104'!G32+'Summary FLT110'!G32)/2 -> 82.8
A33: Markup Food | B33: =('Summary FLT104'!B33+'Summary FLT110'!B33)/2 -> 0 | C33: =('Summary FLT104'!C33+'Summary FLT110'!C33)/2 -> 78.89232 | D33: =('Summary FLT104'!D33+'Summary FLT110'!D33)/2 -> 78.51441 | E33: =('Summary FLT104'!E33+'Summary FLT110'!E33)/2 -> 113.59725 | F33: =('Summary FLT104'!F33+'Summary FLT110'!F33)/2 -> 0 | G33: =('Summary FLT104'!G33+'Summary FLT110'!G33)/2 -> 24.1254
A34: Markup Labor | B34: =('Summary FLT104'!B34+'Summary FLT110'!B34)/2 -> 0 | C34: =('Summary FLT104'!C34+'Summary FLT110'!C34)/2 -> 30.73824 | D34: =('Summary FLT104'!D34+'Summary FLT110'!D34)/2 -> 36.8368 | E34: =('Summary FLT104'!E34+'Summary FLT110'!E34)/2 -> 89.6363 | F34: =('Summary FLT104'!F34+'Summary FLT110'!F34)/2 -> 0 | G34: =('Summary FLT104'!G34+'Summary FLT110'!G34)/2 -> 10.764
A36: Per Pax Avg
A37: OVERHEAD | B37: ='P&L'!$K$30 -> 0 | C37: ='P&L'!$L$30 -> 0 | D37: ='P&L'!$M$30 -> 0 | E37: ='P&L'!$N$30 -> 0 | F37: ='P&L'!$O$30 -> 0 | G37: ='P&L'!$P$30 -> 0
A38: Food Cost (DM) | B38: =IFERROR(B31/B7," ") | C38: =IFERROR(C31/C7," ") -> 18.9645 | D38: =IFERROR(D31/D7," ") -> 13.1295 | E38: =IFERROR(E31/E7," ") -> 4.575 | F38: =IFERROR(F31/F7," ") | G38: =IFERROR(G31/G7," ") -> 30.93
A39: Wage Cost (DL) | B39: =IFERROR(B32/B7," ") | C39: =IFERROR(C32/C7," ") -> 7.389 | D39: =IFERROR(D32/D7," ") -> 6.16 | E39: =IFERROR(E32/E7," ") -> 3.61 | F39: =IFERROR(F32/F7," ") | G39: =IFERROR(G32/G7," ") -> 13.8
A40: Markup Food | B40: =IFERROR(B33/B8," ") | C40: =IFERROR(C33/C7," ") -> 2.465385 | D40: =IFERROR(D33/D7," ") -> 1.706835 | E40: =IFERROR(E33/E7," ") -> 0.59475 | F40: =IFERROR(F33/F7," ") | G40: =IFERROR(G33/G7," ") -> 4.0209
A41: Markup Labor | B41: =IFERROR(B34/B7," ") | C41: =IFERROR(C34/C7," ") -> 0.96057 | D41: =IFERROR(D34/D7," ") -> 0.8008 | E41: =IFERROR(E34/E7," ") -> 0.4693 | F41: =IFERROR(F34/F7," ") | G41: =IFERROR(G34/G7," ") -> 1.794
A108: 388
A109: 787

Sheet Summary Short Haul
A2: Customer | G2: Flights Per week | H2: ='Summary 735'!H2+'Summary 2221'!H2+'Summary 2439'!H2+'Summary 2682'!H2+'Summary 2855'!H2 -> 0 | L2: AC type | M2: Cycle
E3: AC Type | F3: 737 | G3: Flights Per Month | H3: =H4/12 -> 0 | J3: Total Revenues | L3: 737 | M3: 1
E4: Load | F4: ='P&L'!R4 -> 0.85 | G4: Annual Flights | H4: =H2*52 -> 0 | J4: =H17*H4 -> #REF!
A5: Summary
A6: BNA | B6: FC | C6: BC | D6: PY | E6: EY | F6: TC | G6: CY | H6: Total | I6: Hnd
A7: FLIGHT CONFIG | B7: =+'FlightConfig '!B17 -> 0 | C7: =+'FlightConfig '!C17 -> 34 | D7: =+'FlightConfig '!D17 -> 48 | E7: =+'FlightConfig '!E17 -> 198 | F7: =+'FlightConfig '!F17 -> 0 | G7: =+'FlightConfig '!G17 -> 6 | H7: =SUM(B7:G7) -> 286
A8: Load Factor | B8: =ROUNDUP(B7*$F$4,0) -> 0 | C8: =ROUNDUP(C7*$F$4,0) -> 29 | D8: =ROUNDUP(D7*$F$4,0) -> 41 | E8: =ROUNDUP(E7*$F$4,0) -> 169 | F8: =ROUNDUP(F7*$F$4,0) -> 0 | G8: =ROUNDUP(G7*$F$4,0) -> 6 | H8: =SUM(B8:G8) -> 245
B9: FIRST CLASS | C9: BUSINESS CLASS | D9: PREMIUM ECONOMY CLASS | E9: ECONOMY CLASS | F9: TECH CREW CLASS | G9: cABIN CREW CLASS | H9: Per Flight | J9: Annual
A10: OVERHEAD | B10: =B37*B8 -> 0 | C10: =('Summary 735'!C10+'Summary 2221'!C10+'Summary 2439'!C10+'Summary 2682'!C10+'Summary 2855'!C10+#REF!+'Summary FLT104'!C10+'Summary FLT110'!C10+#REF!+#REF!+#REF!+'Summary 2037'!C10+'Summary 2817'!C10)/13 -> #REF! | D10: =('Summary 735'!D10+'Summary 2221'!D10+'Summary 2439'!D10+'Summary 2682'!D10+'Summary 2855'!D10+#REF!+'Summary FLT104'!D10+'Summary FLT110'!D10+#REF!+#REF!+#REF!+'Summary 2037'!D10+'Summary 2817'!D10)/13 -> #REF! | E10: =('Summary 735'!E10+'Summary 2221'!E10+'Summary 2439'!E10+'Summary 2682'!E10+'Summary 2855'!E10+#REF!+'Summary FLT104'!E10+'Summary FLT110'!E10+#REF!+#REF!+#REF!+'Summary 2037'!E10+'Summary 2817'!E10)/13 -> #REF! | F10: =('Summary 735'!F10+'Summary 2221'!F10+'Summary 2439'!F10+'Summary 2682'!F10+'Summary 2855'!F10+#REF!+'Summary FLT104'!F10+'Summary FLT110'!F10+#REF!+#REF!+#REF!+'Summary 2037'!F10+'Summary 2817'!F10)/13 -> #REF! | G10: =('Summary 735'!G10+'Summary 2221'!G10+'Summary 2439'!G10+'Summary 2682'!G10+'Summary 2855'!G10+#REF!+'Summary FLT104'!G10+'Summary FLT110'!G10+#REF!+#REF!+#REF!+'Summary 2037'!G10+'Summary 2817'!G10)/13 -> #REF! | H10: =SUM(B10:G10) -> #REF! | J10: =H10*$H$4 -> #REF!
A11: Food Cost (DM) | B11: =('Summary 735'!B11+'Summary 2221'!B11+'Summary 2439'!B11+'Summary 2682'!B11+'Summary 2855'!B11)/5 -> 0 | C11: =('Summary 735'!C11+'Summary 2221'!C11+'Summary 2439'!C11+'Summary 2682'!C11+'Summary 2855'!C11)/5 -> 0 | D11: =('Summary 735'!D11+'Summary 2221'!D11+'Summary 2439'!D11+'Summary 2682'!D11+'Summary 2855'!D11)/5 -> 0 | E11: =('Summary 735'!E11+'Summary 2221'!E11+'Summary 2439'!E11+'Summary 2682'!E11+'Summary 2855'!E11)/5 -> 0 | F11: =('Summary 735'!F11+'Summary 2221'!F11+'Summary 2439'!F11+'Summary 2682'!F11+'Summary 2855'!F11)/5 -> 0 | G11: =('Summary 735'!G11+'Summary 2221'!G11+'Summary 2439'!G11+'Summary 2682'!G11+'Summary 2855'!G11)/5 -> 0 | H11: =SUM(B11:G11) -> 0 | I11: =I12*45% -> #REF! | J11: =H11*$H$4 -> 0
A12: Wage Cost (DL) | B12: =('Summary 735'!B12+'Summary 2221'!B12+'Summary 2439'!B12+'Summary 2682'!B12+'Summary 2855'!B12+#REF!+'Summary FLT104'!B12+'Summary FLT110'!B12+#REF!+#REF!+#REF!+'Summary 2037'!B12+'Summary 2817'!B12)/13 -> #REF! | C12: =('Summary 735'!C12+'Summary 2221'!C12+'Summary 2439'!C12+'Summary 2682'!C12+'Summary 2855'!C12)/5 -> 0 | D12: =('Summary 735'!D12+'Summary 2221'!D12+'Summary 2439'!D12+'Summary 2682'!D12+'Summary 2855'!D12)/5 -> 0 | E12: =('Summary 735'!E12+'Summary 2221'!E12+'Summary 2439'!E12+'Summary 2682'!E12+'Summary 2855'!E12)/5 -> 0 | F12: =('Summary 735'!F12+'Summary 2221'!F12+'Summary 2439'!F12+'Summary 2682'!F12+'Summary 2855'!F12)/5 -> 0 | G12: =('Summary 735'!G12+'Summary 2221'!G12+'Summary 2439'!G12+'Summary 2682'!G12+'Summary 2855'!G12)/5 -> 0 | H12: =SUM(B12:G12) -> #REF! | I12: =H11+H12 -> #REF! | J12: =H12*$H$4 -> #REF!
A13: Food Mark up | B13: =('Summary 735'!B13+'Summary 2221'!B13+'Summary 2439'!B13+'Summary 2682'!B13+'Summary 2855'!B13+#REF!+'Summary FLT104'!B13+'Summary FLT110'!B13+#REF!+#REF!+#REF!+'Summary 2037'!B13+'Summary 2817'!B13)/13 -> #VALUE! | C13: =('Summary 735'!C13+'Summary 2221'!C13+'Summary 2439'!C13+'Summary 2682'!C13+'Summary 2855'!C13)/5 -> 0 | D13: =('Summary 735'!D13+'Summary 2221'!D13+'Summary 2439'!D13+'Summary 2682'!D13+'Summary 2855'!D13)/5 -> 0 | E13: =('Summary 735'!E13+'Summary 2221'!E13+'Summary 2439'!E13+'Summary 2682'!E13+'Summary 2855'!E13)/5 -> 0 | F13: =('Summary 735'!F13+'Summary 2221'!F13+'Summary 2439'!F13+'Summary 2682'!F13+'Summary 2855'!F13)/5 -> 0 | G13: =('Summary 735'!G13+'Summary 2221'!G13+'Summary 2439'!G13+'Summary 2682'!G13+'Summary 2855'!G13)/5 -> 0 | H13: =SUM(B13:G13) -> #VALUE! | J13: =H13*$H$4 -> #VALUE!
A14: Labor Mark up | B14: =('Summary 735'!B14+'Summary 2221'!B14+'Summary 2439'!B14+'Summary 2682'!B14+'Summary 2855'!B14+#REF!+'Summary FLT104'!B14+'Summary FLT110'!B14+#REF!+#REF!+#REF!+'Summary 2037'!B14+'Summary 2817'!B14)/13 -> #VALUE! | C14: =('Summary 735'!C14+'Summary 2221'!C14+'Summary 2439'!C14+'Summary 2682'!C14+'Summary 2855'!C14)/5 -> 0 | D14: =('Summary 735'!D14+'Summary 2221'!D14+'Summary 2439'!D14+'Summary 2682'!D14+'Summary 2855'!D14)/5 -> 0 | E14: =('Summary 735'!E14+'Summary 2221'!E14+'Summary 2439'!E14+'Summary 2682'!E14+'Summary 2855'!E14)/5 -> 0 | F14: =('Summary 735'!F14+'Summary 2221'!F14+'Summary 2439'!F14+'Summary 2682'!F14+'Summary 2855'!F14)/5 -> 0 | G14: =('Summary 735'!G14+'Summary 2221'!G14+'Summary 2439'!G14+'Summary 2682'!G14+'Summary 2855'!G14)/5 -> 0 | H14: =SUM(B14:G14) -> #VALUE! | J14: =H14*$H$4 -> #VALUE! | L14: Direct Labour
A15: Handling Cost | B15: =SUM('Summary 735'!B15+'Summary 2221'!B15+'Summary 2221'!B15+'Summary 2439'!B15+'Summary 2682'!B15+'Summary 2855'!B15+#REF!+'Summary FLT104'!B15+'Summary FLT110'!B15+#REF!+#REF!+#REF!+'Summary 2037'!B15+'Summary 2817'!B15)/13 -> #REF! | C15: =('Summary 735'!C15+'Summary 2221'!C15+'Summary 2439'!C15+'Summary 2682'!C15+'Summary 2855'!C15)/5 -> 0 | D15: =('Summary 735'!D15+'Summary 2221'!D15+'Summary 2439'!D15+'Summary 2682'!D15+'Summary 2855'!D15)/5 -> 0 | E15: =('Summary 735'!E15+'Summary 2221'!E15+'Summary 2439'!E15+'Summary 2682'!E15+'Summary 2855'!E15)/5 -> 0 | F15: =('Summary 735'!F15+'Summary 2221'!F15+'Summary 2439'!F15+'Summary 2682'!F15+'Summary 2855'!F15)/5 -> 0 | G15: =('Summary 735'!G15+'Summary 2221'!G15+'Summary 2439'!G15+'Summary 2682'!G15+'Summary 2855'!G15)/5 -> 0 | H15: =SUM(B15:G15) -> #REF! | J15: =H15*$H$4 -> #REF! | L15: =J12+J15 -> #REF! | M15: 1
A16: Handling Mark up | B16: =SUM('Summary 735'!B16+'Summary 2221'!B16+'Summary 2221'!B16+'Summary 2439'!B16+'Summary 2682'!B16+'Summary 2855'!B16+#REF!+'Summary FLT104'!B16+'Summary FLT110'!B16+#REF!+#REF!+#REF!+'Summary 2037'!B16+'Summary 2817'!B16)/13 -> #REF! | C16: =('Summary 735'!C16+'Summary 2221'!C16+'Summary 2439'!C16+'Summary 2682'!C16+'Summary 2855'!C16)/5 -> 0 | D16: =('Summary 735'!D16+'Summary 2221'!D16+'Summary 2439'!D16+'Summary 2682'!D16+'Summary 2855'!D16)/5 -> 0 | E16: =('Summary 735'!E16+'Summary 2221'!E16+'Summary 2439'!E16+'Summary 2682'!E16+'Summary 2855'!E16)/5 -> 0 | F16: =('Summary 735'!F16+'Summary 2221'!F16+'Summary 2439'!F16+'Summary 2682'!F16+'Summary 2855'!F16)/5 -> 0 | G16: =('Summary 735'!G16+'Summary 2221'!G16+'Summary 2439'!G16+'Summary 2682'!G16+'Summary 2855'!G16)/5 -> 0 | H16: =SUM(B16:G16) -> #REF! | J16: =H16*$H$4 -> #REF! | L16: =L15*M16 -> #REF! | M16: 0.8
A17: Total Per Flight | B17: =SUM(B11:B16) -> #REF! | C17: =SUM(C11:C16) -> 0 | D17: =SUM(D10:D16) -> #REF! | E17: =SUM(E10:E16) -> #REF! | F17: =SUM(F10:F16) -> #REF! | G17: =SUM(G10:G16) -> #REF! | H17: =SUM(H10:H16) -> #REF! | J17: =H17*$H$4 -> #REF! | L17: =L15*M17 -> #REF! | M17: 0.2
B18: =B17 -> #REF! | C18: =C17 -> 0 | D18: =D17 -> #REF! | E18: =E17-E15-E16 -> #REF! | F18: =F17 -> #REF! | G18: =G17 -> #REF! | I18: =E15+E16 -> 0
A19: Handling | B19: Cost | C19: Mark Up | D19: Price | I19: =E16 -> 0
A20: 737 Handling | B20: =SUM('Summary 735'!B20+'Summary 2221'!B20+'Summary 2221'!B20+'Summary 2439'!B20+'Summary 2682'!B20+'Summary 2855'!B20+#REF!+'Summary FLT104'!B20+'Summary FLT110'!B20+#REF!+#REF!+#REF!+'Summary 2037'!B20+'Summary 2817'!B20)/13 -> #REF! | C20: =B20*'P&L'!$R$10 -> #REF! | D20: =SUM(B20:C20) -> #REF!
A21: B777 Handling | B21: =Handling!#REF! -> #REF! | C21: =Handling!#REF! -> #REF! | D21: =Handling!#REF! -> #REF!
A22: A380 Handling | B22: =Handling!#REF! -> #REF! | C22: =Handling!#REF! -> #REF! | D22: =Handling!#REF! -> #REF!
A24: Avg Price Per Pax | B24: =IFERROR(((B11+B12+B13+B14)/B8),0) -> 0 | C24: =IFERROR(((C11+C12+C13+C14)/C8),0) -> 0 | D24: =IFERROR(((D10+D11+D12+D13+D14)/D8),0) -> 0 | E24: =IFERROR(((E10+E11+E12+E13+E14)/E8),0) -> 0 | F24: =IFERROR(((F10+F11+F12+F13+F14)/F8),0) -> 0 | G24: =IFERROR(((G10+G11+G12+G13+G14)/G8),0) -> 0
A25: Avg Mark up Per Pax | B25: =IFERROR(((B13+B14)/B8),0) -> 0 | C25: =IFERROR(((C13+C14)/C8),0) -> 0 | D25: =IFERROR(((D13+D14)/D8),0) -> 0 | E25: =IFERROR(((E13+E14)/E8),0) -> 0 | F25: =IFERROR(((F13+F14)/F8),0) -> 0 | G25: =IFERROR(((G13+G14)/G8),0) -> 0
A26: Over head Per Pax | B26: =IFERROR((B10/B8),0) -> 0 | C26: =IFERROR((C10/C8),0) -> 0 | D26: =IFERROR((D10/D8),0) -> 0 | E26: =IFERROR((E10/E8),0) -> 0 | F26: =IFERROR((F10/F8),0) -> 0 | G26: =IFERROR((G10/G8),0) -> 0
B28: CYCLE | C28: FLT
A29: Config | B29: ='P&L'!R5 -> 1
A30: OVERHEAD | B30: =B37*B8 -> 0 | C30: =C37*C8 -> 0 | D30: =D37*D8 -> 0 | E30: =E37*E8 -> 0 | F30: =F37*F8 -> 0 | G30: =G37*G8 -> 0
A31: Food Cost (DM) | B31: =('Summary 735'!B31+'Summary 2221'!B31+'Summary 2439'!B31+'Summary 2682'!B31+'Summary 2855'!B31)/5 -> 0 | C31: =('Summary 735'!C31+'Summary 2221'!C31+'Summary 2439'!C31+'Summary 2682'!C31+'Summary 2855'!C31+#REF!+'Summary FLT104'!C31+'Summary FLT110'!C31+#REF!+#REF!+#REF!+'Summary 2037'!C31+'Summary 2817'!C31)/13 -> #REF! | D31: =('Summary 735'!D31+'Summary 2221'!D31+'Summary 2439'!D31+'Summary 2682'!D31+'Summary 2855'!D31+#REF!+'Summary FLT104'!D31+'Summary FLT110'!D31+#REF!+#REF!+#REF!+'Summary 2037'!D31+'Summary 2817'!D31)/13 -> #REF! | E31: =('Summary 735'!E31+'Summary 2221'!E31+'Summary 2439'!E31+'Summary 2682'!E31+'Summary 2855'!E31)/5 -> 0 | F31: =('Summary 735'!F31+'Summary 2221'!F31+'Summary 2439'!F31+'Summary 2682'!F31+'Summary 2855'!F31+#REF!+'Summary FLT104'!F31+'Summary FLT110'!F31+#REF!+#REF!+#REF!+'Summary 2037'!F31+'Summary 2817'!F31)/13 -> #REF! | G31: =('Summary 735'!G31+'Summary 2221'!G31+'Summary 2439'!G31+'Summary 2682'!G31+'Summary 2855'!G31+#REF!+'Summary FLT104'!G31+'Summary FLT110'!G31+#REF!+#REF!+#REF!+'Summary 2037'!G31+'Summary 2817'!G31)/13 -> #REF!
A32: Wage Cost (DL) | B32: =('Summary 735'!B32+'Summary 2221'!B32+'Summary 2439'!B32+'Summary 2682'!B32+'Summary 2855'!B32)/5 -> 0 | C32: =('Summary 735'!C32+'Summary 2221'!C32+'Summary 2439'!C32+'Summary 2682'!C32+'Summary 2855'!C32+#REF!+'Summary FLT104'!C32+'Summary FLT110'!C32+#REF!+#REF!+#REF!+'Summary 2037'!C32+'Summary 2817'!C32)/13 -> #REF! | D32: =('Summary 735'!D32+'Summary 2221'!D32+'Summary 2439'!D32+'Summary 2682'!D32+'Summary 2855'!D32+#REF!+'Summary FLT104'!D32+'Summary FLT110'!D32+#REF!+#REF!+#REF!+'Summary 2037'!D32+'Summary 2817'!D32)/13 -> #REF! | E32: =('Summary 735'!E32+'Summary 2221'!E32+'Summary 2439'!E32+'Summary 2682'!E32+'Summary 2855'!E32)/5 -> 0 | F32: =('Summary 735'!F32+'Summary 2221'!F32+'Summary 2439'!F32+'Summary 2682'!F32+'Summary 2855'!F32+#REF!+'Summary FLT104'!F32+'Summary FLT110'!F32+#REF!+#REF!+#REF!+'Summary 2037'!F32+'Summary 2817'!F32)/13 -> #REF! | G32: =('Summary 735'!G32+'Summary 2221'!G32+'Summary 2439'!G32+'Summary 2682'!G32+'Summary 2855'!G32+#REF!+'Summary FLT104'!G32+'Summary FLT110'!G32+#REF!+#REF!+#REF!+'Summary 2037'!G32+'Summary 2817'!G32)/13 -> #REF!
A33: Markup Food | B33: =('Summary 735'!B33+'Summary 2221'!B33+'Summary 2439'!B33+'Summary 2682'!B33+'Summary 2855'!B33)/5 -> 0 | C33: =('Summary 735'!C33+'Summary 2221'!C33+'Summary 2439'!C33+'Summary 2682'!C33+'Summary 2855'!C33+#REF!+'Summary FLT104'!C33+'Summary FLT110'!C33+#REF!+#REF!+#REF!+'Summary 2037'!C33+'Summary 2817'!C33)/13 -> #REF! | D33: =('Summary 735'!D33+'Summary 2221'!D33+'Summary 2439'!D33+'Summary 2682'!D33+'Summary 2855'!D33+#REF!+'Summary FLT104'!D33+'Summary FLT110'!D33+#REF!+#REF!+#REF!+'Summary 2037'!D33+'Summary 2817'!D33)/13 -> #REF! | E33: =('Summary 735'!E33+'Summary 2221'!E33+'Summary 2439'!E33+'Summary 2682'!E33+'Summary 2855'!E33)/5 -> 0 | F33: =('Summary 735'!F33+'Summary 2221'!F33+'Summary 2439'!F33+'Summary 2682'!F33+'Summary 2855'!F33+#REF!+'Summary FLT104'!F33+'Summary FLT110'!F33+#REF!+#REF!+#REF!+'Summary 2037'!F33+'Summary 2817'!F33)/13 -> #REF! | G33: =('Summary 735'!G33+'Summary 2221'!G33+'Summary 2439'!G33+'Summary 2682'!G33+'Summary 2855'!G33+#REF!+'Summary FLT104'!G33+'Summary FLT110'!G33+#REF!+#REF!+#REF!+'Summary 2037'!G33+'Summary 2817'!G33)/13 -> #REF!
A34: Markup Labor | B34: =('Summary 735'!B34+'Summary 2221'!B34+'Summary 2439'!B34+'Summary 2682'!B34+'Summary 2855'!B34)/5 -> 0 | C34: =('Summary 735'!C34+'Summary 2221'!C34+'Summary 2439'!C34+'Summary 2682'!C34+'Summary 2855'!C34+#REF!+'Summary FLT104'!C34+'Summary FLT110'!C34+#REF!+#REF!+#REF!+'Summary 2037'!C34+'Summary 2817'!C34)/13 -> #REF! | D34: =('Summary 735'!D34+'Summary 2221'!D34+'Summary 2439'!D34+'Summary 2682'!D34+'Summary 2855'!D34+#REF!+'Summary FLT104'!D34+'Summary FLT110'!D34+#REF!+#REF!+#REF!+'Summary 2037'!D34+'Summary 2817'!D34)/13 -> #REF! | E34: =('Summary 735'!E34+'Summary 2221'!E34+'Summary 2439'!E34+'Summary 2682'!E34+'Summary 2855'!E34)/5 -> 0 | F34: =('Summary 735'!F34+'Summary 2221'!F34+'Summary 2439'!F34+'Summary 2682'!F34+'Summary 2855'!F34+#REF!+'Summary FLT104'!F34+'Summary FLT110'!F34+#REF!+#REF!+#REF!+'Summary 2037'!F34+'Summary 2817'!F34)/13 -> #REF! | G34: =('Summary 735'!G34+'Summary 2221'!G34+'Summary 2439'!G34+'Summary 2682'!G34+'Summary 2855'!G34+#REF!+'Summary FLT104'!G34+'Summary FLT110'!G34+#REF!+#REF!+#REF!+'Summary 2037'!G34+'Summary 2817'!G34)/13 -> #REF!
A36: Per Pax Avg
A37: OVERHEAD | B37: ='P&L'!$K$30 -> 0 | C37: ='P&L'!$L$30 -> 0 | D37: ='P&L'!$M$30 -> 0 | E37: ='P&L'!$N$30 -> 0 | F37: ='P&L'!$O$30 -> 0 | G37: ='P&L'!$P$30 -> 0
A38: Food Cost (DM) | B38: =IFERROR(B31/B7," ") | C38: =IFERROR(C31/C7," ") | D38: =IFERROR(D31/D7," ") | E38: =IFERROR(E31/E7," ") -> 0 | F38: =IFERROR(F31/F7," ") | G38: =IFERROR(G31/G7," ")
A39: Wage Cost (DL) | B39: =IFERROR(B32/B7," ") | C39: =IFERROR(C32/C7," ") | D39: =IFERROR(D32/D7," ") | E39: =IFERROR(E32/E7," ") -> 0 | F39: =IFERROR(F32/F7," ") | G39: =IFERROR(G32/G7," ")
A40: Markup Food | B40: =IFERROR(B33/B8," ") | C40: =IFERROR(C33/C7," ") | D40: =IFERROR(D33/D7," ") | E40: =IFERROR(E33/E7," ") -> 0 | F40: =IFERROR(F33/F7," ") | G40: =IFERROR(G33/G7," ")
A41: Markup Labor | B41: =IFERROR(B34/B7," ") | C41: =IFERROR(C34/C7," ") | D41: =IFERROR(D34/D7," ") | E41: =IFERROR(E34/E7," ") -> 0 | F41: =IFERROR(F34/F7," ") | G41: =IFERROR(G34/G7," ")
A108: 388
A109: 787

Sheet Summary Long Haul
A2: Customer | G2: Flights Per week | H2: =#REF!+'Summary FLT104'!H2+'Summary FLT110'!H2+#REF!+#REF!+#REF!+'Summary 2037'!H2+'Summary 2817'!H2 -> #REF! | L2: AC type | M2: Cycle
E3: AC Type | F3: 737 | G3: Flights Per Month | H3: =H4/12 -> #REF! | J3: Total Revenues | L3: 737 | M3: 1
E4: Load | F4: ='P&L'!R4 -> 0.85 | G4: Annual Flights | H4: =H2*52 -> #REF! | J4: =H17*H4 -> #REF!
A5: Summary
A6: BNA | B6: FC | C6: BC | D6: PY | E6: EY | F6: TC | G6: CY | H6: Total | I6: Hnd
A7: FLIGHT CONFIG | B7: =+'FlightConfig '!B17 -> 0 | C7: =+'FlightConfig '!C17 -> 34 | D7: =+'FlightConfig '!D17 -> 48 | E7: =+'FlightConfig '!E17 -> 198 | F7: =+'FlightConfig '!F17 -> 0 | G7: =+'FlightConfig '!G17 -> 6 | H7: =SUM(B7:G7) -> 286
A8: Load Factor | B8: =ROUNDUP(B7*$F$4,0) -> 0 | C8: =ROUNDUP(C7*$F$4,0) -> 29 | D8: =ROUNDUP(D7*$F$4,0) -> 41 | E8: =ROUNDUP(E7*$F$4,0) -> 169 | F8: =ROUNDUP(F7*$F$4,0) -> 0 | G8: =ROUNDUP(G7*$F$4,0) -> 6 | H8: =SUM(B8:G8) -> 245
B9: FIRST CLASS | C9: BUSINESS CLASS | D9: PREMIUM ECONOMY CLASS | E9: ECONOMY CLASS | F9: TECH CREW CLASS | G9: cABIN CREW CLASS | H9: Per Flight | J9: Annual
A10: OVERHEAD | B10: =(#REF!+'Summary FLT104'!B10+'Summary FLT110'!B10+#REF!+#REF!+#REF!)/6 -> #REF! | C10: =(#REF!+'Summary FLT104'!C10+'Summary FLT110'!C10+#REF!+#REF!+#REF!)/6 -> #REF! | D10: =(#REF!+'Summary FLT104'!D10+'Summary FLT110'!D10+#REF!+#REF!+#REF!)/6 -> #REF! | E10: =(#REF!+'Summary FLT104'!E10+'Summary FLT110'!E10+#REF!+#REF!+#REF!)/6 -> #REF! | F10: =(#REF!+'Summary FLT104'!F10+'Summary FLT110'!F10+#REF!+#REF!+#REF!)/6 -> #REF! | G10: =(#REF!+'Summary FLT104'!G10+'Summary FLT110'!G10+#REF!+#REF!+#REF!)/6 -> #REF! | H10: =(#REF!+'Summary FLT104'!H10+'Summary FLT110'!H10+#REF!+#REF!+#REF!)/6 -> #REF! | J10: =H10*$H$4 -> #REF!
A11: Food Cost (DM) | B11: =(#REF!+'Summary FLT104'!B11+'Summary FLT110'!B11+#REF!+#REF!+#REF!)/6 -> #REF! | C11: =(#REF!+'Summary FLT104'!C11+'Summary FLT110'!C11+#REF!+#REF!+#REF!)/6 -> #REF! | D11: =(#REF!+'Summary FLT104'!D11+'Summary FLT110'!D11+#REF!+#REF!+#REF!)/6 -> #REF! | E11: =(#REF!+'Summary FLT104'!E11+'Summary FLT110'!E11+#REF!+#REF!+#REF!)/6 -> #REF! | F11: =(#REF!+'Summary FLT104'!F11+'Summary FLT110'!F11+#REF!+#REF!+#REF!)/6 -> #REF! | G11: =(#REF!+'Summary FLT104'!G11+'Summary FLT110'!G11+#REF!+#REF!+#REF!)/6 -> #REF! | H11: =(#REF!+'Summary FLT104'!H11+'Summary FLT110'!H11+#REF!+#REF!+#REF!)/6 -> #REF! | I11: =I12*45% -> #REF! | J11: =H11*$H$4 -> #REF!
A12: Wage Cost (DL) | B12: =(#REF!+'Summary FLT104'!B12+'Summary FLT110'!B12+#REF!+#REF!+#REF!)/6 -> #REF! | C12: =(#REF!+'Summary FLT104'!C12+'Summary FLT110'!C12+#REF!+#REF!+#REF!)/6 -> #REF! | D12: =(#REF!+'Summary FLT104'!D12+'Summary FLT110'!D12+#REF!+#REF!+#REF!)/6 -> #REF! | E12: =(#REF!+'Summary FLT104'!E12+'Summary FLT110'!E12+#REF!+#REF!+#REF!)/6 -> #REF! | F12: =(#REF!+'Summary FLT104'!F12+'Summary FLT110'!F12+#REF!+#REF!+#REF!)/6 -> #REF! | G12: =(#REF!+'Summary FLT104'!G12+'Summary FLT110'!G12+#REF!+#REF!+#REF!)/6 -> #REF! | H12: =(#REF!+'Summary FLT104'!H12+'Summary FLT110'!H12+#REF!+#REF!+#REF!)/6 -> #REF! | I12: =H11+H12 -> #REF! | J12: =H12*$H$4 -> #REF!
A13: Food Mark up | B13: =(#REF!+'Summary FLT104'!B13+'Summary FLT110'!B13+#REF!+#REF!+#REF!)/6 -> #REF! | C13: =(#REF!+'Summary FLT104'!C13+'Summary FLT110'!C13+#REF!+#REF!+#REF!)/6 -> #REF! | D13: =(#REF!+'Summary FLT104'!D13+'Summary FLT110'!D13+#REF!+#REF!+#REF!)/6 -> #REF! | E13: =(#REF!+'Summary FLT104'!E13+'Summary FLT110'!E13+#REF!+#REF!+#REF!)/6 -> #REF! | F13: =(#REF!+'Summary FLT104'!F13+'Summary FLT110'!F13+#REF!+#REF!+#REF!)/6 -> #REF! | G13: =(#REF!+'Summary FLT104'!G13+'Summary FLT110'!G13+#REF!+#REF!+#REF!)/6 -> #REF! | H13: =(#REF!+'Summary FLT104'!H13+'Summary FLT110'!H13+#REF!+#REF!+#REF!)/6 -> #REF! | J13: =H13*$H$4 -> #REF!
A14: Labor Mark up | B14: =(#REF!+'Summary FLT104'!B14+'Summary FLT110'!B14+#REF!+#REF!+#REF!)/6 -> #REF! | C14: =(#REF!+'Summary FLT104'!C14+'Summary FLT110'!C14+#REF!+#REF!+#REF!)/6 -> #REF! | D14: =(#REF!+'Summary FLT104'!D14+'Summary FLT110'!D14+#REF!+#REF!+#REF!)/6 -> #REF! | E14: =(#REF!+'Summary FLT104'!E14+'Summary FLT110'!E14+#REF!+#REF!+#REF!)/6 -> #REF! | F14: =(#REF!+'Summary FLT104'!F14+'Summary FLT110'!F14+#REF!+#REF!+#REF!)/6 -> #REF! | G14: =(#REF!+'Summary FLT104'!G14+'Summary FLT110'!G14+#REF!+#REF!+#REF!)/6 -> #REF! | H14: =(#REF!+'Summary FLT104'!H14+'Summary FLT110'!H14+#REF!+#REF!+#REF!)/6 -> #REF! | J14: =H14*$H$4 -> #REF! | L14: Direct Labour
A15: Handling Cost | B15: =(#REF!+'Summary FLT104'!B15+'Summary FLT110'!B15+#REF!+#REF!+#REF!)/6 -> #REF! | C15: =(#REF!+'Summary FLT104'!C15+'Summary FLT110'!C15+#REF!+#REF!+#REF!)/6 -> #REF! | D15: =(#REF!+'Summary FLT104'!D15+'Summary FLT110'!D15+#REF!+#REF!+#REF!)/6 -> #REF! | E15: =(#REF!+'Summary FLT104'!E15+'Summary FLT110'!E15+#REF!+#REF!+#REF!)/6 -> #REF! | F15: =(#REF!+'Summary FLT104'!F15+'Summary FLT110'!F15+#REF!+#REF!+#REF!)/6 -> #REF! | G15: =(#REF!+'Summary FLT104'!G15+'Summary FLT110'!G15+#REF!+#REF!+#REF!)/6 -> #REF! | H15: =(#REF!+'Summary FLT104'!H15+'Summary FLT110'!H15+#REF!+#REF!+#REF!)/6 -> #REF! | J15: =H15*$H$4 -> #REF! | L15: =J12+J15 -> #REF! | M15: 1
A16: Handling Mark up | B16: =(#REF!+'Summary FLT104'!B16+'Summary FLT110'!B16+#REF!+#REF!+#REF!)/6 -> #REF! | C16: =(#REF!+'Summary FLT104'!C16+'Summary FLT110'!C16+#REF!+#REF!+#REF!)/6 -> #REF! | D16: =(#REF!+'Summary FLT104'!D16+'Summary FLT110'!D16+#REF!+#REF!+#REF!)/6 -> #REF! | E16: =(#REF!+'Summary FLT104'!E16+'Summary FLT110'!E16+#REF!+#REF!+#REF!)/6 -> #REF! | F16: =(#REF!+'Summary FLT104'!F16+'Summary FLT110'!F16+#REF!+#REF!+#REF!)/6 -> #REF! | G16: =(#REF!+'Summary FLT104'!G16+'Summary FLT110'!G16+#REF!+#REF!+#REF!)/6 -> #REF! | H16: =(#REF!+'Summary FLT104'!H16+'Summary FLT110'!H16+#REF!+#REF!+#REF!)/6 -> #REF! | J16: =H16*$H$4 -> #REF! | L16: =L15*M16 -> #REF! | M16: 0.8
A17: Total Per Flight | B17: =SUM(B11:B16) -> #REF! | C17: =SUM(C11:C16) -> #REF! | D17: =SUM(D10:D16) -> #REF! | E17: =SUM(E10:E16) -> #REF! | F17: =SUM(F10:F16) -> #REF! | G17: =SUM(G10:G16) -> #REF! | H17: =SUM(H10:H16) -> #REF! | J17: =H17*$H$4 -> #REF! | L17: =L15*M17 -> #REF! | M17: 0.2
B18: =B17 -> #REF! | C18: =C17 -> #REF! | D18: =D17 -> #REF! | E18: =E17-E15-E16 -> #REF! | F18: =F17 -> #REF! | G18: =G17 -> #REF! | I18: =E15+E16 -> #REF!
A19: Handling | B19: Cost | C19: Mark Up | D19: Price | I19: =E16 -> #REF!
A20: 737 Handling | B20: =(#REF!+'Summary FLT104'!B20+'Summary FLT110'!B20+#REF!+#REF!+#REF!+'Summary 2037'!B20+'Summary 2817'!B20)/8 -> #REF! | C20: =B20*'P&L'!$R$10 -> #REF! | D20: =SUM(B20:C20) -> #REF!
A21: B777 Handling | B21: =Handling!#REF! -> #REF! | C21: =Handling!#REF! -> #REF! | D21: =Handling!#REF! -> #REF!
A22: A380 Handling | B22: =Handling!#REF! -> #REF! | C22: =Handling!#REF! -> #REF! | D22: =Handling!#REF! -> #REF!
A24: Avg Price Per Pax | B24: =IFERROR(((B11+B12+B13+B14)/B8),0) -> 0 | C24: =IFERROR(((C11+C12+C13+C14)/C8),0) -> 0 | D24: =IFERROR(((D10+D11+D12+D13+D14)/D8),0) -> 0 | E24: =IFERROR(((E10+E11+E12+E13+E14)/E8),0) -> 0 | F24: =IFERROR(((F10+F11+F12+F13+F14)/F8),0) -> 0 | G24: =IFERROR(((G10+G11+G12+G13+G14)/G8),0) -> 0
A25: Avg Mark up Per Pax | B25: =IFERROR(((B13+B14)/B8),0) -> 0 | C25: =IFERROR(((C13+C14)/C8),0) -> 0 | D25: =IFERROR(((D13+D14)/D8),0) -> 0 | E25: =IFERROR(((E13+E14)/E8),0) -> 0 | F25: =IFERROR(((F13+F14)/F8),0) -> 0 | G25: =IFERROR(((G13+G14)/G8),0) -> 0
A26: Over head Per Pax | B26: =IFERROR((B10/B8),0) -> 0 | C26: =IFERROR((C10/C8),0) -> 0 | D26: =IFERROR((D10/D8),0) -> 0 | E26: =IFERROR((E10/E8),0) -> 0 | F26: =IFERROR((F10/F8),0) -> 0 | G26: =IFERROR((G10/G8),0) -> 0
B28: CYCLE | C28: FLT
A29: Config | B29: ='P&L'!R5 -> 1
A30: OVERHEAD | B30: =(#REF!+'Summary FLT104'!B30+'Summary FLT110'!B30+#REF!+#REF!+#REF!)/6 -> #REF! | C30: =(#REF!+'Summary FLT104'!C30+'Summary FLT110'!C30+#REF!+#REF!+#REF!)/6 -> #REF! | D30: =(#REF!+'Summary FLT104'!D30+'Summary FLT110'!D30+#REF!+#REF!+#REF!)/6 -> #REF! | E30: =(#REF!+'Summary FLT104'!E30+'Summary FLT110'!E30+#REF!+#REF!+#REF!)/6 -> #REF! | F30: =(#REF!+'Summary FLT104'!F30+'Summary FLT110'!F30+#REF!+#REF!+#REF!)/6 -> #REF! | G30: =(#REF!+'Summary FLT104'!G30+'Summary FLT110'!G30+#REF!+#REF!+#REF!)/6 -> #REF!
A31: Food Cost (DM) | B31: =(#REF!+'Summary FLT104'!B31+'Summary FLT110'!B31+#REF!+#REF!+#REF!)/6 -> #REF! | C31: =(#REF!+'Summary FLT104'!C31+'Summary FLT110'!C31+#REF!+#REF!+#REF!)/6 -> #REF! | D31: =(#REF!+'Summary FLT104'!D31+'Summary FLT110'!D31+#REF!+#REF!+#REF!)/6 -> #REF! | E31: =(#REF!+'Summary FLT104'!E31+'Summary FLT110'!E31+#REF!+#REF!+#REF!)/6 -> #REF! | F31: =(#REF!+'Summary FLT104'!F31+'Summary FLT110'!F31+#REF!+#REF!+#REF!)/6 -> #REF! | G31: =(#REF!+'Summary FLT104'!G31+'Summary FLT110'!G31+#REF!+#REF!+#REF!)/6 -> #REF!
A32: Wage Cost (DL) | B32: =(#REF!+'Summary FLT104'!B32+'Summary FLT110'!B32+#REF!+#REF!+#REF!)/6 -> #REF! | C32: =(#REF!+'Summary FLT104'!C32+'Summary FLT110'!C32+#REF!+#REF!+#REF!)/6 -> #REF! | D32: =(#REF!+'Summary FLT104'!D32+'Summary FLT110'!D32+#REF!+#REF!+#REF!)/6 -> #REF! | E32: =(#REF!+'Summary FLT104'!E32+'Summary FLT110'!E32+#REF!+#REF!+#REF!)/6 -> #REF! | F32: =(#REF!+'Summary FLT104'!F32+'Summary FLT110'!F32+#REF!+#REF!+#REF!)/6 -> #REF! | G32: =(#REF!+'Summary FLT104'!G32+'Summary FLT110'!G32+#REF!+#REF!+#REF!)/6 -> #REF!
A33: Markup Food | B33: =(#REF!+'Summary FLT104'!B33+'Summary FLT110'!B33+#REF!+#REF!+#REF!)/6 -> #REF! | C33: =(#REF!+'Summary FLT104'!C33+'Summary FLT110'!C33+#REF!+#REF!+#REF!)/6 -> #REF! | D33: =(#REF!+'Summary FLT104'!D33+'Summary FLT110'!D33+#REF!+#REF!+#REF!)/6 -> #REF! | E33: =(#REF!+'Summary FLT104'!E33+'Summary FLT110'!E33+#REF!+#REF!+#REF!)/6 -> #REF! | F33: =(#REF!+'Summary FLT104'!F33+'Summary FLT110'!F33+#REF!+#REF!+#REF!)/6 -> #REF! | G33: =(#REF!+'Summary FLT104'!G33+'Summary FLT110'!G33+#REF!+#REF!+#REF!)/6 -> #REF!
A34: Markup Labor | B34: =(#REF!+'Summary FLT104'!B34+'Summary FLT110'!B34+#REF!+#REF!+#REF!)/6 -> #REF! | C34: =(#REF!+'Summary FLT104'!C34+'Summary FLT110'!C34+#REF!+#REF!+#REF!)/6 -> #REF! | D34: =(#REF!+'Summary FLT104'!D34+'Summary FLT110'!D34+#REF!+#REF!+#REF!)/6 -> #REF! | E34: =(#REF!+'Summary FLT104'!E34+'Summary FLT110'!E34+#REF!+#REF!+#REF!)/6 -> #REF! | F34: =(#REF!+'Summary FLT104'!F34+'Summary FLT110'!F34+#REF!+#REF!+#REF!)/6 -> #REF! | G34: =(#REF!+'Summary FLT104'!G34+'Summary FLT110'!G34+#REF!+#REF!+#REF!)/6 -> #REF!
A36: Per Pax Avg
A37: OVERHEAD | B37: ='P&L'!$K$30 -> 0 | C37: ='P&L'!$L$30 -> 0 | D37: ='P&L'!$M$30 -> 0 | E37: ='P&L'!$N$30 -> 0 | F37: ='P&L'!$O$30 -> 0 | G37: ='P&L'!$P$30 -> 0
A38: Food Cost (DM) | B38: =IFERROR(B31/B7," ") | C38: =IFERROR(C31/C7," ") | D38: =IFERROR(D31/D7," ") | E38: =IFERROR(E31/E7," ") | F38: =IFERROR(F31/F7," ") | G38: =IFERROR(G31/G7," ")
A39: Wage Cost (DL) | B39: =IFERROR(B32/B7," ") | C39: =IFERROR(C32/C7," ") | D39: =IFERROR(D32/D7," ") | E39: =IFERROR(E32/E7," ") | F39: =IFERROR(F32/F7," ") | G39: =IFERROR(G32/G7," ")
A40: Markup Food | B40: =IFERROR(B33/B8," ") | C40: =IFERROR(C33/C7," ") | D40: =IFERROR(D33/D7," ") | E40: =IFERROR(E33/E7," ") | F40: =IFERROR(F33/F7," ") | G40: =IFERROR(G33/G7," ")
A41: Markup Labor | B41: =IFERROR(B34/B7," ") | C41: =IFERROR(C34/C7," ") | D41: =IFERROR(D34/D7," ") | E41: =IFERROR(E34/E7," ") | F41: =IFERROR(F34/F7," ") | G41: =IFERROR(G34/G7," ")
A108: 388
A109: 787

Sheet Summary  735
A2: Customer | G2: Flights Per week | H2: 0 | L2: AC type | M2: Cycle
E3: AC Type | F3: 738 | G3: Flights Per Month | H3: =H4/12 -> 0 | J3: Total Revenues | L3: 737 | M3: 1
E4: Load | F4: ='P&L'!R4 -> 0.85 | G4: Annual Flights | H4: =H2*52 -> 0 | J4: =H17*H4 -> 0
A5: Summary
A6: BNA | B6: FC | C6: BC | D6: PY | E6: EY | F6: TC | G6: CY | H6: Total | I6: Hnd
A7: FLIGHT CONFIG | B7: =+'FlightConfig '!B17 -> 0 | C7: =+'FlightConfig '!C17 -> 34 | D7: =+'FlightConfig '!D17 -> 48 | E7: =+'FlightConfig '!E17 -> 198 | F7: =+'FlightConfig '!F17 -> 0 | G7: =+'FlightConfig '!G17 -> 6 | H7: =SUM(B7:G7) -> 286
A8: Load Factor | B8: =ROUNDUP(B7*$F$4,0) -> 0 | C8: =ROUNDUP(C7*$F$4,0) -> 29 | D8: =ROUNDUP(D7*$F$4,0) -> 41 | E8: =ROUNDUP(E7*$F$4,0) -> 169 | F8: =ROUNDUP(F7*$F$4,0) -> 0 | G8: =ROUNDUP(G7*$F$4,0) -> 6 | H8: =SUM(B8:G8) -> 245
B9: FIRST CLASS | C9: BUSINESS CLASS | D9: PREMIUM ECONOMY CLASS | E9: ECONOMY CLASS | F9: TECH CREW CLASS | G9: cABIN CREW CLASS | H9: Per Flight | J9: Annual
A10: OVERHEAD | B10: =B37*B8 -> 0 | C10: =C37*C8 -> 0 | D10: =D37*D8 -> 0 | E10: =E37*E8 -> 0 | F10: =F37*F8 -> 0 | G10: =G37*G8 -> 0 | H10: =SUM(B10:G10) -> 0 | J10: =H10*$H$4 -> 0
A11: Food Cost (DM) | B11: =IFERROR(B38*B8,0) -> 0 | C11: =IFERROR(C38*$C$8,0) -> 0 | D11: =IFERROR(D38*$D$8,0) -> 0 | E11: =IFERROR(E38*$E$8,0) -> 0 | F11: =IFERROR(F38*$F$8,0) -> 0 | G11: =IFERROR(G38*G8,0) -> 0 | H11: =SUM(B11:G11) -> 0 | I11: =I12*45% -> 0 | J11: =H11*$H$4 -> 0
A12: Wage Cost (DL) | B12: =IFERROR(B39*B8,0) -> 0 | C12: =IFERROR(C39*$C$8,0) -> 0 | D12: =IFERROR(D39*$D$8,0) -> 0 | E12: =IFERROR(E39*$E$8,0) -> 0 | F12: =IFERROR(F39*$F$8,0) -> 0 | G12: =IFERROR(G39*G8,0) -> 0 | H12: =SUM(B12:G12) -> 0 | I12: =H11+H12 -> 0 | J12: =H12*$H$4 -> 0
A13: Food Mark up | B13: =IFERROR(B40*B8," ") | C13: =IFERROR(C40*$C$8,0) -> 0 | D13: =IFERROR(D40*$D$8,0) -> 0 | E13: =IFERROR(E40*$E$8,0) -> 0 | F13: =IFERROR(F40*$F$8,0) -> 0 | G13: 0 | H13: =SUM(B13:G13) -> 0 | J13: =H13*$H$4 -> 0
A14: Labor Mark up | B14: =IFERROR(B41*B8," ") | C14: =IFERROR(C41*$C$8,0) -> 0 | D14: =IFERROR(D41*$D$8,0) -> 0 | E14: =IFERROR(E41*$E$8,0) -> 0 | F14: =IFERROR(F41*$F$8,0) -> 0 | G14: 0 | H14: =SUM(B14:G14) -> 0 | J14: =H14*$H$4 -> 0 | L14: Direct Labour
A15: Handling Cost | B15: 0 | C15: 0 | D15: 0 | E15: =+B20 -> 0 | F15: 0 | G15: 0 | H15: =SUM(B15:G15) -> 0 | J15: =H15*$H$4 -> 0 | L15: =J12+J15 -> 0 | M15: 1
A16: Handling Mark up | B16: 0 | C16: 0 | D16: 0 | E16: =+C20 -> 0 | F16: 0 | G16: 0 | H16: =SUM(B16:G16) -> 0 | J16: =H16*$H$4 -> 0 | L16: =L15*M16 -> 0 | M16: 0.8
A17: Total Per Flight | B17: =SUM(B11:B16) -> 0 | C17: =SUM(C11:C16) -> 0 | D17: =SUM(D10:D16) -> 0 | E17: =SUM(E10:E16) -> 0 | F17: =SUM(F10:F16) -> 0 | G17: =SUM(G10:G16) -> 0 | H17: =SUM(H10:H16) -> 0 | J17: =H17*$H$4 -> 0 | L17: =L15*M17 -> 0 | M17: 0.2
B18: =B17 -> 0 | C18: =C17 -> 0 | D18: =D17 -> 0 | E18: =E17-E15-E16 -> 0 | F18: =F17 -> 0 | G18: =G17 -> 0 | I18: =E15+E16 -> 0
A19: Handling | B19: Cost | C19: Mark Up | D19: Price | I19: =E16 -> 0
A20: 738 Handling | B20: =Handling!C56 -> 0 | C20: =B20*'P&L'!$R$10 -> 0 | D20: =SUM(B20:C20) -> 0
A21: B777 Handling | B21: =Handling!#REF! -> #REF! | C21: =Handling!#REF! -> #REF! | D21: =Handling!#REF! -> #REF!
A22: A380 Handling | B22: =Handling!#REF! -> #REF! | C22: =Handling!#REF! -> #REF! | D22: =Handling!#REF! -> #REF!
A24: Avg Price Per Pax | B24: =IFERROR(((B11+B12+B13+B14)/B8),0) -> 0 | C24: =IFERROR(((C11+C12+C13+C14)/C8),0) -> 0 | D24: =IFERROR(((D10+D11+D12+D13+D14)/D8),0) -> 0 | E24: =IFERROR(((E10+E11+E12+E13+E14)/E8),0) -> 0 | F24: =IFERROR(((F10+F11+F12+F13+F14)/F8),0) -> 0 | G24: =IFERROR(((G10+G11+G12+G13+G14)/G8),0) -> 0
A25: Avg Mark up Per Pax | B25: =IFERROR(((B13+B14)/B8),0) -> 0 | C25: =IFERROR(((C13+C14)/C8),0) -> 0 | D25: =IFERROR(((D13+D14)/D8),0) -> 0 | E25: =IFERROR(((E13+E14)/E8),0) -> 0 | F25: =IFERROR(((F13+F14)/F8),0) -> 0 | G25: =IFERROR(((G13+G14)/G8),0) -> 0
A26: Over head Per Pax | B26: =IFERROR((B10/B8),0) -> 0 | C26: =IFERROR((C10/C8),0) -> 0 | D26: =IFERROR((D10/D8),0) -> 0 | E26: =IFERROR((E10/E8),0) -> 0 | F26: =IFERROR((F10/F8),0) -> 0 | G26: =IFERROR((G10/G8),0) -> 0
B28: CYCLE | C28: FLT
A29: Config | B29: ='P&L'!R5 -> 1 | C29: 735
A30: OVERHEAD | B30: =B37*B8 -> 0 | C30: =C37*C8 -> 0 | D30: =D37*D8 -> 0 | E30: =E37*E8 -> 0 | F30: =F37*F8 -> 0 | G30: =G37*G8 -> 0
A31: Food Cost (DM) | B31: =IFERROR(IF($B$29=$B$29,SUMIF(Food!$C:$C,B$9&$B$29&$C$29,Food!$U:$U),0),"") -> 0 | C31: =IFERROR(IF($B$29=$B$29,SUMIF(Food!$C:$C,C$9&$B$29&$C$29,Food!$U:$U),0),"") -> 0 | D31: =IFERROR(IF($B$29=$B$29,SUMIF(Food!$C:$C,D$9&$B$29&$C$29,Food!$U:$U),0),"") -> 0 | E31: =IFERROR(IF($B$29=$B$29,SUMIF(Food!$C:$C,E$9&$B$29&$C$29,Food!$U:$U),0),"") -> 0 | F31: =IFERROR(IF($B$29=$B$29,SUMIF(Food!$C:$C,F$9&$B$29&$C$29,Food!$U:$U),0),"") -> 0 | G31: =IFERROR(IF($B$29=$B$29,SUMIF(Food!$C:$C,G$9&$B$29&$C$29,Food!$U:$U),0),"") -> 0
A32: Wage Cost (DL) | B32: =IFERROR(IF($B$29=$B$29,SUMIF(Food!$C:$C,B$9&$B$29&$C$29,Food!$W:$W),0),"") -> 0 | C32: =IFERROR(IF($B$29=$B$29,SUMIF(Food!$C:$C,C$9&$B$29&$C$29,Food!$W:$W),0),"") -> 0 | D32: =IFERROR(IF($B$29=$B$29,SUMIF(Food!$C:$C,D$9&$B$29&$C$29,Food!$W:$W),0),"") -> 0 | E32: =IFERROR(IF($B$29=$B$29,SUMIF(Food!$C:$C,E$9&$B$29&$C$29,Food!$W:$W),0),"") -> 0 | F32: =IFERROR(IF($B$29=$B$29,SUMIF(Food!$C:$C,F$9&$B$29&$C$29,Food!$W:$W),0),"") -> 0 | G32: =IFERROR(IF($B$29=$B$29,SUMIF(Food!$C:$C,G$9&$B$29&$C$29,Food!$W:$W),0),"") -> 0
A33: Markup Food | B33: =IFERROR(IF($B$29=$B$29,SUMIF(Food!$C:$C,B$9&$B$29&$C$29,Food!$Y:$Y),0),"") -> 0 | C33: =IFERROR(IF($B$29=$B$29,SUMIF(Food!$C:$C,C$9&$B$29&$C$29,Food!$Y:$Y),0),"") -> 0 | D33: =IFERROR(IF($B$29=$B$29,SUMIF(Food!$C:$C,D$9&$B$29&$C$29,Food!$Y:$Y),0),"") -> 0 | E33: =IFERROR(IF($B$29=$B$29,SUMIF(Food!$C:$C,E$9&$B$29&$C$29,Food!$Y:$Y),0),"") -> 0 | F33: =IFERROR(IF($B$29=$B$29,SUMIF(Food!$C:$C,F$9&$B$29&$C$29,Food!$Y:$Y),0),"") -> 0 | G33: =IFERROR(IF($B$29=$B$29,SUMIF(Food!$C:$C,G$9&$B$29&$C$29,Food!$O:$O),0),"") -> 0
A34: Markup Labor | B34: =IFERROR(IF($B$29=$B$29,SUMIF(Food!$C:$C,B$9&$B$29&$C$29,Food!$Z:$Z),0),"") -> 0 | C34: =IFERROR(IF($B$29=$B$29,SUMIF(Food!$C:$C,C$9&$B$29&$C$29,Food!$Z:$Z),0),"") -> 0 | D34: =IFERROR(IF($B$29=$B$29,SUMIF(Food!$C:$C,D$9&$B$29&$C$29,Food!$Z:$Z),0),"") -> 0 | E34: =IFERROR(IF($B$29=$B$29,SUMIF(Food!$C:$C,E$9&$B$29&$C$29,Food!$Z:$Z),0),"") -> 0 | F34: =IFERROR(IF($B$29=$B$29,SUMIF(Food!$C:$C,F$9&$B$29&$C$29,Food!$Z:$Z),0),"") -> 0 | G34: =IFERROR(IF($B$29=$B$29,SUMIF(Food!$C:$C,G$9&$B$29&$C$29,Food!$P:$P),0),"") -> 0
A36: Per Pax Avg
A37: OVERHEAD | B37: ='P&L'!$K$30 -> 0 | C37: ='P&L'!$L$30 -> 0 | D37: ='P&L'!$M$30 -> 0 | E37: ='P&L'!$N$30 -> 0 | F37: ='P&L'!$O$30 -> 0 | G37: ='P&L'!$P$30 -> 0
A38: Food Cost (DM) | B38: =IFERROR(B31/B7," ") | C38: =IFERROR(C31/C7," ") -> 0 | D38: =IFERROR(D31/D7," ") -> 0 | E38: =IFERROR(E31/E7," ") -> 0 | F38: =IFERROR(F31/F7," ") | G38: =IFERROR(G31/G7," ") -> 0
A39: Wage Cost (DL) | B39: =IFERROR(B32/B7," ") | C39: =IFERROR(C32/C7," ") -> 0 | D39: =IFERROR(D32/D7," ") -> 0 | E39: =IFERROR(E32/E7," ") -> 0 | F39: =IFERROR(F32/F7," ") | G39: =IFERROR(G32/G7," ") -> 0
A40: Markup Food | B40: =IFERROR(B33/B8," ") | C40: =IFERROR(C33/C7," ") -> 0 | D40: =IFERROR(D33/D7," ") -> 0 | E40: =IFERROR(E33/E7," ") -> 0 | F40: =IFERROR(F33/F7," ") | G40: =IFERROR(G33/G7," ") -> 0
A41: Markup Labor | B41: =IFERROR(B34/B7," ") | C41: =IFERROR(C34/C7," ") -> 0 | D41: =IFERROR(D34/D7," ") -> 0 | E41: =IFERROR(E34/E7," ") -> 0 | F41: =IFERROR(F34/F7," ") | G41: =IFERROR(G34/G7," ") -> 0
A108: 388
A109: 787

Sheet Summary 2221
A2: Customer | G2: Flights Per week | H2: 0 | L2: AC type | M2: Cycle
E3: AC Type | F3: 738 | G3: Flights Per Month | H3: =H4/12 -> 0 | J3: Total Revenues | L3: 737 | M3: 1
E4: Load | F4: ='P&L'!R4 -> 0.85 | G4: Annual Flights | H4: =H2*52 -> 0 | J4: =H17*H4 -> 0
A5: Summary
A6: BNA | B6: FC | C6: BC | D6: PY | E6: EY | F6: TC | G6: CY | H6: Total | I6: Hnd
A7: FLIGHT CONFIG | B7: =+'FlightConfig '!B17 -> 0 | C7: =+'FlightConfig '!C17 -> 34 | D7: =+'FlightConfig '!D17 -> 48 | E7: =+'FlightConfig '!E17 -> 198 | F7: =+'FlightConfig '!F17 -> 0 | G7: =+'FlightConfig '!G17 -> 6 | H7: =SUM(B7:G7) -> 286
A8: Load Factor | B8: =ROUNDUP(B7*$F$4,0) -> 0 | C8: =ROUNDUP(C7*$F$4,0) -> 29 | D8: =ROUNDUP(D7*$F$4,0) -> 41 | E8: =ROUNDUP(E7*$F$4,0) -> 169 | F8: =ROUNDUP(F7*$F$4,0) -> 0 | G8: =ROUNDUP(G7*$F$4,0) -> 6 | H8: =SUM(B8:G8) -> 245
B9: FIRST CLASS | C9: BUSINESS CLASS | D9: PREMIUM ECONOMY CLASS | E9: ECONOMY CLASS | F9: TECH CREW CLASS | G9: cABIN CREW CLASS | H9: Per Flight | J9: Annual
A10: OVERHEAD | B10: =B37*B8 -> 0 | C10: =C37*C8 -> 0 | D10: =D37*D8 -> 0 | E10: =E37*E8 -> 0 | F10: =F37*F8 -> 0 | G10: =G37*G8 -> 0 | H10: =SUM(B10:G10) -> 0 | J10: =H10*$H$4 -> 0
A11: Food Cost (DM) | B11: =IFERROR(B38*B8,0) -> 0 | C11: =IFERROR(C38*$C$8,0) -> 0 | D11: =IFERROR(D38*$D$8,0) -> 0 | E11: =IFERROR(E38*$E$8,0) -> 0 | F11: =IFERROR(F38*$F$8,0) -> 0 | G11: =IFERROR(G38*G8,0) -> 0 | H11: =SUM(B11:G11) -> 0 | I11: =I12*45% -> 0 | J11: =H11*$H$4 -> 0
A12: Wage Cost (DL) | B12: =IFERROR(B39*B8,0) -> 0 | C12: =IFERROR(C39*$C$8,0) -> 0 | D12: =IFERROR(D39*$D$8,0) -> 0 | E12: =IFERROR(E39*$E$8,0) -> 0 | F12: =IFERROR(F39*$F$8,0) -> 0 | G12: =IFERROR(G39*G8,0) -> 0 | H12: =SUM(B12:G12) -> 0 | I12: =H11+H12 -> 0 | J12: =H12*$H$4 -> 0
A13: Food Mark up | B13: =IFERROR(B40*B8," ") | C13: =IFERROR(C40*$C$8,0) -> 0 | D13: =IFERROR(D40*$D$8,0) -> 0 | E13: =IFERROR(E40*$E$8,0) -> 0 | F13: =IFERROR(F40*$F$8,0) -> 0 | G13: 0 | H13: =SUM(B13:G13) -> 0 | J13: =H13*$H$4 -> 0
A14: Labor Mark up | B14: =IFERROR(B41*B8," ") | C14: =IFERROR(C41*$C$8,0) -> 0 | D14: =IFERROR(D41*$D$8,0) -> 0 | E14: =IFERROR(E41*$E$8,0) -> 0 | F14: =IFERROR(F41*$F$8,0) -> 0 | G14: 0 | H14: =SUM(B14:G14) -> 0 | J14: =H14*$H$4 -> 0 | L14: Direct Labour
A15: Handling Cost | B15: 0 | C15: 0 | D15: 0 | E15: =+B20 -> 0 | F15: 0 | G15: 0 | H15: =SUM(B15:G15) -> 0 | J15: =H15*$H$4 -> 0 | L15: =J12+J15 -> 0 | M15: 1
A16: Handling Mark up | B16: 0 | C16: 0 | D16: 0 | E16: =+C20 -> 0 | F16: 0 | G16: 0 | H16: =SUM(B16:G16) -> 0 | J16: =H16*$H$4 -> 0 | L16: =L15*M16 -> 0 | M16: 0.8
A17: Total Per Flight | B17: =SUM(B11:B16) -> 0 | C17: =SUM(C11:C16) -> 0 | D17: =SUM(D10:D16) -> 0 | E17: =SUM(E10:E16) -> 0 | F17: =SUM(F10:F16) -> 0 | G17: =SUM(G10:G16) -> 0 | H17: =SUM(H10:H16) -> 0 | J17: =H17*$H$4 -> 0 | L17: =L15*M17 -> 0 | M17: 0.2
B18: =B17 -> 0 | C18: =C17 -> 0 | D18: =D17 -> 0 | E18: =E17-E15-E16 -> 0 | F18: =F17 -> 0 | G18: =G17 -> 0 | I18: =E15+E16 -> 0
A19: Handling | B19: Cost | C19: Mark Up | D19: Price | I19: =E16 -> 0
A20: 738 Handling | B20: =Handling!C56 -> 0 | C20: =B20*'P&L'!$R$10 -> 0 | D20: =SUM(B20:C20) -> 0
A21: B777 Handling | B21: =Handling!#REF! -> #REF! | C21: =Handling!#REF! -> #REF! | D21: =Handling!#REF! -> #REF!
A22: A380 Handling | B22: =Handling!#REF! -> #REF! | C22: =Handling!#REF! -> #REF! | D22: =Handling!#REF! -> #REF!
A24: Avg Price Per Pax | B24: =IFERROR(((B11+B12+B13+B14)/B8),0) -> 0 | C24: =IFERROR(((C11+C12+C13+C14)/C8),0) -> 0 | D24: =IFERROR(((D10+D11+D12+D13+D14)/D8),0) -> 0 | E24: =IFERROR(((E10+E11+E12+E13+E14)/E8),0) -> 0 | F24: =IFERROR(((F10+F11+F12+F13+F14)/F8),0) -> 0 | G24: =IFERROR(((G10+G11+G12+G13+G14)/G8),0) -> 0
A25: Avg Mark up Per Pax | B25: =IFERROR(((B13+B14)/B8),0) -> 0 | C25: =IFERROR(((C13+C14)/C8),0) -> 0 | D25: =IFERROR(((D13+D14)/D8),0) -> 0 | E25: =IFERROR(((E13+E14)/E8),0) -> 0 | F25: =IFERROR(((F13+F14)/F8),0) -> 0 | G25: =IFERROR(((G13+G14)/G8),0) -> 0
A26: Over head Per Pax | B26: =IFERROR((B10/B8),0) -> 0 | C26: =IFERROR((C10/C8),0) -> 0 | D26: =IFERROR((D10/D8),0) -> 0 | E26: =IFERROR((E10/E8),0) -> 0 | F26: =IFERROR((F10/F8),0) -> 0 | G26: =IFERROR((G10/G8),0) -> 0
B28: CYCLE | C28: FLT
A29: Config | B29: ='P&L'!R5 -> 1 | C29: 2221
A30: OVERHEAD | B30: =B37*B8 -> 0 | C30: =C37*C8 -> 0 | D30: =D37*D8 -> 0 | E30: =E37*E8 -> 0 | F30: =F37*F8 -> 0 | G30: =G37*G8 -> 0
A31: Food Cost (DM) | B31: =IFERROR(IF($B$29=$B$29,SUMIF(Food!$C:$C,B$9&$B$29&$C$29,Food!$U:$U),0),"") -> 0 | C31: =IFERROR(IF($B$29=$B$29,SUMIF(Food!$C:$C,C$9&$B$29&$C$29,Food!$U:$U),0),"") -> 0 | D31: =IFERROR(IF($B$29=$B$29,SUMIF(Food!$C:$C,D$9&$B$29&$C$29,Food!$U:$U),0),"") -> 0 | E31: =IFERROR(IF($B$29=$B$29,SUMIF(Food!$C:$C,E$9&$B$29&$C$29,Food!$U:$U),0),"") -> 0 | F31: =IFERROR(IF($B$29=$B$29,SUMIF(Food!$C:$C,F$9&$B$29&$C$29,Food!$U:$U),0),"") -> 0 | G31: =IFERROR(IF($B$29=$B$29,SUMIF(Food!$C:$C,G$9&$B$29&$C$29,Food!$U:$U),0),"") -> 0
A32: Wage Cost (DL) | B32: =IFERROR(IF($B$29=$B$29,SUMIF(Food!$C:$C,B$9&$B$29&$C$29,Food!$W:$W),0),"") -> 0 | C32: =IFERROR(IF($B$29=$B$29,SUMIF(Food!$C:$C,C$9&$B$29&$C$29,Food!$W:$W),0),"") -> 0 | D32: =IFERROR(IF($B$29=$B$29,SUMIF(Food!$C:$C,D$9&$B$29&$C$29,Food!$W:$W),0),"") -> 0 | E32: =IFERROR(IF($B$29=$B$29,SUMIF(Food!$C:$C,E$9&$B$29&$C$29,Food!$W:$W),0),"") -> 0 | F32: =IFERROR(IF($B$29=$B$29,SUMIF(Food!$C:$C,F$9&$B$29&$C$29,Food!$W:$W),0),"") -> 0 | G32: =IFERROR(IF($B$29=$B$29,SUMIF(Food!$C:$C,G$9&$B$29&$C$29,Food!$W:$W),0),"") -> 0
A33: Markup Food | B33: =IFERROR(IF($B$29=$B$29,SUMIF(Food!$C:$C,B$9&$B$29&$C$29,Food!$Y:$Y),0),"") -> 0 | C33: =IFERROR(IF($B$29=$B$29,SUMIF(Food!$C:$C,C$9&$B$29&$C$29,Food!$Y:$Y),0),"") -> 0 | D33: =IFERROR(IF($B$29=$B$29,SUMIF(Food!$C:$C,D$9&$B$29&$C$29,Food!$Y:$Y),0),"") -> 0 | E33: =IFERROR(IF($B$29=$B$29,SUMIF(Food!$C:$C,E$9&$B$29&$C$29,Food!$Y:$Y),0),"") -> 0 | F33: =IFERROR(IF($B$29=$B$29,SUMIF(Food!$C:$C,F$9&$B$29&$C$29,Food!$Y:$Y),0),"") -> 0 | G33: =IFERROR(IF($B$29=$B$29,SUMIF(Food!$C:$C,G$9&$B$29&$C$29,Food!$O:$O),0),"") -> 0
A34: Markup Labor | B34: =IFERROR(IF($B$29=$B$29,SUMIF(Food!$C:$C,B$9&$B$29&$C$29,Food!$Z:$Z),0),"") -> 0 | C34: =IFERROR(IF($B$29=$B$29,SUMIF(Food!$C:$C,C$9&$B$29&$C$29,Food!$Z:$Z),0),"") -> 0 | D34: =IFERROR(IF($B$29=$B$29,SUMIF(Food!$C:$C,D$9&$B$29&$C$29,Food!$Z:$Z),0),"") -> 0 | E34: =IFERROR(IF($B$29=$B$29,SUMIF(Food!$C:$C,E$9&$B$29&$C$29,Food!$Z:$Z),0),"") -> 0 | F34: =IFERROR(IF($B$29=$B$29,SUMIF(Food!$C:$C,F$9&$B$29&$C$29,Food!$Z:$Z),0),"") -> 0 | G34: =IFERROR(IF($B$29=$B$29,SUMIF(Food!$C:$C,G$9&$B$29&$C$29,Food!$P:$P),0),"") -> 0
A36: Per Pax Avg
A37: OVERHEAD | B37: ='P&L'!$K$30 -> 0 | C37: ='P&L'!$L$30 -> 0 | D37: ='P&L'!$M$30 -> 0 | E37: ='P&L'!$N$30 -> 0 | F37: ='P&L'!$O$30 -> 0 | G37: ='P&L'!$P$30 -> 0
A38: Food Cost (DM) | B38: =IFERROR(B31/B7," ") | C38: =IFERROR(C31/C7," ") -> 0 | D38: =IFERROR(D31/D7," ") -> 0 | E38: =IFERROR(E31/E7," ") -> 0 | F38: =IFERROR(F31/F7," ") | G38: =IFERROR(G31/G7," ") -> 0
A39: Wage Cost (DL) | B39: =IFERROR(B32/B7," ") | C39: =IFERROR(C32/C7," ") -> 0 | D39: =IFERROR(D32/D7," ") -> 0 | E39: =IFERROR(E32/E7," ") -> 0 | F39: =IFERROR(F32/F7," ") | G39: =IFERROR(G32/G7," ") -> 0
A40: Markup Food | B40: =IFERROR(B33/B8," ") | C40: =IFERROR(C33/C7," ") -> 0 | D40: =IFERROR(D33/D7," ") -> 0 | E40: =IFERROR(E33/E7," ") -> 0 | F40: =IFERROR(F33/F7," ") | G40: =IFERROR(G33/G7," ") -> 0
A41: Markup Labor | B41: =IFERROR(B34/B7," ") | C41: =IFERROR(C34/C7," ") -> 0 | D41: =IFERROR(D34/D7," ") -> 0 | E41: =IFERROR(E34/E7," ") -> 0 | F41: =IFERROR(F34/F7," ") | G41: =IFERROR(G34/G7," ") -> 0
A108: 388
A109: 787

Sheet Summary 2439
A2: Customer | G2: Flights Per week | H2: 0 | L2: AC type | M2: Cycle
E3: AC Type | F3: 738 | G3: Flights Per Month | H3: =H4/12 -> 0 | J3: Total Revenues | L3: 737 | M3: 1
E4: Load | F4: ='P&L'!R4 -> 0.85 | G4: Annual Flights | H4: =H2*52 -> 0 | J4: =H17*H4 -> 0
A5: Summary
A6: BNA | B6: FC | C6: BC | D6: PY | E6: EY | F6: TC | G6: CY | H6: Total | I6: Hnd
A7: FLIGHT CONFIG | B7: =+'FlightConfig '!B17 -> 0 | C7: =+'FlightConfig '!C17 -> 34 | D7: =+'FlightConfig '!D17 -> 48 | E7: =+'FlightConfig '!E17 -> 198 | F7: =+'FlightConfig '!F17 -> 0 | G7: =+'FlightConfig '!G17 -> 6 | H7: =SUM(B7:G7) -> 286
