Workbook
Name Data: [1]Summary!$A$2:$F$5004
Name DryItemList: '[2]DRY ITEM LIST'!$D$4:$D$46
Name DryItemList: 'DRY ITEM LIST'!$D$4:$D$61

Sheet Inv Summary
A1: ET $ | B1: D Note
H2: 45887
E8: TO: Ethiopian Airlines Group
E9: ="FLIGHT NO: "&'Inv Detail'!J2 -> FLIGHT NO: ET519
E10: Route ATL-ADD
E11: Period Date : 05/22/2026 to 05/31/2026
E12: ="Invoice Number: "&'Inv Detail'!G1 -> Invoice Number: ET202605B
E13: ="DATE: "&TEXT('Inv Detail'!G2,"dd-mmm-yyyy") -> DATE: 18-Jun-2026
A15: 14 | B15: F17 | E15: FOOD | F15: =SUM('Inv Detail'!Q15:Q58) -> 39619.977 | G15: =IF(G$9="","",'DN01'!$F$14+'DN01'!$J$25-3)
A16: 16 | B16: F29
A17: 18 | B17: F32 | E17: SERVICE | F17: =SUM('Inv Detail'!Q10:Q14) -> 4200
A18: 21 | B18: F30
A19: 17 | B19: F31 | E19: SUBTOTAL | F19: =SUM(F15:F18) -> 43819.977
A20: 19 | B20: M
A21: 20 | B21: M | E21: TAX | F21: 0
A22: 78 | B22: F16
A23: 98 | B23: F19 | E23: PORT FEE | F23: 0
A24: XX | B24: XX
A25: 39 | B25: F33 | E25: TOTAL DUE | F25: =SUM(F19:F23) -> 43819.977
A26: 41 | B26: **
A27: 43 | B27: ** | E27: DUE DATE: | F27: ='Inv Detail'!G3 -> 46221
A28: 33 | B28: G17
A29: 88 | B29: G16
A30: 105 | B30: G20
A31: XX | B31: XX
A32: 42 | B32: **
A33: 44 | B33: **
A34: DRY | B34: ITEM
G51: =SUMPRODUCT($F$10:$F$50,G10:G50) -> 0 | H51: =SUMPRODUCT($F$10:$F$50,H10:H50) -> 0 | I51: =SUMPRODUCT($F$10:$F$50,I10:I50) -> 0 | J51: =SUMPRODUCT($F$10:$F$50,J10:J50) -> 0 | K51: =SUMPRODUCT($F$10:$F$50,K10:K50) -> 0 | L51: =SUMPRODUCT($F$10:$F$50,L10:L50) -> 0 | M51: =SUMPRODUCT($F$10:$F$50,M10:M50) -> 0

Sheet Inv Detail
A1: ET $ | B1: D Note | F1: Invoice #: | G1: ="ET"&TEXT(G9,"YYYYMM")&IF(DAY(G9)<16,"A","B") -> ET202605B | I1: Bill-to: | J1: Ethiopian Airlines Group | V1: Cycle 1 | W1: Cycle 2 | X1: Cycle 3
F2: Inv Date: | G2: 46191 | I2: Flight No: | J2: ET519 | V2: 46023 | W2: 46082 | X2: 46143
F3: Due Date: | G3: =G2+30 -> 46221 | I3: Route ATL-ADD | T3: Cycle #
T4: 3
E7: +
G8: =TEXT(G9,"DDD") -> Fri | H8: =TEXT(H9,"DDD") -> Mon | I8: =TEXT(I9,"DDD") -> Wed | J8: =TEXT(J9,"DDD") -> Fri | K8: =TEXT(K9,"DDD") | L8: =TEXT(L9,"DDD") | M8: =TEXT(M9,"DDD") | N8: =TEXT(N9,"DDD") | ... P8: =TEXT(P9,"DDD") | V8: According to the contract , BC total 35 and (-3) complimetary but no Special meal added
D9: No. | E9: CODE | F9: PRICE | G9: =IF('DN01'!$N$1="","",'DN01'!$N$1) -> 46164 | H9: =IF('DN02'!$N$1="","",'DN02'!$N$1) -> 46167 | I9: =IF('DN03'!$N$1="","",'DN03'!$N$1) -> 46169 | J9: =IF('DN04'!$N$1="","",'DN04'!$N$1) -> 46171 | K9: =IF('DN05'!$N$1="","",'DN05'!$N$1) | L9: =IF('DN06'!$N$1="","",'DN06'!$N$1) | M9: =IF('DN07'!$N$1="","",'DN07'!$N$1) | N9: =IF('DN08'!$N$1="","",'DN08'!$N$1) | O9: =IF('DN09'!$N$1="","",'DN09'!$N$1) | P9: =IF('DN10'!$N$1="","",'DN10'!$N$1) | Q9: SUBTOTAL | T9: ** REF ONLY ** | V9: According to the contract , EY total 135 and (-10) complimetary but no Special meal added
A10: 49 | B10: M | D10: 1 | E10: Handling charges Per A/C - Turnaround 1 trip - B787 | F10: {=_xlfn.XLOOKUP($A10,'ET Standar Price List'!$A:$A,_xlfn.SWITCH($T$4,1,'ET Standar Price List'!$G:$G,2,'ET Standar Price List'!$J:$J,3,'ET Standar Price List'!$M:$M),"XX")} -> 400 | G10: =IF(G$9="","",'DN01'!$F$35) -> 1 | H10: =IF(H$9="","",'DN02'!$F$35) -> 1 | I10: =IF(I$9="","",'DN02'!$F$35) -> 1 | J10: =IF(J$9="","",'DN04'!$F$35) -> 1 | K10: =IF(K$9="","",'DN05'!$F$35) | L10: =IF(L$9="","",'DN06'!$F$35) | M10: =IF(M$9="","",'DN07'!$F$35) | N10: =IF(N$9="","",'DN08'!$F$35) | O10: =IF(O$9="","",'DN09'!$F$35) | P10: =IF(P$9="","",'DN10'!$F$35) | Q10: =IF(F10="","",SUM(G10:P10)*F10) -> 1600 | T10: =IF(G10="","",VLOOKUP(A10,'ET Standar Price List'!A:M,4,0)) -> B787
A11: 51 | B11: M | D11: =D10+1 -> 2 | E11: Van Trip | F11: {=_xlfn.XLOOKUP($A11,'ET Standar Price List'!$A:$A,_xlfn.SWITCH($T$4,1,'ET Standar Price List'!$G:$G,2,'ET Standar Price List'!$J:$J,3,'ET Standar Price List'!$M:$M),"XX")} -> 200 | G11: =IF(G$9="","",'DN01'!$F$36) -> 1 | H11: =IF(H$9="","",'DN02'!$F$36) -> 1 | I11: =IF(I$9="","",'DN02'!$F$36) -> 1 | J11: =IF(J$9="","",'DN04'!$F$36) -> 1 | K11: =IF(K$9="","",'DN05'!$F$36) | L11: =IF(L$9="","",'DN06'!$F$36) | M11: =IF(M$9="","",'DN07'!$F$36) | N11: =IF(N$9="","",'DN08'!$F$36) | O11: =IF(O$9="","",'DN09'!$F$36) | P11: =IF(P$9="","",'DN10'!$F$36) | Q11: =IF(F11="","",SUM(G11:P11)*F11) -> 800 | T11: =IF(G11="","",VLOOKUP(A11,'ET Standar Price List'!A:M,4,0)) -> Van Trip
A12: 52 | B12: M | D12: 3 | E12: Custom Clearance Charge | F12: {=_xlfn.XLOOKUP($A12,'ET Standar Price List'!$A:$A,_xlfn.SWITCH($T$4,1,'ET Standar Price List'!$G:$G,2,'ET Standar Price List'!$J:$J,3,'ET Standar Price List'!$M:$M),"XX")} -> 250 | G12: 0 | H12: 0 | I12: 0 | J12: 0 | K12: 0 | L12: 0 | M12: 0 | N12: 0 | O12: 0 | P12: 0 | Q12: =IF(F12="","",SUM(G12:P12)*F12) -> 0 | T12: =IF(G12="","",VLOOKUP(A12,'ET Standar Price List'!A:M,4,0)) -> Custom Clearance Chrg
A13: 54 | B13: M | D13: 4 | E13: LAUNDARY CHARGES (per kg) | F13: {=_xlfn.XLOOKUP($A13,'ET Standar Price List'!$A:$A,_xlfn.SWITCH($T$4,1,'ET Standar Price List'!$G:$G,2,'ET Standar Price List'!$J:$J,3,'ET Standar Price List'!$M:$M),"XX")} -> 200 | G13: =IF(G$9="","",'DN01'!$F$34) -> 0.5 | H13: =IF(H$9="","",'DN01'!$F$34) -> 0.5 | I13: =IF(I$9="","",'DN01'!$F$34) -> 0.5 | J13: =IF(J$9="","",'DN01'!$F$34) -> 0.5 | K13: =IF(K$9="","",'DN01'!$F$34) | L13: =IF(L$9="","",'DN01'!$F$34) | M13: =IF(M$9="","",'DN01'!$F$34) | N13: =IF(N$9="","",'DN01'!$F$34) | ... P13: =IF(P$9="","",'DN01'!$F$34) | Q13: =IF(F13="","",SUM(G13:P13)*F13) -> 400 | T13: =IF(G13="","",VLOOKUP(A13,'ET Standar Price List'!A:M,4,0)) -> Linen Napkin (Laundry Items are charged per KG
A14: 55 | B14: M | D14: 5 | E14: INTERNATIONAL TRASH REMOVAL | F14: {=_xlfn.XLOOKUP($A14,'ET Standar Price List'!$A:$A,_xlfn.SWITCH($T$4,1,'ET Standar Price List'!$G:$G,2,'ET Standar Price List'!$J:$J,3,'ET Standar Price List'!$M:$M),"XX")} -> 350 | G14: =IF(G$9="","",'DN01'!$F$37) -> 1 | H14: =IF(H$9="","",'DN01'!$F$37) -> 1 | I14: =IF(I$9="","",'DN01'!$F$37) -> 1 | J14: =IF(J$9="","",'DN01'!$F$37) -> 1 | K14: =IF(K$9="","",'DN01'!$F$37) | L14: =IF(L$9="","",'DN01'!$F$37) | M14: =IF(M$9="","",'DN01'!$F$37) | N14: =IF(N$9="","",'DN01'!$F$37) | ... P14: =IF(P$9="","",'DN01'!$F$37) | Q14: =IF(F14=" "," ",SUM(G14:P14)*F14) -> 1400 | T14: =IF(G14="","",VLOOKUP(A14,'ET Standar Price List'!A:M,4,0)) -> 0
A15: 14 | B15: F17 | D15: 6 | E15: ="CYC "&T4&" BC LCH/DNR" -> CYC 3 BC LCH/DNR | F15: {=_xlfn.XLOOKUP($A15,'ET Standar Price List'!$A:$A,_xlfn.SWITCH($T$4,1,'ET Standar Price List'!$G:$G,2,'ET Standar Price List'!$J:$J,3,'ET Standar Price List'!$M:$M),"XX")} -> 29.315022 | G15: =MAX(IF(G$9="","",'DN01'!$F$14+'DN01'!$J$25-3),32) -> 33 | H15: =MAX(IF(H$9="","",'DN02'!$F$14+'DN02'!$J$25-3),32) -> 36 | I15: =MAX(IF(I$9="","",'DN03'!$F$14+'DN03'!$J$25-3),32) -> 33 | J15: =MAX(IF(J$9="","",'DN04'!$F$14+'DN04'!$J$25-3),32) -> 36 | K15: =IF(K$9="","",'DN05'!$F$14+'DN05'!$J$25-3) | L15: =IF(L$9="","",'DN06'!$F$14+'DN06'!$J$25-3) | M15: =IF(M$9="","",'DN07'!$F$14+'DN07'!$J$25-3) | N15: =IF(N$9="","",'DN08'!$F$14+'DN08'!$J$25-3) | O15: =IF(O$9="","",'DN09'!$F$14+'DN09'!$J$25-3) | P15: =IF(P$9="","",'DN10'!$F$14+'DN10'!$J$25-3) | Q15: =IF(F15="","",SUM(G15:P15)*F15) -> 4045.4731 | T15: =IF(G15="","",VLOOKUP(A15,'ET Standar Price List'!A:M,4,0)) -> BC LCH/DNR Price per passenger Total
A16: 16 | B16: F29 | D16: 7 | E16: Fruit Platter (Std ) | F16: {=_xlfn.XLOOKUP($A16,'ET Standar Price List'!$A:$A,_xlfn.SWITCH($T$4,1,'ET Standar Price List'!$G:$G,2,'ET Standar Price List'!$J:$J,3,'ET Standar Price List'!$M:$M),"XX")} -> 16.605 | G16: =IF(G$9="","",1) -> 1 | H16: =IF(H$9="","",1) -> 1 | I16: =IF(I$9="","",1) -> 1 | J16: =IF(J$9="","",1) -> 1 | K16: 0 | L16: =IF(L$9="","",1) | M16: =IF(M$9="","",1) | N16: =IF(N$9="","",1) | O16: =IF(O$9="","",1) | P16: =IF(P$9="","",1) | Q16: =IF(F16="","",SUM(G16:P16)*F16) -> 66.42 | T16: =IF(G16="","",VLOOKUP(A16,'ET Standar Price List'!A:M,4,0)) -> Fruit Platter (STD ) =18 pieces
A17: 18 | B17: F32 | D17: 8 | E17: Garlic Bread (Std) | F17: {=_xlfn.XLOOKUP($A17,'ET Standar Price List'!$A:$A,_xlfn.SWITCH($T$4,1,'ET Standar Price List'!$G:$G,2,'ET Standar Price List'!$J:$J,3,'ET Standar Price List'!$M:$M),"XX")} -> 6.75 | G17: =IF(G$9="","",'DN01'!$F$32) -> 1 | H17: =IF(H$9="","",'DN02'!$F$32) -> 2 | I17: =IF(I$9="","",'DN03'!$F$32) -> 2 | J17: =IF(J$9="","",'DN04'!$F$32) -> 1 | K17: =IF(K$9="","",'DN05'!$F$32) | L17: =IF(L$9="","",'DN06'!$F$32) | M17: =IF(M$9="","",'DN07'!$F$32) | N17: =IF(N$9="","",'DN08'!$F$32) | O17: =IF(O$9="","",'DN09'!$F$32) | P17: =IF(P$9="","",'DN10'!$F$32) | Q17: =IF(F17="","",SUM(G17:P17)*F17) -> 40.5 | T17: =IF(G17="","",VLOOKUP(A17,'ET Standar Price List'!A:M,4,0)) -> Garlic Bread 1 OF 10 PCS
A18: 21 | B18: F30 | D18: 9 | E18: Cheese Tray (Std) | F18: {=_xlfn.XLOOKUP($A18,'ET Standar Price List'!$A:$A,_xlfn.SWITCH($T$4,1,'ET Standar Price List'!$G:$G,2,'ET Standar Price List'!$J:$J,3,'ET Standar Price List'!$M:$M),"XX")} -> 26.941556 | G18: =IF(G$9="","",'DN01'!$F$30) -> 1 | H18: =IF(H$9="","",'DN02'!$F$30) -> 2 | I18: =IF(I$9="","",'DN03'!$F$30) -> 2 | J18: =IF(J$9="","",'DN04'!$F$30) -> 2 | K18: =IF(K$9="","",'DN05'!$F$30) | L18: =IF(L$9="","",'DN06'!$F$30) | M18: =IF(M$9="","",'DN07'!$F$30) | N18: =IF(N$9="","",'DN08'!$F$30) | O18: =IF(O$9="","",'DN09'!$F$30) | P18: =IF(P$9="","",'DN10'!$F$30) | Q18: =IF(F18="","",SUM(G18:P18)*F18) -> 188.59089 | T18: =IF(G18="","",VLOOKUP(A18,'ET Standar Price List'!A:M,4,0)) -> Cheese Tray
A19: 17 | B19: F31 | D19: =D18+1 -> 10 | E19: 2L Fresh OJ (Std) | F19: {=_xlfn.XLOOKUP($A19,'ET Standar Price List'!$A:$A,_xlfn.SWITCH($T$4,1,'ET Standar Price List'!$G:$G,2,'ET Standar Price List'!$J:$J,3,'ET Standar Price List'!$M:$M),"XX")} -> 6.53 | G19: =IF(G$9="","",'DN01'!$F$31) -> 1 | H19: =IF(H$9="","",'DN02'!$F$31) -> 1 | I19: =IF(I$9="","",'DN03'!$F$31) -> 3 | J19: =IF(J$9="","",'DN04'!$F$31) -> 1 | K19: =IF(K$9="","",'DN05'!$F$31) | L19: =IF(L$9="","",'DN06'!$F$31) | M19: =IF(M$9="","",'DN07'!$F$31) | N19: =IF(N$9="","",'DN08'!$F$31) | O19: =IF(O$9="","",'DN09'!$F$31) | P19: =IF(P$9="","",'DN10'!$F$31) | Q19: =IF(F19="","",SUM(G19:P19)*F19) -> 39.18 | T19: =IF(G19="","",VLOOKUP(A19,'ET Standar Price List'!A:M,4,0)) -> 1L Fresh OJ (1-8)
A20: 19 | B20: M | D20: 11 | E20: Fresh Milk (Std) | F20: {=_xlfn.XLOOKUP($A20,'ET Standar Price List'!$A:$A,_xlfn.SWITCH($T$4,1,'ET Standar Price List'!$G:$G,2,'ET Standar Price List'!$J:$J,3,'ET Standar Price List'!$M:$M),"XX")} -> 5.85 | G20: =IF(G$9="","",1) -> 1 | H20: =IF(H$9="","",1) -> 1 | I20: =IF(I$9="","",1) -> 1 | J20: =IF(J$9="","",1) -> 1 | K20: =IF(K$9="","",1) | L20: =IF(L$9="","",1) | M20: =IF(M$9="","",1) | N20: =IF(N$9="","",1) | ... P20: =IF(P$9="","",1) | Q20: =IF(F20="","",SUM(G20:P20)*F20) -> 23.4 | T20: =IF(G20="","",VLOOKUP(A20,'ET Standar Price List'!A:M,4,0)) -> FRESH MILK
A21: 20 | B21: M | D21: 12 | E21: Condiments and Chocolate (Std) | F21: {=_xlfn.XLOOKUP($A21,'ET Standar Price List'!$A:$A,_xlfn.SWITCH($T$4,1,'ET Standar Price List'!$G:$G,2,'ET Standar Price List'!$J:$J,3,'ET Standar Price List'!$M:$M),"XX")} -> 1.8 | G21: =IF(G$9="","",1) -> 1 | H21: =IF(H$9="","",1) -> 1 | I21: =IF(I$9="","",1) -> 1 | J21: =IF(J$9="","",1) -> 1 | K21: =IF(K$9="","",1) | L21: =IF(L$9="","",1) | M21: =IF(M$9="","",1) | N21: =IF(N$9="","",1) | ... P21: =IF(P$9="","",1) | Q21: =IF(F21="","",SUM(G21:P21)*F21) -> 7.2 | T21: =IF(G21="","",VLOOKUP(A21,'ET Standar Price List'!A:M,4,0)) -> CONDIMENTS AND CHOCOLATE
A22: 78 | B22: F16 | D22: 13 | E22: BC HBF | F22: {=_xlfn.XLOOKUP($A22,'ET Standar Price List'!$A:$A,_xlfn.SWITCH($T$4,1,'ET Standar Price List'!$G:$G,2,'ET Standar Price List'!$J:$J,3,'ET Standar Price List'!$M:$M),"XX")} -> 18.906477 | G22: =MAX(IF(G$9="","",'DN01'!$F$13+'DN01'!$J$25-3),32) -> 33 | H22: =MAX(IF(H$9="","",'DN02'!$F$13+'DN02'!$J$25-3),32) -> 36 | I22: =MAX(IF(I$9="","",'DN03'!$F$13+'DN03'!$J$25-3),32) -> 33 | J22: =MAX(IF(J$9="","",'DN04'!$F$13+'DN04'!$J$25-3),32) -> 36 | K22: =IF(K$9="","",'DN05'!$F$13+'DN05'!$J$25-3) | L22: =IF(L$9="","",'DN06'!$F$13+'DN06'!$J$25-3) | M22: =IF(M$9="","",'DN07'!$F$13+'DN07'!$J$25-3) | N22: =IF(N$9="","",'DN08'!$F$13+'DN08'!$J$25-3) | O22: =IF(O$9="","",'DN09'!$F$13+'DN09'!$J$25-3) | P22: =IF(P$9="","",'DN10'!$F$13+'DN10'!$J$25-3) | Q22: =IF(F22="","",SUM(G22:P22)*F22) -> 2609.0938 | T22: =IF(G22="","",VLOOKUP(A22,'ET Standar Price List'!A:M,4,0)) -> BC HBF Price per passenger Total
A23: 98 | B23: F19 | D23: =D22+1 -> 14 | E23: ="CYC "&T4&" BC HCP" -> CYC 3 BC HCP | F23: {=_xlfn.XLOOKUP($A23,'ET Standar Price List'!$A:$A,_xlfn.SWITCH($T$4,1,'ET Standar Price List'!$G:$G,2,'ET Standar Price List'!$J:$J,3,'ET Standar Price List'!$M:$M),"XX")} -> 8.7645188 | G23: =MAX(IF(G$9="","",'DN01'!$F$16+'DN01'!$J$25-3),32) -> 33 | H23: =MAX(IF(H$9="","",'DN02'!$F$16+'DN02'!$J$25-3),32) -> 36 | I23: =MAX(IF(I$9="","",'DN03'!$F$16+'DN03'!$J$25-3),32) -> 33 | J23: =MAX(IF(J$9="","",'DN04'!$F$16+'DN04'!$J$25-3),32) -> 36 | K23: =IF(K$9="","",'DN05'!$F$16+'DN05'!$J$25-3) | L23: =IF(L$9="","",'DN06'!$F$16+'DN06'!$J$25-3) | M23: =IF(M$9="","",'DN07'!$F$16+'DN07'!$J$25-3) | N23: =IF(N$9="","",'DN08'!$F$16+'DN08'!$J$25-3) | O23: =IF(O$9="","",'DN09'!$F$16+'DN09'!$J$25-3) | P23: =IF(P$9="","",'DN10'!$F$16+'DN10'!$J$25-3) | Q23: =IF(F23="","",SUM(G23:P23)*F23) -> 1209.5036 | T23: =IF(G23="","",VLOOKUP(A23,'ET Standar Price List'!A:M,4,0)) -> BC HCP Per passenger Charge Total
A24: 14 | B24: XX | D24: 15 | E24: Xtra BC Fasting Meals | F24: {=_xlfn.XLOOKUP($A24,'ET Standar Price List'!$A:$A,_xlfn.SWITCH($T$4,1,'ET Standar Price List'!$G:$G,2,'ET Standar Price List'!$J:$J,3,'ET Standar Price List'!$M:$M),"XX")} -> 29.315022 | G24: =IF(G$9="","",'DN01'!$F$20) -> 0 | H24: =IF(H$9="","",'DN02'!$F$20) -> 0 | I24: =IF(I$9="","",'DN03'!$F$20) -> 0 | J24: =IF(J$9="","",'DN04'!$F$20) -> 0 | K24: =IF(K$9="","",'DN05'!$F$20) | L24: =IF(L$9="","",'DN06'!$F$20) | M24: =IF(M$9="","",'DN07'!$F$20) | N24: =IF(N$9="","",'DN08'!$F$20) | O24: =IF(O$9="","",'DN09'!$F$20) | P24: =IF(P$9="","",'DN10'!$F$20) | Q24: =IF(F24="","",SUM(G24:P24)*F24) -> 0
A25: 39 | B25: F33 | D25: =D24+1 -> 16 | E25: STANDARD UP LIFT | F25: {=_xlfn.XLOOKUP($A25,'ET Standar Price List'!$A:$A,_xlfn.SWITCH($T$4,1,'ET Standar Price List'!$G:$G,2,'ET Standar Price List'!$J:$J,3,'ET Standar Price List'!$M:$M),"XX")} -> 15.62 | G25: =IF(G$9="","",'DN01'!$F$33) -> 1 | H25: =IF(H$9="","",'DN02'!$F$33) -> 1 | I25: =IF(I$9="","",'DN03'!$F$33) -> 1 | J25: =IF(J$9="","",'DN04'!$F$33) -> 1 | K25: =IF(K$9="","",'DN05'!$F$33) | L25: =IF(L$9="","",'DN06'!$F$33) | M25: =IF(M$9="","",'DN07'!$F$33) | N25: =IF(N$9="","",'DN08'!$F$33) | O25: =IF(O$9="","",'DN09'!$F$33) | P25: =IF(P$9="","",'DN10'!$F$33) | Q25: =IF(F25="","",SUM(G25:P25)*F25) -> 62.48 | T25: =IF(G25="","",VLOOKUP(A25,'ET Standar Price List'!A:M,4,0)) -> Standard Uplift Total Price
A26: 41 | B26: ** | D26: 17 | E26: ALL IATA BC SPML (NO KSML) DNR | F26: {=_xlfn.XLOOKUP($A26,'ET Standar Price List'!$A:$A,_xlfn.SWITCH($T$4,1,'ET Standar Price List'!$G:$G,2,'ET Standar Price List'!$J:$J,3,'ET Standar Price List'!$M:$M),"XX")} -> 25.34 | G26: =IF(G$9="","",('DN01'!$J$25)-G28) -> 2 | H26: =IF(H$9="","",('DN02'!$J$25)-H28) -> 3 | I26: =IF(I$9="","",('DN03'!$J$25)-I28) -> 0 | J26: =IF(J$9="","",('DN04'!$J$25)-J28) -> 1 | K26: =IF(K$9="","",('DN01'!$J$25)-K28) | L26: =IF(L$9="","",('DN01'!$J$25)-L28) | M26: =IF(M$9="","",('DN01'!$J$25)-M28) | N26: =IF(N$9="","",('DN01'!$J$25)-N28) | O26: =IF(O$9="","",('DN01'!$J$25)-O28) | P26: =IF(P$9="","",('DN01'!$J$25)-P28) | Q26: =IF(F26="","",SUM(G26:P26)*F26) -> 152.04 | T26: =IF(G26="","",VLOOKUP(A26,'ET Standar Price List'!A:M,4,0)) -> ALL IATA BC SPML (NO KSML)
A27: 45 | B27: ** | D27: =D26+1 -> 18 | E27: ALL IATA BC SPML (NO KSML) : HBF | F27: {=_xlfn.XLOOKUP($A27,'ET Standar Price List'!$A:$A,_xlfn.SWITCH($T$4,1,'ET Standar Price List'!$G:$G,2,'ET Standar Price List'!$J:$J,3,'ET Standar Price List'!$M:$M),"XX")} -> 19.98 | G27: =IF(G$9="","",('DN01'!$N$25)-G28) -> 2 | H27: =IF(H$9="","",('DN02'!$N$25)-H28) -> 3 | I27: =IF(I$9="","",('DN03'!$N$25)-I28) -> 0 | J27: =IF(J$9="","",('DN04'!$N$25)-J28) -> 1 | K27: =IF(K$9="","",('DN01'!$N$25)-K28) | L27: =IF(L$9="","",('DN01'!$N$25)-L28) | M27: =IF(M$9="","",('DN01'!$N$25)-M28) | N27: =IF(N$9="","",('DN01'!$N$25)-N28) | O27: =IF(O$9="","",('DN01'!$N$25)-O28) | P27: =IF(P$9="","",('DN01'!$N$25)-P28) | Q27: =IF(F27="","",SUM(G27:P27)*F27) -> 119.88 | T27: =IF(G27="","",VLOOKUP(A27,'ET Standar Price List'!A:M,4,0)) -> ALL IATA BC SPML (NO KSML) HBF
A28: 43 | B28: ** | D28: =D27+1 -> 19 | E28: KSML BC | F28: {=_xlfn.XLOOKUP($A28,'ET Standar Price List'!$A:$A,_xlfn.SWITCH($T$4,1,'ET Standar Price List'!$G:$G,2,'ET Standar Price List'!$J:$J,3,'ET Standar Price List'!$M:$M),"XX")} -> 50 | G28: =IF(G$9="","",SUMIFS('DN01'!$J$12:$J$24,'DN01'!$I$12:$I$24,"KSML")+SUMIFS('DN01'!$L$12:$L$24,'DN01'!$I$12:$I$24,"KSML")+SUMIFS('DN01'!$N$12:$N$24,'DN01'!$I$12:$I$24,"KSML")) -> 0 | H28: =IF(H$9="","",SUMIFS('DN02'!$J$12:$J$24,'DN02'!$I$12:$I$24,"KSML")+SUMIFS('DN02'!$L$12:$L$24,'DN02'!$I$12:$I$24,"KSML")+SUMIFS('DN02'!$N$12:$N$24,'DN02'!$I$12:$I$24,"KSML")) -> 0 | I28: =IF(I$9="","",SUMIFS('DN03'!$J$12:$J$24,'DN03'!$I$12:$I$24,"KSML")+SUMIFS('DN03'!$L$12:$L$24,'DN03'!$I$12:$I$24,"KSML")+SUMIFS('DN03'!$N$12:$N$24,'DN03'!$I$12:$I$24,"KSML")) -> 0 | J28: =IF(J$9="","",SUMIFS('DN04'!$J$12:$J$24,'DN04'!$I$12:$I$24,"KSML")+SUMIFS('DN04'!$L$12:$L$24,'DN04'!$I$12:$I$24,"KSML")+SUMIFS('DN04'!$N$12:$N$24,'DN04'!$I$12:$I$24,"KSML")) -> 0 | K28: =IF(K$9="","",SUMIFS('DN05'!$J$12:$J$24,'DN05'!$I$12:$I$24,"KSML")+SUMIFS('DN05'!$L$12:$L$24,'DN05'!$I$12:$I$24,"KSML")+SUMIFS('DN05'!$N$12:$N$24,'DN05'!$I$12:$I$24,"KSML")) | L28: =IF(L$9="","",SUMIFS('DN06'!$J$12:$J$24,'DN06'!$I$12:$I$24,"KSML")+SUMIFS('DN06'!$L$12:$L$24,'DN06'!$I$12:$I$24,"KSML")+SUMIFS('DN06'!$N$12:$N$24,'DN06'!$I$12:$I$24,"KSML")) | M28: =IF(M$9="","",SUMIFS('DN07'!$J$12:$J$24,'DN07'!$I$12:$I$24,"KSML")+SUMIFS('DN07'!$L$12:$L$24,'DN07'!$I$12:$I$24,"KSML")+SUMIFS('DN07'!$N$12:$N$24,'DN07'!$I$12:$I$24,"KSML")) | N28: =IF(N$9="","",SUMIFS('DN08'!$J$12:$J$24,'DN08'!$I$12:$I$24,"KSML")+SUMIFS('DN08'!$L$12:$L$24,'DN08'!$I$12:$I$24,"KSML")+SUMIFS('DN08'!$N$12:$N$24,'DN08'!$I$12:$I$24,"KSML")) | O28: =IF(O$9="","",SUMIFS('DN09'!$J$12:$J$24,'DN09'!$I$12:$I$24,"KSML")+SUMIFS('DN09'!$L$12:$L$24,'DN09'!$I$12:$I$24,"KSML")+SUMIFS('DN09'!$N$12:$N$24,'DN09'!$I$12:$I$24,"KSML")) | P28: =IF(P$9="","",SUMIFS('DN10'!$J$12:$J$24,'DN10'!$I$12:$I$24,"KSML")+SUMIFS('DN10'!$L$12:$L$24,'DN10'!$I$12:$I$24,"KSML")+SUMIFS('DN10'!$N$12:$N$24,'DN10'!$I$12:$I$24,"KSML")) | Q28: =IF(F28="","",SUM(G28:P28)*F28) -> 0 | T28: =IF(G28="","",VLOOKUP(A28,'ET Standar Price List'!A:M,4,0)) -> KSML BC LCH/DNR
A29: 47 | B29: ** | D29: =D28+1 -> 20 | E29: KSML HBF | F29: {=_xlfn.XLOOKUP($A29,'ET Standar Price List'!$A:$A,_xlfn.SWITCH($T$4,1,'ET Standar Price List'!$G:$G,2,'ET Standar Price List'!$J:$J,3,'ET Standar Price List'!$M:$M),"XX")} -> 45 | G29: =IF(G$9="","",SUMIFS('DN01'!$J$12:$J$24,'DN01'!$I$12:$I$24,"KSML")+SUMIFS('DN01'!$L$12:$L$24,'DN01'!$I$12:$I$24,"KSML")+SUMIFS('DN01'!$N$12:$N$24,'DN01'!$I$12:$I$24,"KSML")) -> 0 | H29: =IF(H$9="","",SUMIFS('DN02'!$J$12:$J$24,'DN02'!$I$12:$I$24,"KSML")+SUMIFS('DN02'!$L$12:$L$24,'DN02'!$I$12:$I$24,"KSML")+SUMIFS('DN02'!$N$12:$N$24,'DN02'!$I$12:$I$24,"KSML")) -> 0 | I29: =IF(I$9="","",SUMIFS('DN03'!$J$12:$J$24,'DN03'!$I$12:$I$24,"KSML")+SUMIFS('DN03'!$L$12:$L$24,'DN03'!$I$12:$I$24,"KSML")+SUMIFS('DN03'!$N$12:$N$24,'DN03'!$I$12:$I$24,"KSML")) -> 0 | J29: =IF(J$9="","",SUMIFS('DN04'!$J$12:$J$24,'DN04'!$I$12:$I$24,"KSML")+SUMIFS('DN04'!$L$12:$L$24,'DN04'!$I$12:$I$24,"KSML")+SUMIFS('DN04'!$N$12:$N$24,'DN04'!$I$12:$I$24,"KSML")) -> 0 | K29: =IF(K$9="","",SUMIFS('DN05'!$J$12:$J$24,'DN05'!$I$12:$I$24,"KSML")+SUMIFS('DN05'!$L$12:$L$24,'DN05'!$I$12:$I$24,"KSML")+SUMIFS('DN05'!$N$12:$N$24,'DN05'!$I$12:$I$24,"KSML")) | L29: =IF(L$9="","",SUMIFS('DN06'!$J$12:$J$24,'DN06'!$I$12:$I$24,"KSML")+SUMIFS('DN06'!$L$12:$L$24,'DN06'!$I$12:$I$24,"KSML")+SUMIFS('DN06'!$N$12:$N$24,'DN06'!$I$12:$I$24,"KSML")) | M29: =IF(M$9="","",SUMIFS('DN07'!$J$12:$J$24,'DN07'!$I$12:$I$24,"KSML")+SUMIFS('DN07'!$L$12:$L$24,'DN07'!$I$12:$I$24,"KSML")+SUMIFS('DN07'!$N$12:$N$24,'DN07'!$I$12:$I$24,"KSML")) | N29: =IF(N$9="","",SUMIFS('DN08'!$J$12:$J$24,'DN08'!$I$12:$I$24,"KSML")+SUMIFS('DN08'!$L$12:$L$24,'DN08'!$I$12:$I$24,"KSML")+SUMIFS('DN08'!$N$12:$N$24,'DN08'!$I$12:$I$24,"KSML")) | O29: =IF(O$9="","",SUMIFS('DN09'!$J$12:$J$24,'DN09'!$I$12:$I$24,"KSML")+SUMIFS('DN09'!$L$12:$L$24,'DN09'!$I$12:$I$24,"KSML")+SUMIFS('DN09'!$N$12:$N$24,'DN09'!$I$12:$I$24,"KSML")) | P29: =IF(P$9="","",SUMIFS('DN10'!$J$12:$J$24,'DN10'!$I$12:$I$24,"KSML")+SUMIFS('DN10'!$L$12:$L$24,'DN10'!$I$12:$I$24,"KSML")+SUMIFS('DN10'!$N$12:$N$24,'DN10'!$I$12:$I$24,"KSML")) | Q29: =IF(F29="","",SUM(G29:P29)*F29) -> 0
A30: 33 | B30: G17 | D30: =D29+1 -> 21 | E30: ="CYC "&T4&" EY LCH/DNR" -> CYC 3 EY LCH/DNR | F30: {=_xlfn.XLOOKUP($A30,'ET Standar Price List'!$A:$A,_xlfn.SWITCH($T$4,1,'ET Standar Price List'!$G:$G,2,'ET Standar Price List'!$J:$J,3,'ET Standar Price List'!$M:$M),"XX")} -> 14.381359 | G30: =MAX(IF(G$9="","",'DN01'!$G$14+'DN01'!$K$25-10),125) -> 235 | H30: =MAX(IF(H$9="","",'DN02'!$G$14+'DN02'!$K$25-10),125) -> 240 | I30: =MAX(IF(I$9="","",'DN03'!$G$14+'DN03'!$K$25-10),125) -> 230 | J30: =MAX(IF(J$9="","",'DN04'!$G$14+'DN04'!$K$25-10),125) -> 215 | K30: =IF(K$9="","",'DN05'!$G$14+'DN05'!$K$25-10) | L30: =IF(L$9="","",'DN06'!$G$14+'DN06'!$K$25-10) | M30: =IF(M$9="","",'DN07'!$G$14+'DN07'!$K$25-10) | N30: =IF(N$9="","",'DN08'!$G$14+'DN08'!$K$25-10) | O30: =IF(O$9="","",'DN09'!$G$14+'DN09'!$K$25-10) | P30: =IF(P$9="","",'DN10'!$G$14+'DN10'!$K$25-10) | Q30: =IF(F30="","",SUM(G30:P30)*F30) -> 13230.85 | T30: =IF(G30="","",VLOOKUP(A30,'ET Standar Price List'!A:M,4,0)) -> EY LCH/DNR Price per passenger Total
A31: 88 | B31: G16 | D31: =D30+1 -> 22 | E31: EY HBF | F31: {=_xlfn.XLOOKUP($A31,'ET Standar Price List'!$A:$A,_xlfn.SWITCH($T$4,1,'ET Standar Price List'!$G:$G,2,'ET Standar Price List'!$J:$J,3,'ET Standar Price List'!$M:$M),"XX")} -> 11.50308 | G31: =MAX(IF(G$9="","",'DN01'!$G$13+'DN01'!$K$25-10),125) -> 235 | H31: =MAX(IF(H$9="","",'DN02'!$G$13+'DN02'!$K$25-10),125) -> 240 | I31: =MAX(IF(I$9="","",'DN03'!$G$13+'DN03'!$K$25-10),125) -> 230 | J31: =MAX(IF(J$9="","",'DN04'!$G$13+'DN04'!$K$25-10),125) -> 215 | K31: =IF(K$9="","",'DN05'!$G$13+'DN05'!$K$25-10) | L31: =IF(L$9="","",'DN06'!$G$13+'DN06'!$K$25-10) | M31: =IF(M$9="","",'DN07'!$G$13+'DN07'!$K$25-10) | N31: =IF(N$9="","",'DN08'!$G$13+'DN08'!$K$25-10) | O31: =IF(O$9="","",'DN09'!$G$13+'DN09'!$K$25-10) | P31: =IF(P$9="","",'DN10'!$G$13+'DN10'!$K$25-10) | Q31: =IF(F31="","",SUM(G31:P31)*F31) -> 10582.833 | T31: =IF(G31="","",VLOOKUP(A31,'ET Standar Price List'!A:M,4,0)) -> EY HBF Price per passenger Total
A32: 105 | B32: G20 | D32: =D31+1 -> 23 | E32: EY SWH | F32: {=_xlfn.XLOOKUP($A32,'ET Standar Price List'!$A:$A,_xlfn.SWITCH($T$4,1,'ET Standar Price List'!$G:$G,2,'ET Standar Price List'!$J:$J,3,'ET Standar Price List'!$M:$M),"XX")} -> 2.4031838 | G32: =MAX(IF(G$9="","",'DN01'!$G$17+'DN01'!$K$25-10),125) -> 235 | H32: =MAX(IF(H$9="","",'DN02'!$G$17+'DN02'!$K$25-10),125) -> 240 | I32: =MAX(IF(I$9="","",'DN03'!$G$17+'DN03'!$K$25-10),125) -> 230 | J32: =MAX(IF(J$9="","",'DN04'!$G$17+'DN04'!$K$25-10),125) -> 215 | K32: =IF(K$9="","",'DN05'!$G$17+'DN05'!$K$25-10) | L32: =IF(L$9="","",'DN06'!$G$17+'DN06'!$K$25-10) | M32: =IF(M$9="","",'DN07'!$G$17+'DN07'!$K$25-10) | N32: =IF(N$9="","",'DN08'!$G$17+'DN08'!$K$25-10) | O32: =IF(O$9="","",'DN09'!$G$17+'DN09'!$K$25-10) | P32: =IF(P$9="","",'DN10'!$G$17+'DN10'!$K$25-10) | Q32: =IF(F32="","",SUM(G32:P32)*F32) -> 2210.9291 | T32: =IF(G32="","",VLOOKUP(A32,'ET Standar Price List'!A:M,4,0)) -> EY SWH Per passenger Charge Total
A33: 33 | B33: XX | D33: =D32+1 -> 24 | E33: Xtra EC Fasting Meals | F33: {=_xlfn.XLOOKUP($A33,'ET Standar Price List'!$A:$A,_xlfn.SWITCH($T$4,1,'ET Standar Price List'!$G:$G,2,'ET Standar Price List'!$J:$J,3,'ET Standar Price List'!$M:$M),"XX")} -> 14.381359 | G33: =IF(G$9="","",'DN01'!$G$20) -> 0 | H33: =IF(H$9="","",'DN02'!$G$20) -> 0 | I33: =IF(I$9="","",'DN03'!$G$20) -> 0 | J33: =IF(J$9="","",'DN04'!$G$20) -> 0 | K33: =IF(K$9="","",'DN05'!$G$20) | L33: =IF(L$9="","",'DN06'!$G$20) | M33: =IF(M$9="","",'DN07'!$G$20) | N33: =IF(N$9="","",'DN08'!$G$20) | O33: =IF(O$9="","",'DN09'!$G$20) | P33: =IF(P$9="","",'DN10'!$G$20) | Q33: =IF(F33="","",SUM(G33:P33)*F33) -> 0
A34: 42 | B34: ** | D34: =D33+1 -> 25 | E34: ALL IATA EY SPML (NO KSML) DNR | F34: {=_xlfn.XLOOKUP($A34,'ET Standar Price List'!$A:$A,_xlfn.SWITCH($T$4,1,'ET Standar Price List'!$G:$G,2,'ET Standar Price List'!$J:$J,3,'ET Standar Price List'!$M:$M),"XX")} -> 15.68 | G34: =IF(G$9="","",('DN01'!$K$25)-G36) -> 14 | H34: =IF(H$9="","",('DN02'!$K$25)-H36) -> 11 | I34: =IF(I$9="","",('DN03'!$K$25)-I36) -> 14 | J34: =IF(J$9="","",('DN04'!$K$25)-J36) -> 3 | K34: =IF(K$9="","",('DN01'!$K$25)-K36) | L34: =IF(L$9="","",('DN01'!$K$25)-L36) | M34: =IF(M$9="","",('DN01'!$K$25)-M36) | N34: =IF(N$9="","",('DN01'!$K$25)-N36) | O34: =IF(O$9="","",('DN01'!$K$25)-O36) | P34: =IF(P$9="","",('DN01'!$K$25)-P36) | Q34: =IF(F34="","",SUM(G34:P34)*F34) -> 658.56 | T34: =IF(G34="","",VLOOKUP(A34,'ET Standar Price List'!A:M,4,0)) -> ALL IATA EY SPML (NO KSML)
A35: 46 | B35: ** | D35: =D34+1 -> 26 | E35: ALL IATA EY SPML (NO KSML) HBF | F35: {=_xlfn.XLOOKUP($A35,'ET Standar Price List'!$A:$A,_xlfn.SWITCH($T$4,1,'ET Standar Price List'!$G:$G,2,'ET Standar Price List'!$J:$J,3,'ET Standar Price List'!$M:$M),"XX")} -> 11.35 | G35: =IF(G$9="","",('DN01'!$O$25)-G36) -> 14 | H35: =IF(H$9="","",('DN02'!$O$25)-H36) -> 11 | I35: =IF(I$9="","",('DN03'!$O$25)-I37) -> 14 | J35: =IF(J$9="","",('DN04'!$O$25)-J36) -> 3 | K35: =IF(K$9="","",('DN01'!$O$25)-K36) | L35: =IF(L$9="","",('DN01'!$O$25)-L36) | M35: =IF(M$9="","",('DN01'!$O$25)-M36) | N35: =IF(N$9="","",('DN01'!$O$25)-N36) | O35: =IF(O$9="","",('DN01'!$O$25)-O36) | P35: =IF(P$9="","",('DN01'!$O$25)-P36) | Q35: =IF(F35="","",SUM(G35:P35)*F35) -> 476.7 | T35: =IF(G35="","",VLOOKUP(A35,'ET Standar Price List'!A:M,4,0)) -> ALL IATA EY SPML (NO KSML) HBF
A36: 44 | B36: ** | D36: =D35+1 -> 27 | E36: KSML EY | F36: {=_xlfn.XLOOKUP($A36,'ET Standar Price List'!$A:$A,_xlfn.SWITCH($T$4,1,'ET Standar Price List'!$G:$G,2,'ET Standar Price List'!$J:$J,3,'ET Standar Price List'!$M:$M),"XX")} -> 45 | G36: =IF(G$9="","",SUMIFS('DN01'!$K$12:$K$24,'DN01'!$I$12:$I$24,"KSML")+SUMIFS('DN01'!$M$12:$M$24,'DN01'!$I$12:$I$24,"KSML")) -> 0 | H36: =IF(H$9="","",SUMIFS('DN02'!$K$12:$K$24,'DN02'!$I$12:$I$24,"KSML")+SUMIFS('DN02'!$M$12:$M$24,'DN02'!$I$12:$I$24,"KSML")) -> 0 | I36: =IF(I$9="","",SUMIFS('DN03'!$K$12:$K$24,'DN03'!$I$12:$I$24,"KSML")) -> 1 | J36: =IF(J$9="","",SUMIFS('DN04'!$K$12:$K$24,'DN04'!$I$12:$I$24,"KSML")+SUMIFS('DN04'!$M$12:$M$24,'DN04'!$I$12:$I$24,"KSML")) -> 0 | K36: =IF(K$9="","",SUMIFS('DN05'!$K$12:$K$24,'DN05'!$I$12:$I$24,"KSML")+SUMIFS('DN05'!$M$12:$M$24,'DN05'!$I$12:$I$24,"KSML")+SUMIFS('DN05'!$O$12:$O$24,'DN05'!$I$12:$I$24,"KSML")) | L36: =IF(L$9="","",SUMIFS('DN06'!$K$12:$K$24,'DN06'!$I$12:$I$24,"KSML")+SUMIFS('DN06'!$M$12:$M$24,'DN06'!$I$12:$I$24,"KSML")+SUMIFS('DN06'!$O$12:$O$24,'DN06'!$I$12:$I$24,"KSML")) | M36: =IF(M$9="","",SUMIFS('DN07'!$K$12:$K$24,'DN07'!$I$12:$I$24,"KSML")+SUMIFS('DN07'!$M$12:$M$24,'DN07'!$I$12:$I$24,"KSML")+SUMIFS('DN07'!$O$12:$O$24,'DN07'!$I$12:$I$24,"KSML")) | N36: =IF(N$9="","",SUMIFS('DN08'!$K$12:$K$24,'DN08'!$I$12:$I$24,"KSML")+SUMIFS('DN08'!$M$12:$M$24,'DN08'!$I$12:$I$24,"KSML")+SUMIFS('DN08'!$O$12:$O$24,'DN08'!$I$12:$I$24,"KSML")) | O36: =IF(O$9="","",SUMIFS('DN09'!$K$12:$K$24,'DN09'!$I$12:$I$24,"KSML")+SUMIFS('DN09'!$M$12:$M$24,'DN09'!$I$12:$I$24,"KSML")+SUMIFS('DN09'!$O$12:$O$24,'DN09'!$I$12:$I$24,"KSML")) | P36: =IF(P$9="","",SUMIFS('DN10'!$K$12:$K$24,'DN10'!$I$12:$I$24,"KSML")+SUMIFS('DN10'!$M$12:$M$24,'DN10'!$I$12:$I$24,"KSML")+SUMIFS('DN10'!$O$12:$O$24,'DN10'!$I$12:$I$24,"KSML")) | Q36: =IF(F36="","",SUM(G36:P36)*F36) -> 45 | T36: =IF(G36="","",VLOOKUP(A36,'ET Standar Price List'!A:M,4,0)) -> KSML EY LCH/DNR
A37: 48 | B37: ** | D37: =D36+1 -> 28 | E37: KSML HBF | F37: {=_xlfn.XLOOKUP($A37,'ET Standar Price List'!$A:$A,_xlfn.SWITCH($T$4,1,'ET Standar Price List'!$G:$G,2,'ET Standar Price List'!$J:$J,3,'ET Standar Price List'!$M:$M),"XX")} -> 28 | G37: =IF(G$9="","",SUMIFS('DN01'!$O$12:$O$24,'DN01'!$I$12:$I$24,"KSML")) -> 0 | H37: =IF(H$9="","",SUMIFS('DN02'!$O$12:$O$24,'DN02'!$I$12:$I$24,"KSML")) -> 0 | I37: =IF(I$9="","",SUMIFS('DN03'!$O$12:$O$24,'DN03'!$I$12:$I$24,"KSML")) -> 1 | J37: =IF(J$9="","",SUMIFS('DN04'!$O$12:$O$24,'DN04'!$I$12:$I$24,"KSML")) -> 0 | Q37: =IF(F37="","",SUM(G37:P37)*F37) -> 28
A38: DRY | B38: ITEM | D38: =D37+1 -> 29 | E38: {=_xlfn.UNIQUE(_xlfn._xlws.FILTER(_xlfn.VSTACK('DN01:DN13'!$O$30:$O$51),_xlfn.VSTACK('DN01:DN13'!$N$30:$N$51)<>""))} -> 3013499 - Mineral Water 1.5L | F38: =IF(E38="","",VLOOKUP(E38,'DRY ITEM LIST'!B:F,5,0)) -> 4 | G38: =IF(G$9="","",IF($E38=0,0,_xlfn.XLOOKUP($E38,'DN01'!$O$30:$O$51,'DN01'!$N$30:$N$51,0)+IF(LEFT(E38,7)="3013522",-2,0))) -> 100 | H38: =IF(H$9="","",IF($E38=0,0,_xlfn.XLOOKUP($E38,'DN02'!$O$30:$O$51,'DN02'!$N$30:$N$51,0)+IF(LEFT(E38,7)="3013522",-2,0))) -> 36 | I38: =IF(I$9="","",IF($E38=0,0,_xlfn.XLOOKUP($E38,'DN03'!$O$30:$O$51,'DN03'!$N$30:$N$51,0)+IF(LEFT(E38,7)="3013522",-2,0))) -> 48 | J38: =IF(J$9="","",IF($E38=0,0,_xlfn.XLOOKUP($E38,'DN04'!$O$30:$O$51,'DN04'!$N$30:$N$51,0)+IF(LEFT(E38,7)="3013522",-2,0))) -> 90 | K38: =IF(K$9="","",IF($E38=0,0,_xlfn.XLOOKUP($E38,'DN05'!$O$30:$O$51,'DN05'!$N$30:$N$51,0)+IF(LEFT(E38,7)="3013522",-2,0))) | L38: =IF(L$9="","",IF($E38=0,0,_xlfn.XLOOKUP($E38,'DN06'!$O$30:$O$51,'DN06'!$N$30:$N$51,0)+IF(LEFT(E38,7)="3013522",-2,0))) | M38: =IF(M$9="","",IF($E38=0,0,_xlfn.XLOOKUP($E38,'DN07'!$O$30:$O$51,'DN07'!$N$30:$N$51,0)+IF(LEFT(F38,7)="3013522",-2,0))) | N38: =IF(N$9="","",IF($E38=0,0,_xlfn.XLOOKUP($E38,'DN08'!$O$30:$O$51,'DN08'!$N$30:$N$51,0)+IF(LEFT(G38,7)="3013522",-2,0))) | O38: =IF(O$9="","",IF($E38=0,0,_xlfn.XLOOKUP($E38,'DN09'!$O$30:$O$51,'DN09'!$N$30:$N$51,0)+IF(LEFT(H38,7)="3013522",-2,0))) | P38: =IF(P$9="","",IF($E38=0,0,_xlfn.XLOOKUP($E38,'DN10'!$O$30:$O$49,'DN10'!$N$30:$N$49,0)+IF(LEFT(I38,7)="3013522",-2,0))) | Q38: =IF(F38="","",SUM(G38:P38)*F38) -> 1096 | W38: 20 | X38: 3013506 - Juice Apple 1L | Y38: 18 | Z38: 5 | AA38: 90
A39: DRY | B39: ITEM | D39: =D38+1 -> 30 | E39: 3013498 - Mineral Water 330mL | F39: =IF(E39="","",VLOOKUP(E39,'DRY ITEM LIST'!B:F,5,0)) -> 2 | G39: =IF(G$9="","",IF($E39=0,0,_xlfn.XLOOKUP($E39,'DN01'!$O$30:$O$51,'DN01'!$N$30:$N$51,0)+IF(LEFT(E39,7)="3013522",-2,0))) -> 72 | H39: =IF(H$9="","",IF($E39=0,0,_xlfn.XLOOKUP($E39,'DN02'!$O$30:$O$51,'DN02'!$N$30:$N$51,0)+IF(LEFT(E39,7)="3013522",-2,0))) -> 48 | I39: =IF(I$9="","",IF($E39=0,0,_xlfn.XLOOKUP($E39,'DN03'!$O$30:$O$51,'DN03'!$N$30:$N$51,0)+IF(LEFT(E39,7)="3013522",-2,0))) -> 24 | J39: =IF(J$9="","",IF($E39=0,0,_xlfn.XLOOKUP($E39,'DN04'!$O$30:$O$51,'DN04'!$N$30:$N$51,0)+IF(LEFT(E39,7)="3013522",-2,0))) -> 36 | K39: =IF(K$9="","",IF($E39=0,0,_xlfn.XLOOKUP($E39,'DN05'!$O$30:$O$51,'DN05'!$N$30:$N$51,0)+IF(LEFT(E39,7)="3013522",-2,0))) | L39: =IF(L$9="","",IF($E39=0,0,_xlfn.XLOOKUP($E39,'DN06'!$O$30:$O$51,'DN06'!$N$30:$N$51,0)+IF(LEFT(E39,7)="3013522",-2,0))) | M39: =IF(M$9="","",IF($E39=0,0,_xlfn.XLOOKUP($E39,'DN07'!$O$30:$O$51,'DN07'!$N$30:$N$51,0)+IF(LEFT(F39,7)="3013522",-2,0))) | N39: =IF(N$9="","",IF($E39=0,0,_xlfn.XLOOKUP($E39,'DN08'!$O$30:$O$51,'DN08'!$N$30:$N$51,0)+IF(LEFT(G39,7)="3013522",-2,0))) | O39: =IF(O$9="","",IF($E39=0,0,_xlfn.XLOOKUP($E39,'DN09'!$O$30:$O$51,'DN09'!$N$30:$N$51,0)+IF(LEFT(H39,7)="3013522",-2,0))) | P39: =IF(P$9="","",IF($E39=0,0,_xlfn.XLOOKUP($E39,'DN10'!$O$30:$O$49,'DN10'!$N$30:$N$49,0)+IF(LEFT(I39,7)="3013522",-2,0))) | Q39: =IF(F39="","",SUM(G39:P39)*F39) -> 360
A40: DRY | B40: ITEM | D40: =D39+1 -> 31 | E40: 3013495 - Coke 355mL | F40: =IF(E40="","",VLOOKUP(E40,'DRY ITEM LIST'!B:F,5,0)) -> 3 | G40: =IF(G$9="","",IF($E40=0,0,_xlfn.XLOOKUP($E40,'DN01'!$O$30:$O$51,'DN01'!$N$30:$N$51,0)+IF(LEFT(E40,7)="3013522",-2,0))) -> 48 | H40: =IF(H$9="","",IF($E40=0,0,_xlfn.XLOOKUP($E40,'DN02'!$O$30:$O$51,'DN02'!$N$30:$N$51,0)+IF(LEFT(E40,7)="3013522",-2,0))) -> 0 | I40: =IF(I$9="","",IF($E40=0,0,_xlfn.XLOOKUP($E40,'DN03'!$O$30:$O$51,'DN03'!$N$30:$N$51,0)+IF(LEFT(E40,7)="3013522",-2,0))) -> 24 | J40: =IF(J$9="","",IF($E40=0,0,_xlfn.XLOOKUP($E40,'DN04'!$O$30:$O$51,'DN04'!$N$30:$N$51,0)+IF(LEFT(E40,7)="3013522",-2,0))) -> 0 | K40: =IF(K$9="","",IF($E40=0,0,_xlfn.XLOOKUP($E40,'DN05'!$O$30:$O$51,'DN05'!$N$30:$N$51,0)+IF(LEFT(E40,7)="3013522",-2,0))) | L40: =IF(L$9="","",IF($E40=0,0,_xlfn.XLOOKUP($E40,'DN06'!$O$30:$O$51,'DN06'!$N$30:$N$51,0)+IF(LEFT(E40,7)="3013522",-2,0))) | M40: =IF(M$9="","",IF($E40=0,0,_xlfn.XLOOKUP($E40,'DN07'!$O$30:$O$51,'DN07'!$N$30:$N$51,0)+IF(LEFT(F40,7)="3013522",-2,0))) | N40: =IF(N$9="","",IF($E40=0,0,_xlfn.XLOOKUP($E40,'DN08'!$O$30:$O$51,'DN08'!$N$30:$N$51,0)+IF(LEFT(G40,7)="3013522",-2,0))) | O40: =IF(O$9="","",IF($E40=0,0,_xlfn.XLOOKUP($E40,'DN09'!$O$30:$O$51,'DN09'!$N$30:$N$51,0)+IF(LEFT(H40,7)="3013522",-2,0))) | P40: =IF(P$9="","",IF($E40=0,0,_xlfn.XLOOKUP($E40,'DN10'!$O$30:$O$49,'DN10'!$N$30:$N$49,0)+IF(LEFT(I40,7)="3013522",-2,0))) | Q40: =IF(F40="","",SUM(G40:P40)*F40) -> 216 | W40: 21 | X40: 3013499 - Mineral Water 1.5L | Y40: 60 | Z40: 4 | AA40: 240
A41: DRY | B41: ITEM | D41: =D40+1 -> 32 | E41: 3013497 - Sprite 355mL | F41: =IF(E41="","",VLOOKUP(E41,'DRY ITEM LIST'!B:F,5,0)) -> 3 | G41: =IF(G$9="","",IF($E41=0,0,_xlfn.XLOOKUP($E41,'DN01'!$O$30:$O$51,'DN01'!$N$30:$N$51,0)+IF(LEFT(E41,7)="3013522",-2,0))) -> 48 | H41: =IF(H$9="","",IF($E41=0,0,_xlfn.XLOOKUP($E41,'DN02'!$O$30:$O$51,'DN02'!$N$30:$N$51,0)+IF(LEFT(E41,7)="3013522",-2,0))) -> 36 | I41: =IF(I$9="","",IF($E41=0,0,_xlfn.XLOOKUP($E41,'DN03'!$O$30:$O$51,'DN03'!$N$30:$N$51,0)+IF(LEFT(E41,7)="3013522",-2,0))) -> 0 | J41: =IF(J$9="","",IF($E41=0,0,_xlfn.XLOOKUP($E41,'DN04'!$O$30:$O$51,'DN04'!$N$30:$N$51,0)+IF(LEFT(E41,7)="3013522",-2,0))) -> 0 | K41: =IF(K$9="","",IF($E41=0,0,_xlfn.XLOOKUP($E41,'DN05'!$O$30:$O$51,'DN05'!$N$30:$N$51,0)+IF(LEFT(E41,7)="3013522",-2,0))) | L41: =IF(L$9="","",IF($E41=0,0,_xlfn.XLOOKUP($E41,'DN06'!$O$30:$O$51,'DN06'!$N$30:$N$51,0)+IF(LEFT(E41,7)="3013522",-2,0))) | M41: =IF(M$9="","",IF($E41=0,0,_xlfn.XLOOKUP($E41,'DN07'!$O$30:$O$51,'DN07'!$N$30:$N$51,0)+IF(LEFT(F41,7)="3013522",-2,0))) | N41: =IF(N$9="","",IF($E41=0,0,_xlfn.XLOOKUP($E41,'DN08'!$O$30:$O$51,'DN08'!$N$30:$N$51,0)+IF(LEFT(G41,7)="3013522",-2,0))) | O41: =IF(O$9="","",IF($E41=0,0,_xlfn.XLOOKUP($E41,'DN09'!$O$30:$O$51,'DN09'!$N$30:$N$51,0)+IF(LEFT(H41,7)="3013522",-2,0))) | P41: =IF(P$9="","",IF($E41=0,0,_xlfn.XLOOKUP($E41,'DN10'!$O$30:$O$49,'DN10'!$N$30:$N$49,0)+IF(LEFT(I41,7)="3013522",-2,0))) | Q41: =IF(F41="","",SUM(G41:P41)*F41) -> 252 | W41: 22 | X41: 3013498 - Mineral Water 330mL | Y41: 36 | Z41: 2 | AA41: 72
A42: DRY | B42: ITEM | D42: =D41+1 -> 33 | E42: 3013522 - Wet Ice 5kg Bag | F42: =IF(E42="","",VLOOKUP(E42,'DRY ITEM LIST'!B:F,5,0)) -> 5.5 | G42: =IF(G$9="","",IF($E42=0,0,_xlfn.XLOOKUP($E42,'DN01'!$O$30:$O$51,'DN01'!$N$30:$N$51,0)+IF(LEFT(E42,7)="3013522",-2,0))) -> 8 | H42: =IF(H$9="","",IF($E42=0,0,_xlfn.XLOOKUP($E42,'DN02'!$O$30:$O$51,'DN02'!$N$30:$N$51,0)+IF(LEFT(E42,7)="3013522",-2,0))) -> 8 | I42: =IF(I$9="","",IF($E42=0,0,_xlfn.XLOOKUP($E42,'DN03'!$O$30:$O$51,'DN03'!$N$30:$N$51,0)+IF(LEFT(E42,7)="3013522",-2,0))) -> 8 | J42: =IF(J$9="","",IF($E42=0,0,_xlfn.XLOOKUP($E42,'DN04'!$O$30:$O$51,'DN04'!$N$30:$N$51,0)+IF(LEFT(E42,7)="3013522",-2,0)))+10 -> 18 | K42: =IF(K$9="","",IF($E42=0,0,_xlfn.XLOOKUP($E42,'DN05'!$O$30:$O$51,'DN05'!$N$30:$N$51,0)+IF(LEFT(E42,7)="3013522",-2,0))) | L42: =IF(L$9="","",IF($E42=0,0,_xlfn.XLOOKUP($E42,'DN06'!$O$30:$O$51,'DN06'!$N$30:$N$51,0)+IF(LEFT(E42,7)="3013522",-2,0))) | M42: =IF(M$9="","",IF($E42=0,0,_xlfn.XLOOKUP($E42,'DN07'!$O$30:$O$51,'DN07'!$N$30:$N$51,0)+IF(LEFT(F42,7)="3013522",-2,0))) | N42: =IF(N$9="","",IF($E42=0,0,_xlfn.XLOOKUP($E42,'DN08'!$O$30:$O$51,'DN08'!$N$30:$N$51,0)+IF(LEFT(G42,7)="3013522",-2,0))) | O42: =IF(O$9="","",IF($E42=0,0,_xlfn.XLOOKUP($E42,'DN09'!$O$30:$O$51,'DN09'!$N$30:$N$51,0)+IF(LEFT(H42,7)="3013522",-2,0))) | P42: =IF(P$9="","",IF($E42=0,0,_xlfn.XLOOKUP($E42,'DN10'!$O$30:$O$49,'DN10'!$N$30:$N$49,0)+IF(LEFT(I42,7)="3013522",-2,0))) | Q42: =IF(F42="","",SUM(G42:P42)*F42) -> 231 | W42: 23 | X42: 3013495 - Coke 355mL | Y42: 48 | Z42: 3 | AA42: 144
...

Sheet DN01
A1: A/C TYPE | C1: STATION NAME | E1: DELIVERY NOTE | M1: DATE : | N1: 46164
E2: FLIGHT NO | G2: DEPARTURE TIME | I2: FROM | K2: TO | M2: SALES #
A3: B787-900 | C3: ATL | E3: ET519 | G3: 0.45138889 | I3: ATL | K3: ADD | M3: ="ET"&TEXT(N1,"YYYYMMDD") -> ET20260522
D5: Reg Meal | E5: Special Meal
A6: Meal count | B6: Business class: | D6: 20 | E6: 02 GFML
A7: Email | B7: Economy class: | D7: 231 | E7: 03 SPML, 01 LCML, 03 AVML, 01 FPML, 03 MOML, 01 DBML, 01 AVML BBML, 01 MOML BBML
I9: LCH/DNR | L9: HCP /SWH | N9: HBF
A10: SERVICE | F10: FINAL ORDER | I10: 1st SVC/leg | L10: 2nd SVC/ leg | N10: 3rd SVC/leg
B11: PRELIMINARY ORDER | I11: SPML | J11: BC | K11: EY | L11: BC | M11: EY | N11: BC | O11: EY
B12: BC | C12: EY | D12: CR | E12: CP | F12: BC | G12: EY | I12: {=_xlfn.LET(_xlpm.vBC,_xlfn.TEXTSPLIT(E6," ",", "),_xlpm.vEY,_xlfn.TEXTSPLIT(E7," ",", "),_xlpm.vML,_xlfn.UNIQUE(_xlfn.VSTACK(INDEX(_xlpm.vBC,,2),INDEX(_xlpm.vEY,,2))), CHOOSE({1,2,3},_xlpm.vML,VALUE(_xlfn.XLOOKUP(_xlpm.vML,INDEX(_xlpm.vBC,,2),INDEX(_xlpm.vBC,,1),0)),VALUE(_xlfn.XLOOKUP(_xlpm.vML,INDEX(_xlpm.vEY,,2),INDEX(_xlpm.vEY,,1),0))))} -> GFML | J12: 2 | K12: 0 | L12: =J12 -> 2 | M12: =K12 -> 0 | N12: =J12 -> 2 | O12: =K12 -> 0
A13: HBF | B13: =$D$6 -> 20 | C13: =$D$7 -> 231 | D13: 11 | E13: 3 | F13: =SUM(B13,D13:E13) -> 34 | G13: =C13 -> 231 | I13: SPML | J13: 0 | K13: 3 | L13: =J13 -> 0 | M13: =K13 -> 3 | N13: =J13 -> 0 | O13: =K13 -> 3
A14: LCH/DNR | B14: =$D$6 -> 20 | C14: =$D$7 -> 231 | D14: 11 | E14: 3 | F14: =SUM(B14,D14:E14) -> 34 | G14: =C14 -> 231 | I14: LCML | J14: 0 | K14: 1 | L14: =J14 -> 0 | M14: =K14 -> 1 | N14: =J14 -> 0 | O14: =K14 -> 1
A15: HLM | B15: 0 | C15: 0 | F15: 0 | G15: 0 | I15: AVML | J15: 0 | K15: 3 | L15: =J15 -> 0 | M15: =K15 -> 3 | N15: =J15 -> 0 | O15: =K15 -> 3
A16: HCP | B16: =$D$6 -> 20 | C16: 0 | D16: 11 | E16: 3 | F16: =SUM(B16,D16:E16) -> 34 | G16: 0 | I16: FPML | J16: 0 | K16: 1 | L16: =J16 -> 0 | M16: =K16 -> 1 | N16: =J16 -> 0 | O16: =K16 -> 1
A17: SWH | B17: 0 | C17: =$D$7 -> 231 | F17: 0 | G17: =C17 -> 231 | I17: MOML | J17: 0 | K17: 3 | L17: =J17 -> 0 | M17: =K17 -> 3 | N17: =J17 -> 0 | O17: =K17 -> 3
A18: CCP | B18: 0 | C18: 0 | I18: DBML | J18: 0 | K18: 1 | L18: =J18 -> 0 | M18: =K18 -> 1 | N18: =J18 -> 0 | O18: =K18 -> 1
A19: Eye opener | C19: 0 | I19: AVML BBML | J19: 0 | K19: 1 | L19: =J19 -> 0 | M19: =K19 -> 1 | N19: =J19 -> 0 | O19: =K19 -> 1
A20: Fasting Meals | I20: MOML BBML | J20: 0 | K20: 1 | L20: =J20 -> 0 | M20: =K20 -> 1 | N20: =J20 -> 0 | O20: =K20 -> 1
L21: =J21 -> 0 | M21: =K21 -> 0 | N21: =J21 -> 0 | O21: =K21 -> 0
L22: =J22 -> 0 | M22: =K22 -> 0 | N22: =J22 -> 0 | O22: =K22 -> 0
L23: =J23 -> 0 | M23: =K23 -> 0 | N23: =J23 -> 0 | O23: =K23 -> 0
L24: =J24 -> 0 | M24: =K24 -> 0 | N24: =J24 -> 0 | O24: =K24 -> 0
J25: =SUM(J12:J24) -> 2 | K25: =SUM(K12:K24) -> 14 | L25: =SUM(L12:L24) -> 2 | M25: =SUM(M12:M24) -> 14 | N25: =SUM(N12:N24) -> 2 | O25: =SUM(O12:O24) -> 14
A28: NO. | B28: DESCRIPTION | E28: PLAN | F28: AMOUNT | I28: DRY ITEM LIST
A29: 1 | B29: FRUIT BASKET | E29: 1 | F29: 0 | I29: NO. | J29: DESCRIPTION | M29: AMOUNT | N29: AMOUNT
A30: 2 | B30: CHEESE AND CRACKER | E30: 1 | F30: 1 | I30: 1 | J30: ORANGE JUICE | O30: 3013505 - Juice Orange 1L
A31: 3 | B31: FRESH ORANGE JUICE | E31: 1 | F31: 1 | I31: 2 | J31: APPLE JUICE | O31: 3013506 - Juice Apple 1L
A32: 4 | B32: BREAD BASKET | E32: 1 | F32: 1 | I32: 3 | J32: PINEAPLE JUICE | O32: 3013504 - Juice Pineapple 1L
A33: 5 | B33: Standard Uplift | E33: 1 | F33: 1 | I33: 4 | J33: TOMATO JUICE | O33: 3013507 - Juice Tomato 1L
A34: 6 | B34: LAUNDRY SERVICE | E34: 0.5 | F34: 0.5 | I34: 5 | J34: MINERAL WATER 1. L | N34: 100 | O34: 3013499 - Mineral Water 1.5L
A35: 7 | B35: HANDLING CHARGES | E35: 1 | F35: 1 | I35: 6 | J35: MINERAL WATER 0.5 L | N35: 72 | O35: 3013498 - Mineral Water 330mL
A36: 8 | B36: EXTRA VAN CHARGE | E36: 1 | F36: 1 | I36: 7 | J36: COCA COLA BOTTLE 1.5 L
A37: 9 | B37: INTERNATIONAL TRASH REMOVAL | E37: 1 | F37: 1 | I37: 8 | J37: COCA COLA CAN | N37: 48 | O37: 3013495 - Coke 355mL
A38: 10 | B38: Custom Clearance Charge | E38: 1 | F38: 1 | I38: 9 | J38: Sugar Sachet White | O38: =IF(J38="","",_xlfn.XLOOKUP(J38,'DRY ITEM LIST'!D:D,'DRY ITEM LIST'!B:B,"")) -> 3013509 - Sugar Sachet White
A39: 11 | I39: 10 | J39: SPRIT CAN | N39: 48 | O39: 3013497 - Sprite 355mL
A40: 12 | I40: 11 | J40: Wet Ice 5kg Bag | N40: 10 | O40: 3013522 - Wet Ice 5kg Bag
A41: 13 | I41: 12 | J41: Water 1.5 L
A42: 14 | I42: 13 | J42: Water 0.5 L
A43: 15 | I43: 14 | J43: Coke Light 355mL | N43: 24 | O43: =IF(J43="","",_xlfn.XLOOKUP(J43,'DRY ITEM LIST'!D:D,'DRY ITEM LIST'!B:B,"")) -> 3013496 - Coke Light 355mL
I44: 15 | J44: Creamer | O44: =IF(J44="","",_xlfn.XLOOKUP(J44,'DRY ITEM LIST'!D:D,'DRY ITEM LIST'!B:B,"")) -> 3013542 - Creamer
...

Sheet DN02
A1: A/C TYPE | C1: STATION NAME | E1: DELIVERY NOTE | M1: DATE : | N1: 46167
E2: FLIGHT NO | G2: DEPARTURE TIME | I2: FROM | K2: TO | M2: SALES #
A3: B787-900 | C3: ATL | E3: ET519 | G3: 0.45138889 | I3: ATL | K3: ADD | M3: ="ET"&TEXT(N1,"YYYYMMDD") -> ET20260525
D5: Reg Meal | E5: Special Meal
A6: Meal count | B6: Business class: | D6: 22 | E6: 01 CHML, 01 VGML, 01 KIDS
A7: Email | B7: Economy class: | D7: 239 | E7: 01 BBML, 07 MOML, 02 CHML, 01 SFML
I9: LCH/DNR | L9: HCP /SWH | N9: HBF
A10: SERVICE | F10: FINAL ORDER | I10: 1st SVC/leg | L10: 2nd SVC/ leg | N10: 3rd SVC/leg
B11: PRELIMINARY ORDER | I11: SPML | J11: BC | K11: EY | L11: BC | M11: EY | N11: BC | O11: EY
B12: BC | C12: EY | D12: CR | E12: CP | F12: BC | G12: EY | I12: {=_xlfn.LET(_xlpm.vBC,_xlfn.TEXTSPLIT(E6," ",", "),_xlpm.vEY,_xlfn.TEXTSPLIT(E7," ",", "),_xlpm.vML,_xlfn.UNIQUE(_xlfn.VSTACK(INDEX(_xlpm.vBC,,2),INDEX(_xlpm.vEY,,2))), CHOOSE({1,2,3},_xlpm.vML,VALUE(_xlfn.XLOOKUP(_xlpm.vML,INDEX(_xlpm.vBC,,2),INDEX(_xlpm.vBC,,1),0)),VALUE(_xlfn.XLOOKUP(_xlpm.vML,INDEX(_xlpm.vEY,,2),INDEX(_xlpm.vEY,,1),0))))} -> CHML | J12: 1 | K12: 2 | L12: =J12 -> 1 | M12: =K12 -> 2 | N12: =J12 -> 1 | O12: =K12 -> 2
A13: HBF | B13: =$D$6 -> 22 | C13: =$D$7 -> 239 | D13: 11 | E13: 3 | F13: =SUM(B13,D13:E13) -> 36 | G13: =C13 -> 239 | I13: VGML | J13: 1 | K13: 0 | L13: =J13 -> 1 | M13: =K13 -> 0 | N13: =J13 -> 1 | O13: =K13 -> 0
A14: LCH/DNR | B14: =$D$6 -> 22 | C14: =$D$7 -> 239 | D14: 11 | E14: 3 | F14: =SUM(B14,D14:E14) -> 36 | G14: =C14 -> 239 | I14: KIDS | J14: 1 | K14: 0 | L14: =J14 -> 1 | M14: =K14 -> 0 | N14: =J14 -> 1 | O14: =K14 -> 0
A15: HLM | B15: 0 | C15: 0 | F15: 0 | G15: 0 | I15: BBML | J15: 0 | K15: 1 | L15: =J15 -> 0 | M15: =K15 -> 1 | N15: =J15 -> 0 | O15: =K15 -> 1
A16: HCP | B16: =$D$6 -> 22 | C16: 0 | D16: 11 | E16: 3 | F16: =SUM(B16,D16:E16) -> 36 | G16: 0 | I16: MOML | J16: 0 | K16: 7 | L16: =J16 -> 0 | M16: =K16 -> 7 | N16: =J16 -> 0 | O16: =K16 -> 7
A17: SWH | B17: 0 | C17: =$D$7 -> 239 | F17: 0 | G17: =C17 -> 239 | I17: SFML | J17: 0 | K17: 1 | L17: =J17 -> 0 | M17: =K17 -> 1 | N17: =J17 -> 0 | O17: =K17 -> 1
A18: CCP | B18: 0 | C18: 0 | L18: =J18 -> 0 | M18: =K18 -> 0 | N18: =J18 -> 0 | O18: =K18 -> 0
A19: Eye opener | C19: 0 | L19: =J19 -> 0 | M19: =K19 -> 0 | N19: =J19 -> 0 | O19: =K19 -> 0
A20: Fasting Meals | L20: =J20 -> 0 | M20: =K20 -> 0 | N20: =J20 -> 0 | O20: =K20 -> 0
L21: =J21 -> 0 | M21: =K21 -> 0 | N21: =J21 -> 0 | O21: =K21 -> 0
L22: =J22 -> 0 | M22: =K22 -> 0 | N22: =J22 -> 0 | O22: =K22 -> 0
L23: =J23 -> 0 | M23: =K23 -> 0 | N23: =J23 -> 0 | O23: =K23 -> 0
L24: =J24 -> 0 | M24: =K24 -> 0 | N24: =J24 -> 0 | O24: =K24 -> 0
J25: =SUM(J12:J24) -> 3 | K25: =SUM(K12:K24) -> 11 | L25: =SUM(L12:L24) -> 3 | M25: =SUM(M12:M24) -> 11 | N25: =SUM(N12:N24) -> 3 | O25: =SUM(O12:O24) -> 11
A28: NO. | B28: DESCRIPTION | E28: PLAN | F28: AMOUNT | I28: DRY ITEM LIST
A29: 1 | B29: FRUIT BASKET | E29: 1 | F29: 0 | I29: NO. | J29: DESCRIPTION | M29: AMOUNT | N29: AMOUNT
A30: 2 | B30: CHEESE AND CRACKER | E30: 1 | F30: 2 | I30: 1 | J30: ORANGE JUICE | N30: 2 | O30: 3013505 - Juice Orange 1L
A31: 3 | B31: FRESH ORANGE JUICE | E31: 1 | F31: 1 | I31: 2 | J31: APPLE JUICE | N31: 16 | O31: 3013506 - Juice Apple 1L
A32: 4 | B32: BREAD BASKET | E32: 1 | F32: 2 | I32: 3 | J32: PINEAPLE JUICE | O32: 3013504 - Juice Pineapple 1L
A33: 5 | B33: Standard Uplift | E33: 1 | F33: 1 | I33: 4 | J33: TOMATO JUICE | O33: 3013507 - Juice Tomato 1L
A34: 6 | B34: LAUNDRY SERVICE | E34: 0.5 | F34: 0.5 | I34: 5 | J34: MINERAL WATER 1. L | N34: 36 | O34: 3013499 - Mineral Water 1.5L
A35: 7 | B35: HANDLING CHARGES | E35: 1 | F35: 1 | I35: 6 | J35: MINERAL WATER 0.5 L | N35: 48 | O35: 3013498 - Mineral Water 330mL
A36: 8 | B36: EXTRA VAN CHARGE | E36: 1 | F36: 1 | I36: 7 | J36: COCA COLA BOTTLE 1.5 L
A37: 9 | B37: INTERNATIONAL TRASH REMOVAL | E37: 1 | F37: 1 | I37: 8 | J37: COCA COLA CAN | O37: 3013495 - Coke 355mL
A38: 10 | B38: Custom Clearance Charge | E38: 1 | F38: 1 | I38: 9 | J38: Coke Light 355mL | O38: =IF(J38="","",_xlfn.XLOOKUP(J38,'DRY ITEM LIST'!D:D,'DRY ITEM LIST'!B:B,"")) -> 3013496 - Coke Light 355mL
A39: 11 | I39: 10 | J39: SPRIT CAN | N39: 36 | O39: 3013497 - Sprite 355mL
A40: 12 | I40: 11 | J40: Wet Ice 5kg Bag | N40: 10 | O40: 3013522 - Wet Ice 5kg Bag
A41: 13 | I41: 12 | J41: Water 1.5 L
A42: 14 | I42: 13 | J42: Water 0.5 L
A43: 15 | I43: 14 | J43: Fruit Platters | N43: =42/3 -> 14 | O43: =IF(J43="","",_xlfn.XLOOKUP(J43,'DRY ITEM LIST'!D:D,'DRY ITEM LIST'!B:B,"")) -> 3013538 - Fruit Platters
I44: 15 | J44: Ginger Ale 355mL | O44: =IF(J44="","",_xlfn.XLOOKUP(J44,'DRY ITEM LIST'!D:D,'DRY ITEM LIST'!B:B,"")) -> 3013540 - Ginger Ale 355mL
...

Sheet DN03
A1: A/C TYPE | C1: STATION NAME | E1: DELIVERY NOTE | M1: DATE : | N1: 46169
E2: FLIGHT NO | G2: DEPARTURE TIME | I2: FROM | K2: TO | M2: SALES #
A3: B787-900 | C3: ATL | E3: ET519 | G3: 0.45138889 | I3: ATL | K3: ADD | M3: ="ET"&TEXT(N1,"YYYYMMDD") -> ET20260527
D5: Reg Meal | E5: Special Meal
A6: Meal count | B6: Business class: | D6: 20 | E6: 00 SFML
A7: Email | B7: Economy class: | D7: 225 | E7: 01 LFML 02 VLML, 01 SFML, 01 VGML, 03 AVML, 03 FPML, 01 KSML, 01 HNML, 01 CHML, 01 GFML
I9: LCH/DNR | L9: HCP /SWH | N9: HBF
A10: SERVICE | F10: FINAL ORDER | I10: 1st SVC/leg | L10: 2nd SVC/ leg | N10: 3rd SVC/leg
B11: PRELIMINARY ORDER | I11: SPML | J11: BC | K11: EY | L11: BC | M11: EY | N11: BC | O11: EY
B12: BC | C12: EY | D12: CR | E12: CP | F12: BC | G12: EY | I12: {=_xlfn.LET(_xlpm.vBC,_xlfn.TEXTSPLIT(E6," ",", "),_xlpm.vEY,_xlfn.TEXTSPLIT(E7," ",", "),_xlpm.vML,_xlfn.UNIQUE(_xlfn.VSTACK(INDEX(_xlpm.vBC,,2),INDEX(_xlpm.vEY,,2))), CHOOSE({1,2,3},_xlpm.vML,VALUE(_xlfn.XLOOKUP(_xlpm.vML,INDEX(_xlpm.vBC,,2),INDEX(_xlpm.vBC,,1),0)),VALUE(_xlfn.XLOOKUP(_xlpm.vML,INDEX(_xlpm.vEY,,2),INDEX(_xlpm.vEY,,1),0))))} -> SFML | J12: 0 | K12: 1 | L12: =J12 -> 0 | M12: =K12 -> 1 | N12: =J12 -> 0 | O12: =K12 -> 1
A13: HBF | B13: =D6 -> 20 | C13: =$D$7 -> 225 | D13: 11 | E13: 5 | F13: =SUM(B13,D13:E13) -> 36 | G13: =C13 -> 225 | I13: LFML | J13: 0 | K13: 1 | L13: =J13 -> 0 | M13: =K13 -> 1 | N13: =J13 -> 0 | O13: =K13 -> 1
A14: LCH/DNR | B14: =D6 -> 20 | C14: =$D$7 -> 225 | D14: 11 | E14: 5 | F14: =SUM(B14,D14:E14) -> 36 | G14: =C14 -> 225 | I14: VGML | J14: 0 | K14: 1 | L14: =J14 -> 0 | M14: =K14 -> 1 | N14: =J14 -> 0 | O14: =K14 -> 1
A15: HLM | B15: 0 | C15: 0 | F15: 0 | G15: 0 | I15: AVML | J15: 0 | K15: 3 | L15: =J15 -> 0 | M15: =K15 -> 3 | N15: =J15 -> 0 | O15: =K15 -> 3
A16: HCP | B16: =D6 -> 20 | C16: 0 | D16: 11 | E16: 5 | F16: =SUM(B16,D16:E16) -> 36 | G16: 0 | I16: FPML | J16: 0 | K16: 3 | L16: =J16 -> 0 | M16: =K16 -> 3 | N16: =J16 -> 0 | O16: =K16 -> 3
A17: SWH | B17: 0 | C17: =$D$7 -> 225 | F17: 0 | G17: =C17 -> 225 | I17: KSML | J17: 0 | K17: 1 | L17: =J17 -> 0 | M17: =K17 -> 1 | N17: =J17 -> 0 | O17: =K17 -> 1
A18: CCP | B18: 0 | C18: 0 | I18: HNML | J18: 0 | K18: 1 | L18: =J18 -> 0 | M18: =K18 -> 1 | N18: =J18 -> 0 | O18: =K18 -> 1
A19: Eye opener | C19: 0 | I19: CHML | J19: 0 | K19: 1 | L19: =J19 -> 0 | M19: =K19 -> 1 | N19: =J19 -> 0 | O19: =K19 -> 1
A20: Fasting Meals | I20: GFML | J20: 0 | K20: 1 | L20: =J20 -> 0 | M20: =K20 -> 1 | N20: =J20 -> 0 | O20: =K20 -> 1
I21: VLML | J21: 0 | K21: 2 | L21: =J21 -> 0 | M21: =K21 -> 2 | N21: =J21 -> 0 | O21: =K21 -> 2
L22: =J22 -> 0 | M22: =K22 -> 0 | N22: =J22 -> 0 | O22: =K22 -> 0
L23: =J23 -> 0 | M23: =K23 -> 0 | N23: =J23 -> 0 | O23: =K23 -> 0
L24: =J24 -> 0 | M24: =K24 -> 0 | N24: =J24 -> 0 | O24: =K24 -> 0
J25: =SUM(J12:J24) -> 0 | K25: =SUM(K12:K24) -> 15 | L25: =SUM(L12:L24) -> 0 | M25: =SUM(M12:M24) -> 15 | N25: =SUM(N12:N24) -> 0 | O25: =SUM(O12:O24) -> 15
A28: NO. | B28: DESCRIPTION | E28: PLAN | F28: AMOUNT | I28: DRY ITEM LIST
A29: 1 | B29: FRUIT BASKET | E29: 1 | F29: 0 | I29: NO. | J29: DESCRIPTION | M29: AMOUNT | N29: AMOUNT
A30: 2 | B30: CHEESE AND CRACKER | E30: 1 | F30: 2 | I30: 1 | J30: ORANGE JUICE | N30: 6 | O30: 3013505 - Juice Orange 1L
A31: 3 | B31: FRESH ORANGE JUICE | E31: 1 | F31: 3 | I31: 2 | J31: APPLE JUICE | N31: 0 | O31: 3013506 - Juice Apple 1L
A32: 4 | B32: BREAD BASKET | E32: 1 | F32: 2 | I32: 3 | J32: PINEAPLE JUICE | O32: 3013504 - Juice Pineapple 1L
A33: 5 | B33: Standard Uplift | E33: 1 | F33: 1 | I33: 4 | J33: TOMATO JUICE | O33: 3013507 - Juice Tomato 1L
A34: 6 | B34: LAUNDRY SERVICE | E34: 0.5 | F34: 0.5 | I34: 5 | J34: MINERAL WATER 1.5 L | N34: 48 | O34: 3013499 - Mineral Water 1.5L
A35: 7 | B35: HANDLING CHARGES | E35: 1 | F35: 1 | I35: 6 | J35: MINERAL WATER 0.5 L | N35: 24 | O35: 3013498 - Mineral Water 330mL
A36: 8 | B36: EXTRA VAN CHARGE | E36: 1 | F36: 1 | I36: 7 | J36: COCA COLA BOTTLE 1.5 L
A37: 9 | B37: INTERNATIONAL TRASH REMOVAL | E37: 1 | F37: 1 | I37: 8 | J37: COCA COLA CAN | N37: 24 | O37: 3013495 - Coke 355mL
A38: 10 | B38: Custom Clearance Charge | E38: 1 | F38: 1 | I38: 9 | J38: SPRIT BOTTLE 1.5 L | O38: =IF(J38="","",_xlfn.XLOOKUP(J38,'DRY ITEM LIST'!D:D,'DRY ITEM LIST'!B:B,""))
A39: 11 | I39: 10 | J39: SPRIT CAN | O39: 3013497 - Sprite 355mL
A40: 12 | I40: 11 | J40: Wet Ice 5kg Bag | N40: 10 | O40: 3013522 - Wet Ice 5kg Bag
A41: 13 | I41: 12 | J41: Tonic Water 355mL | N41: 12 | O41: =IF(J41="","",_xlfn.XLOOKUP(J41,'DRY ITEM LIST'!D:D,'DRY ITEM LIST'!B:B,"")) -> 3013503 - Tonic Water 355mL
A42: 14 | I42: 13 | J42: Toilet Paper | O42: =IF(J42="","",_xlfn.XLOOKUP(J42,'DRY ITEM LIST'!D:D,'DRY ITEM LIST'!B:B,""))
A43: 15 | I43: 14 | J43: Sparkling Water | N43: 12 | O43: =IF(J43="","",_xlfn.XLOOKUP(J43,'DRY ITEM LIST'!D:D,'DRY ITEM LIST'!B:B,"")) -> 3013541 - Sparkling Water
I44: 15 | J44: Fruit Platters | N44: =40/3 -> 13.333333 | O44: =IF(J44="","",_xlfn.XLOOKUP(J44,'DRY ITEM LIST'!D:D,'DRY ITEM LIST'!B:B,"")) -> 3013538 - Fruit Platters
...

Sheet DN04
A1: A/C TYPE | C1: STATION NAME | E1: DELIVERY NOTE | M1: DATE : | N1: 46171
E2: FLIGHT NO | G2: DEPARTURE TIME | I2: FROM | K2: TO | M2: SALES #
A3: B787-900 | C3: ATL | E3: ET519 | G3: 0.45138889 | I3: ATL | K3: ADD | M3: ="ET"&TEXT(N1,"YYYYMMDD") -> ET20260529
D5: Reg Meal | E5: Special Meal
A6: Meal count | B6: Business class: | D6: 22 | E6: 01 AVML
A7: Email | B7: Economy class: | D7: 222 | E7: 01 MOML , 02 CHML
I9: LCH/DNR | L9: HCP /SWH | N9: HBF
A10: SERVICE | F10: FINAL ORDER | I10: 1st SVC/leg | L10: 2nd SVC/ leg | N10: 3rd SVC/leg
B11: PRELIMINARY ORDER | I11: SPML | J11: BC | K11: EY | L11: BC | M11: EY | N11: BC | O11: EY
B12: BC | C12: EY | D12: CR | E12: CP | F12: BC | G12: EY | I12: {=_xlfn.LET(_xlpm.vBC,_xlfn.TEXTSPLIT(E6," ",", "),_xlpm.vEY,_xlfn.TEXTSPLIT(E7," ",", "),_xlpm.vML,_xlfn.UNIQUE(_xlfn.VSTACK(INDEX(_xlpm.vBC,,2),INDEX(_xlpm.vEY,,2))), CHOOSE({1,2,3},_xlpm.vML,VALUE(_xlfn.XLOOKUP(_xlpm.vML,INDEX(_xlpm.vBC,,2),INDEX(_xlpm.vBC,,1),0)),VALUE(_xlfn.XLOOKUP(_xlpm.vML,INDEX(_xlpm.vEY,,2),INDEX(_xlpm.vEY,,1),0))))} -> AVML | J12: 1 | K12: 0 | L12: =J12 -> 1 | M12: =K12 -> 0 | N12: =J12 -> 1 | O12: =K12 -> 0
A13: HBF | B13: =$D$6 -> 22 | C13: =$D$7 -> 222 | D13: 11 | E13: 5 | F13: =SUM(B13,D13:E13) -> 38 | G13: =C13 -> 222 | I13: MOML | J13: 0 | K13: 1 | L13: =J13 -> 0 | M13: =K13 -> 1 | N13: =J13 -> 0 | O13: =K13 -> 1
A14: LCH/DNR | B14: =$D$6 -> 22 | C14: =$D$7 -> 222 | D14: 11 | E14: 5 | F14: =SUM(B14,D14:E14) -> 38 | G14: =C14 -> 222 | I14: CHML | J14: 0 | K14: 2 | L14: =J14 -> 0 | M14: =K14 -> 2 | N14: =J14 -> 0 | O14: =K14 -> 2
A15: HLM | B15: 0 | C15: 0 | F15: 0 | G15: 0 | L15: =J15 -> 0 | M15: =K15 -> 0 | N15: =J15 -> 0 | O15: =K15 -> 0
A16: HCP | B16: =$D$6 -> 22 | C16: 0 | D16: 11 | E16: 5 | F16: =SUM(B16,D16:E16) -> 38 | G16: 0 | L16: =J16 -> 0 | M16: =K16 -> 0 | N16: =J16 -> 0 | O16: =K16 -> 0
A17: SWH | B17: 0 | C17: =$D$7 -> 222 | F17: 0 | G17: =C17 -> 222 | L17: =J17 -> 0 | M17: =K17 -> 0 | N17: =J17 -> 0 | O17: =K17 -> 0
A18: CCP | B18: 0 | C18: 0 | L18: =J18 -> 0 | M18: =K18 -> 0 | N18: =J18 -> 0 | O18: =K18 -> 0
A19: Eye opener | C19: 0 | L19: =J19 -> 0 | M19: =K19 -> 0 | N19: =J19 -> 0 | O19: =K19 -> 0
A20: Fasting | L20: =J20 -> 0 | M20: =K20 -> 0 | N20: =J20 -> 0 | O20: =K20 -> 0
L21: =J21 -> 0 | M21: =K21 -> 0 | N21: =J21 -> 0 | O21: =K21 -> 0
L22: =J22 -> 0 | M22: =K22 -> 0 | N22: =J22 -> 0 | O22: =K22 -> 0
L23: =J23 -> 0 | M23: =K23 -> 0 | N23: =J23 -> 0 | O23: =K23 -> 0
L24: =J24 -> 0 | M24: =K24 -> 0 | N24: =J24 -> 0 | O24: =K24 -> 0
J25: =SUM(J12:J24) -> 1 | K25: =SUM(K12:K24) -> 3 | L25: =SUM(L12:L24) -> 1 | M25: =SUM(M12:M24) -> 3 | N25: =SUM(N12:N24) -> 1 | O25: =SUM(O12:O24) -> 3
A28: NO. | B28: DESCRIPTION | E28: PLAN | F28: AMOUNT | I28: DRY ITEM LIST
A29: 1 | B29: FRUIT BASKET | E29: 1 | F29: 0 | I29: NO. | J29: DESCRIPTION | M29: AMOUNT | N29: AMOUNT
A30: 2 | B30: CHEESE AND CRACKER | E30: 1 | F30: 2 | I30: 1 | J30: ORANGE JUICE | N30: 2 | O30: 3013505 - Juice Orange 1L
A31: 3 | B31: FRESH ORANGE JUICE | E31: 1 | F31: 1 | I31: 2 | J31: APPLE JUICE | N31: 12 | O31: 3013506 - Juice Apple 1L
A32: 4 | B32: BREAD BASKET | E32: 1 | F32: 1 | I32: 3 | J32: PINEAPLE JUICE | O32: 3013504 - Juice Pineapple 1L
A33: 5 | B33: Standard Uplift | E33: 1 | F33: 1 | I33: 4 | J33: TOMATO JUICE | O33: 3013507 - Juice Tomato 1L
A34: 6 | B34: LAUNDRY SERVICE | E34: 0.5 | F34: 0.5 | I34: 5 | J34: MINERAL WATER 1.5 L | N34: 90 | O34: 3013499 - Mineral Water 1.5L
A35: 7 | B35: HANDLING CHARGES | E35: 1 | F35: 1 | I35: 6 | J35: MINERAL WATER 0.5 L | N35: 36 | O35: 3013498 - Mineral Water 330mL
A36: 8 | B36: EXTRA VAN CHARGE | E36: 1 | F36: 1 | I36: 7 | J36: COCA COLA BOTTLE 1.5 L
A37: 9 | B37: INTERNATIONAL TRASH REMOVAL | E37: 1 | F37: 1 | I37: 8 | J37: COCA COLA CAN | O37: 3013495 - Coke 355mL
A38: 10 | B38: Custom Clearance Charge | E38: 1 | F38: 1 | I38: 9 | J38: SPRIT BOTTLE 1.5 L | O38: =IF(J38="","",_xlfn.XLOOKUP(J38,'DRY ITEM LIST'!D:D,'DRY ITEM LIST'!B:B,""))
A39: 11 | I39: 10 | J39: SPRIT CAN | O39: 3013497 - Sprite 355mL
A40: 12 | I40: 11 | J40: Wet Ice 5kg Bag | N40: 10 | O40: 3013522 - Wet Ice 5kg Bag
A41: 13 | I41: 12 | J41: Water 1.5 L
A42: 14 | I42: 13 | J42: Water 0.5 L
A43: 15 | I43: 14 | J43: Ginger Ale 355mL | N43: 36 | O43: =IF(J43="","",_xlfn.XLOOKUP(J43,'DRY ITEM LIST'!D:D,'DRY ITEM LIST'!B:B,"")) -> 3013540 - Ginger Ale 355mL
I44: 15 | J44: Fruit Platters | N44: =38/3 -> 12.666667 | O44: =IF(J44="","",_xlfn.XLOOKUP(J44,'DRY ITEM LIST'!D:D,'DRY ITEM LIST'!B:B,"")) -> 3013538 - Fruit Platters
...

Sheet DN05
A1: A/C TYPE | C1: STATION NAME | E1: DELIVERY NOTE | M1: DATE :
E2: FLIGHT NO | G2: DEPARTURE TIME | I2: FROM | K2: TO | M2: SALES #
A3: B787-900 | C3: ATL | E3: ET519 | G3: 0.45138889 | I3: ATL | K3: ADD | M3: ="ET"&TEXT(N1,"YYYYMMDD") -> ET19000100
D5: Reg Meal | E5: Special Meal
A6: Meal count | B6: Business class: | D6: 15 | E6: 00 VGML
A7: Email | B7: Economy class: | D7: 65 | E7: 01 KSML, 01 AVML
I9: LCH/DNR | L9: HCP /SWH | N9: HBF
A10: SERVICE | F10: FINAL ORDER | I10: 1st SVC/leg | L10: 2nd SVC/ leg | N10: 3rd SVC/leg
B11: PRELIMINARY ORDER | I11: SPML | J11: BC | K11: EY | L11: BC | M11: EY | N11: BC | O11: EY
B12: BC | C12: EY | D12: CR | E12: CP | F12: BC | G12: EY | I12: {=_xlfn.LET(_xlpm.vBC,_xlfn.TEXTSPLIT(E6," ",", "),_xlpm.vEY,_xlfn.TEXTSPLIT(E7," ",", "),_xlpm.vML,_xlfn.UNIQUE(_xlfn.VSTACK(INDEX(_xlpm.vBC,,2),INDEX(_xlpm.vEY,,2))), CHOOSE({1,2,3},_xlpm.vML,VALUE(_xlfn.XLOOKUP(_xlpm.vML,INDEX(_xlpm.vBC,,2),INDEX(_xlpm.vBC,,1),0)),VALUE(_xlfn.XLOOKUP(_xlpm.vML,INDEX(_xlpm.vEY,,2),INDEX(_xlpm.vEY,,1),0))))} -> VGML | J12: 0 | K12: 0 | L12: =J12 -> 0 | M12: =K12 -> 0 | N12: =J12 -> 0 | O12: =K12 -> 0
A13: HBF | B13: =$D$6 -> 15 | C13: =$D$7 -> 65 | D13: 14 | E13: 3 | F13: =SUM(B13,D13:E13) -> 32 | G13: =C13 -> 65 | I13: KSML | J13: 0 | K13: 1 | L13: =J13 -> 0 | M13: =K13 -> 1 | N13: =J13 -> 0 | O13: =K13 -> 1
A14: LCH/DNR | B14: =$D$6 -> 15 | C14: =$D$7 -> 65 | D14: 14 | E14: 3 | F14: =SUM(B14,D14:E14) -> 32 | G14: =C14 -> 65 | I14: AVML | J14: 0 | K14: 1 | L14: =J14 -> 0 | M14: =K14 -> 1 | N14: =J14 -> 0 | O14: =K14 -> 1
A15: HLM | B15: 0 | C15: 0 | F15: 0 | G15: 0 | L15: =J15 -> 0 | M15: =K15 -> 0 | N15: =J15 -> 0 | O15: =K15 -> 0
A16: HCP | B16: =$D$6 -> 15 | C16: 0 | D16: 14 | E16: 3 | F16: =SUM(B16,D16:E16) -> 32 | G16: 0 | L16: =J16 -> 0 | M16: =K16 -> 0 | N16: =J16 -> 0 | O16: =K16 -> 0
A17: SWH | B17: 0 | C17: =$D$7 -> 65 | F17: 0 | G17: =C17 -> 65 | L17: =J17 -> 0 | M17: =K17 -> 0 | N17: =J17 -> 0 | O17: =K17 -> 0
A18: CCP | B18: 0 | C18: 0 | L18: =J18 -> 0 | M18: =K18 -> 0 | N18: =J18 -> 0 | O18: =K18 -> 0
A19: Eye opener | C19: 0 | L19: =J19 -> 0 | M19: =K19 -> 0 | N19: =J19 -> 0 | O19: =K19 -> 0
A20: Fasting Meals | L20: =J20 -> 0 | M20: =K20 -> 0 | N20: =J20 -> 0 | O20: =K20 -> 0
L21: =J21 -> 0 | M21: =K21 -> 0 | N21: =J21 -> 0 | O21: =K21 -> 0
L22: =J22 -> 0 | M22: =K22 -> 0 | N22: =J22 -> 0 | O22: =K22 -> 0
L23: =J23 -> 0 | M23: =K23 -> 0 | N23: =J23 -> 0 | O23: =K23 -> 0
L24: =J24 -> 0 | M24: =K24 -> 0 | N24: =J24 -> 0 | O24: =K24 -> 0
J25: =SUM(J12:J24) -> 0 | K25: =SUM(K12:K24) -> 2 | L25: =SUM(L12:L24) -> 0 | M25: =SUM(M12:M24) -> 2 | N25: =SUM(N12:N24) -> 0 | O25: =SUM(O12:O24) -> 2
A28: NO. | B28: DESCRIPTION | E28: PLAN | F28: AMOUNT | I28: DRY ITEM LIST
A29: 1 | B29: FRUIT BASKET | E29: 1 | F29: 1 | I29: NO. | J29: DESCRIPTION | M29: AMOUNT | N29: AMOUNT
A30: 2 | B30: CHEESE AND CRACKER | E30: 1 | F30: 2 | I30: 1 | J30: ORANGE JUICE | N30: 3 | O30: 3013505 - Juice Orange 1L
A31: 3 | B31: FRESH ORANGE JUICE | E31: 1 | F31: 3 | I31: 2 | J31: APPLE JUICE | O31: 3013506 - Juice Apple 1L
A32: 4 | B32: BREAD BASKET | E32: 1 | F32: 2 | I32: 3 | J32: PINEAPLE JUICE | O32: 3013504 - Juice Pineapple 1L
A33: 5 | B33: Standard Uplift | E33: 1 | F33: 1 | I33: 4 | J33: TOMATO JUICE | O33: 3013507 - Juice Tomato 1L
A34: 6 | B34: LAUNDRY SERVICE | E34: 0.5 | F34: 0.5 | I34: 5 | J34: MINERAL WATER 1.5 L | N34: 42 | O34: 3013499 - Mineral Water 1.5L
A35: 7 | B35: HANDLING CHARGES | E35: 1 | F35: 1 | I35: 6 | J35: MINERAL WATER 0.5 L | N35: 24 | O35: 3013498 - Mineral Water 330mL
A36: 8 | B36: EXTRA VAN CHARGE | E36: 1 | F36: 1 | I36: 7 | J36: COCA COLA BOTTLE 1.5 L
A37: 9 | I37: 8 | J37: COCA COLA CAN | O37: 3013495 - Coke 355mL
A38: 10 | I38: 9 | J38: Sugar Sachet White | O38: =IF(J38="","",_xlfn.XLOOKUP(J38,'DRY ITEM LIST'!D:D,'DRY ITEM LIST'!B:B,"")) -> 3013509 - Sugar Sachet White
A39: 11 | I39: 10 | J39: SPRIT CAN | O39: 3013497 - Sprite 355mL
A40: 12 | I40: 11 | J40: Wet Ice 5kg Bag | N40: 10 | O40: 3013522 - Wet Ice 5kg Bag
A41: 13 | I41: 12 | J41: Fruit Platters | N41: =35/3 -> 11.666667 | O41: =IF(J41="","",_xlfn.XLOOKUP(J41,'DRY ITEM LIST'!D:D,'DRY ITEM LIST'!B:B,"")) -> 3013538 - Fruit Platters
I42: 13 | J42: Ginger Ale 355mL | N42: 12 | O42: =IF(J42="","",_xlfn.XLOOKUP(J42,'DRY ITEM LIST'!D:D,'DRY ITEM LIST'!B:B,"")) -> 3013540 - Ginger Ale 355mL
I43: 14 | J43: Soda Water 355L | O43: =IF(J43="","",_xlfn.XLOOKUP(J43,'DRY ITEM LIST'!D:D,'DRY ITEM LIST'!B:B,"")) -> 3013502 - Soda Water 355L
